Workbook

Sheet Curs, Seminar
C2: Mecanica Teoretică. Anul de studii: Titular: Grupa: Șeful grupei: Nume, Prenume, telefon | AA2: Nota semestrială | AD2: Ev.finală (0.5) | AE2: Nota finală | AI2: Examen:
E3: Curs | L3: Seminar | U3: Sesiunea | AA3: Componente | AC3: Media trunchiată (0.5) | AE3: în sist.național, trunchiată | AG3: Conform ECTS | AI3: Borderou | AJ3: Prezenti | AK3: Admisi | AL3: Eliberati | AN3: A | AO3: B | AP3: C | AQ3: D | AR3: E | AS3: FX | AT3: F | AU3: n/p | AV3: n/a | AX3: Reușita din nr. total, % | AY3: Reușita din nr. prez., %
E4: C1 | F4: C2 | G4: C3 | H4: C4 | I4: C5 | J4: C6 | K4: Ore absențe Curs | L4: S1 | M4: S2 | N4: S3 | O4: S4 | P4: S5 | Q4: S6 | R4: Ore absențe Sem | S4: Ore absențe total | U4: Examen | V4: Reexam | W4: Puncte activ. suplim | X4: Puncte utilizate | Y4: Exam | AA4: Evaluarea curentă | AB4: Lucrul individual
B5: Nr. | C5: Nume, Prenume | D5: e-mail | S5: Frecventa | Y5: Prezenta | Z5: Eliberati | AI5: =COUNTA(C6:C105) -> 1 | AJ5: =AI5-COUNTIFS(B6:B105,">0",Y6:Y105,"a") -> 1 | AK5: =AI5-COUNTIF(AD6:AD105,"n/a") -> 0 | AL5: =COUNTA(Z6:Z105) -> 0 | AN5: =COUNTIF($AG$6:$AG$105,AN3) -> 0 | AO5: =COUNTIF($AG$6:$AG$105,AO3) -> 0 | AP5: =COUNTIF($AG$6:$AG$105,AP3) -> 0 | AQ5: =COUNTIF($AG$6:$AG$105,AQ3) -> 0 | AR5: =COUNTIF($AG$6:$AG$105,AR3) -> 0 | AS5: =COUNTIF($AG$6:$AG$105,AS3) -> 0 | AT5: =COUNTIF($AG$6:$AG$105,AT3) -> 0 | AU5: =COUNTIF($AD$6:$AD$105,AU3) -> 0 | AV5: =COUNTIF($AD$6:$AD$105,AV3) -> 1 | AX5: =SUM(AN5:AR5)/AI5 -> 0 | AY5: =SUM(AN5:AR5)/AJ5 -> 0
B6: =IF(NOT(ISBLANK(C6)),COUNTA($C$6:C6),"") -> 1 | C6: Nume, Prenume | R6: =IF(NOT(ISBLANK(C6)),IF(COUNTIF(E6:Q6,"a")<>0,COUNTIF(E6:Q6,"a")*2,""),"") | U6: =Examen!G2 -> n/p | V6: =ReExaminare!G2 -> n/p | W6: =IF(NOT(ISBLANK(B6)), IF(SUM(E6:Q6)<>0,SUM(E6:Q6),""), "") | AA6: ='Ev. Curentă'!I2 -> n/p | AB6: ='L. Indiv.'!H2 -> n/p | AC6: =IF(NOT(ISBLANK(C6)), IF(OR(AA6="n/p",AB6="n/p",AA6<5,AB6<5)," ",TRUNC(SUM(AA6:AB6)/2,2)), "") | AD6: =IF(NOT(ISBLANK(C6)), IF(AC6=" ","n/a", IF(Z6,Z6, IF(COUNT(MAX(AVERAGE(U6:V6),0)),MAX(U6:V6),"n/p"))), "") -> n/a | AE6: =IF(NOT(ISBLANK(C6)), IF(OR(AD6="n/a",AD6="n/p")," ", IF(AD6<5,AD6,TRUNC(AC6*0.5+AD6*0.5,2))), "") | AF6: =IF(NOT(ISBLANK(C6)), IF(AE6=" "," ", IF(AND(AE6>=1,AE6<2),"(unu, "&ROUNDUP(MOD(AE6*100,100),0)&")", IF(AND(AE6>=2,AE6<3),"(doi, "&ROUNDUP(MOD(AE6*100,100),0)&")", IF(AND(AE6>=3,AE6<4),"(trei, "&ROUNDUP(MOD(AE6*100,100),0)&")", IF(AND(AE6>=4,AE6<5),"(patru, "&ROUNDUP(MOD(AE6*100,100),0)&")", IF(AND(AE6>=5,AE6<6),"(cinci, "&ROUNDUP(MOD(AE6*100,100),0)&")", IF(AND(AE6>=6,AE6<7),"(şase, "&ROUNDUP(MOD(AE6*100,100),0)&")", IF(AND(AE6>=7,AE6<8),"(şapte, "&ROUNDUP(MOD(AE6*100,100),0)&")", IF(AND(AE6>=8,AE6<9),"(opt, "&ROUNDUP(MOD(AE6*100,100),0)&")", IF(AND(AE6>=9,AE6<10),"(nouă, "&ROUNDUP(MOD(AE6*100,100),0)&")", IF(AE6=10,"(zece, 00)", ))))))))))),"") | AG6: =IF(NOT(ISBLANK(C6)), IF(AE6=" "," ", IF(AND(AE6>=1,AE6<=3),"F", IF(AND(AE6>3,AE6<5),"FX", IF(AND(AE6>=5,AE6<=6),"E", IF(AND(AE6>6,AE6<=7),"D", IF(AND(AE6>7,AE6<=8),"C", IF(AND(AE6>8,AE6<=9),"B", IF(AND(AE6>9,AE6<=10),"A", )))))))),"")
B7: =IF(NOT(ISBLANK(C7)),COUNTA($C$6:C7),"") | R7: =IF(NOT(ISBLANK(C7)),IF(COUNTIF(E7:Q7,"a")<>0,COUNTIF(E7:Q7,"a")*2,""),"") | U7: =Examen!G3 | V7: =ReExaminare!G3 | W7: =IF(NOT(ISBLANK(B7)), IF(SUM(E7:Q7)<>0,SUM(E7:Q7),""), "") | AA7: ='Ev. Curentă'!I3 | AB7: ='L. Indiv.'!H3 | AC7: =IF(NOT(ISBLANK(C7)), IF(OR(AA7="n/p",AB7="n/p",AA7<5,AB7<5)," ",TRUNC(SUM(AA7:AB7)/2,2)), "") | AD7: =IF(NOT(ISBLANK(C7)), IF(AC7=" ","n/a", IF(Z7,Z7, IF(COUNT(MAX(AVERAGE(U7:V7),0)),MAX(U7:V7),"n/p"))), "") | AE7: =IF(NOT(ISBLANK(C7)), IF(OR(AD7="n/a",AD7="n/p")," ", IF(AD7<5,AD7,TRUNC(AC7*0.5+AD7*0.5,2))), "") | AF7: =IF(NOT(ISBLANK(C7)), IF(AE7=" "," ", IF(AND(AE7>=1,AE7<2),"(unu, "&ROUNDUP(MOD(AE7*100,100),0)&")", IF(AND(AE7>=2,AE7<3),"(doi, "&ROUNDUP(MOD(AE7*100,100),0)&")", IF(AND(AE7>=3,AE7<4),"(trei, "&ROUNDUP(MOD(AE7*100,100),0)&")", IF(AND(AE7>=4,AE7<5),"(patru, "&ROUNDUP(MOD(AE7*100,100),0)&")", IF(AND(AE7>=5,AE7<6),"(cinci, "&ROUNDUP(MOD(AE7*100,100),0)&")", IF(AND(AE7>=6,AE7<7),"(şase, "&ROUNDUP(MOD(AE7*100,100),0)&")", IF(AND(AE7>=7,AE7<8),"(şapte, "&ROUNDUP(MOD(AE7*100,100),0)&")", IF(AND(AE7>=8,AE7<9),"(opt, "&ROUNDUP(MOD(AE7*100,100),0)&")", IF(AND(AE7>=9,AE7<10),"(nouă, "&ROUNDUP(MOD(AE7*100,100),0)&")", IF(AE7=10,"(zece, 00)", ))))))))))),"") | AG7: =IF(NOT(ISBLANK(C7)), IF(AE7=" "," ", IF(AND(AE7>=1,AE7<=3),"F", IF(AND(AE7>3,AE7<5),"FX", IF(AND(AE7>=5,AE7<=6),"E", IF(AND(AE7>6,AE7<=7),"D", IF(AND(AE7>7,AE7<=8),"C", IF(AND(AE7>8,AE7<=9),"B", IF(AND(AE7>9,AE7<=10),"A", )))))))),"")
B8: =IF(NOT(ISBLANK(C8)),COUNTA($C$6:C8),"") | R8: =IF(NOT(ISBLANK(C8)),IF(COUNTIF(E8:Q8,"a")<>0,COUNTIF(E8:Q8,"a")*2,""),"") | U8: =Examen!G4 | V8: =ReExaminare!G4 | W8: =IF(NOT(ISBLANK(B8)), IF(SUM(E8:Q8)<>0,SUM(E8:Q8),""), "") | AA8: ='Ev. Curentă'!I4 | AB8: ='L. Indiv.'!H4 | AC8: =IF(NOT(ISBLANK(C8)), IF(OR(AA8="n/p",AB8="n/p",AA8<5,AB8<5)," ",TRUNC(SUM(AA8:AB8)/2,2)), "") | AD8: =IF(NOT(ISBLANK(C8)), IF(AC8=" ","n/a", IF(Z8,Z8, IF(COUNT(MAX(AVERAGE(U8:V8),0)),MAX(U8:V8),"n/p"))), "") | AE8: =IF(NOT(ISBLANK(C8)), IF(OR(AD8="n/a",AD8="n/p")," ", IF(AD8<5,AD8,TRUNC(AC8*0.5+AD8*0.5,2))), "") | AF8: =IF(NOT(ISBLANK(C8)), IF(AE8=" "," ", IF(AND(AE8>=1,AE8<2),"(unu, "&ROUNDUP(MOD(AE8*100,100),0)&")", IF(AND(AE8>=2,AE8<3),"(doi, "&ROUNDUP(MOD(AE8*100,100),0)&")", IF(AND(AE8>=3,AE8<4),"(trei, "&ROUNDUP(MOD(AE8*100,100),0)&")", IF(AND(AE8>=4,AE8<5),"(patru, "&ROUNDUP(MOD(AE8*100,100),0)&")", IF(AND(AE8>=5,AE8<6),"(cinci, "&ROUNDUP(MOD(AE8*100,100),0)&")", IF(AND(AE8>=6,AE8<7),"(şase, "&ROUNDUP(MOD(AE8*100,100),0)&")", IF(AND(AE8>=7,AE8<8),"(şapte, "&ROUNDUP(MOD(AE8*100,100),0)&")", IF(AND(AE8>=8,AE8<9),"(opt, "&ROUNDUP(MOD(AE8*100,100),0)&")", IF(AND(AE8>=9,AE8<10),"(nouă, "&ROUNDUP(MOD(AE8*100,100),0)&")", IF(AE8=10,"(zece, 00)", ))))))))))),"") | AG8: =IF(NOT(ISBLANK(C8)), IF(AE8=" "," ", IF(AND(AE8>=1,AE8<=3),"F", IF(AND(AE8>3,AE8<5),"FX", IF(AND(AE8>=5,AE8<=6),"E", IF(AND(AE8>6,AE8<=7),"D", IF(AND(AE8>7,AE8<=8),"C", IF(AND(AE8>8,AE8<=9),"B", IF(AND(AE8>9,AE8<=10),"A", )))))))),"")
B9: =IF(NOT(ISBLANK(C9)),COUNTA($C$6:C9),"") | R9: =IF(NOT(ISBLANK(C9)),IF(COUNTIF(E9:Q9,"a")<>0,COUNTIF(E9:Q9,"a")*2,""),"") | U9: =Examen!G5 | V9: =ReExaminare!G5 | W9: =IF(NOT(ISBLANK(B9)), IF(SUM(E9:Q9)<>0,SUM(E9:Q9),""), "") | AA9: ='Ev. Curentă'!I5 | AB9: ='L. Indiv.'!H5 | AC9: =IF(NOT(ISBLANK(C9)), IF(OR(AA9="n/p",AB9="n/p",AA9<5,AB9<5)," ",TRUNC(SUM(AA9:AB9)/2,2)), "") | AD9: =IF(NOT(ISBLANK(C9)), IF(AC9=" ","n/a", IF(Z9,Z9, IF(COUNT(MAX(AVERAGE(U9:V9),0)),MAX(U9:V9),"n/p"))), "") | AE9: =IF(NOT(ISBLANK(C9)), IF(OR(AD9="n/a",AD9="n/p")," ", IF(AD9<5,AD9,TRUNC(AC9*0.5+AD9*0.5,2))), "") | AF9: =IF(NOT(ISBLANK(C9)), IF(AE9=" "," ", IF(AND(AE9>=1,AE9<2),"(unu, "&ROUNDUP(MOD(AE9*100,100),0)&")", IF(AND(AE9>=2,AE9<3),"(doi, "&ROUNDUP(MOD(AE9*100,100),0)&")", IF(AND(AE9>=3,AE9<4),"(trei, "&ROUNDUP(MOD(AE9*100,100),0)&")", IF(AND(AE9>=4,AE9<5),"(patru, "&ROUNDUP(MOD(AE9*100,100),0)&")", IF(AND(AE9>=5,AE9<6),"(cinci, "&ROUNDUP(MOD(AE9*100,100),0)&")", IF(AND(AE9>=6,AE9<7),"(şase, "&ROUNDUP(MOD(AE9*100,100),0)&")", IF(AND(AE9>=7,AE9<8),"(şapte, "&ROUNDUP(MOD(AE9*100,100),0)&")", IF(AND(AE9>=8,AE9<9),"(opt, "&ROUNDUP(MOD(AE9*100,100),0)&")", IF(AND(AE9>=9,AE9<10),"(nouă, "&ROUNDUP(MOD(AE9*100,100),0)&")", IF(AE9=10,"(zece, 00)", ))))))))))),"") | AG9: =IF(NOT(ISBLANK(C9)), IF(AE9=" "," ", IF(AND(AE9>=1,AE9<=3),"F", IF(AND(AE9>3,AE9<5),"FX", IF(AND(AE9>=5,AE9<=6),"E", IF(AND(AE9>6,AE9<=7),"D", IF(AND(AE9>7,AE9<=8),"C", IF(AND(AE9>8,AE9<=9),"B", IF(AND(AE9>9,AE9<=10),"A", )))))))),"")
B10: =IF(NOT(ISBLANK(C10)),COUNTA($C$6:C10),"") | R10: =IF(NOT(ISBLANK(C10)),IF(COUNTIF(E10:Q10,"a")<>0,COUNTIF(E10:Q10,"a")*2,""),"") | U10: =Examen!G6 | V10: =ReExaminare!G6 | W10: =IF(NOT(ISBLANK(B10)), IF(SUM(E10:Q10)<>0,SUM(E10:Q10),""), "") | AA10: ='Ev. Curentă'!I6 | AB10: ='L. Indiv.'!H6 | AC10: =IF(NOT(ISBLANK(C10)), IF(OR(AA10="n/p",AB10="n/p",AA10<5,AB10<5)," ",TRUNC(SUM(AA10:AB10)/2,2)), "") | AD10: =IF(NOT(ISBLANK(C10)), IF(AC10=" ","n/a", IF(Z10,Z10, IF(COUNT(MAX(AVERAGE(U10:V10),0)),MAX(U10:V10),"n/p"))), "") | AE10: =IF(NOT(ISBLANK(C10)), IF(OR(AD10="n/a",AD10="n/p")," ", IF(AD10<5,AD10,TRUNC(AC10*0.5+AD10*0.5,2))), "") | AF10: =IF(NOT(ISBLANK(C10)), IF(AE10=" "," ", IF(AND(AE10>=1,AE10<2),"(unu, "&ROUNDUP(MOD(AE10*100,100),0)&")", IF(AND(AE10>=2,AE10<3),"(doi, "&ROUNDUP(MOD(AE10*100,100),0)&")", IF(AND(AE10>=3,AE10<4),"(trei, "&ROUNDUP(MOD(AE10*100,100),0)&")", IF(AND(AE10>=4,AE10<5),"(patru, "&ROUNDUP(MOD(AE10*100,100),0)&")", IF(AND(AE10>=5,AE10<6),"(cinci, "&ROUNDUP(MOD(AE10*100,100),0)&")", IF(AND(AE10>=6,AE10<7),"(şase, "&ROUNDUP(MOD(AE10*100,100),0)&")", IF(AND(AE10>=7,AE10<8),"(şapte, "&ROUNDUP(MOD(AE10*100,100),0)&")", IF(AND(AE10>=8,AE10<9),"(opt, "&ROUNDUP(MOD(AE10*100,100),0)&")", IF(AND(AE10>=9,AE10<10),"(nouă, "&ROUNDUP(MOD(AE10*100,100),0)&")", IF(AE10=10,"(zece, 00)", ))))))))))),"") | AG10: =IF(NOT(ISBLANK(C10)), IF(AE10=" "," ", IF(AND(AE10>=1,AE10<=3),"F", IF(AND(AE10>3,AE10<5),"FX", IF(AND(AE10>=5,AE10<=6),"E", IF(AND(AE10>6,AE10<=7),"D", IF(AND(AE10>7,AE10<=8),"C", IF(AND(AE10>8,AE10<=9),"B", IF(AND(AE10>9,AE10<=10),"A", )))))))),"")
B11: =IF(NOT(ISBLANK(C11)),COUNTA($C$6:C11),"") | R11: =IF(NOT(ISBLANK(C11)),IF(COUNTIF(E11:Q11,"a")<>0,COUNTIF(E11:Q11,"a")*2,""),"") | U11: =Examen!G7 | V11: =ReExaminare!G7 | W11: =IF(NOT(ISBLANK(B11)), IF(SUM(E11:Q11)<>0,SUM(E11:Q11),""), "") | AA11: ='Ev. Curentă'!I7 | AB11: ='L. Indiv.'!H7 | AC11: =IF(NOT(ISBLANK(C11)), IF(OR(AA11="n/p",AB11="n/p",AA11<5,AB11<5)," ",TRUNC(SUM(AA11:AB11)/2,2)), "") | AD11: =IF(NOT(ISBLANK(C11)), IF(AC11=" ","n/a", IF(Z11,Z11, IF(COUNT(MAX(AVERAGE(U11:V11),0)),MAX(U11:V11),"n/p"))), "") | AE11: =IF(NOT(ISBLANK(C11)), IF(OR(AD11="n/a",AD11="n/p")," ", IF(AD11<5,AD11,TRUNC(AC11*0.5+AD11*0.5,2))), "") | AF11: =IF(NOT(ISBLANK(C11)), IF(AE11=" "," ", IF(AND(AE11>=1,AE11<2),"(unu, "&ROUNDUP(MOD(AE11*100,100),0)&")", IF(AND(AE11>=2,AE11<3),"(doi, "&ROUNDUP(MOD(AE11*100,100),0)&")", IF(AND(AE11>=3,AE11<4),"(trei, "&ROUNDUP(MOD(AE11*100,100),0)&")", IF(AND(AE11>=4,AE11<5),"(patru, "&ROUNDUP(MOD(AE11*100,100),0)&")", IF(AND(AE11>=5,AE11<6),"(cinci, "&ROUNDUP(MOD(AE11*100,100),0)&")", IF(AND(AE11>=6,AE11<7),"(şase, "&ROUNDUP(MOD(AE11*100,100),0)&")", IF(AND(AE11>=7,AE11<8),"(şapte, "&ROUNDUP(MOD(AE11*100,100),0)&")", IF(AND(AE11>=8,AE11<9),"(opt, "&ROUNDUP(MOD(AE11*100,100),0)&")", IF(AND(AE11>=9,AE11<10),"(nouă, "&ROUNDUP(MOD(AE11*100,100),0)&")", IF(AE11=10,"(zece, 00)", ))))))))))),"") | AG11: =IF(NOT(ISBLANK(C11)), IF(AE11=" "," ", IF(AND(AE11>=1,AE11<=3),"F", IF(AND(AE11>3,AE11<5),"FX", IF(AND(AE11>=5,AE11<=6),"E", IF(AND(AE11>6,AE11<=7),"D", IF(AND(AE11>7,AE11<=8),"C", IF(AND(AE11>8,AE11<=9),"B", IF(AND(AE11>9,AE11<=10),"A", )))))))),"")
B12: =IF(NOT(ISBLANK(C12)),COUNTA($C$6:C12),"") | R12: =IF(NOT(ISBLANK(C12)),IF(COUNTIF(E12:Q12,"a")<>0,COUNTIF(E12:Q12,"a")*2,""),"") | U12: =Examen!G8 | V12: =ReExaminare!G8 | W12: =IF(NOT(ISBLANK(B12)), IF(SUM(E12:Q12)<>0,SUM(E12:Q12),""), "") | AA12: ='Ev. Curentă'!I8 | AB12: ='L. Indiv.'!H8 | AC12: =IF(NOT(ISBLANK(C12)), IF(OR(AA12="n/p",AB12="n/p",AA12<5,AB12<5)," ",TRUNC(SUM(AA12:AB12)/2,2)), "") | AD12: =IF(NOT(ISBLANK(C12)), IF(AC12=" ","n/a", IF(Z12,Z12, IF(COUNT(MAX(AVERAGE(U12:V12),0)),MAX(U12:V12),"n/p"))), "") | AE12: =IF(NOT(ISBLANK(C12)), IF(OR(AD12="n/a",AD12="n/p")," ", IF(AD12<5,AD12,TRUNC(AC12*0.5+AD12*0.5,2))), "") | AF12: =IF(NOT(ISBLANK(C12)), IF(AE12=" "," ", IF(AND(AE12>=1,AE12<2),"(unu, "&ROUNDUP(MOD(AE12*100,100),0)&")", IF(AND(AE12>=2,AE12<3),"(doi, "&ROUNDUP(MOD(AE12*100,100),0)&")", IF(AND(AE12>=3,AE12<4),"(trei, "&ROUNDUP(MOD(AE12*100,100),0)&")", IF(AND(AE12>=4,AE12<5),"(patru, "&ROUNDUP(MOD(AE12*100,100),0)&")", IF(AND(AE12>=5,AE12<6),"(cinci, "&ROUNDUP(MOD(AE12*100,100),0)&")", IF(AND(AE12>=6,AE12<7),"(şase, "&ROUNDUP(MOD(AE12*100,100),0)&")", IF(AND(AE12>=7,AE12<8),"(şapte, "&ROUNDUP(MOD(AE12*100,100),0)&")", IF(AND(AE12>=8,AE12<9),"(opt, "&ROUNDUP(MOD(AE12*100,100),0)&")", IF(AND(AE12>=9,AE12<10),"(nouă, "&ROUNDUP(MOD(AE12*100,100),0)&")", IF(AE12=10,"(zece, 00)", ))))))))))),"") | AG12: =IF(NOT(ISBLANK(C12)), IF(AE12=" "," ", IF(AND(AE12>=1,AE12<=3),"F", IF(AND(AE12>3,AE12<5),"FX", IF(AND(AE12>=5,AE12<=6),"E", IF(AND(AE12>6,AE12<=7),"D", IF(AND(AE12>7,AE12<=8),"C", IF(AND(AE12>8,AE12<=9),"B", IF(AND(AE12>9,AE12<=10),"A", )))))))),"")
B13: =IF(NOT(ISBLANK(C13)),COUNTA($C$6:C13),"") | R13: =IF(NOT(ISBLANK(C13)),IF(COUNTIF(E13:Q13,"a")<>0,COUNTIF(E13:Q13,"a")*2,""),"") | U13: =Examen!G9 | V13: =ReExaminare!G9 | W13: =IF(NOT(ISBLANK(B13)), IF(SUM(E13:Q13)<>0,SUM(E13:Q13),""), "") | AA13: ='Ev. Curentă'!I9 | AB13: ='L. Indiv.'!H9 | AC13: =IF(NOT(ISBLANK(C13)), IF(OR(AA13="n/p",AB13="n/p",AA13<5,AB13<5)," ",TRUNC(SUM(AA13:AB13)/2,2)), "") | AD13: =IF(NOT(ISBLANK(C13)), IF(AC13=" ","n/a", IF(Z13,Z13, IF(COUNT(MAX(AVERAGE(U13:V13),0)),MAX(U13:V13),"n/p"))), "") | AE13: =IF(NOT(ISBLANK(C13)), IF(OR(AD13="n/a",AD13="n/p")," ", IF(AD13<5,AD13,TRUNC(AC13*0.5+AD13*0.5,2))), "") | AF13: =IF(NOT(ISBLANK(C13)), IF(AE13=" "," ", IF(AND(AE13>=1,AE13<2),"(unu, "&ROUNDUP(MOD(AE13*100,100),0)&")", IF(AND(AE13>=2,AE13<3),"(doi, "&ROUNDUP(MOD(AE13*100,100),0)&")", IF(AND(AE13>=3,AE13<4),"(trei, "&ROUNDUP(MOD(AE13*100,100),0)&")", IF(AND(AE13>=4,AE13<5),"(patru, "&ROUNDUP(MOD(AE13*100,100),0)&")", IF(AND(AE13>=5,AE13<6),"(cinci, "&ROUNDUP(MOD(AE13*100,100),0)&")", IF(AND(AE13>=6,AE13<7),"(şase, "&ROUNDUP(MOD(AE13*100,100),0)&")", IF(AND(AE13>=7,AE13<8),"(şapte, "&ROUNDUP(MOD(AE13*100,100),0)&")", IF(AND(AE13>=8,AE13<9),"(opt, "&ROUNDUP(MOD(AE13*100,100),0)&")", IF(AND(AE13>=9,AE13<10),"(nouă, "&ROUNDUP(MOD(AE13*100,100),0)&")", IF(AE13=10,"(zece, 00)", ))))))))))),"") | AG13: =IF(NOT(ISBLANK(C13)), IF(AE13=" "," ", IF(AND(AE13>=1,AE13<=3),"F", IF(AND(AE13>3,AE13<5),"FX", IF(AND(AE13>=5,AE13<=6),"E", IF(AND(AE13>6,AE13<=7),"D", IF(AND(AE13>7,AE13<=8),"C", IF(AND(AE13>8,AE13<=9),"B", IF(AND(AE13>9,AE13<=10),"A", )))))))),"")
B14: =IF(NOT(ISBLANK(C14)),COUNTA($C$6:C14),"") | R14: =IF(NOT(ISBLANK(C14)),IF(COUNTIF(E14:Q14,"a")<>0,COUNTIF(E14:Q14,"a")*2,""),"") | U14: =Examen!G10 | V14: =ReExaminare!G10 | W14: =IF(NOT(ISBLANK(B14)), IF(SUM(E14:Q14)<>0,SUM(E14:Q14),""), "") | AA14: ='Ev. Curentă'!I10 | AB14: ='L. Indiv.'!H10 | AC14: =IF(NOT(ISBLANK(C14)), IF(OR(AA14="n/p",AB14="n/p",AA14<5,AB14<5)," ",TRUNC(SUM(AA14:AB14)/2,2)), "") | AD14: =IF(NOT(ISBLANK(C14)), IF(AC14=" ","n/a", IF(Z14,Z14, IF(COUNT(MAX(AVERAGE(U14:V14),0)),MAX(U14:V14),"n/p"))), "") | AE14: =IF(NOT(ISBLANK(C14)), IF(OR(AD14="n/a",AD14="n/p")," ", IF(AD14<5,AD14,TRUNC(AC14*0.5+AD14*0.5,2))), "") | AF14: =IF(NOT(ISBLANK(C14)), IF(AE14=" "," ", IF(AND(AE14>=1,AE14<2),"(unu, "&ROUNDUP(MOD(AE14*100,100),0)&")", IF(AND(AE14>=2,AE14<3),"(doi, "&ROUNDUP(MOD(AE14*100,100),0)&")", IF(AND(AE14>=3,AE14<4),"(trei, "&ROUNDUP(MOD(AE14*100,100),0)&")", IF(AND(AE14>=4,AE14<5),"(patru, "&ROUNDUP(MOD(AE14*100,100),0)&")", IF(AND(AE14>=5,AE14<6),"(cinci, "&ROUNDUP(MOD(AE14*100,100),0)&")", IF(AND(AE14>=6,AE14<7),"(şase, "&ROUNDUP(MOD(AE14*100,100),0)&")", IF(AND(AE14>=7,AE14<8),"(şapte, "&ROUNDUP(MOD(AE14*100,100),0)&")", IF(AND(AE14>=8,AE14<9),"(opt, "&ROUNDUP(MOD(AE14*100,100),0)&")", IF(AND(AE14>=9,AE14<10),"(nouă, "&ROUNDUP(MOD(AE14*100,100),0)&")", IF(AE14=10,"(zece, 00)", ))))))))))),"") | AG14: =IF(NOT(ISBLANK(C14)), IF(AE14=" "," ", IF(AND(AE14>=1,AE14<=3),"F", IF(AND(AE14>3,AE14<5),"FX", IF(AND(AE14>=5,AE14<=6),"E", IF(AND(AE14>6,AE14<=7),"D", IF(AND(AE14>7,AE14<=8),"C", IF(AND(AE14>8,AE14<=9),"B", IF(AND(AE14>9,AE14<=10),"A", )))))))),"")
B15: =IF(NOT(ISBLANK(C15)),COUNTA($C$6:C15),"") | R15: =IF(NOT(ISBLANK(C15)),IF(COUNTIF(E15:Q15,"a")<>0,COUNTIF(E15:Q15,"a")*2,""),"") | U15: =Examen!G11 | V15: =ReExaminare!G11 | W15: =IF(NOT(ISBLANK(B15)), IF(SUM(E15:Q15)<>0,SUM(E15:Q15),""), "") | AA15: ='Ev. Curentă'!I11 | AB15: ='L. Indiv.'!H11 | AC15: =IF(NOT(ISBLANK(C15)), IF(OR(AA15="n/p",AB15="n/p",AA15<5,AB15<5)," ",TRUNC(SUM(AA15:AB15)/2,2)), "") | AD15: =IF(NOT(ISBLANK(C15)), IF(AC15=" ","n/a", IF(Z15,Z15, IF(COUNT(MAX(AVERAGE(U15:V15),0)),MAX(U15:V15),"n/p"))), "") | AE15: =IF(NOT(ISBLANK(C15)), IF(OR(AD15="n/a",AD15="n/p")," ", IF(AD15<5,AD15,TRUNC(AC15*0.5+AD15*0.5,2))), "") | AF15: =IF(NOT(ISBLANK(C15)), IF(AE15=" "," ", IF(AND(AE15>=1,AE15<2),"(unu, "&ROUNDUP(MOD(AE15*100,100),0)&")", IF(AND(AE15>=2,AE15<3),"(doi, "&ROUNDUP(MOD(AE15*100,100),0)&")", IF(AND(AE15>=3,AE15<4),"(trei, "&ROUNDUP(MOD(AE15*100,100),0)&")", IF(AND(AE15>=4,AE15<5),"(patru, "&ROUNDUP(MOD(AE15*100,100),0)&")", IF(AND(AE15>=5,AE15<6),"(cinci, "&ROUNDUP(MOD(AE15*100,100),0)&")", IF(AND(AE15>=6,AE15<7),"(şase, "&ROUNDUP(MOD(AE15*100,100),0)&")", IF(AND(AE15>=7,AE15<8),"(şapte, "&ROUNDUP(MOD(AE15*100,100),0)&")", IF(AND(AE15>=8,AE15<9),"(opt, "&ROUNDUP(MOD(AE15*100,100),0)&")", IF(AND(AE15>=9,AE15<10),"(nouă, "&ROUNDUP(MOD(AE15*100,100),0)&")", IF(AE15=10,"(zece, 00)", ))))))))))),"") | AG15: =IF(NOT(ISBLANK(C15)), IF(AE15=" "," ", IF(AND(AE15>=1,AE15<=3),"F", IF(AND(AE15>3,AE15<5),"FX", IF(AND(AE15>=5,AE15<=6),"E", IF(AND(AE15>6,AE15<=7),"D", IF(AND(AE15>7,AE15<=8),"C", IF(AND(AE15>8,AE15<=9),"B", IF(AND(AE15>9,AE15<=10),"A", )))))))),"")
B16: =IF(NOT(ISBLANK(C16)),COUNTA($C$6:C16),"") | R16: =IF(NOT(ISBLANK(C16)),IF(COUNTIF(E16:Q16,"a")<>0,COUNTIF(E16:Q16,"a")*2,""),"") | U16: =Examen!G12 | V16: =ReExaminare!G12 | W16: =IF(NOT(ISBLANK(B16)), IF(SUM(E16:Q16)<>0,SUM(E16:Q16),""), "") | AA16: ='Ev. Curentă'!I12 | AB16: ='L. Indiv.'!H12 | AC16: =IF(NOT(ISBLANK(C16)), IF(OR(AA16="n/p",AB16="n/p",AA16<5,AB16<5)," ",TRUNC(SUM(AA16:AB16)/2,2)), "") | AD16: =IF(NOT(ISBLANK(C16)), IF(AC16=" ","n/a", IF(Z16,Z16, IF(COUNT(MAX(AVERAGE(U16:V16),0)),MAX(U16:V16),"n/p"))), "") | AE16: =IF(NOT(ISBLANK(C16)), IF(OR(AD16="n/a",AD16="n/p")," ", IF(AD16<5,AD16,TRUNC(AC16*0.5+AD16*0.5,2))), "") | AF16: =IF(NOT(ISBLANK(C16)), IF(AE16=" "," ", IF(AND(AE16>=1,AE16<2),"(unu, "&ROUNDUP(MOD(AE16*100,100),0)&")", IF(AND(AE16>=2,AE16<3),"(doi, "&ROUNDUP(MOD(AE16*100,100),0)&")", IF(AND(AE16>=3,AE16<4),"(trei, "&ROUNDUP(MOD(AE16*100,100),0)&")", IF(AND(AE16>=4,AE16<5),"(patru, "&ROUNDUP(MOD(AE16*100,100),0)&")", IF(AND(AE16>=5,AE16<6),"(cinci, "&ROUNDUP(MOD(AE16*100,100),0)&")", IF(AND(AE16>=6,AE16<7),"(şase, "&ROUNDUP(MOD(AE16*100,100),0)&")", IF(AND(AE16>=7,AE16<8),"(şapte, "&ROUNDUP(MOD(AE16*100,100),0)&")", IF(AND(AE16>=8,AE16<9),"(opt, "&ROUNDUP(MOD(AE16*100,100),0)&")", IF(AND(AE16>=9,AE16<10),"(nouă, "&ROUNDUP(MOD(AE16*100,100),0)&")", IF(AE16=10,"(zece, 00)", ))))))))))),"") | AG16: =IF(NOT(ISBLANK(C16)), IF(AE16=" "," ", IF(AND(AE16>=1,AE16<=3),"F", IF(AND(AE16>3,AE16<5),"FX", IF(AND(AE16>=5,AE16<=6),"E", IF(AND(AE16>6,AE16<=7),"D", IF(AND(AE16>7,AE16<=8),"C", IF(AND(AE16>8,AE16<=9),"B", IF(AND(AE16>9,AE16<=10),"A", )))))))),"")
B17: =IF(NOT(ISBLANK(C17)),COUNTA($C$6:C17),"") | R17: =IF(NOT(ISBLANK(C17)),IF(COUNTIF(E17:Q17,"a")<>0,COUNTIF(E17:Q17,"a")*2,""),"") | U17: =Examen!G13 | V17: =ReExaminare!G13 | W17: =IF(NOT(ISBLANK(B17)), IF(SUM(E17:Q17)<>0,SUM(E17:Q17),""), "") | AA17: ='Ev. Curentă'!I13 | AB17: ='L. Indiv.'!H13 | AC17: =IF(NOT(ISBLANK(C17)), IF(OR(AA17="n/p",AB17="n/p",AA17<5,AB17<5)," ",TRUNC(SUM(AA17:AB17)/2,2)), "") | AD17: =IF(NOT(ISBLANK(C17)), IF(AC17=" ","n/a", IF(Z17,Z17, IF(COUNT(MAX(AVERAGE(U17:V17),0)),MAX(U17:V17),"n/p"))), "") | AE17: =IF(NOT(ISBLANK(C17)), IF(OR(AD17="n/a",AD17="n/p")," ", IF(AD17<5,AD17,TRUNC(AC17*0.5+AD17*0.5,2))), "") | AF17: =IF(NOT(ISBLANK(C17)), IF(AE17=" "," ", IF(AND(AE17>=1,AE17<2),"(unu, "&ROUNDUP(MOD(AE17*100,100),0)&")", IF(AND(AE17>=2,AE17<3),"(doi, "&ROUNDUP(MOD(AE17*100,100),0)&")", IF(AND(AE17>=3,AE17<4),"(trei, "&ROUNDUP(MOD(AE17*100,100),0)&")", IF(AND(AE17>=4,AE17<5),"(patru, "&ROUNDUP(MOD(AE17*100,100),0)&")", IF(AND(AE17>=5,AE17<6),"(cinci, "&ROUNDUP(MOD(AE17*100,100),0)&")", IF(AND(AE17>=6,AE17<7),"(şase, "&ROUNDUP(MOD(AE17*100,100),0)&")", IF(AND(AE17>=7,AE17<8),"(şapte, "&ROUNDUP(MOD(AE17*100,100),0)&")", IF(AND(AE17>=8,AE17<9),"(opt, "&ROUNDUP(MOD(AE17*100,100),0)&")", IF(AND(AE17>=9,AE17<10),"(nouă, "&ROUNDUP(MOD(AE17*100,100),0)&")", IF(AE17=10,"(zece, 00)", ))))))))))),"") | AG17: =IF(NOT(ISBLANK(C17)), IF(AE17=" "," ", IF(AND(AE17>=1,AE17<=3),"F", IF(AND(AE17>3,AE17<5),"FX", IF(AND(AE17>=5,AE17<=6),"E", IF(AND(AE17>6,AE17<=7),"D", IF(AND(AE17>7,AE17<=8),"C", IF(AND(AE17>8,AE17<=9),"B", IF(AND(AE17>9,AE17<=10),"A", )))))))),"")
B18: =IF(NOT(ISBLANK(C18)),COUNTA($C$6:C18),"") | R18: =IF(NOT(ISBLANK(C18)),IF(COUNTIF(E18:Q18,"a")<>0,COUNTIF(E18:Q18,"a")*2,""),"") | U18: =Examen!G14 | V18: =ReExaminare!G14 | W18: =IF(NOT(ISBLANK(B18)), IF(SUM(E18:Q18)<>0,SUM(E18:Q18),""), "") | AA18: ='Ev. Curentă'!I14 | AB18: ='L. Indiv.'!H14 | AC18: =IF(NOT(ISBLANK(C18)), IF(OR(AA18="n/p",AB18="n/p",AA18<5,AB18<5)," ",TRUNC(SUM(AA18:AB18)/2,2)), "") | AD18: =IF(NOT(ISBLANK(C18)), IF(AC18=" ","n/a", IF(Z18,Z18, IF(COUNT(MAX(AVERAGE(U18:V18),0)),MAX(U18:V18),"n/p"))), "") | AE18: =IF(NOT(ISBLANK(C18)), IF(OR(AD18="n/a",AD18="n/p")," ", IF(AD18<5,AD18,TRUNC(AC18*0.5+AD18*0.5,2))), "") | AF18: =IF(NOT(ISBLANK(C18)), IF(AE18=" "," ", IF(AND(AE18>=1,AE18<2),"(unu, "&ROUNDUP(MOD(AE18*100,100),0)&")", IF(AND(AE18>=2,AE18<3),"(doi, "&ROUNDUP(MOD(AE18*100,100),0)&")", IF(AND(AE18>=3,AE18<4),"(trei, "&ROUNDUP(MOD(AE18*100,100),0)&")", IF(AND(AE18>=4,AE18<5),"(patru, "&ROUNDUP(MOD(AE18*100,100),0)&")", IF(AND(AE18>=5,AE18<6),"(cinci, "&ROUNDUP(MOD(AE18*100,100),0)&")", IF(AND(AE18>=6,AE18<7),"(şase, "&ROUNDUP(MOD(AE18*100,100),0)&")", IF(AND(AE18>=7,AE18<8),"(şapte, "&ROUNDUP(MOD(AE18*100,100),0)&")", IF(AND(AE18>=8,AE18<9),"(opt, "&ROUNDUP(MOD(AE18*100,100),0)&")", IF(AND(AE18>=9,AE18<10),"(nouă, "&ROUNDUP(MOD(AE18*100,100),0)&")", IF(AE18=10,"(zece, 00)", ))))))))))),"") | AG18: =IF(NOT(ISBLANK(C18)), IF(AE18=" "," ", IF(AND(AE18>=1,AE18<=3),"F", IF(AND(AE18>3,AE18<5),"FX", IF(AND(AE18>=5,AE18<=6),"E", IF(AND(AE18>6,AE18<=7),"D", IF(AND(AE18>7,AE18<=8),"C", IF(AND(AE18>8,AE18<=9),"B", IF(AND(AE18>9,AE18<=10),"A", )))))))),"")
... B105: =IF(NOT(ISBLANK(C105)),COUNTA($C$6:C105),"") | R105: =IF(NOT(ISBLANK(C105)),IF(COUNTIF(E105:Q105,"a")<>0,COUNTIF(E105:Q105,"a")*2,""),"") | U105: =Examen!G101 | V105: =ReExaminare!G101 | W105: =IF(NOT(ISBLANK(B105)), IF(SUM(E105:Q105)<>0,SUM(E105:Q105),""), "") | AA105: ='Ev. Curentă'!I101 | AB105: ='L. Indiv.'!H101 | AC105: =IF(NOT(ISBLANK(C105)), IF(OR(AA105="n/p",AB105="n/p",AA105<5,AB105<5)," ",TRUNC(SUM(AA105:AB105)/2,2)), "") | AD105: =IF(NOT(ISBLANK(C105)), IF(AC105=" ","n/a", IF(Z105,Z105, IF(COUNT(MAX(AVERAGE(U105:V105),0)),MAX(U105:V105),"n/p"))), "") | AE105: =IF(NOT(ISBLANK(C105)), IF(OR(AD105="n/a",AD105="n/p")," ", IF(AD105<5,AD105,TRUNC(AC105*0.5+AD105*0.5,2))), "") | AF105: =IF(NOT(ISBLANK(C105)), IF(AE105=" "," ", IF(AND(AE105>=1,AE105<2),"(unu, "&ROUNDUP(MOD(AE105*100,100),0)&")", IF(AND(AE105>=2,AE105<3),"(doi, "&ROUNDUP(MOD(AE105*100,100),0)&")", IF(AND(AE105>=3,AE105<4),"(trei, "&ROUNDUP(MOD(AE105*100,100),0)&")", IF(AND(AE105>=4,AE105<5),"(patru, "&ROUNDUP(MOD(AE105*100,100),0)&")", IF(AND(AE105>=5,AE105<6),"(cinci, "&ROUNDUP(MOD(AE105*100,100),0)&")", IF(AND(AE105>=6,AE105<7),"(şase, "&ROUNDUP(MOD(AE105*100,100),0)&")", IF(AND(AE105>=7,AE105<8),"(şapte, "&ROUNDUP(MOD(AE105*100,100),0)&")", IF(AND(AE105>=8,AE105<9),"(opt, "&ROUNDUP(MOD(AE105*100,100),0)&")", IF(AND(AE105>=9,AE105<10),"(nouă, "&ROUNDUP(MOD(AE105*100,100),0)&")", IF(AE105=10,"(zece, 00)", ))))))))))),"") | AG105: =IF(NOT(ISBLANK(C105)), IF(AE105=" "," ", IF(AND(AE105>=1,AE105<=3),"F", IF(AND(AE105>3,AE105<5),"FX", IF(AND(AE105>=5,AE105<=6),"E", IF(AND(AE105>6,AE105<=7),"D", IF(AND(AE105>7,AE105<=8),"C", IF(AND(AE105>8,AE105<=9),"B", IF(AND(AE105>9,AE105<=10),"A", )))))))),"")
AE106: =IF(NOT(ISBLANK(C106)), IF(OR(AD106="n/a",AD106="n/p")," ", IF(AD106<5,AD106,TRUNC(AC106*0.5+AD106*0.5,2))), "") | AG106: =IF(NOT(ISBLANK(C106)), IF(AE106=" "," ", IF(AND(AE106>=1,AE106<=3),"F", IF(AND(AE106>3,AE106<5),"FX", IF(AND(AE106>=5,AE106<=6),"E", IF(AND(AE106>6,AE106<=7),"D", IF(AND(AE106>7,AE106<=8),"C", IF(AND(AE106>8,AE106<=9),"B", IF(AND(AE106>9,AE106<=10),"A", )))))))),"")

Sheet Ev. Curentă
A1: Nr. | B1: Nume, Prenume | C1: item 1 | D1: item 2 | E1: item 3 | F1: item 4 | G1: item 5 | H1: Pctj Total | I1: Nota | J1: Baremul de evaluare | M1: Statistica
A2: =IF(NOT(ISBLANK('Curs, Seminar'!B6)),'Curs, Seminar'!B6,"") -> 1 | B2: =IF(NOT(ISBLANK('Curs, Seminar'!C6)),'Curs, Seminar'!C6,"") -> Nume, Prenume | H2: =IF(NOT(ISBLANK('Curs, Seminar'!C6)),ROUND(SUM(C2:G2),0),"") -> 0 | I2: =IF(NOT(ISBLANK('Curs, Seminar'!C6)), IF(H2=0,"n/p", IF(AND(H2>=$J$3,H2<=$K$3),$L$3, IF(AND(H2>=$J$4,H2<=$K$4),$L$4, IF(AND(H2>=$J$5,H2<=$K$5),$L$5, IF(AND(H2>=$J$6,H2<=$K$6),$L$6, IF(AND(H2>=$J$7,H2<=$K$7),$L$7, IF(AND(H2>=$J$8,H2<=$K$8),$L$8, IF(AND(H2>=$J$9,H2<=$K$9),$L$9, IF(AND(H2>=$J$10,H2<=$K$10),$L$10, IF(AND(H2>=$J$11,H2<=$K$11),$L$11)))))))))), "") -> n/p | J2: Punctajul acumulat | L2: Nota | M2: Nota | N2: Nr de note
A3: =IF(NOT(ISBLANK('Curs, Seminar'!B7)),'Curs, Seminar'!B7,"") | B3: =IF(NOT(ISBLANK('Curs, Seminar'!C7)),'Curs, Seminar'!C7,"") | H3: =IF(NOT(ISBLANK('Curs, Seminar'!C7)),ROUND(SUM(C3:G3),0),"") | I3: =IF(NOT(ISBLANK('Curs, Seminar'!C7)), IF(H3=0,"n/p", IF(AND(H3>=$J$3,H3<=$K$3),$L$3, IF(AND(H3>=$J$4,H3<=$K$4),$L$4, IF(AND(H3>=$J$5,H3<=$K$5),$L$5, IF(AND(H3>=$J$6,H3<=$K$6),$L$6, IF(AND(H3>=$J$7,H3<=$K$7),$L$7, IF(AND(H3>=$J$8,H3<=$K$8),$L$8, IF(AND(H3>=$J$9,H3<=$K$9),$L$9, IF(AND(H3>=$J$10,H3<=$K$10),$L$10, IF(AND(H3>=$J$11,H3<=$K$11),$L$11)))))))))), "") | J3: 0 | K3: 3 | L3: 2 | M3: 1 | N3: =COUNTIF($I$2:$I$101,M3) -> 0
A4: =IF(NOT(ISBLANK('Curs, Seminar'!B8)),'Curs, Seminar'!B8,"") | B4: =IF(NOT(ISBLANK('Curs, Seminar'!C8)),'Curs, Seminar'!C8,"") | H4: =IF(NOT(ISBLANK('Curs, Seminar'!C8)),ROUND(SUM(C4:G4),0),"") | I4: =IF(NOT(ISBLANK('Curs, Seminar'!C8)), IF(H4=0,"n/p", IF(AND(H4>=$J$3,H4<=$K$3),$L$3, IF(AND(H4>=$J$4,H4<=$K$4),$L$4, IF(AND(H4>=$J$5,H4<=$K$5),$L$5, IF(AND(H4>=$J$6,H4<=$K$6),$L$6, IF(AND(H4>=$J$7,H4<=$K$7),$L$7, IF(AND(H4>=$J$8,H4<=$K$8),$L$8, IF(AND(H4>=$J$9,H4<=$K$9),$L$9, IF(AND(H4>=$J$10,H4<=$K$10),$L$10, IF(AND(H4>=$J$11,H4<=$K$11),$L$11)))))))))), "") | J4: 4 | K4: 7 | L4: 3 | M4: 2 | N4: =COUNTIF($I$2:$I$101,M4) -> 0
A5: =IF(NOT(ISBLANK('Curs, Seminar'!B9)),'Curs, Seminar'!B9,"") | B5: =IF(NOT(ISBLANK('Curs, Seminar'!C9)),'Curs, Seminar'!C9,"") | H5: =IF(NOT(ISBLANK('Curs, Seminar'!C9)),ROUND(SUM(C5:G5),0),"") | I5: =IF(NOT(ISBLANK('Curs, Seminar'!C9)), IF(H5=0,"n/p", IF(AND(H5>=$J$3,H5<=$K$3),$L$3, IF(AND(H5>=$J$4,H5<=$K$4),$L$4, IF(AND(H5>=$J$5,H5<=$K$5),$L$5, IF(AND(H5>=$J$6,H5<=$K$6),$L$6, IF(AND(H5>=$J$7,H5<=$K$7),$L$7, IF(AND(H5>=$J$8,H5<=$K$8),$L$8, IF(AND(H5>=$J$9,H5<=$K$9),$L$9, IF(AND(H5>=$J$10,H5<=$K$10),$L$10, IF(AND(H5>=$J$11,H5<=$K$11),$L$11)))))))))), "") | J5: 8 | K5: 12 | L5: 4 | M5: 3 | N5: =COUNTIF($I$2:$I$101,M5) -> 0
A6: =IF(NOT(ISBLANK('Curs, Seminar'!B10)),'Curs, Seminar'!B10,"") | B6: =IF(NOT(ISBLANK('Curs, Seminar'!C10)),'Curs, Seminar'!C10,"") | H6: =IF(NOT(ISBLANK('Curs, Seminar'!C10)),ROUND(SUM(C6:G6),0),"") | I6: =IF(NOT(ISBLANK('Curs, Seminar'!C10)), IF(H6=0,"n/p", IF(AND(H6>=$J$3,H6<=$K$3),$L$3, IF(AND(H6>=$J$4,H6<=$K$4),$L$4, IF(AND(H6>=$J$5,H6<=$K$5),$L$5, IF(AND(H6>=$J$6,H6<=$K$6),$L$6, IF(AND(H6>=$J$7,H6<=$K$7),$L$7, IF(AND(H6>=$J$8,H6<=$K$8),$L$8, IF(AND(H6>=$J$9,H6<=$K$9),$L$9, IF(AND(H6>=$J$10,H6<=$K$10),$L$10, IF(AND(H6>=$J$11,H6<=$K$11),$L$11)))))))))), "") | J6: 13 | K6: 15 | L6: 5 | M6: 4 | N6: =COUNTIF($I$2:$I$101,M6) -> 0
A7: =IF(NOT(ISBLANK('Curs, Seminar'!B11)),'Curs, Seminar'!B11,"") | B7: =IF(NOT(ISBLANK('Curs, Seminar'!C11)),'Curs, Seminar'!C11,"") | H7: =IF(NOT(ISBLANK('Curs, Seminar'!C11)),ROUND(SUM(C7:G7),0),"") | I7: =IF(NOT(ISBLANK('Curs, Seminar'!C11)), IF(H7=0,"n/p", IF(AND(H7>=$J$3,H7<=$K$3),$L$3, IF(AND(H7>=$J$4,H7<=$K$4),$L$4, IF(AND(H7>=$J$5,H7<=$K$5),$L$5, IF(AND(H7>=$J$6,H7<=$K$6),$L$6, IF(AND(H7>=$J$7,H7<=$K$7),$L$7, IF(AND(H7>=$J$8,H7<=$K$8),$L$8, IF(AND(H7>=$J$9,H7<=$K$9),$L$9, IF(AND(H7>=$J$10,H7<=$K$10),$L$10, IF(AND(H7>=$J$11,H7<=$K$11),$L$11)))))))))), "") | J7: 16 | K7: 18 | L7: 6 | M7: 5 | N7: =COUNTIF($I$2:$I$101,M7) -> 0
A8: =IF(NOT(ISBLANK('Curs, Seminar'!B12)),'Curs, Seminar'!B12,"") | B8: =IF(NOT(ISBLANK('Curs, Seminar'!C12)),'Curs, Seminar'!C12,"") | H8: =IF(NOT(ISBLANK('Curs, Seminar'!C12)),ROUND(SUM(C8:G8),0),"") | I8: =IF(NOT(ISBLANK('Curs, Seminar'!C12)), IF(H8=0,"n/p", IF(AND(H8>=$J$3,H8<=$K$3),$L$3, IF(AND(H8>=$J$4,H8<=$K$4),$L$4, IF(AND(H8>=$J$5,H8<=$K$5),$L$5, IF(AND(H8>=$J$6,H8<=$K$6),$L$6, IF(AND(H8>=$J$7,H8<=$K$7),$L$7, IF(AND(H8>=$J$8,H8<=$K$8),$L$8, IF(AND(H8>=$J$9,H8<=$K$9),$L$9, IF(AND(H8>=$J$10,H8<=$K$10),$L$10, IF(AND(H8>=$J$11,H8<=$K$11),$L$11)))))))))), "") | J8: 19 | K8: 21 | L8: 7 | M8: 6 | N8: =COUNTIF($I$2:$I$101,M8) -> 0
A9: =IF(NOT(ISBLANK('Curs, Seminar'!B13)),'Curs, Seminar'!B13,"") | B9: =IF(NOT(ISBLANK('Curs, Seminar'!C13)),'Curs, Seminar'!C13,"") | H9: =IF(NOT(ISBLANK('Curs, Seminar'!C13)),ROUND(SUM(C9:G9),0),"") | I9: =IF(NOT(ISBLANK('Curs, Seminar'!C13)), IF(H9=0,"n/p", IF(AND(H9>=$J$3,H9<=$K$3),$L$3, IF(AND(H9>=$J$4,H9<=$K$4),$L$4, IF(AND(H9>=$J$5,H9<=$K$5),$L$5, IF(AND(H9>=$J$6,H9<=$K$6),$L$6, IF(AND(H9>=$J$7,H9<=$K$7),$L$7, IF(AND(H9>=$J$8,H9<=$K$8),$L$8, IF(AND(H9>=$J$9,H9<=$K$9),$L$9, IF(AND(H9>=$J$10,H9<=$K$10),$L$10, IF(AND(H9>=$J$11,H9<=$K$11),$L$11)))))))))), "") | J9: 22 | K9: 24 | L9: 8 | M9: 7 | N9: =COUNTIF($I$2:$I$101,M9) -> 0
A10: =IF(NOT(ISBLANK('Curs, Seminar'!B14)),'Curs, Seminar'!B14,"") | B10: =IF(NOT(ISBLANK('Curs, Seminar'!C14)),'Curs, Seminar'!C14,"") | H10: =IF(NOT(ISBLANK('Curs, Seminar'!C14)),ROUND(SUM(C10:G10),0),"") | I10: =IF(NOT(ISBLANK('Curs, Seminar'!C14)), IF(H10=0,"n/p", IF(AND(H10>=$J$3,H10<=$K$3),$L$3, IF(AND(H10>=$J$4,H10<=$K$4),$L$4, IF(AND(H10>=$J$5,H10<=$K$5),$L$5, IF(AND(H10>=$J$6,H10<=$K$6),$L$6, IF(AND(H10>=$J$7,H10<=$K$7),$L$7, IF(AND(H10>=$J$8,H10<=$K$8),$L$8, IF(AND(H10>=$J$9,H10<=$K$9),$L$9, IF(AND(H10>=$J$10,H10<=$K$10),$L$10, IF(AND(H10>=$J$11,H10<=$K$11),$L$11)))))))))), "") | J10: 25 | K10: 27 | L10: 9 | M10: 8 | N10: =COUNTIF($I$2:$I$101,M10) -> 0
A11: =IF(NOT(ISBLANK('Curs, Seminar'!B15)),'Curs, Seminar'!B15,"") | B11: =IF(NOT(ISBLANK('Curs, Seminar'!C15)),'Curs, Seminar'!C15,"") | H11: =IF(NOT(ISBLANK('Curs, Seminar'!C15)),ROUND(SUM(C11:G11),0),"") | I11: =IF(NOT(ISBLANK('Curs, Seminar'!C15)), IF(H11=0,"n/p", IF(AND(H11>=$J$3,H11<=$K$3),$L$3, IF(AND(H11>=$J$4,H11<=$K$4),$L$4, IF(AND(H11>=$J$5,H11<=$K$5),$L$5, IF(AND(H11>=$J$6,H11<=$K$6),$L$6, IF(AND(H11>=$J$7,H11<=$K$7),$L$7, IF(AND(H11>=$J$8,H11<=$K$8),$L$8, IF(AND(H11>=$J$9,H11<=$K$9),$L$9, IF(AND(H11>=$J$10,H11<=$K$10),$L$10, IF(AND(H11>=$J$11,H11<=$K$11),$L$11)))))))))), "") | J11: 28 | K11: 30 | L11: 10 | M11: 9 | N11: =COUNTIF($I$2:$I$101,M11) -> 0
A12: =IF(NOT(ISBLANK('Curs, Seminar'!B16)),'Curs, Seminar'!B16,"") | B12: =IF(NOT(ISBLANK('Curs, Seminar'!C16)),'Curs, Seminar'!C16,"") | H12: =IF(NOT(ISBLANK('Curs, Seminar'!C16)),ROUND(SUM(C12:G12),0),"") | I12: =IF(NOT(ISBLANK('Curs, Seminar'!C16)), IF(H12=0,"n/p", IF(AND(H12>=$J$3,H12<=$K$3),$L$3, IF(AND(H12>=$J$4,H12<=$K$4),$L$4, IF(AND(H12>=$J$5,H12<=$K$5),$L$5, IF(AND(H12>=$J$6,H12<=$K$6),$L$6, IF(AND(H12>=$J$7,H12<=$K$7),$L$7, IF(AND(H12>=$J$8,H12<=$K$8),$L$8, IF(AND(H12>=$J$9,H12<=$K$9),$L$9, IF(AND(H12>=$J$10,H12<=$K$10),$L$10, IF(AND(H12>=$J$11,H12<=$K$11),$L$11)))))))))), "") | M12: 10 | N12: =COUNTIF($I$2:$I$101,M12) -> 0
A13: =IF(NOT(ISBLANK('Curs, Seminar'!B17)),'Curs, Seminar'!B17,"") | B13: =IF(NOT(ISBLANK('Curs, Seminar'!C17)),'Curs, Seminar'!C17,"") | H13: =IF(NOT(ISBLANK('Curs, Seminar'!C17)),ROUND(SUM(C13:G13),0),"") | I13: =IF(NOT(ISBLANK('Curs, Seminar'!C17)), IF(H13=0,"n/p", IF(AND(H13>=$J$3,H13<=$K$3),$L$3, IF(AND(H13>=$J$4,H13<=$K$4),$L$4, IF(AND(H13>=$J$5,H13<=$K$5),$L$5, IF(AND(H13>=$J$6,H13<=$K$6),$L$6, IF(AND(H13>=$J$7,H13<=$K$7),$L$7, IF(AND(H13>=$J$8,H13<=$K$8),$L$8, IF(AND(H13>=$J$9,H13<=$K$9),$L$9, IF(AND(H13>=$J$10,H13<=$K$10),$L$10, IF(AND(H13>=$J$11,H13<=$K$11),$L$11)))))))))), "") | M13: n/p | N13: =COUNTIF($I$2:$I$101,M13) -> 1
A14: =IF(NOT(ISBLANK('Curs, Seminar'!B18)),'Curs, Seminar'!B18,"") | B14: =IF(NOT(ISBLANK('Curs, Seminar'!C18)),'Curs, Seminar'!C18,"") | H14: =IF(NOT(ISBLANK('Curs, Seminar'!C18)),ROUND(SUM(C14:G14),0),"") | I14: =IF(NOT(ISBLANK('Curs, Seminar'!C18)), IF(H14=0,"n/p", IF(AND(H14>=$J$3,H14<=$K$3),$L$3, IF(AND(H14>=$J$4,H14<=$K$4),$L$4, IF(AND(H14>=$J$5,H14<=$K$5),$L$5, IF(AND(H14>=$J$6,H14<=$K$6),$L$6, IF(AND(H14>=$J$7,H14<=$K$7),$L$7, IF(AND(H14>=$J$8,H14<=$K$8),$L$8, IF(AND(H14>=$J$9,H14<=$K$9),$L$9, IF(AND(H14>=$J$10,H14<=$K$10),$L$10, IF(AND(H14>=$J$11,H14<=$K$11),$L$11)))))))))), "")
A15: =IF(NOT(ISBLANK('Curs, Seminar'!B19)),'Curs, Seminar'!B19,"") | B15: =IF(NOT(ISBLANK('Curs, Seminar'!C19)),'Curs, Seminar'!C19,"") | H15: =IF(NOT(ISBLANK('Curs, Seminar'!C19)),ROUND(SUM(C15:G15),0),"") | I15: =IF(NOT(ISBLANK('Curs, Seminar'!C19)), IF(H15=0,"n/p", IF(AND(H15>=$J$3,H15<=$K$3),$L$3, IF(AND(H15>=$J$4,H15<=$K$4),$L$4, IF(AND(H15>=$J$5,H15<=$K$5),$L$5, IF(AND(H15>=$J$6,H15<=$K$6),$L$6, IF(AND(H15>=$J$7,H15<=$K$7),$L$7, IF(AND(H15>=$J$8,H15<=$K$8),$L$8, IF(AND(H15>=$J$9,H15<=$K$9),$L$9, IF(AND(H15>=$J$10,H15<=$K$10),$L$10, IF(AND(H15>=$J$11,H15<=$K$11),$L$11)))))))))), "")
A16: =IF(NOT(ISBLANK('Curs, Seminar'!B20)),'Curs, Seminar'!B20,"") | B16: =IF(NOT(ISBLANK('Curs, Seminar'!C20)),'Curs, Seminar'!C20,"") | H16: =IF(NOT(ISBLANK('Curs, Seminar'!C20)),ROUND(SUM(C16:G16),0),"") | I16: =IF(NOT(ISBLANK('Curs, Seminar'!C20)), IF(H16=0,"n/p", IF(AND(H16>=$J$3,H16<=$K$3),$L$3, IF(AND(H16>=$J$4,H16<=$K$4),$L$4, IF(AND(H16>=$J$5,H16<=$K$5),$L$5, IF(AND(H16>=$J$6,H16<=$K$6),$L$6, IF(AND(H16>=$J$7,H16<=$K$7),$L$7, IF(AND(H16>=$J$8,H16<=$K$8),$L$8, IF(AND(H16>=$J$9,H16<=$K$9),$L$9, IF(AND(H16>=$J$10,H16<=$K$10),$L$10, IF(AND(H16>=$J$11,H16<=$K$11),$L$11)))))))))), "")
A17: =IF(NOT(ISBLANK('Curs, Seminar'!B21)),'Curs, Seminar'!B21,"") | B17: =IF(NOT(ISBLANK('Curs, Seminar'!C21)),'Curs, Seminar'!C21,"") | H17: =IF(NOT(ISBLANK('Curs, Seminar'!C21)),ROUND(SUM(C17:G17),0),"") | I17: =IF(NOT(ISBLANK('Curs, Seminar'!C21)), IF(H17=0,"n/p", IF(AND(H17>=$J$3,H17<=$K$3),$L$3, IF(AND(H17>=$J$4,H17<=$K$4),$L$4, IF(AND(H17>=$J$5,H17<=$K$5),$L$5, IF(AND(H17>=$J$6,H17<=$K$6),$L$6, IF(AND(H17>=$J$7,H17<=$K$7),$L$7, IF(AND(H17>=$J$8,H17<=$K$8),$L$8, IF(AND(H17>=$J$9,H17<=$K$9),$L$9, IF(AND(H17>=$J$10,H17<=$K$10),$L$10, IF(AND(H17>=$J$11,H17<=$K$11),$L$11)))))))))), "")
A18: =IF(NOT(ISBLANK('Curs, Seminar'!B22)),'Curs, Seminar'!B22,"") | B18: =IF(NOT(ISBLANK('Curs, Seminar'!C22)),'Curs, Seminar'!C22,"") | H18: =IF(NOT(ISBLANK('Curs, Seminar'!C22)),ROUND(SUM(C18:G18),0),"") | I18: =IF(NOT(ISBLANK('Curs, Seminar'!C22)), IF(H18=0,"n/p", IF(AND(H18>=$J$3,H18<=$K$3),$L$3, IF(AND(H18>=$J$4,H18<=$K$4),$L$4, IF(AND(H18>=$J$5,H18<=$K$5),$L$5, IF(AND(H18>=$J$6,H18<=$K$6),$L$6, IF(AND(H18>=$J$7,H18<=$K$7),$L$7, IF(AND(H18>=$J$8,H18<=$K$8),$L$8, IF(AND(H18>=$J$9,H18<=$K$9),$L$9, IF(AND(H18>=$J$10,H18<=$K$10),$L$10, IF(AND(H18>=$J$11,H18<=$K$11),$L$11)))))))))), "")
A19: =IF(NOT(ISBLANK('Curs, Seminar'!B23)),'Curs, Seminar'!B23,"") | B19: =IF(NOT(ISBLANK('Curs, Seminar'!C23)),'Curs, Seminar'!C23,"") | H19: =IF(NOT(ISBLANK('Curs, Seminar'!C23)),ROUND(SUM(C19:G19),0),"") | I19: =IF(NOT(ISBLANK('Curs, Seminar'!C23)), IF(H19=0,"n/p", IF(AND(H19>=$J$3,H19<=$K$3),$L$3, IF(AND(H19>=$J$4,H19<=$K$4),$L$4, IF(AND(H19>=$J$5,H19<=$K$5),$L$5, IF(AND(H19>=$J$6,H19<=$K$6),$L$6, IF(AND(H19>=$J$7,H19<=$K$7),$L$7, IF(AND(H19>=$J$8,H19<=$K$8),$L$8, IF(AND(H19>=$J$9,H19<=$K$9),$L$9, IF(AND(H19>=$J$10,H19<=$K$10),$L$10, IF(AND(H19>=$J$11,H19<=$K$11),$L$11)))))))))), "")
A20: =IF(NOT(ISBLANK('Curs, Seminar'!B24)),'Curs, Seminar'!B24,"") | B20: =IF(NOT(ISBLANK('Curs, Seminar'!C24)),'Curs, Seminar'!C24,"") | H20: =IF(NOT(ISBLANK('Curs, Seminar'!C24)),ROUND(SUM(C20:G20),0),"") | I20: =IF(NOT(ISBLANK('Curs, Seminar'!C24)), IF(H20=0,"n/p", IF(AND(H20>=$J$3,H20<=$K$3),$L$3, IF(AND(H20>=$J$4,H20<=$K$4),$L$4, IF(AND(H20>=$J$5,H20<=$K$5),$L$5, IF(AND(H20>=$J$6,H20<=$K$6),$L$6, IF(AND(H20>=$J$7,H20<=$K$7),$L$7, IF(AND(H20>=$J$8,H20<=$K$8),$L$8, IF(AND(H20>=$J$9,H20<=$K$9),$L$9, IF(AND(H20>=$J$10,H20<=$K$10),$L$10, IF(AND(H20>=$J$11,H20<=$K$11),$L$11)))))))))), "")
A21: =IF(NOT(ISBLANK('Curs, Seminar'!B25)),'Curs, Seminar'!B25,"") | B21: =IF(NOT(ISBLANK('Curs, Seminar'!C25)),'Curs, Seminar'!C25,"") | H21: =IF(NOT(ISBLANK('Curs, Seminar'!C25)),ROUND(SUM(C21:G21),0),"") | I21: =IF(NOT(ISBLANK('Curs, Seminar'!C25)), IF(H21=0,"n/p", IF(AND(H21>=$J$3,H21<=$K$3),$L$3, IF(AND(H21>=$J$4,H21<=$K$4),$L$4, IF(AND(H21>=$J$5,H21<=$K$5),$L$5, IF(AND(H21>=$J$6,H21<=$K$6),$L$6, IF(AND(H21>=$J$7,H21<=$K$7),$L$7, IF(AND(H21>=$J$8,H21<=$K$8),$L$8, IF(AND(H21>=$J$9,H21<=$K$9),$L$9, IF(AND(H21>=$J$10,H21<=$K$10),$L$10, IF(AND(H21>=$J$11,H21<=$K$11),$L$11)))))))))), "")
A22: =IF(NOT(ISBLANK('Curs, Seminar'!B26)),'Curs, Seminar'!B26,"") | B22: =IF(NOT(ISBLANK('Curs, Seminar'!C26)),'Curs, Seminar'!C26,"") | H22: =IF(NOT(ISBLANK('Curs, Seminar'!C26)),ROUND(SUM(C22:G22),0),"") | I22: =IF(NOT(ISBLANK('Curs, Seminar'!C26)), IF(H22=0,"n/p", IF(AND(H22>=$J$3,H22<=$K$3),$L$3, IF(AND(H22>=$J$4,H22<=$K$4),$L$4, IF(AND(H22>=$J$5,H22<=$K$5),$L$5, IF(AND(H22>=$J$6,H22<=$K$6),$L$6, IF(AND(H22>=$J$7,H22<=$K$7),$L$7, IF(AND(H22>=$J$8,H22<=$K$8),$L$8, IF(AND(H22>=$J$9,H22<=$K$9),$L$9, IF(AND(H22>=$J$10,H22<=$K$10),$L$10, IF(AND(H22>=$J$11,H22<=$K$11),$L$11)))))))))), "")
A23: =IF(NOT(ISBLANK('Curs, Seminar'!B27)),'Curs, Seminar'!B27,"") | B23: =IF(NOT(ISBLANK('Curs, Seminar'!C27)),'Curs, Seminar'!C27,"") | H23: =IF(NOT(ISBLANK('Curs, Seminar'!C27)),ROUND(SUM(C23:G23),0),"") | I23: =IF(NOT(ISBLANK('Curs, Seminar'!C27)), IF(H23=0,"n/p", IF(AND(H23>=$J$3,H23<=$K$3),$L$3, IF(AND(H23>=$J$4,H23<=$K$4),$L$4, IF(AND(H23>=$J$5,H23<=$K$5),$L$5, IF(AND(H23>=$J$6,H23<=$K$6),$L$6, IF(AND(H23>=$J$7,H23<=$K$7),$L$7, IF(AND(H23>=$J$8,H23<=$K$8),$L$8, IF(AND(H23>=$J$9,H23<=$K$9),$L$9, IF(AND(H23>=$J$10,H23<=$K$10),$L$10, IF(AND(H23>=$J$11,H23<=$K$11),$L$11)))))))))), "")
A24: =IF(NOT(ISBLANK('Curs, Seminar'!B28)),'Curs, Seminar'!B28,"") | B24: =IF(NOT(ISBLANK('Curs, Seminar'!C28)),'Curs, Seminar'!C28,"") | H24: =IF(NOT(ISBLANK('Curs, Seminar'!C28)),ROUND(SUM(C24:G24),0),"") | I24: =IF(NOT(ISBLANK('Curs, Seminar'!C28)), IF(H24=0,"n/p", IF(AND(H24>=$J$3,H24<=$K$3),$L$3, IF(AND(H24>=$J$4,H24<=$K$4),$L$4, IF(AND(H24>=$J$5,H24<=$K$5),$L$5, IF(AND(H24>=$J$6,H24<=$K$6),$L$6, IF(AND(H24>=$J$7,H24<=$K$7),$L$7, IF(AND(H24>=$J$8,H24<=$K$8),$L$8, IF(AND(H24>=$J$9,H24<=$K$9),$L$9, IF(AND(H24>=$J$10,H24<=$K$10),$L$10, IF(AND(H24>=$J$11,H24<=$K$11),$L$11)))))))))), "")
A25: =IF(NOT(ISBLANK('Curs, Seminar'!B29)),'Curs, Seminar'!B29,"") | B25: =IF(NOT(ISBLANK('Curs, Seminar'!C29)),'Curs, Seminar'!C29,"") | H25: =IF(NOT(ISBLANK('Curs, Seminar'!C29)),ROUND(SUM(C25:G25),0),"") | I25: =IF(NOT(ISBLANK('Curs, Seminar'!C29)), IF(H25=0,"n/p", IF(AND(H25>=$J$3,H25<=$K$3),$L$3, IF(AND(H25>=$J$4,H25<=$K$4),$L$4, IF(AND(H25>=$J$5,H25<=$K$5),$L$5, IF(AND(H25>=$J$6,H25<=$K$6),$L$6, IF(AND(H25>=$J$7,H25<=$K$7),$L$7, IF(AND(H25>=$J$8,H25<=$K$8),$L$8, IF(AND(H25>=$J$9,H25<=$K$9),$L$9, IF(AND(H25>=$J$10,H25<=$K$10),$L$10, IF(AND(H25>=$J$11,H25<=$K$11),$L$11)))))))))), "")
... A101: =IF(NOT(ISBLANK('Curs, Seminar'!B105)),'Curs, Seminar'!B105,"") | B101: =IF(NOT(ISBLANK('Curs, Seminar'!C105)),'Curs, Seminar'!C105,"") | H101: =IF(NOT(ISBLANK('Curs, Seminar'!C105)),ROUND(SUM(C101:G101),0),"") | I101: =IF(NOT(ISBLANK('Curs, Seminar'!C105)), IF(H101=0,"n/p", IF(AND(H101>=$J$3,H101<=$K$3),$L$3, IF(AND(H101>=$J$4,H101<=$K$4),$L$4, IF(AND(H101>=$J$5,H101<=$K$5),$L$5, IF(AND(H101>=$J$6,H101<=$K$6),$L$6, IF(AND(H101>=$J$7,H101<=$K$7),$L$7, IF(AND(H101>=$J$8,H101<=$K$8),$L$8, IF(AND(H101>=$J$9,H101<=$K$9),$L$9, IF(AND(H101>=$J$10,H101<=$K$10),$L$10, IF(AND(H101>=$J$11,H101<=$K$11),$L$11)))))))))), "")

Sheet L. Indiv.
A1: Nr. | B1: Nume, Prenume | C1: Var | D1: S1 | E1: C2 | F1: C3 | G1: D3 | H1: Nota | J1: Statistica
A2: =IF(NOT(ISBLANK('Curs, Seminar'!B6)),'Curs, Seminar'!B6,"") -> 1 | B2: =IF(NOT(ISBLANK('Curs, Seminar'!C6)),'Curs, Seminar'!C6,"") -> Nume, Prenume | C2: 01 | H2: =IF(NOT(ISBLANK('Curs, Seminar'!C6)),IF(AND(NOT(ISBLANK(D2)),NOT(ISBLANK(G2)),D2>=5,G2>=5),ROUND(AVERAGE(D2:G2),0),"n/p"),"") -> n/p | J2: Nota | K2: Nr de note
A3: =IF(NOT(ISBLANK('Curs, Seminar'!B7)),'Curs, Seminar'!B7,"") | B3: =IF(NOT(ISBLANK('Curs, Seminar'!C7)),'Curs, Seminar'!C7,"") | C3: 02 | H3: =IF(NOT(ISBLANK('Curs, Seminar'!C7)),IF(AND(NOT(ISBLANK(D3)),NOT(ISBLANK(G3)),D3>=5,G3>=5),ROUND(AVERAGE(D3:G3),0),"n/p"),"") | J3: 1 | K3: =COUNTIF($H$2:$H$101,J3) -> 0
A4: =IF(NOT(ISBLANK('Curs, Seminar'!B8)),'Curs, Seminar'!B8,"") | B4: =IF(NOT(ISBLANK('Curs, Seminar'!C8)),'Curs, Seminar'!C8,"") | H4: =IF(NOT(ISBLANK('Curs, Seminar'!C8)),IF(AND(NOT(ISBLANK(D4)),NOT(ISBLANK(G4)),D4>=5,G4>=5),ROUND(AVERAGE(D4:G4),0),"n/p"),"") | J4: 2 | K4: =COUNTIF($H$2:$H$101,J4) -> 0
A5: =IF(NOT(ISBLANK('Curs, Seminar'!B9)),'Curs, Seminar'!B9,"") | B5: =IF(NOT(ISBLANK('Curs, Seminar'!C9)),'Curs, Seminar'!C9,"") | H5: =IF(NOT(ISBLANK('Curs, Seminar'!C9)),IF(AND(NOT(ISBLANK(D5)),NOT(ISBLANK(G5)),D5>=5,G5>=5),ROUND(AVERAGE(D5:G5),0),"n/p"),"") | J5: 3 | K5: =COUNTIF($H$2:$H$101,J5) -> 0
A6: =IF(NOT(ISBLANK('Curs, Seminar'!B10)),'Curs, Seminar'!B10,"") | B6: =IF(NOT(ISBLANK('Curs, Seminar'!C10)),'Curs, Seminar'!C10,"") | H6: =IF(NOT(ISBLANK('Curs, Seminar'!C10)),IF(AND(NOT(ISBLANK(D6)),NOT(ISBLANK(G6)),D6>=5,G6>=5),ROUND(AVERAGE(D6:G6),0),"n/p"),"") | J6: 4 | K6: =COUNTIF($H$2:$H$101,J6) -> 0
A7: =IF(NOT(ISBLANK('Curs, Seminar'!B11)),'Curs, Seminar'!B11,"") | B7: =IF(NOT(ISBLANK('Curs, Seminar'!C11)),'Curs, Seminar'!C11,"") | H7: =IF(NOT(ISBLANK('Curs, Seminar'!C11)),IF(AND(NOT(ISBLANK(D7)),NOT(ISBLANK(G7)),D7>=5,G7>=5),ROUND(AVERAGE(D7:G7),0),"n/p"),"") | J7: 5 | K7: =COUNTIF($H$2:$H$101,J7) -> 0
A8: =IF(NOT(ISBLANK('Curs, Seminar'!B12)),'Curs, Seminar'!B12,"") | B8: =IF(NOT(ISBLANK('Curs, Seminar'!C12)),'Curs, Seminar'!C12,"") | H8: =IF(NOT(ISBLANK('Curs, Seminar'!C12)),IF(AND(NOT(ISBLANK(D8)),NOT(ISBLANK(G8)),D8>=5,G8>=5),ROUND(AVERAGE(D8:G8),0),"n/p"),"") | J8: 6 | K8: =COUNTIF($H$2:$H$101,J8) -> 0
A9: =IF(NOT(ISBLANK('Curs, Seminar'!B13)),'Curs, Seminar'!B13,"") | B9: =IF(NOT(ISBLANK('Curs, Seminar'!C13)),'Curs, Seminar'!C13,"") | H9: =IF(NOT(ISBLANK('Curs, Seminar'!C13)),IF(AND(NOT(ISBLANK(D9)),NOT(ISBLANK(G9)),D9>=5,G9>=5),ROUND(AVERAGE(D9:G9),0),"n/p"),"") | J9: 7 | K9: =COUNTIF($H$2:$H$101,J9) -> 0
A10: =IF(NOT(ISBLANK('Curs, Seminar'!B14)),'Curs, Seminar'!B14,"") | B10: =IF(NOT(ISBLANK('Curs, Seminar'!C14)),'Curs, Seminar'!C14,"") | H10: =IF(NOT(ISBLANK('Curs, Seminar'!C14)),IF(AND(NOT(ISBLANK(D10)),NOT(ISBLANK(G10)),D10>=5,G10>=5),ROUND(AVERAGE(D10:G10),0),"n/p"),"") | J10: 8 | K10: =COUNTIF($H$2:$H$101,J10) -> 0
A11: =IF(NOT(ISBLANK('Curs, Seminar'!B15)),'Curs, Seminar'!B15,"") | B11: =IF(NOT(ISBLANK('Curs, Seminar'!C15)),'Curs, Seminar'!C15,"") | H11: =IF(NOT(ISBLANK('Curs, Seminar'!C15)),IF(AND(NOT(ISBLANK(D11)),NOT(ISBLANK(G11)),D11>=5,G11>=5),ROUND(AVERAGE(D11:G11),0),"n/p"),"") | J11: 9 | K11: =COUNTIF($H$2:$H$101,J11) -> 0
A12: =IF(NOT(ISBLANK('Curs, Seminar'!B16)),'Curs, Seminar'!B16,"") | B12: =IF(NOT(ISBLANK('Curs, Seminar'!C16)),'Curs, Seminar'!C16,"") | H12: =IF(NOT(ISBLANK('Curs, Seminar'!C16)),IF(AND(NOT(ISBLANK(D12)),NOT(ISBLANK(G12)),D12>=5,G12>=5),ROUND(AVERAGE(D12:G12),0),"n/p"),"") | J12: 10 | K12: =COUNTIF($H$2:$H$101,J12) -> 0
A13: =IF(NOT(ISBLANK('Curs, Seminar'!B17)),'Curs, Seminar'!B17,"") | B13: =IF(NOT(ISBLANK('Curs, Seminar'!C17)),'Curs, Seminar'!C17,"") | H13: =IF(NOT(ISBLANK('Curs, Seminar'!C17)),IF(AND(NOT(ISBLANK(D13)),NOT(ISBLANK(G13)),D13>=5,G13>=5),ROUND(AVERAGE(D13:G13),0),"n/p"),"") | J13: n/p | K13: =COUNTIF($H$2:$H$101,J13) -> 1
A14: =IF(NOT(ISBLANK('Curs, Seminar'!B18)),'Curs, Seminar'!B18,"") | B14: =IF(NOT(ISBLANK('Curs, Seminar'!C18)),'Curs, Seminar'!C18,"") | H14: =IF(NOT(ISBLANK('Curs, Seminar'!C18)),IF(AND(NOT(ISBLANK(D14)),NOT(ISBLANK(G14)),D14>=5,G14>=5),ROUND(AVERAGE(D14:G14),0),"n/p"),"")
A15: =IF(NOT(ISBLANK('Curs, Seminar'!B19)),'Curs, Seminar'!B19,"") | B15: =IF(NOT(ISBLANK('Curs, Seminar'!C19)),'Curs, Seminar'!C19,"") | H15: =IF(NOT(ISBLANK('Curs, Seminar'!C19)),IF(AND(NOT(ISBLANK(D15)),NOT(ISBLANK(G15)),D15>=5,G15>=5),ROUND(AVERAGE(D15:G15),0),"n/p"),"")
A16: =IF(NOT(ISBLANK('Curs, Seminar'!B20)),'Curs, Seminar'!B20,"") | B16: =IF(NOT(ISBLANK('Curs, Seminar'!C20)),'Curs, Seminar'!C20,"") | H16: =IF(NOT(ISBLANK('Curs, Seminar'!C20)),IF(AND(NOT(ISBLANK(D16)),NOT(ISBLANK(G16)),D16>=5,G16>=5),ROUND(AVERAGE(D16:G16),0),"n/p"),"")
A17: =IF(NOT(ISBLANK('Curs, Seminar'!B21)),'Curs, Seminar'!B21,"") | B17: =IF(NOT(ISBLANK('Curs, Seminar'!C21)),'Curs, Seminar'!C21,"") | H17: =IF(NOT(ISBLANK('Curs, Seminar'!C21)),IF(AND(NOT(ISBLANK(D17)),NOT(ISBLANK(G17)),D17>=5,G17>=5),ROUND(AVERAGE(D17:G17),0),"n/p"),"")
A18: =IF(NOT(ISBLANK('Curs, Seminar'!B22)),'Curs, Seminar'!B22,"") | B18: =IF(NOT(ISBLANK('Curs, Seminar'!C22)),'Curs, Seminar'!C22,"") | H18: =IF(NOT(ISBLANK('Curs, Seminar'!C22)),IF(AND(NOT(ISBLANK(D18)),NOT(ISBLANK(G18)),D18>=5,G18>=5),ROUND(AVERAGE(D18:G18),0),"n/p"),"")
A19: =IF(NOT(ISBLANK('Curs, Seminar'!B23)),'Curs, Seminar'!B23,"") | B19: =IF(NOT(ISBLANK('Curs, Seminar'!C23)),'Curs, Seminar'!C23,"") | H19: =IF(NOT(ISBLANK('Curs, Seminar'!C23)),IF(AND(NOT(ISBLANK(D19)),NOT(ISBLANK(G19)),D19>=5,G19>=5),ROUND(AVERAGE(D19:G19),0),"n/p"),"")
A20: =IF(NOT(ISBLANK('Curs, Seminar'!B24)),'Curs, Seminar'!B24,"") | B20: =IF(NOT(ISBLANK('Curs, Seminar'!C24)),'Curs, Seminar'!C24,"") | H20: =IF(NOT(ISBLANK('Curs, Seminar'!C24)),IF(AND(NOT(ISBLANK(D20)),NOT(ISBLANK(G20)),D20>=5,G20>=5),ROUND(AVERAGE(D20:G20),0),"n/p"),"")
A21: =IF(NOT(ISBLANK('Curs, Seminar'!B25)),'Curs, Seminar'!B25,"") | B21: =IF(NOT(ISBLANK('Curs, Seminar'!C25)),'Curs, Seminar'!C25,"") | H21: =IF(NOT(ISBLANK('Curs, Seminar'!C25)),IF(AND(NOT(ISBLANK(D21)),NOT(ISBLANK(G21)),D21>=5,G21>=5),ROUND(AVERAGE(D21:G21),0),"n/p"),"")
A22: =IF(NOT(ISBLANK('Curs, Seminar'!B26)),'Curs, Seminar'!B26,"") | B22: =IF(NOT(ISBLANK('Curs, Seminar'!C26)),'Curs, Seminar'!C26,"") | H22: =IF(NOT(ISBLANK('Curs, Seminar'!C26)),IF(AND(NOT(ISBLANK(D22)),NOT(ISBLANK(G22)),D22>=5,G22>=5),ROUND(AVERAGE(D22:G22),0),"n/p"),"")
A23: =IF(NOT(ISBLANK('Curs, Seminar'!B27)),'Curs, Seminar'!B27,"") | B23: =IF(NOT(ISBLANK('Curs, Seminar'!C27)),'Curs, Seminar'!C27,"") | H23: =IF(NOT(ISBLANK('Curs, Seminar'!C27)),IF(AND(NOT(ISBLANK(D23)),NOT(ISBLANK(G23)),D23>=5,G23>=5),ROUND(AVERAGE(D23:G23),0),"n/p"),"")
A24: =IF(NOT(ISBLANK('Curs, Seminar'!B28)),'Curs, Seminar'!B28,"") | B24: =IF(NOT(ISBLANK('Curs, Seminar'!C28)),'Curs, Seminar'!C28,"") | H24: =IF(NOT(ISBLANK('Curs, Seminar'!C28)),IF(AND(NOT(ISBLANK(D24)),NOT(ISBLANK(G24)),D24>=5,G24>=5),ROUND(AVERAGE(D24:G24),0),"n/p"),"")
A25: =IF(NOT(ISBLANK('Curs, Seminar'!B29)),'Curs, Seminar'!B29,"") | B25: =IF(NOT(ISBLANK('Curs, Seminar'!C29)),'Curs, Seminar'!C29,"") | H25: =IF(NOT(ISBLANK('Curs, Seminar'!C29)),IF(AND(NOT(ISBLANK(D25)),NOT(ISBLANK(G25)),D25>=5,G25>=5),ROUND(AVERAGE(D25:G25),0),"n/p"),"")
... A101: =IF(NOT(ISBLANK('Curs, Seminar'!B105)),'Curs, Seminar'!B105,"") | B101: =IF(NOT(ISBLANK('Curs, Seminar'!C105)),'Curs, Seminar'!C105,"") | H101: =IF(NOT(ISBLANK('Curs, Seminar'!C105)),IF(AND(NOT(ISBLANK(D101)),NOT(ISBLANK(G101)),D101>=5,G101>=5),ROUND(AVERAGE(D101:G101),0),"n/p"),"")
H102: =IF(NOT(ISBLANK('Curs, Seminar'!C106)),IF(AND(NOT(ISBLANK(D102)),NOT(ISBLANK(G102))),ROUND(AVERAGE(D102:G102),0),"n/p"),"")
H103: =IF(NOT(ISBLANK('Curs, Seminar'!C107)),IF(AND(NOT(ISBLANK(D103)),NOT(ISBLANK(G103))),ROUND(AVERAGE(D103:G103),0),"n/p"),"")
H104: =IF(NOT(ISBLANK('Curs, Seminar'!C108)),IF(AND(NOT(ISBLANK(D104)),NOT(ISBLANK(G104))),ROUND(AVERAGE(D104:G104),0),"n/p"),"")

Sheet Examen
A1: Nr. | B1: Nume, Prenume | C1: item 1 6 p | D1: item 2 10 p | E1: item 3 14 p | F1: Pctj Total | G1: Nota | H1: Baremul de evaluare | K1: Statistica
A2: =IF(NOT(ISBLANK('Curs, Seminar'!B6)),'Curs, Seminar'!B6,"") -> 1 | B2: =IF(NOT(ISBLANK('Curs, Seminar'!C6)),'Curs, Seminar'!C6,"") -> Nume, Prenume | F2: =IF(NOT(ISBLANK('Curs, Seminar'!C6)), IF('Curs, Seminar'!Z6,"Eliberat", ROUND(SUM(C2:E2),0)), "") -> 0 | G2: =IF(NOT(ISBLANK('Curs, Seminar'!C6)), IF('Curs, Seminar'!Z6,'Curs, Seminar'!Z6, IF(F2=0,"n/p", IF(AND(F2>=$H$3,F2<=$I$3),$J$3, IF(AND(F2>=$H$4,F2<=$I$4),$J$4, IF(AND(F2>=$H$5,F2<=$I$5),$J$5, IF(AND(F2>=$H$6,F2<=$I$6),$J$6, IF(AND(F2>=$H$7,F2<=$I$7),$J$7, IF(AND(F2>=$H$8,F2<=$I$8),$J$8, IF(AND(F2>=$H$9,F2<=$I$9),$J$9, IF(AND(F2>=$H$10,F2<=$I$10),$J$10, IF(AND(F2>=$H$11,F2<=$I$11),$J$11))))))))))), "") -> n/p | H2: Punctajul acumulat | J2: Nota | K2: Nota | L2: Nr de note
A3: =IF(NOT(ISBLANK('Curs, Seminar'!B7)),'Curs, Seminar'!B7,"") | B3: =IF(NOT(ISBLANK('Curs, Seminar'!C7)),'Curs, Seminar'!C7,"") | F3: =IF(NOT(ISBLANK('Curs, Seminar'!C7)), IF('Curs, Seminar'!Z7,"Eliberat", ROUND(SUM(C3:E3),0)), "") | G3: =IF(NOT(ISBLANK('Curs, Seminar'!C7)), IF('Curs, Seminar'!Z7,'Curs, Seminar'!Z7, IF(F3=0,"n/p", IF(AND(F3>=$H$3,F3<=$I$3),$J$3, IF(AND(F3>=$H$4,F3<=$I$4),$J$4, IF(AND(F3>=$H$5,F3<=$I$5),$J$5, IF(AND(F3>=$H$6,F3<=$I$6),$J$6, IF(AND(F3>=$H$7,F3<=$I$7),$J$7, IF(AND(F3>=$H$8,F3<=$I$8),$J$8, IF(AND(F3>=$H$9,F3<=$I$9),$J$9, IF(AND(F3>=$H$10,F3<=$I$10),$J$10, IF(AND(F3>=$H$11,F3<=$I$11),$J$11))))))))))), "") | H3: 0 | I3: 3 | J3: 2 | K3: 1 | L3: =COUNTIF($G$2:$G101,K3) -> 0
A4: =IF(NOT(ISBLANK('Curs, Seminar'!B8)),'Curs, Seminar'!B8,"") | B4: =IF(NOT(ISBLANK('Curs, Seminar'!C8)),'Curs, Seminar'!C8,"") | F4: =IF(NOT(ISBLANK('Curs, Seminar'!C8)), IF('Curs, Seminar'!Z8,"Eliberat", ROUND(SUM(C4:E4),0)), "") | G4: =IF(NOT(ISBLANK('Curs, Seminar'!C8)), IF('Curs, Seminar'!Z8,'Curs, Seminar'!Z8, IF(F4=0,"n/p", IF(AND(F4>=$H$3,F4<=$I$3),$J$3, IF(AND(F4>=$H$4,F4<=$I$4),$J$4, IF(AND(F4>=$H$5,F4<=$I$5),$J$5, IF(AND(F4>=$H$6,F4<=$I$6),$J$6, IF(AND(F4>=$H$7,F4<=$I$7),$J$7, IF(AND(F4>=$H$8,F4<=$I$8),$J$8, IF(AND(F4>=$H$9,F4<=$I$9),$J$9, IF(AND(F4>=$H$10,F4<=$I$10),$J$10, IF(AND(F4>=$H$11,F4<=$I$11),$J$11))))))))))), "") | H4: 4 | I4: 7 | J4: 3 | K4: 2 | L4: =COUNTIF($G$2:$G102,K4) -> 0
A5: =IF(NOT(ISBLANK('Curs, Seminar'!B9)),'Curs, Seminar'!B9,"") | B5: =IF(NOT(ISBLANK('Curs, Seminar'!C9)),'Curs, Seminar'!C9,"") | F5: =IF(NOT(ISBLANK('Curs, Seminar'!C9)), IF('Curs, Seminar'!Z9,"Eliberat", ROUND(SUM(C5:E5),0)), "") | G5: =IF(NOT(ISBLANK('Curs, Seminar'!C9)), IF('Curs, Seminar'!Z9,'Curs, Seminar'!Z9, IF(F5=0,"n/p", IF(AND(F5>=$H$3,F5<=$I$3),$J$3, IF(AND(F5>=$H$4,F5<=$I$4),$J$4, IF(AND(F5>=$H$5,F5<=$I$5),$J$5, IF(AND(F5>=$H$6,F5<=$I$6),$J$6, IF(AND(F5>=$H$7,F5<=$I$7),$J$7, IF(AND(F5>=$H$8,F5<=$I$8),$J$8, IF(AND(F5>=$H$9,F5<=$I$9),$J$9, IF(AND(F5>=$H$10,F5<=$I$10),$J$10, IF(AND(F5>=$H$11,F5<=$I$11),$J$11))))))))))), "") | H5: 8 | I5: 12 | J5: 4 | K5: 3 | L5: =COUNTIF($G$2:$G103,K5) -> 0
A6: =IF(NOT(ISBLANK('Curs, Seminar'!B10)),'Curs, Seminar'!B10,"") | B6: =IF(NOT(ISBLANK('Curs, Seminar'!C10)),'Curs, Seminar'!C10,"") | F6: =IF(NOT(ISBLANK('Curs, Seminar'!C10)), IF('Curs, Seminar'!Z10,"Eliberat", ROUND(SUM(C6:E6),0)), "") | G6: =IF(NOT(ISBLANK('Curs, Seminar'!C10)), IF('Curs, Seminar'!Z10,'Curs, Seminar'!Z10, IF(F6=0,"n/p", IF(AND(F6>=$H$3,F6<=$I$3),$J$3, IF(AND(F6>=$H$4,F6<=$I$4),$J$4, IF(AND(F6>=$H$5,F6<=$I$5),$J$5, IF(AND(F6>=$H$6,F6<=$I$6),$J$6, IF(AND(F6>=$H$7,F6<=$I$7),$J$7, IF(AND(F6>=$H$8,F6<=$I$8),$J$8, IF(AND(F6>=$H$9,F6<=$I$9),$J$9, IF(AND(F6>=$H$10,F6<=$I$10),$J$10, IF(AND(F6>=$H$11,F6<=$I$11),$J$11))))))))))), "") | H6: 13 | I6: 15 | J6: 5 | K6: 4 | L6: =COUNTIF($G$2:$G104,K6) -> 0
A7: =IF(NOT(ISBLANK('Curs, Seminar'!B11)),'Curs, Seminar'!B11,"") | B7: =IF(NOT(ISBLANK('Curs, Seminar'!C11)),'Curs, Seminar'!C11,"") | F7: =IF(NOT(ISBLANK('Curs, Seminar'!C11)), IF('Curs, Seminar'!Z11,"Eliberat", ROUND(SUM(C7:E7),0)), "") | G7: =IF(NOT(ISBLANK('Curs, Seminar'!C11)), IF('Curs, Seminar'!Z11,'Curs, Seminar'!Z11, IF(F7=0,"n/p", IF(AND(F7>=$H$3,F7<=$I$3),$J$3, IF(AND(F7>=$H$4,F7<=$I$4),$J$4, IF(AND(F7>=$H$5,F7<=$I$5),$J$5, IF(AND(F7>=$H$6,F7<=$I$6),$J$6, IF(AND(F7>=$H$7,F7<=$I$7),$J$7, IF(AND(F7>=$H$8,F7<=$I$8),$J$8, IF(AND(F7>=$H$9,F7<=$I$9),$J$9, IF(AND(F7>=$H$10,F7<=$I$10),$J$10, IF(AND(F7>=$H$11,F7<=$I$11),$J$11))))))))))), "") | H7: 16 | I7: 18 | J7: 6 | K7: 5 | L7: =COUNTIF($G$2:$G105,K7) -> 0
A8: =IF(NOT(ISBLANK('Curs, Seminar'!B12)),'Curs, Seminar'!B12,"") | B8: =IF(NOT(ISBLANK('Curs, Seminar'!C12)),'Curs, Seminar'!C12,"") | F8: =IF(NOT(ISBLANK('Curs, Seminar'!C12)), IF('Curs, Seminar'!Z12,"Eliberat", ROUND(SUM(C8:E8),0)), "") | G8: =IF(NOT(ISBLANK('Curs, Seminar'!C12)), IF('Curs, Seminar'!Z12,'Curs, Seminar'!Z12, IF(F8=0,"n/p", IF(AND(F8>=$H$3,F8<=$I$3),$J$3, IF(AND(F8>=$H$4,F8<=$I$4),$J$4, IF(AND(F8>=$H$5,F8<=$I$5),$J$5, IF(AND(F8>=$H$6,F8<=$I$6),$J$6, IF(AND(F8>=$H$7,F8<=$I$7),$J$7, IF(AND(F8>=$H$8,F8<=$I$8),$J$8, IF(AND(F8>=$H$9,F8<=$I$9),$J$9, IF(AND(F8>=$H$10,F8<=$I$10),$J$10, IF(AND(F8>=$H$11,F8<=$I$11),$J$11))))))))))), "") | H8: 19 | I8: 21 | J8: 7 | K8: 6 | L8: =COUNTIF($G$2:$G106,K8) -> 0
A9: =IF(NOT(ISBLANK('Curs, Seminar'!B13)),'Curs, Seminar'!B13,"") | B9: =IF(NOT(ISBLANK('Curs, Seminar'!C13)),'Curs, Seminar'!C13,"") | F9: =IF(NOT(ISBLANK('Curs, Seminar'!C13)), IF('Curs, Seminar'!Z13,"Eliberat", ROUND(SUM(C9:E9),0)), "") | G9: =IF(NOT(ISBLANK('Curs, Seminar'!C13)), IF('Curs, Seminar'!Z13,'Curs, Seminar'!Z13, IF(F9=0,"n/p", IF(AND(F9>=$H$3,F9<=$I$3),$J$3, IF(AND(F9>=$H$4,F9<=$I$4),$J$4, IF(AND(F9>=$H$5,F9<=$I$5),$J$5, IF(AND(F9>=$H$6,F9<=$I$6),$J$6, IF(AND(F9>=$H$7,F9<=$I$7),$J$7, IF(AND(F9>=$H$8,F9<=$I$8),$J$8, IF(AND(F9>=$H$9,F9<=$I$9),$J$9, IF(AND(F9>=$H$10,F9<=$I$10),$J$10, IF(AND(F9>=$H$11,F9<=$I$11),$J$11))))))))))), "") | H9: 22 | I9: 24 | J9: 8 | K9: 7 | L9: =COUNTIF($G$2:$G107,K9) -> 0
A10: =IF(NOT(ISBLANK('Curs, Seminar'!B14)),'Curs, Seminar'!B14,"") | B10: =IF(NOT(ISBLANK('Curs, Seminar'!C14)),'Curs, Seminar'!C14,"") | F10: =IF(NOT(ISBLANK('Curs, Seminar'!C14)), IF('Curs, Seminar'!Z14,"Eliberat", ROUND(SUM(C10:E10),0)), "") | G10: =IF(NOT(ISBLANK('Curs, Seminar'!C14)), IF('Curs, Seminar'!Z14,'Curs, Seminar'!Z14, IF(F10=0,"n/p", IF(AND(F10>=$H$3,F10<=$I$3),$J$3, IF(AND(F10>=$H$4,F10<=$I$4),$J$4, IF(AND(F10>=$H$5,F10<=$I$5),$J$5, IF(AND(F10>=$H$6,F10<=$I$6),$J$6, IF(AND(F10>=$H$7,F10<=$I$7),$J$7, IF(AND(F10>=$H$8,F10<=$I$8),$J$8, IF(AND(F10>=$H$9,F10<=$I$9),$J$9, IF(AND(F10>=$H$10,F10<=$I$10),$J$10, IF(AND(F10>=$H$11,F10<=$I$11),$J$11))))))))))), "") | H10: 25 | I10: 27 | J10: 9 | K10: 8 | L10: =COUNTIF($G$2:$G108,K10) -> 0
A11: =IF(NOT(ISBLANK('Curs, Seminar'!B15)),'Curs, Seminar'!B15,"") | B11: =IF(NOT(ISBLANK('Curs, Seminar'!C15)),'Curs, Seminar'!C15,"") | F11: =IF(NOT(ISBLANK('Curs, Seminar'!C15)), IF('Curs, Seminar'!Z15,"Eliberat", ROUND(SUM(C11:E11),0)), "") | G11: =IF(NOT(ISBLANK('Curs, Seminar'!C15)), IF('Curs, Seminar'!Z15,'Curs, Seminar'!Z15, IF(F11=0,"n/p", IF(AND(F11>=$H$3,F11<=$I$3),$J$3, IF(AND(F11>=$H$4,F11<=$I$4),$J$4, IF(AND(F11>=$H$5,F11<=$I$5),$J$5, IF(AND(F11>=$H$6,F11<=$I$6),$J$6, IF(AND(F11>=$H$7,F11<=$I$7),$J$7, IF(AND(F11>=$H$8,F11<=$I$8),$J$8, IF(AND(F11>=$H$9,F11<=$I$9),$J$9, IF(AND(F11>=$H$10,F11<=$I$10),$J$10, IF(AND(F11>=$H$11,F11<=$I$11),$J$11))))))))))), "") | H11: 28 | I11: 30 | J11: 10 | K11: 9 | L11: =COUNTIF($G$2:$G109,K11) -> 0
A12: =IF(NOT(ISBLANK('Curs, Seminar'!B16)),'Curs, Seminar'!B16,"") | B12: =IF(NOT(ISBLANK('Curs, Seminar'!C16)),'Curs, Seminar'!C16,"") | F12: =IF(NOT(ISBLANK('Curs, Seminar'!C16)), IF('Curs, Seminar'!Z16,"Eliberat", ROUND(SUM(C12:E12),0)), "") | G12: =IF(NOT(ISBLANK('Curs, Seminar'!C16)), IF('Curs, Seminar'!Z16,'Curs, Seminar'!Z16, IF(F12=0,"n/p", IF(AND(F12>=$H$3,F12<=$I$3),$J$3, IF(AND(F12>=$H$4,F12<=$I$4),$J$4, IF(AND(F12>=$H$5,F12<=$I$5),$J$5, IF(AND(F12>=$H$6,F12<=$I$6),$J$6, IF(AND(F12>=$H$7,F12<=$I$7),$J$7, IF(AND(F12>=$H$8,F12<=$I$8),$J$8, IF(AND(F12>=$H$9,F12<=$I$9),$J$9, IF(AND(F12>=$H$10,F12<=$I$10),$J$10, IF(AND(F12>=$H$11,F12<=$I$11),$J$11))))))))))), "") | K12: 10 | L12: =COUNTIF($G$2:$G110,K12) -> 0
A13: =IF(NOT(ISBLANK('Curs, Seminar'!B17)),'Curs, Seminar'!B17,"") | B13: =IF(NOT(ISBLANK('Curs, Seminar'!C17)),'Curs, Seminar'!C17,"") | F13: =IF(NOT(ISBLANK('Curs, Seminar'!C17)), IF('Curs, Seminar'!Z17,"Eliberat", ROUND(SUM(C13:E13),0)), "") | G13: =IF(NOT(ISBLANK('Curs, Seminar'!C17)), IF('Curs, Seminar'!Z17,'Curs, Seminar'!Z17, IF(F13=0,"n/p", IF(AND(F13>=$H$3,F13<=$I$3),$J$3, IF(AND(F13>=$H$4,F13<=$I$4),$J$4, IF(AND(F13>=$H$5,F13<=$I$5),$J$5, IF(AND(F13>=$H$6,F13<=$I$6),$J$6, IF(AND(F13>=$H$7,F13<=$I$7),$J$7, IF(AND(F13>=$H$8,F13<=$I$8),$J$8, IF(AND(F13>=$H$9,F13<=$I$9),$J$9, IF(AND(F13>=$H$10,F13<=$I$10),$J$10, IF(AND(F13>=$H$11,F13<=$I$11),$J$11))))))))))), "") | K13: n/p | L13: =COUNTIF($G$2:$G111,K13) -> 1
A14: =IF(NOT(ISBLANK('Curs, Seminar'!B18)),'Curs, Seminar'!B18,"") | B14: =IF(NOT(ISBLANK('Curs, Seminar'!C18)),'Curs, Seminar'!C18,"") | F14: =IF(NOT(ISBLANK('Curs, Seminar'!C18)), IF('Curs, Seminar'!Z18,"Eliberat", ROUND(SUM(C14:E14),0)), "") | G14: =IF(NOT(ISBLANK('Curs, Seminar'!C18)), IF('Curs, Seminar'!Z18,'Curs, Seminar'!Z18, IF(F14=0,"n/p", IF(AND(F14>=$H$3,F14<=$I$3),$J$3, IF(AND(F14>=$H$4,F14<=$I$4),$J$4, IF(AND(F14>=$H$5,F14<=$I$5),$J$5, IF(AND(F14>=$H$6,F14<=$I$6),$J$6, IF(AND(F14>=$H$7,F14<=$I$7),$J$7, IF(AND(F14>=$H$8,F14<=$I$8),$J$8, IF(AND(F14>=$H$9,F14<=$I$9),$J$9, IF(AND(F14>=$H$10,F14<=$I$10),$J$10, IF(AND(F14>=$H$11,F14<=$I$11),$J$11))))))))))), "")
A15: =IF(NOT(ISBLANK('Curs, Seminar'!B19)),'Curs, Seminar'!B19,"") | B15: =IF(NOT(ISBLANK('Curs, Seminar'!C19)),'Curs, Seminar'!C19,"") | F15: =IF(NOT(ISBLANK('Curs, Seminar'!C19)), IF('Curs, Seminar'!Z19,"Eliberat", ROUND(SUM(C15:E15),0)), "") | G15: =IF(NOT(ISBLANK('Curs, Seminar'!C19)), IF('Curs, Seminar'!Z19,'Curs, Seminar'!Z19, IF(F15=0,"n/p", IF(AND(F15>=$H$3,F15<=$I$3),$J$3, IF(AND(F15>=$H$4,F15<=$I$4),$J$4, IF(AND(F15>=$H$5,F15<=$I$5),$J$5, IF(AND(F15>=$H$6,F15<=$I$6),$J$6, IF(AND(F15>=$H$7,F15<=$I$7),$J$7, IF(AND(F15>=$H$8,F15<=$I$8),$J$8, IF(AND(F15>=$H$9,F15<=$I$9),$J$9, IF(AND(F15>=$H$10,F15<=$I$10),$J$10, IF(AND(F15>=$H$11,F15<=$I$11),$J$11))))))))))), "")
A16: =IF(NOT(ISBLANK('Curs, Seminar'!B20)),'Curs, Seminar'!B20,"") | B16: =IF(NOT(ISBLANK('Curs, Seminar'!C20)),'Curs, Seminar'!C20,"") | F16: =IF(NOT(ISBLANK('Curs, Seminar'!C20)), IF('Curs, Seminar'!Z20,"Eliberat", ROUND(SUM(C16:E16),0)), "") | G16: =IF(NOT(ISBLANK('Curs, Seminar'!C20)), IF('Curs, Seminar'!Z20,'Curs, Seminar'!Z20, IF(F16=0,"n/p", IF(AND(F16>=$H$3,F16<=$I$3),$J$3, IF(AND(F16>=$H$4,F16<=$I$4),$J$4, IF(AND(F16>=$H$5,F16<=$I$5),$J$5, IF(AND(F16>=$H$6,F16<=$I$6),$J$6, IF(AND(F16>=$H$7,F16<=$I$7),$J$7, IF(AND(F16>=$H$8,F16<=$I$8),$J$8, IF(AND(F16>=$H$9,F16<=$I$9),$J$9, IF(AND(F16>=$H$10,F16<=$I$10),$J$10, IF(AND(F16>=$H$11,F16<=$I$11),$J$11))))))))))), "")
A17: =IF(NOT(ISBLANK('Curs, Seminar'!B21)),'Curs, Seminar'!B21,"") | B17: =IF(NOT(ISBLANK('Curs, Seminar'!C21)),'Curs, Seminar'!C21,"") | F17: =IF(NOT(ISBLANK('Curs, Seminar'!C21)), IF('Curs, Seminar'!Z21,"Eliberat", ROUND(SUM(C17:E17),0)), "") | G17: =IF(NOT(ISBLANK('Curs, Seminar'!C21)), IF('Curs, Seminar'!Z21,'Curs, Seminar'!Z21, IF(F17=0,"n/p", IF(AND(F17>=$H$3,F17<=$I$3),$J$3, IF(AND(F17>=$H$4,F17<=$I$4),$J$4, IF(AND(F17>=$H$5,F17<=$I$5),$J$5, IF(AND(F17>=$H$6,F17<=$I$6),$J$6, IF(AND(F17>=$H$7,F17<=$I$7),$J$7, IF(AND(F17>=$H$8,F17<=$I$8),$J$8, IF(AND(F17>=$H$9,F17<=$I$9),$J$9, IF(AND(F17>=$H$10,F17<=$I$10),$J$10, IF(AND(F17>=$H$11,F17<=$I$11),$J$11))))))))))), "")
A18: =IF(NOT(ISBLANK('Curs, Seminar'!B22)),'Curs, Seminar'!B22,"") | B18: =IF(NOT(ISBLANK('Curs, Seminar'!C22)),'Curs, Seminar'!C22,"") | F18: =IF(NOT(ISBLANK('Curs, Seminar'!C22)), IF('Curs, Seminar'!Z22,"Eliberat", ROUND(SUM(C18:E18),0)), "") | G18: =IF(NOT(ISBLANK('Curs, Seminar'!C22)), IF('Curs, Seminar'!Z22,'Curs, Seminar'!Z22, IF(F18=0,"n/p", IF(AND(F18>=$H$3,F18<=$I$3),$J$3, IF(AND(F18>=$H$4,F18<=$I$4),$J$4, IF(AND(F18>=$H$5,F18<=$I$5),$J$5, IF(AND(F18>=$H$6,F18<=$I$6),$J$6, IF(AND(F18>=$H$7,F18<=$I$7),$J$7, IF(AND(F18>=$H$8,F18<=$I$8),$J$8, IF(AND(F18>=$H$9,F18<=$I$9),$J$9, IF(AND(F18>=$H$10,F18<=$I$10),$J$10, IF(AND(F18>=$H$11,F18<=$I$11),$J$11))))))))))), "")
