Workbook

Sheet CP, Curs, Sem
C2: Științe Aplicate. Anul de studii: Titular: Grupa: FAF- Șeful grupei: Nume, Prenume, telefon | BC2: Rezultate atestări și sesiune | BQ2: Nota semestrială | BV2: Ev.finală (0.4) | BW2: Nota finală | CA2: Examen:
E3: Curs Preuniversitar | U3: Curs Universitar. Curs | AK3: Curs Universitar. Seminar | BC3: Atestarea Nr.1 | BF3: Atestarea Nr.2 | BI3: Sesiunea | BQ3: Componente | BU3: Media trunchiată (0.6) | BW3: în sist.național, trunchiată | BY3: Conform ECTS | CA3: Borderou | CB3: Prezenti | CC3: Admisi | CD3: Eliberati
E4: CP1.1 | F4: CP1.2 | G4: CP2.1 | H4: CP2.2 | I4: CP3.1 | J4: CP3.2 | K4: CP4 | L4: CP5 | M4: CP6.1 | N4: CP6.2 | O4: CP7 | P4: CP8 | Q4: CP9 | R4: CP10 | S4: CP11 | T4: Ore absențe CP | U4: C1F | V4: C2F | W4: C3F | X4: C4F | Y4: C5F | Z4: C6F | AA4: C7F | AB4: C8F | AC4: C10M | AD4: C9F | AE4: C11M | AF4: C12M | AG4: C13M | AH4: C14M | AI4: C15M | AJ4: Ore absențe C | AK4: S1F | AL4: S2F | AM4: S3F | AN4: S4F | AO4: S5F | AP4: S6F | AQ4: S7F | AR4: S1M | AS4: S9F | AT4: S10F | AU4: S11M | AV4: S12M | AW4: S13M | AX4: S14M | AY4: S15M | AZ4: Ore absențe S | BA4: Ore absențe total | BC4: Atest.1.1 | BD4: Atest.1.2 | BE4: Atest.1.3 | BF4: Atest.2.1 | BG4: Atest.2.2 | BH4: Atest.2.3 | BI4: Atest.I | BJ4: Atest.II | BK4: Examen | BL4: Reexam | BM4: Puncte activ. suplim | BN4: Puncte utilizate | BO4: Exam | BQ4: Ev.periodică | BS4: Evaluarea curentă | BT4: Lucrul individual | CF4: A | CG4: B | CH4: C | CI4: D | CJ4: E | CK4: FX | CL4: F | CM4: n/p | CN4: n/a
B5: Nr. | C5: Nume, Prenume | D5: e-mail | E5: 01.02 | U5: 02.03 | AK5: 09.03 | BA5: Frecventa | BC5: 21.03 | BG5: 22.05 | BO5: Prezenta | BP5: Eliberati | BQ5: nr.1 | BR5: nr.2 | CA5: =COUNTA(C6:C105) -> 1 | CB5: =CA5-COUNTIFS(B6:B105,">0",BO6:BO105,"a") -> 1 | CC5: =CA5-COUNTIF(BV6:BV105,"n/a") -> 0 | CD5: =COUNTA(BP6:BP105) -> 0 | CF5: =COUNTIF($BY$6:$BY$105,CF4) -> 0 | CG5: =COUNTIF($BY$6:$BY$105,CG4) -> 0 | CH5: =COUNTIF($BY$6:$BY$105,CH4) -> 0 | CI5: =COUNTIF($BY$6:$BY$105,CI4) -> 0 | CJ5: =COUNTIF($BY$6:$BY$105,CJ4) -> 0 | CK5: =COUNTIF($BY$6:$BY$105,CK4) -> 0 | CL5: =COUNTIF($BY$6:$BY$105,CL4) -> 0 | CM5: =COUNTIF($BV$6:$BV$105,CM4) -> 0 | CN5: =COUNTIF($BV$6:$BV$105,CN4) -> 1
B6: =IF(NOT(ISBLANK(C6)),COUNTA($C$6:C6),"") -> 1 | C6: Nume, Prenume | D6: example@mail.com | T6: =IF(NOT(ISBLANK(C6)),IF(COUNTIF(E6:S6,"a")<>0,COUNTIF(E6:S6,"a")*2,""),"") | AJ6: =IF(NOT(ISBLANK(B6)),IF(COUNTIF(U6:AI6,"a")<>0,COUNTIF(U6:AI6,"a")*2,""),"") | AZ6: =IF(NOT(ISBLANK(B6)),IF(COUNTIF(AK6:AY6,"a")<>0,COUNTIF(AK6:AY6,"a")*2,""),"") | BA6: =IF(NOT(ISBLANK(T6)),IF(SUM(T6,AJ6,AZ6)<>0,SUM(T6,AJ6,AZ6),""),"") | BC6: ='Atest. Nr.1'!K2 -> n/p | BF6: ='Atest. Nr.2'!I2 -> n/p | BI6: =IF(NOT(ISBLANK(C6)),IF(COUNT(MAX(AVERAGE(BC6:BE6),0)),MAX(BC6:BE6),"n/p"),"") -> n/p | BJ6: =IF(NOT(ISBLANK(C6)),IF(COUNT(MAX(AVERAGE(BF6:BH6),0)),MAX(BF6:BH6),"n/p"),"") -> n/p | BK6: =Examen!H2 -> n/p | BM6: =IF(NOT(ISBLANK(B6)),IF(SUM(E6:S6,U6:AI6,AK6:AY6)+SUM(MatLab!E7:R7)+SUM('Lab Fizica'!E7:R7)<>0,SUM(E6:S6,U6:AI6,AK6:AY6)+SUM(MatLab!E7:R7)+SUM('Lab Fizica'!E7:R7),""),"") | BQ6: =BI6 -> n/p | BR6: =BJ6 -> n/p | BS6: =IF(NOT(ISBLANK(C6)), IF(AND('Teste curente'!E2<>"n/p", 'Lab Fizica'!AL7<>""),ROUND(0.5*'Teste curente'!E2+0.5*'Lab Fizica'!AL7,0),"n/p"), "") -> n/p | BT6: =IF(NOT(ISBLANK(C6)), IF(AND(MatLab!AN7="Admis",'Lab Fizica'!AM7<>""),ROUND(0.5*MatLab!AM7+0.5*'Lab Fizica'!AM7,0),"n/p"), "") -> n/p | BU6: =IF(NOT(ISBLANK(C6)), IF(OR(BQ6="n/p",BR6="n/p",BS6="n/p",BT6="n/p",BQ6<5,BR6<5,BS6<5,BT6<5)," ",TRUNC(SUM(BQ6:BT6)/4,2)), "") | BV6: =IF(NOT(ISBLANK(C6)), IF(BU6=" ","n/a", IF(BP6,BP6, IF(COUNT(MAX(AVERAGE(BK6:BL6),0)),MAX(BK6:BL6),"n/p"))), "") -> n/a | BW6: =IF(NOT(ISBLANK(C6)), IF(OR(BV6="n/a",BV6="n/p")," ", IF(BV6<5,BV6,TRUNC(BU6*0.6+BV6*0.4,2))), "") | BX6: =IF(NOT(ISBLANK(C6)), IF(BW6=" "," ", IF(AND(BW6>=1,BW6<2),"(unu, "&ROUNDUP(MOD(BW6*100,100),0)&")", IF(AND(BW6>=2,BW6<3),"(doi, "&ROUNDUP(MOD(BW6*100,100),0)&")", IF(AND(BW6>=3,BW6<4),"(trei, "&ROUNDUP(MOD(BW6*100,100),0)&")", IF(AND(BW6>=4,BW6<5),"(patru, "&ROUNDUP(MOD(BW6*100,100),0)&")", IF(AND(BW6>=5,BW6<6),"(cinci, "&ROUNDUP(MOD(BW6*100,100),0)&")", IF(AND(BW6>=6,BW6<7),"(şase, "&ROUNDUP(MOD(BW6*100,100),0)&")", IF(AND(BW6>=7,BW6<8),"(şapte, "&ROUNDUP(MOD(BW6*100,100),0)&")", IF(AND(BW6>=8,BW6<9),"(opt, "&ROUNDUP(MOD(BW6*100,100),0)&")", IF(AND(BW6>=9,BW6<10),"(nouă, "&ROUNDUP(MOD(BW6*100,100),0)&")", IF(BW6=10,"(zece, 00)", ))))))))))),"") | BY6: =IF(NOT(ISBLANK(C6)), IF(BW6=" "," ", IF(AND(BW6>3,BW6<5),"FX", IF(AND(BW6>=5,BW6<=6),"E", IF(AND(BW6>6,BW6<=7),"D", IF(AND(BW6>7,BW6<=8),"C", IF(AND(BW6>8,BW6<=9),"B", IF(AND(BW6>9,BW6<=10),"A", IF(BW6=10,"(zece, 00)",)))))))), "")
B7: =IF(NOT(ISBLANK(C7)),COUNTA($C$6:C7),"") | T7: =IF(NOT(ISBLANK(C7)),IF(COUNTIF(E7:S7,"a")<>0,COUNTIF(E7:S7,"a")*2,""),"") | AJ7: =IF(NOT(ISBLANK(B7)),IF(COUNTIF(U7:AI7,"a")<>0,COUNTIF(U7:AI7,"a")*2,""),"") | AZ7: =IF(NOT(ISBLANK(B7)),IF(COUNTIF(AK7:AY7,"a")<>0,COUNTIF(AK7:AY7,"a")*2,""),"") | BA7: =IF(NOT(ISBLANK(T7)),IF(SUM(T7,AJ7,AZ7)<>0,SUM(T7,AJ7,AZ7),""),"") | BC7: ='Atest. Nr.1'!K3 | BF7: ='Atest. Nr.2'!I3 | BI7: =IF(NOT(ISBLANK(C7)),IF(COUNT(MAX(AVERAGE(BC7:BE7),0)),MAX(BC7:BE7),"n/p"),"") | BJ7: =IF(NOT(ISBLANK(C7)),IF(COUNT(MAX(AVERAGE(BF7:BH7),0)),MAX(BF7:BH7),"n/p"),"") | BK7: =Examen!H3 | BM7: =IF(NOT(ISBLANK(B7)),IF(SUM(E7:S7,U7:AI7,AK7:AY7)+SUM(MatLab!E8:R8)+SUM('Lab Fizica'!E8:R8)<>0,SUM(E7:S7,U7:AI7,AK7:AY7)+SUM(MatLab!E8:R8)+SUM('Lab Fizica'!E8:R8),""),"") | BQ7: =BI7 | BR7: =BJ7 | BS7: =IF(NOT(ISBLANK(C7)), IF(AND('Teste curente'!E3<>"n/p", 'Lab Fizica'!AL8<>""),ROUND(0.5*'Teste curente'!E3+0.5*'Lab Fizica'!AL8,0),"n/p"), "") | BT7: =IF(NOT(ISBLANK(C7)), IF(AND(MatLab!AN8="Admis",'Lab Fizica'!AM8<>""),ROUND(0.5*MatLab!AM8+0.5*'Lab Fizica'!AM8,0),"n/p"), "") | BU7: =IF(NOT(ISBLANK(C7)), IF(OR(BQ7="n/p",BR7="n/p",BS7="n/p",BT7="n/p",BQ7<5,BR7<5,BS7<5,BT7<5)," ",TRUNC(SUM(BQ7:BT7)/4,2)), "") | BV7: =IF(NOT(ISBLANK(C7)), IF(BU7=" ","n/a", IF(BP7,BP7, IF(COUNT(MAX(AVERAGE(BK7:BL7),0)),MAX(BK7:BL7),"n/p"))), "") | BW7: =IF(NOT(ISBLANK(C7)), IF(OR(BV7="n/a",BV7="n/p")," ", IF(BV7<5,BV7,TRUNC(BU7*0.6+BV7*0.4,2))), "") | BX7: =IF(NOT(ISBLANK(C7)), IF(BW7=" "," ", IF(AND(BW7>=1,BW7<2),"(unu, "&ROUNDUP(MOD(BW7*100,100),0)&")", IF(AND(BW7>=2,BW7<3),"(doi, "&ROUNDUP(MOD(BW7*100,100),0)&")", IF(AND(BW7>=3,BW7<4),"(trei, "&ROUNDUP(MOD(BW7*100,100),0)&")", IF(AND(BW7>=4,BW7<5),"(patru, "&ROUNDUP(MOD(BW7*100,100),0)&")", IF(AND(BW7>=5,BW7<6),"(cinci, "&ROUNDUP(MOD(BW7*100,100),0)&")", IF(AND(BW7>=6,BW7<7),"(şase, "&ROUNDUP(MOD(BW7*100,100),0)&")", IF(AND(BW7>=7,BW7<8),"(şapte, "&ROUNDUP(MOD(BW7*100,100),0)&")", IF(AND(BW7>=8,BW7<9),"(opt, "&ROUNDUP(MOD(BW7*100,100),0)&")", IF(AND(BW7>=9,BW7<10),"(nouă, "&ROUNDUP(MOD(BW7*100,100),0)&")", IF(BW7=10,"(zece, 00)", ))))))))))),"") | BY7: =IF(NOT(ISBLANK(C7)), IF(BW7=" "," ", IF(AND(BW7>3,BW7<5),"FX", IF(AND(BW7>=5,BW7<=6),"E", IF(AND(BW7>6,BW7<=7),"D", IF(AND(BW7>7,BW7<=8),"C", IF(AND(BW7>8,BW7<=9),"B", IF(AND(BW7>9,BW7<=10),"A", IF(BW7=10,"(zece, 00)",)))))))), "")
B8: =IF(NOT(ISBLANK(C8)),COUNTA($C$6:C8),"") | T8: =IF(NOT(ISBLANK(C8)),IF(COUNTIF(E8:S8,"a")<>0,COUNTIF(E8:S8,"a")*2,""),"") | AJ8: =IF(NOT(ISBLANK(B8)),IF(COUNTIF(U8:AI8,"a")<>0,COUNTIF(U8:AI8,"a")*2,""),"") | AZ8: =IF(NOT(ISBLANK(B8)),IF(COUNTIF(AK8:AY8,"a")<>0,COUNTIF(AK8:AY8,"a")*2,""),"") | BA8: =IF(NOT(ISBLANK(T8)),IF(SUM(T8,AJ8,AZ8)<>0,SUM(T8,AJ8,AZ8),""),"") | BC8: ='Atest. Nr.1'!K4 | BF8: ='Atest. Nr.2'!I4 | BI8: =IF(NOT(ISBLANK(C8)),IF(COUNT(MAX(AVERAGE(BC8:BE8),0)),MAX(BC8:BE8),"n/p"),"") | BJ8: =IF(NOT(ISBLANK(C8)),IF(COUNT(MAX(AVERAGE(BF8:BH8),0)),MAX(BF8:BH8),"n/p"),"") | BK8: =Examen!H4 | BM8: =IF(NOT(ISBLANK(B8)),IF(SUM(E8:S8,U8:AI8,AK8:AY8)+SUM(MatLab!E9:R9)+SUM('Lab Fizica'!E9:R9)<>0,SUM(E8:S8,U8:AI8,AK8:AY8)+SUM(MatLab!E9:R9)+SUM('Lab Fizica'!E9:R9),""),"") | BQ8: =BI8 | BR8: =BJ8 | BS8: =IF(NOT(ISBLANK(C8)), IF(AND('Teste curente'!E4<>"n/p", 'Lab Fizica'!AL9<>""),ROUND(0.5*'Teste curente'!E4+0.5*'Lab Fizica'!AL9,0),"n/p"), "") | BT8: =IF(NOT(ISBLANK(C8)), IF(AND(MatLab!AN9="Admis",'Lab Fizica'!AM9<>""),ROUND(0.5*MatLab!AM9+0.5*'Lab Fizica'!AM9,0),"n/p"), "") | BU8: =IF(NOT(ISBLANK(C8)), IF(OR(BQ8="n/p",BR8="n/p",BS8="n/p",BT8="n/p",BQ8<5,BR8<5,BS8<5,BT8<5)," ",TRUNC(SUM(BQ8:BT8)/4,2)), "") | BV8: =IF(NOT(ISBLANK(C8)), IF(BU8=" ","n/a", IF(BP8,BP8, IF(COUNT(MAX(AVERAGE(BK8:BL8),0)),MAX(BK8:BL8),"n/p"))), "") | BW8: =IF(NOT(ISBLANK(C8)), IF(OR(BV8="n/a",BV8="n/p")," ", IF(BV8<5,BV8,TRUNC(BU8*0.6+BV8*0.4,2))), "") | BX8: =IF(NOT(ISBLANK(C8)), IF(BW8=" "," ", IF(AND(BW8>=1,BW8<2),"(unu, "&ROUNDUP(MOD(BW8*100,100),0)&")", IF(AND(BW8>=2,BW8<3),"(doi, "&ROUNDUP(MOD(BW8*100,100),0)&")", IF(AND(BW8>=3,BW8<4),"(trei, "&ROUNDUP(MOD(BW8*100,100),0)&")", IF(AND(BW8>=4,BW8<5),"(patru, "&ROUNDUP(MOD(BW8*100,100),0)&")", IF(AND(BW8>=5,BW8<6),"(cinci, "&ROUNDUP(MOD(BW8*100,100),0)&")", IF(AND(BW8>=6,BW8<7),"(şase, "&ROUNDUP(MOD(BW8*100,100),0)&")", IF(AND(BW8>=7,BW8<8),"(şapte, "&ROUNDUP(MOD(BW8*100,100),0)&")", IF(AND(BW8>=8,BW8<9),"(opt, "&ROUNDUP(MOD(BW8*100,100),0)&")", IF(AND(BW8>=9,BW8<10),"(nouă, "&ROUNDUP(MOD(BW8*100,100),0)&")", IF(BW8=10,"(zece, 00)", ))))))))))),"") | BY8: =IF(NOT(ISBLANK(C8)), IF(BW8=" "," ", IF(AND(BW8>3,BW8<5),"FX", IF(AND(BW8>=5,BW8<=6),"E", IF(AND(BW8>6,BW8<=7),"D", IF(AND(BW8>7,BW8<=8),"C", IF(AND(BW8>8,BW8<=9),"B", IF(AND(BW8>9,BW8<=10),"A", IF(BW8=10,"(zece, 00)",)))))))), "")
B9: =IF(NOT(ISBLANK(C9)),COUNTA($C$6:C9),"") | T9: =IF(NOT(ISBLANK(C9)),IF(COUNTIF(E9:S9,"a")<>0,COUNTIF(E9:S9,"a")*2,""),"") | AJ9: =IF(NOT(ISBLANK(B9)),IF(COUNTIF(U9:AI9,"a")<>0,COUNTIF(U9:AI9,"a")*2,""),"") | AZ9: =IF(NOT(ISBLANK(B9)),IF(COUNTIF(AK9:AY9,"a")<>0,COUNTIF(AK9:AY9,"a")*2,""),"") | BA9: =IF(NOT(ISBLANK(T9)),IF(SUM(T9,AJ9,AZ9)<>0,SUM(T9,AJ9,AZ9),""),"") | BC9: ='Atest. Nr.1'!K5 | BF9: ='Atest. Nr.2'!I5 | BI9: =IF(NOT(ISBLANK(C9)),IF(COUNT(MAX(AVERAGE(BC9:BE9),0)),MAX(BC9:BE9),"n/p"),"") | BJ9: =IF(NOT(ISBLANK(C9)),IF(COUNT(MAX(AVERAGE(BF9:BH9),0)),MAX(BF9:BH9),"n/p"),"") | BK9: =Examen!H5 | BM9: =IF(NOT(ISBLANK(B9)),IF(SUM(E9:S9,U9:AI9,AK9:AY9)+SUM(MatLab!E10:R10)+SUM('Lab Fizica'!E10:R10)<>0,SUM(E9:S9,U9:AI9,AK9:AY9)+SUM(MatLab!E10:R10)+SUM('Lab Fizica'!E10:R10),""),"") | BQ9: =BI9 | BR9: =BJ9 | BS9: =IF(NOT(ISBLANK(C9)), IF(AND('Teste curente'!E5<>"n/p", 'Lab Fizica'!AL10<>""),ROUND(0.5*'Teste curente'!E5+0.5*'Lab Fizica'!AL10,0),"n/p"), "") | BT9: =IF(NOT(ISBLANK(C9)), IF(AND(MatLab!AN10="Admis",'Lab Fizica'!AM10<>""),ROUND(0.5*MatLab!AM10+0.5*'Lab Fizica'!AM10,0),"n/p"), "") | BU9: =IF(NOT(ISBLANK(C9)), IF(OR(BQ9="n/p",BR9="n/p",BS9="n/p",BT9="n/p",BQ9<5,BR9<5,BS9<5,BT9<5)," ",TRUNC(SUM(BQ9:BT9)/4,2)), "") | BV9: =IF(NOT(ISBLANK(C9)), IF(BU9=" ","n/a", IF(BP9,BP9, IF(COUNT(MAX(AVERAGE(BK9:BL9),0)),MAX(BK9:BL9),"n/p"))), "") | BW9: =IF(NOT(ISBLANK(C9)), IF(OR(BV9="n/a",BV9="n/p")," ", IF(BV9<5,BV9,TRUNC(BU9*0.6+BV9*0.4,2))), "") | BX9: =IF(NOT(ISBLANK(C9)), IF(BW9=" "," ", IF(AND(BW9>=1,BW9<2),"(unu, "&ROUNDUP(MOD(BW9*100,100),0)&")", IF(AND(BW9>=2,BW9<3),"(doi, "&ROUNDUP(MOD(BW9*100,100),0)&")", IF(AND(BW9>=3,BW9<4),"(trei, "&ROUNDUP(MOD(BW9*100,100),0)&")", IF(AND(BW9>=4,BW9<5),"(patru, "&ROUNDUP(MOD(BW9*100,100),0)&")", IF(AND(BW9>=5,BW9<6),"(cinci, "&ROUNDUP(MOD(BW9*100,100),0)&")", IF(AND(BW9>=6,BW9<7),"(şase, "&ROUNDUP(MOD(BW9*100,100),0)&")", IF(AND(BW9>=7,BW9<8),"(şapte, "&ROUNDUP(MOD(BW9*100,100),0)&")", IF(AND(BW9>=8,BW9<9),"(opt, "&ROUNDUP(MOD(BW9*100,100),0)&")", IF(AND(BW9>=9,BW9<10),"(nouă, "&ROUNDUP(MOD(BW9*100,100),0)&")", IF(BW9=10,"(zece, 00)", ))))))))))),"") | BY9: =IF(NOT(ISBLANK(C9)), IF(BW9=" "," ", IF(AND(BW9>3,BW9<5),"FX", IF(AND(BW9>=5,BW9<=6),"E", IF(AND(BW9>6,BW9<=7),"D", IF(AND(BW9>7,BW9<=8),"C", IF(AND(BW9>8,BW9<=9),"B", IF(AND(BW9>9,BW9<=10),"A", IF(BW9=10,"(zece, 00)",)))))))), "")
B10: =IF(NOT(ISBLANK(C10)),COUNTA($C$6:C10),"") | T10: =IF(NOT(ISBLANK(C10)),IF(COUNTIF(E10:S10,"a")<>0,COUNTIF(E10:S10,"a")*2,""),"") | AJ10: =IF(NOT(ISBLANK(B10)),IF(COUNTIF(U10:AI10,"a")<>0,COUNTIF(U10:AI10,"a")*2,""),"") | AZ10: =IF(NOT(ISBLANK(B10)),IF(COUNTIF(AK10:AY10,"a")<>0,COUNTIF(AK10:AY10,"a")*2,""),"") | BA10: =IF(NOT(ISBLANK(T10)),IF(SUM(T10,AJ10,AZ10)<>0,SUM(T10,AJ10,AZ10),""),"") | BC10: ='Atest. Nr.1'!K6 | BF10: ='Atest. Nr.2'!I6 | BI10: =IF(NOT(ISBLANK(C10)),IF(COUNT(MAX(AVERAGE(BC10:BE10),0)),MAX(BC10:BE10),"n/p"),"") | BJ10: =IF(NOT(ISBLANK(C10)),IF(COUNT(MAX(AVERAGE(BF10:BH10),0)),MAX(BF10:BH10),"n/p"),"") | BK10: =Examen!H6 | BM10: =IF(NOT(ISBLANK(B10)),IF(SUM(E10:S10,U10:AI10,AK10:AY10)+SUM(MatLab!E11:R11)+SUM('Lab Fizica'!E11:R11)<>0,SUM(E10:S10,U10:AI10,AK10:AY10)+SUM(MatLab!E11:R11)+SUM('Lab Fizica'!E11:R11),""),"") | BQ10: =BI10 | BR10: =BJ10 | BS10: =IF(NOT(ISBLANK(C10)), IF(AND('Teste curente'!E6<>"n/p", 'Lab Fizica'!AL11<>""),ROUND(0.5*'Teste curente'!E6+0.5*'Lab Fizica'!AL11,0),"n/p"), "") | BT10: =IF(NOT(ISBLANK(C10)), IF(AND(MatLab!AN11="Admis",'Lab Fizica'!AM11<>""),ROUND(0.5*MatLab!AM11+0.5*'Lab Fizica'!AM11,0),"n/p"), "") | BU10: =IF(NOT(ISBLANK(C10)), IF(OR(BQ10="n/p",BR10="n/p",BS10="n/p",BT10="n/p",BQ10<5,BR10<5,BS10<5,BT10<5)," ",TRUNC(SUM(BQ10:BT10)/4,2)), "") | BV10: =IF(NOT(ISBLANK(C10)), IF(BU10=" ","n/a", IF(BP10,BP10, IF(COUNT(MAX(AVERAGE(BK10:BL10),0)),MAX(BK10:BL10),"n/p"))), "") | BW10: =IF(NOT(ISBLANK(C10)), IF(OR(BV10="n/a",BV10="n/p")," ", IF(BV10<5,BV10,TRUNC(BU10*0.6+BV10*0.4,2))), "") | BX10: =IF(NOT(ISBLANK(C10)), IF(BW10=" "," ", IF(AND(BW10>=1,BW10<2),"(unu, "&ROUNDUP(MOD(BW10*100,100),0)&")", IF(AND(BW10>=2,BW10<3),"(doi, "&ROUNDUP(MOD(BW10*100,100),0)&")", IF(AND(BW10>=3,BW10<4),"(trei, "&ROUNDUP(MOD(BW10*100,100),0)&")", IF(AND(BW10>=4,BW10<5),"(patru, "&ROUNDUP(MOD(BW10*100,100),0)&")", IF(AND(BW10>=5,BW10<6),"(cinci, "&ROUNDUP(MOD(BW10*100,100),0)&")", IF(AND(BW10>=6,BW10<7),"(şase, "&ROUNDUP(MOD(BW10*100,100),0)&")", IF(AND(BW10>=7,BW10<8),"(şapte, "&ROUNDUP(MOD(BW10*100,100),0)&")", IF(AND(BW10>=8,BW10<9),"(opt, "&ROUNDUP(MOD(BW10*100,100),0)&")", IF(AND(BW10>=9,BW10<10),"(nouă, "&ROUNDUP(MOD(BW10*100,100),0)&")", IF(BW10=10,"(zece, 00)", ))))))))))),"") | BY10: =IF(NOT(ISBLANK(C10)), IF(BW10=" "," ", IF(AND(BW10>3,BW10<5),"FX", IF(AND(BW10>=5,BW10<=6),"E", IF(AND(BW10>6,BW10<=7),"D", IF(AND(BW10>7,BW10<=8),"C", IF(AND(BW10>8,BW10<=9),"B", IF(AND(BW10>9,BW10<=10),"A", IF(BW10=10,"(zece, 00)",)))))))), "")
B11: =IF(NOT(ISBLANK(C11)),COUNTA($C$6:C11),"") | T11: =IF(NOT(ISBLANK(C11)),IF(COUNTIF(E11:S11,"a")<>0,COUNTIF(E11:S11,"a")*2,""),"") | AJ11: =IF(NOT(ISBLANK(B11)),IF(COUNTIF(U11:AI11,"a")<>0,COUNTIF(U11:AI11,"a")*2,""),"") | AZ11: =IF(NOT(ISBLANK(B11)),IF(COUNTIF(AK11:AY11,"a")<>0,COUNTIF(AK11:AY11,"a")*2,""),"") | BA11: =IF(NOT(ISBLANK(T11)),IF(SUM(T11,AJ11,AZ11)<>0,SUM(T11,AJ11,AZ11),""),"") | BC11: ='Atest. Nr.1'!K7 | BF11: ='Atest. Nr.2'!I7 | BI11: =IF(NOT(ISBLANK(C11)),IF(COUNT(MAX(AVERAGE(BC11:BE11),0)),MAX(BC11:BE11),"n/p"),"") | BJ11: =IF(NOT(ISBLANK(C11)),IF(COUNT(MAX(AVERAGE(BF11:BH11),0)),MAX(BF11:BH11),"n/p"),"") | BK11: =Examen!H7 | BM11: =IF(NOT(ISBLANK(B11)),IF(SUM(E11:S11,U11:AI11,AK11:AY11)+SUM(MatLab!E12:R12)+SUM('Lab Fizica'!E12:R12)<>0,SUM(E11:S11,U11:AI11,AK11:AY11)+SUM(MatLab!E12:R12)+SUM('Lab Fizica'!E12:R12),""),"") | BQ11: =BI11 | BR11: =BJ11 | BS11: =IF(NOT(ISBLANK(C11)), IF(AND('Teste curente'!E7<>"n/p", 'Lab Fizica'!AL12<>""),ROUND(0.5*'Teste curente'!E7+0.5*'Lab Fizica'!AL12,0),"n/p"), "") | BT11: =IF(NOT(ISBLANK(C11)), IF(AND(MatLab!AN12="Admis",'Lab Fizica'!AM12<>""),ROUND(0.5*MatLab!AM12+0.5*'Lab Fizica'!AM12,0),"n/p"), "") | BU11: =IF(NOT(ISBLANK(C11)), IF(OR(BQ11="n/p",BR11="n/p",BS11="n/p",BT11="n/p",BQ11<5,BR11<5,BS11<5,BT11<5)," ",TRUNC(SUM(BQ11:BT11)/4,2)), "") | BV11: =IF(NOT(ISBLANK(C11)), IF(BU11=" ","n/a", IF(BP11,BP11, IF(COUNT(MAX(AVERAGE(BK11:BL11),0)),MAX(BK11:BL11),"n/p"))), "") | BW11: =IF(NOT(ISBLANK(C11)), IF(OR(BV11="n/a",BV11="n/p")," ", IF(BV11<5,BV11,TRUNC(BU11*0.6+BV11*0.4,2))), "") | BX11: =IF(NOT(ISBLANK(C11)), IF(BW11=" "," ", IF(AND(BW11>=1,BW11<2),"(unu, "&ROUNDUP(MOD(BW11*100,100),0)&")", IF(AND(BW11>=2,BW11<3),"(doi, "&ROUNDUP(MOD(BW11*100,100),0)&")", IF(AND(BW11>=3,BW11<4),"(trei, "&ROUNDUP(MOD(BW11*100,100),0)&")", IF(AND(BW11>=4,BW11<5),"(patru, "&ROUNDUP(MOD(BW11*100,100),0)&")", IF(AND(BW11>=5,BW11<6),"(cinci, "&ROUNDUP(MOD(BW11*100,100),0)&")", IF(AND(BW11>=6,BW11<7),"(şase, "&ROUNDUP(MOD(BW11*100,100),0)&")", IF(AND(BW11>=7,BW11<8),"(şapte, "&ROUNDUP(MOD(BW11*100,100),0)&")", IF(AND(BW11>=8,BW11<9),"(opt, "&ROUNDUP(MOD(BW11*100,100),0)&")", IF(AND(BW11>=9,BW11<10),"(nouă, "&ROUNDUP(MOD(BW11*100,100),0)&")", IF(BW11=10,"(zece, 00)", ))))))))))),"") | BY11: =IF(NOT(ISBLANK(C11)), IF(BW11=" "," ", IF(AND(BW11>3,BW11<5),"FX", IF(AND(BW11>=5,BW11<=6),"E", IF(AND(BW11>6,BW11<=7),"D", IF(AND(BW11>7,BW11<=8),"C", IF(AND(BW11>8,BW11<=9),"B", IF(AND(BW11>9,BW11<=10),"A", IF(BW11=10,"(zece, 00)",)))))))), "")
B12: =IF(NOT(ISBLANK(C12)),COUNTA($C$6:C12),"") | T12: =IF(NOT(ISBLANK(C12)),IF(COUNTIF(E12:S12,"a")<>0,COUNTIF(E12:S12,"a")*2,""),"") | AJ12: =IF(NOT(ISBLANK(B12)),IF(COUNTIF(U12:AI12,"a")<>0,COUNTIF(U12:AI12,"a")*2,""),"") | AZ12: =IF(NOT(ISBLANK(B12)),IF(COUNTIF(AK12:AY12,"a")<>0,COUNTIF(AK12:AY12,"a")*2,""),"") | BA12: =IF(NOT(ISBLANK(T12)),IF(SUM(T12,AJ12,AZ12)<>0,SUM(T12,AJ12,AZ12),""),"") | BC12: ='Atest. Nr.1'!K8 | BF12: ='Atest. Nr.2'!I8 | BI12: =IF(NOT(ISBLANK(C12)),IF(COUNT(MAX(AVERAGE(BC12:BE12),0)),MAX(BC12:BE12),"n/p"),"") | BJ12: =IF(NOT(ISBLANK(C12)),IF(COUNT(MAX(AVERAGE(BF12:BH12),0)),MAX(BF12:BH12),"n/p"),"") | BK12: =Examen!H8 | BM12: =IF(NOT(ISBLANK(B12)),IF(SUM(E12:S12,U12:AI12,AK12:AY12)+SUM(MatLab!E13:R13)+SUM('Lab Fizica'!E13:R13)<>0,SUM(E12:S12,U12:AI12,AK12:AY12)+SUM(MatLab!E13:R13)+SUM('Lab Fizica'!E13:R13),""),"") | BQ12: =BI12 | BR12: =BJ12 | BS12: =IF(NOT(ISBLANK(C12)), IF(AND('Teste curente'!E8<>"n/p", 'Lab Fizica'!AL13<>""),ROUND(0.5*'Teste curente'!E8+0.5*'Lab Fizica'!AL13,0),"n/p"), "") | BT12: =IF(NOT(ISBLANK(C12)), IF(AND(MatLab!AN13="Admis",'Lab Fizica'!AM13<>""),ROUND(0.5*MatLab!AM13+0.5*'Lab Fizica'!AM13,0),"n/p"), "") | BU12: =IF(NOT(ISBLANK(C12)), IF(OR(BQ12="n/p",BR12="n/p",BS12="n/p",BT12="n/p",BQ12<5,BR12<5,BS12<5,BT12<5)," ",TRUNC(SUM(BQ12:BT12)/4,2)), "") | BV12: =IF(NOT(ISBLANK(C12)), IF(BU12=" ","n/a", IF(BP12,BP12, IF(COUNT(MAX(AVERAGE(BK12:BL12),0)),MAX(BK12:BL12),"n/p"))), "") | BW12: =IF(NOT(ISBLANK(C12)), IF(OR(BV12="n/a",BV12="n/p")," ", IF(BV12<5,BV12,TRUNC(BU12*0.6+BV12*0.4,2))), "") | BX12: =IF(NOT(ISBLANK(C12)), IF(BW12=" "," ", IF(AND(BW12>=1,BW12<2),"(unu, "&ROUNDUP(MOD(BW12*100,100),0)&")", IF(AND(BW12>=2,BW12<3),"(doi, "&ROUNDUP(MOD(BW12*100,100),0)&")", IF(AND(BW12>=3,BW12<4),"(trei, "&ROUNDUP(MOD(BW12*100,100),0)&")", IF(AND(BW12>=4,BW12<5),"(patru, "&ROUNDUP(MOD(BW12*100,100),0)&")", IF(AND(BW12>=5,BW12<6),"(cinci, "&ROUNDUP(MOD(BW12*100,100),0)&")", IF(AND(BW12>=6,BW12<7),"(şase, "&ROUNDUP(MOD(BW12*100,100),0)&")", IF(AND(BW12>=7,BW12<8),"(şapte, "&ROUNDUP(MOD(BW12*100,100),0)&")", IF(AND(BW12>=8,BW12<9),"(opt, "&ROUNDUP(MOD(BW12*100,100),0)&")", IF(AND(BW12>=9,BW12<10),"(nouă, "&ROUNDUP(MOD(BW12*100,100),0)&")", IF(BW12=10,"(zece, 00)", ))))))))))),"") | BY12: =IF(NOT(ISBLANK(C12)), IF(BW12=" "," ", IF(AND(BW12>3,BW12<5),"FX", IF(AND(BW12>=5,BW12<=6),"E", IF(AND(BW12>6,BW12<=7),"D", IF(AND(BW12>7,BW12<=8),"C", IF(AND(BW12>8,BW12<=9),"B", IF(AND(BW12>9,BW12<=10),"A", IF(BW12=10,"(zece, 00)",)))))))), "")
B13: =IF(NOT(ISBLANK(C13)),COUNTA($C$6:C13),"") | T13: =IF(NOT(ISBLANK(C13)),IF(COUNTIF(E13:S13,"a")<>0,COUNTIF(E13:S13,"a")*2,""),"") | AJ13: =IF(NOT(ISBLANK(B13)),IF(COUNTIF(U13:AI13,"a")<>0,COUNTIF(U13:AI13,"a")*2,""),"") | AZ13: =IF(NOT(ISBLANK(B13)),IF(COUNTIF(AK13:AY13,"a")<>0,COUNTIF(AK13:AY13,"a")*2,""),"") | BA13: =IF(NOT(ISBLANK(T13)),IF(SUM(T13,AJ13,AZ13)<>0,SUM(T13,AJ13,AZ13),""),"") | BC13: ='Atest. Nr.1'!K9 | BF13: ='Atest. Nr.2'!I9 | BI13: =IF(NOT(ISBLANK(C13)),IF(COUNT(MAX(AVERAGE(BC13:BE13),0)),MAX(BC13:BE13),"n/p"),"") | BJ13: =IF(NOT(ISBLANK(C13)),IF(COUNT(MAX(AVERAGE(BF13:BH13),0)),MAX(BF13:BH13),"n/p"),"") | BK13: =Examen!H9 | BM13: =IF(NOT(ISBLANK(B13)),IF(SUM(E13:S13,U13:AI13,AK13:AY13)+SUM(MatLab!E14:R14)+SUM('Lab Fizica'!E14:R14)<>0,SUM(E13:S13,U13:AI13,AK13:AY13)+SUM(MatLab!E14:R14)+SUM('Lab Fizica'!E14:R14),""),"") | BQ13: =BI13 | BR13: =BJ13 | BS13: =IF(NOT(ISBLANK(C13)), IF(AND('Teste curente'!E9<>"n/p", 'Lab Fizica'!AL14<>""),ROUND(0.5*'Teste curente'!E9+0.5*'Lab Fizica'!AL14,0),"n/p"), "") | BT13: =IF(NOT(ISBLANK(C13)), IF(AND(MatLab!AN14="Admis",'Lab Fizica'!AM14<>""),ROUND(0.5*MatLab!AM14+0.5*'Lab Fizica'!AM14,0),"n/p"), "") | BU13: =IF(NOT(ISBLANK(C13)), IF(OR(BQ13="n/p",BR13="n/p",BS13="n/p",BT13="n/p",BQ13<5,BR13<5,BS13<5,BT13<5)," ",TRUNC(SUM(BQ13:BT13)/4,2)), "") | BV13: =IF(NOT(ISBLANK(C13)), IF(BU13=" ","n/a", IF(BP13,BP13, IF(COUNT(MAX(AVERAGE(BK13:BL13),0)),MAX(BK13:BL13),"n/p"))), "") | BW13: =IF(NOT(ISBLANK(C13)), IF(OR(BV13="n/a",BV13="n/p")," ", IF(BV13<5,BV13,TRUNC(BU13*0.6+BV13*0.4,2))), "") | BX13: =IF(NOT(ISBLANK(C13)), IF(BW13=" "," ", IF(AND(BW13>=1,BW13<2),"(unu, "&ROUNDUP(MOD(BW13*100,100),0)&")", IF(AND(BW13>=2,BW13<3),"(doi, "&ROUNDUP(MOD(BW13*100,100),0)&")", IF(AND(BW13>=3,BW13<4),"(trei, "&ROUNDUP(MOD(BW13*100,100),0)&")", IF(AND(BW13>=4,BW13<5),"(patru, "&ROUNDUP(MOD(BW13*100,100),0)&")", IF(AND(BW13>=5,BW13<6),"(cinci, "&ROUNDUP(MOD(BW13*100,100),0)&")", IF(AND(BW13>=6,BW13<7),"(şase, "&ROUNDUP(MOD(BW13*100,100),0)&")", IF(AND(BW13>=7,BW13<8),"(şapte, "&ROUNDUP(MOD(BW13*100,100),0)&")", IF(AND(BW13>=8,BW13<9),"(opt, "&ROUNDUP(MOD(BW13*100,100),0)&")", IF(AND(BW13>=9,BW13<10),"(nouă, "&ROUNDUP(MOD(BW13*100,100),0)&")", IF(BW13=10,"(zece, 00)", ))))))))))),"") | BY13: =IF(NOT(ISBLANK(C13)), IF(BW13=" "," ", IF(AND(BW13>3,BW13<5),"FX", IF(AND(BW13>=5,BW13<=6),"E", IF(AND(BW13>6,BW13<=7),"D", IF(AND(BW13>7,BW13<=8),"C", IF(AND(BW13>8,BW13<=9),"B", IF(AND(BW13>9,BW13<=10),"A", IF(BW13=10,"(zece, 00)",)))))))), "")
B14: =IF(NOT(ISBLANK(C14)),COUNTA($C$6:C14),"") | T14: =IF(NOT(ISBLANK(C14)),IF(COUNTIF(E14:S14,"a")<>0,COUNTIF(E14:S14,"a")*2,""),"") | AJ14: =IF(NOT(ISBLANK(B14)),IF(COUNTIF(U14:AI14,"a")<>0,COUNTIF(U14:AI14,"a")*2,""),"") | AZ14: =IF(NOT(ISBLANK(B14)),IF(COUNTIF(AK14:AY14,"a")<>0,COUNTIF(AK14:AY14,"a")*2,""),"") | BA14: =IF(NOT(ISBLANK(T14)),IF(SUM(T14,AJ14,AZ14)<>0,SUM(T14,AJ14,AZ14),""),"") | BC14: ='Atest. Nr.1'!K10 | BF14: ='Atest. Nr.2'!I10 | BI14: =IF(NOT(ISBLANK(C14)),IF(COUNT(MAX(AVERAGE(BC14:BE14),0)),MAX(BC14:BE14),"n/p"),"") | BJ14: =IF(NOT(ISBLANK(C14)),IF(COUNT(MAX(AVERAGE(BF14:BH14),0)),MAX(BF14:BH14),"n/p"),"") | BK14: =Examen!H10 | BM14: =IF(NOT(ISBLANK(B14)),IF(SUM(E14:S14,U14:AI14,AK14:AY14)+SUM(MatLab!E15:R15)+SUM('Lab Fizica'!E15:R15)<>0,SUM(E14:S14,U14:AI14,AK14:AY14)+SUM(MatLab!E15:R15)+SUM('Lab Fizica'!E15:R15),""),"") | BQ14: =BI14 | BR14: =BJ14 | BS14: =IF(NOT(ISBLANK(C14)), IF(AND('Teste curente'!E10<>"n/p", 'Lab Fizica'!AL15<>""),ROUND(0.5*'Teste curente'!E10+0.5*'Lab Fizica'!AL15,0),"n/p"), "") | BT14: =IF(NOT(ISBLANK(C14)), IF(AND(MatLab!AN15="Admis",'Lab Fizica'!AM15<>""),ROUND(0.5*MatLab!AM15+0.5*'Lab Fizica'!AM15,0),"n/p"), "") | BU14: =IF(NOT(ISBLANK(C14)), IF(OR(BQ14="n/p",BR14="n/p",BS14="n/p",BT14="n/p",BQ14<5,BR14<5,BS14<5,BT14<5)," ",TRUNC(SUM(BQ14:BT14)/4,2)), "") | BV14: =IF(NOT(ISBLANK(C14)), IF(BU14=" ","n/a", IF(BP14,BP14, IF(COUNT(MAX(AVERAGE(BK14:BL14),0)),MAX(BK14:BL14),"n/p"))), "") | BW14: =IF(NOT(ISBLANK(C14)), IF(OR(BV14="n/a",BV14="n/p")," ", IF(BV14<5,BV14,TRUNC(BU14*0.6+BV14*0.4,2))), "") | BX14: =IF(NOT(ISBLANK(C14)), IF(BW14=" "," ", IF(AND(BW14>=1,BW14<2),"(unu, "&ROUNDUP(MOD(BW14*100,100),0)&")", IF(AND(BW14>=2,BW14<3),"(doi, "&ROUNDUP(MOD(BW14*100,100),0)&")", IF(AND(BW14>=3,BW14<4),"(trei, "&ROUNDUP(MOD(BW14*100,100),0)&")", IF(AND(BW14>=4,BW14<5),"(patru, "&ROUNDUP(MOD(BW14*100,100),0)&")", IF(AND(BW14>=5,BW14<6),"(cinci, "&ROUNDUP(MOD(BW14*100,100),0)&")", IF(AND(BW14>=6,BW14<7),"(şase, "&ROUNDUP(MOD(BW14*100,100),0)&")", IF(AND(BW14>=7,BW14<8),"(şapte, "&ROUNDUP(MOD(BW14*100,100),0)&")", IF(AND(BW14>=8,BW14<9),"(opt, "&ROUNDUP(MOD(BW14*100,100),0)&")", IF(AND(BW14>=9,BW14<10),"(nouă, "&ROUNDUP(MOD(BW14*100,100),0)&")", IF(BW14=10,"(zece, 00)", ))))))))))),"") | BY14: =IF(NOT(ISBLANK(C14)), IF(BW14=" "," ", IF(AND(BW14>3,BW14<5),"FX", IF(AND(BW14>=5,BW14<=6),"E", IF(AND(BW14>6,BW14<=7),"D", IF(AND(BW14>7,BW14<=8),"C", IF(AND(BW14>8,BW14<=9),"B", IF(AND(BW14>9,BW14<=10),"A", IF(BW14=10,"(zece, 00)",)))))))), "")
B15: =IF(NOT(ISBLANK(C15)),COUNTA($C$6:C15),"") | T15: =IF(NOT(ISBLANK(C15)),IF(COUNTIF(E15:S15,"a")<>0,COUNTIF(E15:S15,"a")*2,""),"") | AJ15: =IF(NOT(ISBLANK(B15)),IF(COUNTIF(U15:AI15,"a")<>0,COUNTIF(U15:AI15,"a")*2,""),"") | AZ15: =IF(NOT(ISBLANK(B15)),IF(COUNTIF(AK15:AY15,"a")<>0,COUNTIF(AK15:AY15,"a")*2,""),"") | BA15: =IF(NOT(ISBLANK(T15)),IF(SUM(T15,AJ15,AZ15)<>0,SUM(T15,AJ15,AZ15),""),"") | BC15: ='Atest. Nr.1'!K11 | BF15: ='Atest. Nr.2'!I11 | BI15: =IF(NOT(ISBLANK(C15)),IF(COUNT(MAX(AVERAGE(BC15:BE15),0)),MAX(BC15:BE15),"n/p"),"") | BJ15: =IF(NOT(ISBLANK(C15)),IF(COUNT(MAX(AVERAGE(BF15:BH15),0)),MAX(BF15:BH15),"n/p"),"") | BK15: =Examen!H11 | BM15: =IF(NOT(ISBLANK(B15)),IF(SUM(E15:S15,U15:AI15,AK15:AY15)+SUM(MatLab!E16:R16)+SUM('Lab Fizica'!E16:R16)<>0,SUM(E15:S15,U15:AI15,AK15:AY15)+SUM(MatLab!E16:R16)+SUM('Lab Fizica'!E16:R16),""),"") | BQ15: =BI15 | BR15: =BJ15 | BS15: =IF(NOT(ISBLANK(C15)), IF(AND('Teste curente'!E11<>"n/p", 'Lab Fizica'!AL16<>""),ROUND(0.5*'Teste curente'!E11+0.5*'Lab Fizica'!AL16,0),"n/p"), "") | BT15: =IF(NOT(ISBLANK(C15)), IF(AND(MatLab!AN16="Admis",'Lab Fizica'!AM16<>""),ROUND(0.5*MatLab!AM16+0.5*'Lab Fizica'!AM16,0),"n/p"), "") | BU15: =IF(NOT(ISBLANK(C15)), IF(OR(BQ15="n/p",BR15="n/p",BS15="n/p",BT15="n/p",BQ15<5,BR15<5,BS15<5,BT15<5)," ",TRUNC(SUM(BQ15:BT15)/4,2)), "") | BV15: =IF(NOT(ISBLANK(C15)), IF(BU15=" ","n/a", IF(BP15,BP15, IF(COUNT(MAX(AVERAGE(BK15:BL15),0)),MAX(BK15:BL15),"n/p"))), "") | BW15: =IF(NOT(ISBLANK(C15)), IF(OR(BV15="n/a",BV15="n/p")," ", IF(BV15<5,BV15,TRUNC(BU15*0.6+BV15*0.4,2))), "") | BX15: =IF(NOT(ISBLANK(C15)), IF(BW15=" "," ", IF(AND(BW15>=1,BW15<2),"(unu, "&ROUNDUP(MOD(BW15*100,100),0)&")", IF(AND(BW15>=2,BW15<3),"(doi, "&ROUNDUP(MOD(BW15*100,100),0)&")", IF(AND(BW15>=3,BW15<4),"(trei, "&ROUNDUP(MOD(BW15*100,100),0)&")", IF(AND(BW15>=4,BW15<5),"(patru, "&ROUNDUP(MOD(BW15*100,100),0)&")", IF(AND(BW15>=5,BW15<6),"(cinci, "&ROUNDUP(MOD(BW15*100,100),0)&")", IF(AND(BW15>=6,BW15<7),"(şase, "&ROUNDUP(MOD(BW15*100,100),0)&")", IF(AND(BW15>=7,BW15<8),"(şapte, "&ROUNDUP(MOD(BW15*100,100),0)&")", IF(AND(BW15>=8,BW15<9),"(opt, "&ROUNDUP(MOD(BW15*100,100),0)&")", IF(AND(BW15>=9,BW15<10),"(nouă, "&ROUNDUP(MOD(BW15*100,100),0)&")", IF(BW15=10,"(zece, 00)", ))))))))))),"") | BY15: =IF(NOT(ISBLANK(C15)), IF(BW15=" "," ", IF(AND(BW15>3,BW15<5),"FX", IF(AND(BW15>=5,BW15<=6),"E", IF(AND(BW15>6,BW15<=7),"D", IF(AND(BW15>7,BW15<=8),"C", IF(AND(BW15>8,BW15<=9),"B", IF(AND(BW15>9,BW15<=10),"A", IF(BW15=10,"(zece, 00)",)))))))), "")
B16: =IF(NOT(ISBLANK(C16)),COUNTA($C$6:C16),"") | T16: =IF(NOT(ISBLANK(C16)),IF(COUNTIF(E16:S16,"a")<>0,COUNTIF(E16:S16,"a")*2,""),"") | AJ16: =IF(NOT(ISBLANK(B16)),IF(COUNTIF(U16:AI16,"a")<>0,COUNTIF(U16:AI16,"a")*2,""),"") | AZ16: =IF(NOT(ISBLANK(B16)),IF(COUNTIF(AK16:AY16,"a")<>0,COUNTIF(AK16:AY16,"a")*2,""),"") | BA16: =IF(NOT(ISBLANK(T16)),IF(SUM(T16,AJ16,AZ16)<>0,SUM(T16,AJ16,AZ16),""),"") | BC16: ='Atest. Nr.1'!K12 | BF16: ='Atest. Nr.2'!I12 | BI16: =IF(NOT(ISBLANK(C16)),IF(COUNT(MAX(AVERAGE(BC16:BE16),0)),MAX(BC16:BE16),"n/p"),"") | BJ16: =IF(NOT(ISBLANK(C16)),IF(COUNT(MAX(AVERAGE(BF16:BH16),0)),MAX(BF16:BH16),"n/p"),"") | BK16: =Examen!H12 | BM16: =IF(NOT(ISBLANK(B16)),IF(SUM(E16:S16,U16:AI16,AK16:AY16)+SUM(MatLab!E17:R17)+SUM('Lab Fizica'!E17:R17)<>0,SUM(E16:S16,U16:AI16,AK16:AY16)+SUM(MatLab!E17:R17)+SUM('Lab Fizica'!E17:R17),""),"") | BQ16: =BI16 | BR16: =BJ16 | BS16: =IF(NOT(ISBLANK(C16)), IF(AND('Teste curente'!E12<>"n/p", 'Lab Fizica'!AL17<>""),ROUND(0.5*'Teste curente'!E12+0.5*'Lab Fizica'!AL17,0),"n/p"), "") | BT16: =IF(NOT(ISBLANK(C16)), IF(AND(MatLab!AN17="Admis",'Lab Fizica'!AM17<>""),ROUND(0.5*MatLab!AM17+0.5*'Lab Fizica'!AM17,0),"n/p"), "") | BU16: =IF(NOT(ISBLANK(C16)), IF(OR(BQ16="n/p",BR16="n/p",BS16="n/p",BT16="n/p",BQ16<5,BR16<5,BS16<5,BT16<5)," ",TRUNC(SUM(BQ16:BT16)/4,2)), "") | BV16: =IF(NOT(ISBLANK(C16)), IF(BU16=" ","n/a", IF(BP16,BP16, IF(COUNT(MAX(AVERAGE(BK16:BL16),0)),MAX(BK16:BL16),"n/p"))), "") | BW16: =IF(NOT(ISBLANK(C16)), IF(OR(BV16="n/a",BV16="n/p")," ", IF(BV16<5,BV16,TRUNC(BU16*0.6+BV16*0.4,2))), "") | BX16: =IF(NOT(ISBLANK(C16)), IF(BW16=" "," ", IF(AND(BW16>=1,BW16<2),"(unu, "&ROUNDUP(MOD(BW16*100,100),0)&")", IF(AND(BW16>=2,BW16<3),"(doi, "&ROUNDUP(MOD(BW16*100,100),0)&")", IF(AND(BW16>=3,BW16<4),"(trei, "&ROUNDUP(MOD(BW16*100,100),0)&")", IF(AND(BW16>=4,BW16<5),"(patru, "&ROUNDUP(MOD(BW16*100,100),0)&")", IF(AND(BW16>=5,BW16<6),"(cinci, "&ROUNDUP(MOD(BW16*100,100),0)&")", IF(AND(BW16>=6,BW16<7),"(şase, "&ROUNDUP(MOD(BW16*100,100),0)&")", IF(AND(BW16>=7,BW16<8),"(şapte, "&ROUNDUP(MOD(BW16*100,100),0)&")", IF(AND(BW16>=8,BW16<9),"(opt, "&ROUNDUP(MOD(BW16*100,100),0)&")", IF(AND(BW16>=9,BW16<10),"(nouă, "&ROUNDUP(MOD(BW16*100,100),0)&")", IF(BW16=10,"(zece, 00)", ))))))))))),"") | BY16: =IF(NOT(ISBLANK(C16)), IF(BW16=" "," ", IF(AND(BW16>3,BW16<5),"FX", IF(AND(BW16>=5,BW16<=6),"E", IF(AND(BW16>6,BW16<=7),"D", IF(AND(BW16>7,BW16<=8),"C", IF(AND(BW16>8,BW16<=9),"B", IF(AND(BW16>9,BW16<=10),"A", IF(BW16=10,"(zece, 00)",)))))))), "")
B17: =IF(NOT(ISBLANK(C17)),COUNTA($C$6:C17),"") | T17: =IF(NOT(ISBLANK(C17)),IF(COUNTIF(E17:S17,"a")<>0,COUNTIF(E17:S17,"a")*2,""),"") | AJ17: =IF(NOT(ISBLANK(B17)),IF(COUNTIF(U17:AI17,"a")<>0,COUNTIF(U17:AI17,"a")*2,""),"") | AZ17: =IF(NOT(ISBLANK(B17)),IF(COUNTIF(AK17:AY17,"a")<>0,COUNTIF(AK17:AY17,"a")*2,""),"") | BA17: =IF(NOT(ISBLANK(T17)),IF(SUM(T17,AJ17,AZ17)<>0,SUM(T17,AJ17,AZ17),""),"") | BC17: ='Atest. Nr.1'!K13 | BF17: ='Atest. Nr.2'!I13 | BI17: =IF(NOT(ISBLANK(C17)),IF(COUNT(MAX(AVERAGE(BC17:BE17),0)),MAX(BC17:BE17),"n/p"),"") | BJ17: =IF(NOT(ISBLANK(C17)),IF(COUNT(MAX(AVERAGE(BF17:BH17),0)),MAX(BF17:BH17),"n/p"),"") | BK17: =Examen!H13 | BM17: =IF(NOT(ISBLANK(B17)),IF(SUM(E17:S17,U17:AI17,AK17:AY17)+SUM(MatLab!E18:R18)+SUM('Lab Fizica'!E18:R18)<>0,SUM(E17:S17,U17:AI17,AK17:AY17)+SUM(MatLab!E18:R18)+SUM('Lab Fizica'!E18:R18),""),"") | BQ17: =BI17 | BR17: =BJ17 | BS17: =IF(NOT(ISBLANK(C17)), IF(AND('Teste curente'!E13<>"n/p", 'Lab Fizica'!AL18<>""),ROUND(0.5*'Teste curente'!E13+0.5*'Lab Fizica'!AL18,0),"n/p"), "") | BT17: =IF(NOT(ISBLANK(C17)), IF(AND(MatLab!AN18="Admis",'Lab Fizica'!AM18<>""),ROUND(0.5*MatLab!AM18+0.5*'Lab Fizica'!AM18,0),"n/p"), "") | BU17: =IF(NOT(ISBLANK(C17)), IF(OR(BQ17="n/p",BR17="n/p",BS17="n/p",BT17="n/p",BQ17<5,BR17<5,BS17<5,BT17<5)," ",TRUNC(SUM(BQ17:BT17)/4,2)), "") | BV17: =IF(NOT(ISBLANK(C17)), IF(BU17=" ","n/a", IF(BP17,BP17, IF(COUNT(MAX(AVERAGE(BK17:BL17),0)),MAX(BK17:BL17),"n/p"))), "") | BW17: =IF(NOT(ISBLANK(C17)), IF(OR(BV17="n/a",BV17="n/p")," ", IF(BV17<5,BV17,TRUNC(BU17*0.6+BV17*0.4,2))), "") | BX17: =IF(NOT(ISBLANK(C17)), IF(BW17=" "," ", IF(AND(BW17>=1,BW17<2),"(unu, "&ROUNDUP(MOD(BW17*100,100),0)&")", IF(AND(BW17>=2,BW17<3),"(doi, "&ROUNDUP(MOD(BW17*100,100),0)&")", IF(AND(BW17>=3,BW17<4),"(trei, "&ROUNDUP(MOD(BW17*100,100),0)&")", IF(AND(BW17>=4,BW17<5),"(patru, "&ROUNDUP(MOD(BW17*100,100),0)&")", IF(AND(BW17>=5,BW17<6),"(cinci, "&ROUNDUP(MOD(BW17*100,100),0)&")", IF(AND(BW17>=6,BW17<7),"(şase, "&ROUNDUP(MOD(BW17*100,100),0)&")", IF(AND(BW17>=7,BW17<8),"(şapte, "&ROUNDUP(MOD(BW17*100,100),0)&")", IF(AND(BW17>=8,BW17<9),"(opt, "&ROUNDUP(MOD(BW17*100,100),0)&")", IF(AND(BW17>=9,BW17<10),"(nouă, "&ROUNDUP(MOD(BW17*100,100),0)&")", IF(BW17=10,"(zece, 00)", ))))))))))),"") | BY17: =IF(NOT(ISBLANK(C17)), IF(BW17=" "," ", IF(AND(BW17>3,BW17<5),"FX", IF(AND(BW17>=5,BW17<=6),"E", IF(AND(BW17>6,BW17<=7),"D", IF(AND(BW17>7,BW17<=8),"C", IF(AND(BW17>8,BW17<=9),"B", IF(AND(BW17>9,BW17<=10),"A", IF(BW17=10,"(zece, 00)",)))))))), "")
B18: =IF(NOT(ISBLANK(C18)),COUNTA($C$6:C18),"") | T18: =IF(NOT(ISBLANK(C18)),IF(COUNTIF(E18:S18,"a")<>0,COUNTIF(E18:S18,"a")*2,""),"") | AJ18: =IF(NOT(ISBLANK(B18)),IF(COUNTIF(U18:AI18,"a")<>0,COUNTIF(U18:AI18,"a")*2,""),"") | AZ18: =IF(NOT(ISBLANK(B18)),IF(COUNTIF(AK18:AY18,"a")<>0,COUNTIF(AK18:AY18,"a")*2,""),"") | BA18: =IF(NOT(ISBLANK(T18)),IF(SUM(T18,AJ18,AZ18)<>0,SUM(T18,AJ18,AZ18),""),"") | BC18: ='Atest. Nr.1'!K14 | BF18: ='Atest. Nr.2'!I14 | BI18: =IF(NOT(ISBLANK(C18)),IF(COUNT(MAX(AVERAGE(BC18:BE18),0)),MAX(BC18:BE18),"n/p"),"") | BJ18: =IF(NOT(ISBLANK(C18)),IF(COUNT(MAX(AVERAGE(BF18:BH18),0)),MAX(BF18:BH18),"n/p"),"") | BK18: =Examen!H14 | BM18: =IF(NOT(ISBLANK(B18)),IF(SUM(E18:S18,U18:AI18,AK18:AY18)+SUM(MatLab!E19:R19)+SUM('Lab Fizica'!E19:R19)<>0,SUM(E18:S18,U18:AI18,AK18:AY18)+SUM(MatLab!E19:R19)+SUM('Lab Fizica'!E19:R19),""),"") | BQ18: =BI18 | BR18: =BJ18 | BS18: =IF(NOT(ISBLANK(C18)), IF(AND('Teste curente'!E14<>"n/p", 'Lab Fizica'!AL19<>""),ROUND(0.5*'Teste curente'!E14+0.5*'Lab Fizica'!AL19,0),"n/p"), "") | BT18: =IF(NOT(ISBLANK(C18)), IF(AND(MatLab!AN19="Admis",'Lab Fizica'!AM19<>""),ROUND(0.5*MatLab!AM19+0.5*'Lab Fizica'!AM19,0),"n/p"), "") | BU18: =IF(NOT(ISBLANK(C18)), IF(OR(BQ18="n/p",BR18="n/p",BS18="n/p",BT18="n/p",BQ18<5,BR18<5,BS18<5,BT18<5)," ",TRUNC(SUM(BQ18:BT18)/4,2)), "") | BV18: =IF(NOT(ISBLANK(C18)), IF(BU18=" ","n/a", IF(BP18,BP18, IF(COUNT(MAX(AVERAGE(BK18:BL18),0)),MAX(BK18:BL18),"n/p"))), "") | BW18: =IF(NOT(ISBLANK(C18)), IF(OR(BV18="n/a",BV18="n/p")," ", IF(BV18<5,BV18,TRUNC(BU18*0.6+BV18*0.4,2))), "") | BX18: =IF(NOT(ISBLANK(C18)), IF(BW18=" "," ", IF(AND(BW18>=1,BW18<2),"(unu, "&ROUNDUP(MOD(BW18*100,100),0)&")", IF(AND(BW18>=2,BW18<3),"(doi, "&ROUNDUP(MOD(BW18*100,100),0)&")", IF(AND(BW18>=3,BW18<4),"(trei, "&ROUNDUP(MOD(BW18*100,100),0)&")", IF(AND(BW18>=4,BW18<5),"(patru, "&ROUNDUP(MOD(BW18*100,100),0)&")", IF(AND(BW18>=5,BW18<6),"(cinci, "&ROUNDUP(MOD(BW18*100,100),0)&")", IF(AND(BW18>=6,BW18<7),"(şase, "&ROUNDUP(MOD(BW18*100,100),0)&")", IF(AND(BW18>=7,BW18<8),"(şapte, "&ROUNDUP(MOD(BW18*100,100),0)&")", IF(AND(BW18>=8,BW18<9),"(opt, "&ROUNDUP(MOD(BW18*100,100),0)&")", IF(AND(BW18>=9,BW18<10),"(nouă, "&ROUNDUP(MOD(BW18*100,100),0)&")", IF(BW18=10,"(zece, 00)", ))))))))))),"") | BY18: =IF(NOT(ISBLANK(C18)), IF(BW18=" "," ", IF(AND(BW18>3,BW18<5),"FX", IF(AND(BW18>=5,BW18<=6),"E", IF(AND(BW18>6,BW18<=7),"D", IF(AND(BW18>7,BW18<=8),"C", IF(AND(BW18>8,BW18<=9),"B", IF(AND(BW18>9,BW18<=10),"A", IF(BW18=10,"(zece, 00)",)))))))), "")
... B105: =IF(NOT(ISBLANK(C105)),COUNTA($C$6:C105),"") | T105: =IF(NOT(ISBLANK(C105)),IF(COUNTIF(E105:S105,"a")<>0,COUNTIF(E105:S105,"a")*2,""),"") | AJ105: =IF(NOT(ISBLANK(B105)),IF(COUNTIF(U105:AI105,"a")<>0,COUNTIF(U105:AI105,"a")*2,""),"") | AZ105: =IF(NOT(ISBLANK(B105)),IF(COUNTIF(AK105:AY105,"a")<>0,COUNTIF(AK105:AY105,"a")*2,""),"") | BA105: =IF(NOT(ISBLANK(T105)),IF(SUM(T105,AJ105,AZ105)<>0,SUM(T105,AJ105,AZ105),""),"") | BC105: ='Atest. Nr.1'!K101 | BF105: ='Atest. Nr.2'!I101 | BI105: =IF(NOT(ISBLANK(C105)),IF(COUNT(MAX(AVERAGE(BC105:BE105),0)),MAX(BC105:BE105),"n/p"),"") | BJ105: =IF(NOT(ISBLANK(C105)),IF(COUNT(MAX(AVERAGE(BF105:BH105),0)),MAX(BF105:BH105),"n/p"),"") | BK105: =Examen!H101 | BM105: =IF(NOT(ISBLANK(B105)),IF(SUM(E105:S105,U105:AI105,AK105:AY105)+SUM(MatLab!E106:R106)+SUM('Lab Fizica'!E106:R106)<>0,SUM(E105:S105,U105:AI105,AK105:AY105)+SUM(MatLab!E106:R106)+SUM('Lab Fizica'!E106:R106),""),"") | BQ105: =BI105 | BR105: =BJ105 | BS105: =IF(NOT(ISBLANK(C105)), IF(AND('Teste curente'!E101<>"n/p", 'Lab Fizica'!AL106<>""),ROUND(0.5*'Teste curente'!E101+0.5*'Lab Fizica'!AL106,0),"n/p"), "") | BT105: =IF(NOT(ISBLANK(C105)), IF(AND(MatLab!AN106="Admis",'Lab Fizica'!AM106<>""),ROUND(0.5*MatLab!AM106+0.5*'Lab Fizica'!AM106,0),"n/p"), "") | BU105: =IF(NOT(ISBLANK(C105)), IF(OR(BQ105="n/p",BR105="n/p",BS105="n/p",BT105="n/p",BQ105<5,BR105<5,BS105<5,BT105<5)," ",TRUNC(SUM(BQ105:BT105)/4,2)), "") | BV105: =IF(NOT(ISBLANK(C105)), IF(BU105=" ","n/a", IF(BP105,BP105, IF(COUNT(MAX(AVERAGE(BK105:BL105),0)),MAX(BK105:BL105),"n/p"))), "") | BW105: =IF(NOT(ISBLANK(C105)), IF(OR(BV105="n/a",BV105="n/p")," ", IF(BV105<5,BV105,TRUNC(BU105*0.6+BV105*0.4,2))), "") | BX105: =IF(NOT(ISBLANK(C105)), IF(BW105=" "," ", IF(AND(BW105>=1,BW105<2),"(unu, "&ROUNDUP(MOD(BW105*100,100),0)&")", IF(AND(BW105>=2,BW105<3),"(doi, "&ROUNDUP(MOD(BW105*100,100),0)&")", IF(AND(BW105>=3,BW105<4),"(trei, "&ROUNDUP(MOD(BW105*100,100),0)&")", IF(AND(BW105>=4,BW105<5),"(patru, "&ROUNDUP(MOD(BW105*100,100),0)&")", IF(AND(BW105>=5,BW105<6),"(cinci, "&ROUNDUP(MOD(BW105*100,100),0)&")", IF(AND(BW105>=6,BW105<7),"(şase, "&ROUNDUP(MOD(BW105*100,100),0)&")", IF(AND(BW105>=7,BW105<8),"(şapte, "&ROUNDUP(MOD(BW105*100,100),0)&")", IF(AND(BW105>=8,BW105<9),"(opt, "&ROUNDUP(MOD(BW105*100,100),0)&")", IF(AND(BW105>=9,BW105<10),"(nouă, "&ROUNDUP(MOD(BW105*100,100),0)&")", IF(BW105=10,"(zece, 00)", ))))))))))),"") | BY105: =IF(NOT(ISBLANK(C105)), IF(BW105=" "," ", IF(AND(BW105>3,BW105<5),"FX", IF(AND(BW105>=5,BW105<=6),"E", IF(AND(BW105>6,BW105<=7),"D", IF(AND(BW105>7,BW105<=8),"C", IF(AND(BW105>8,BW105<=9),"B", IF(AND(BW105>9,BW105<=10),"A", IF(BW105=10,"(zece, 00)",)))))))), "")
AJ106: =IF(NOT(ISBLANK(B106)),IF(COUNTIF(U106:AI106,"a")<>0,COUNTIF(U106:AI106,"a"),""),"") | BM106: =IF(NOT(ISBLANK(B106)),IF(SUM(E106:S106,U106:AI106,AK106:AY106)+SUM(MatLab!E107:R107)+SUM('Lab Fizica'!E107:R107)<>0,SUM(E106:S106,U106:AI106,AK106:AY106)+SUM(MatLab!E107:R107)+SUM('Lab Fizica'!E107:R107),""),"") | BS106: =IF(NOT(ISBLANK(C106)),IF(AND('Teste curente'!E102<>"n/p", 'Lab Fizica'!AL107<>""),ROUND(0.5*'Teste curente'!E102+0.5*'Lab Fizica'!AL107,0),"n/p"),"")
BM107: =IF(NOT(ISBLANK(B107)),IF(SUM(E107:S107,U107:AI107,AK107:AY107)+SUM(MatLab!E108:R108)+SUM('Lab Fizica'!E108:R108)<>0,SUM(E107:S107,U107:AI107,AK107:AY107)+SUM(MatLab!E108:R108)+SUM('Lab Fizica'!E108:R108),""),"") | BS107: =IF(NOT(ISBLANK(C107)),IF(AND('Teste curente'!E103<>"n/p", 'Lab Fizica'!AL108<>""),ROUND(0.5*'Teste curente'!E103+0.5*'Lab Fizica'!AL108,0),"n/p"),"")
BM108: =IF(NOT(ISBLANK(B108)),IF(SUM(E108:S108,U108:AI108,AK108:AY108)+SUM(MatLab!E109:R109)+SUM('Lab Fizica'!E109:R109)<>0,SUM(E108:S108,U108:AI108,AK108:AY108)+SUM(MatLab!E109:R109)+SUM('Lab Fizica'!E109:R109),""),"")

Sheet MatLab
B2: Prezența | V2: Evaluarea activităților
C4: Nr. Subgrupe - | D4: 1 | X4: L1 | Z4: L2 | AB4: L3 | AD4: L4 | AF4: L5 | AH4: L6 | AJ4: L7 | AL4: Total
E5: L1 | G5: L2 | I5: L3 | K5: L4 | M5: L5 | O5: L6 | Q5: L7 | W5: Data susținerii-- | X5: 14.02 21.02 | Z5: 28.02 7.03 | AB5: 14.03 21.03 | AD5: 28.03 4.04 | AF5: 11.04 25.04 | AH5: 2.05 9.05 | AJ5: 16.05
B6: Nr. | C6: Nume, Prenume | D6: Varianta | E6: 31.01 | T6: Ore absentate | V6: Nr. | W6: Nume, Prenume | X6: Nota | Y6: Penalit | Z6: Nota | AA6: Penalit | AB6: Nota | AC6: Penalit | AD6: Nota | AE6: Penalit | AF6: Nota | AG6: Penalit | AH6: Nota | AI6: Penalit | AJ6: Nota | AK6: Penalit | AL6: Penalități | AM6: Nota MatLab | AN6: Examen (Admis, N/A)
B7: =IF(NOT(ISBLANK('CP, Curs, Sem'!B6)),'CP, Curs, Sem'!B6,"") -> 1 | C7: =IF(NOT(ISBLANK('CP, Curs, Sem'!C6)),'CP, Curs, Sem'!C6,"") -> Nume, Prenume | T7: =IF(C7<>"",IF(COUNTIF(E7:S7,"a")<>0,COUNTIF(E7:S7,"a")*2,""),"") | V7: =IF(NOT(ISBLANK(B7)),B7,"") -> 1 | W7: =IF(NOT(ISBLANK(C7)),C7,"") -> Nume, Prenume | AL7: =IF(NOT(ISBLANK('CP, Curs, Sem'!C6)),IF(ABS(Y7+AA7+AC7+AE7+AG7+AI7+AK7)<>0,ABS(Y7+AA7+AC7+AE7+AG7+AI7+AK7),""),"") | AM7: =IF(NOT(ISBLANK('CP, Curs, Sem'!C6)),IFERROR(SUM(X7,Z7,AB7,AD7,AF7,AH7,AJ7)/COUNT(X7,Z7,AB7,AD7,AF7,AH7,AJ7),""),"")
B8: =IF(NOT(ISBLANK('CP, Curs, Sem'!B7)),'CP, Curs, Sem'!B7,"") | C8: =IF(NOT(ISBLANK('CP, Curs, Sem'!C7)),'CP, Curs, Sem'!C7,"") | T8: =IF(C8<>"",IF(COUNTIF(E8:S8,"a")<>0,COUNTIF(E8:S8,"a")*2,""),"") | V8: =IF(NOT(ISBLANK(B8)),B8,"") | W8: =IF(NOT(ISBLANK(C8)),C8,"") | AL8: =IF(NOT(ISBLANK('CP, Curs, Sem'!C7)),IF(ABS(Y8+AA8+AC8+AE8+AG8+AI8+AK8)<>0,ABS(Y8+AA8+AC8+AE8+AG8+AI8+AK8),""),"")
B9: =IF(NOT(ISBLANK('CP, Curs, Sem'!B8)),'CP, Curs, Sem'!B8,"") | C9: =IF(NOT(ISBLANK('CP, Curs, Sem'!C8)),'CP, Curs, Sem'!C8,"") | T9: =IF(C9<>"",IF(COUNTIF(E9:S9,"a")<>0,COUNTIF(E9:S9,"a")*2,""),"") | V9: =IF(NOT(ISBLANK(B9)),B9,"") | W9: =IF(NOT(ISBLANK(C9)),C9,"") | AL9: =IF(NOT(ISBLANK('CP, Curs, Sem'!C8)),IF(ABS(Y9+AA9+AC9+AE9+AG9+AI9+AK9)<>0,ABS(Y9+AA9+AC9+AE9+AG9+AI9+AK9),""),"") | AM9: =IF(NOT(ISBLANK('CP, Curs, Sem'!C8)),IFERROR(SUM(X9,Z9,AB9,AD9,AF9,AH9,AJ9)/COUNT(X9,Z9,AB9,AD9,AF9,AH9,AJ9),""),"")
B10: =IF(NOT(ISBLANK('CP, Curs, Sem'!B9)),'CP, Curs, Sem'!B9,"") | C10: =IF(NOT(ISBLANK('CP, Curs, Sem'!C9)),'CP, Curs, Sem'!C9,"") | T10: =IF(C10<>"",IF(COUNTIF(E10:S10,"a")<>0,COUNTIF(E10:S10,"a")*2,""),"") | V10: =IF(NOT(ISBLANK(B10)),B10,"") | W10: =IF(NOT(ISBLANK(C10)),C10,"") | AL10: =IF(NOT(ISBLANK('CP, Curs, Sem'!C9)),IF(ABS(Y10+AA10+AC10+AE10+AG10+AI10+AK10)<>0,ABS(Y10+AA10+AC10+AE10+AG10+AI10+AK10),""),"") | AM10: =IF(NOT(ISBLANK('CP, Curs, Sem'!C9)),IFERROR(SUM(X10,Z10,AB10,AD10,AF10,AH10,AJ10)/COUNT(X10,Z10,AB10,AD10,AF10,AH10,AJ10),""),"")
B11: =IF(NOT(ISBLANK('CP, Curs, Sem'!B10)),'CP, Curs, Sem'!B10,"") | C11: =IF(NOT(ISBLANK('CP, Curs, Sem'!C10)),'CP, Curs, Sem'!C10,"") | T11: =IF(C11<>"",IF(COUNTIF(E11:S11,"a")<>0,COUNTIF(E11:S11,"a")*2,""),"") | V11: =IF(NOT(ISBLANK(B11)),B11,"") | W11: =IF(NOT(ISBLANK(C11)),C11,"") | AL11: =IF(NOT(ISBLANK('CP, Curs, Sem'!C10)),IF(ABS(Y11+AA11+AC11+AE11+AG11+AI11+AK11)<>0,ABS(Y11+AA11+AC11+AE11+AG11+AI11+AK11),""),"") | AM11: =IF(NOT(ISBLANK('CP, Curs, Sem'!C10)),IFERROR(SUM(X11,Z11,AB11,AD11,AF11,AH11,AJ11)/COUNT(X11,Z11,AB11,AD11,AF11,AH11,AJ11),""),"")
B12: =IF(NOT(ISBLANK('CP, Curs, Sem'!B11)),'CP, Curs, Sem'!B11,"") | C12: =IF(NOT(ISBLANK('CP, Curs, Sem'!C11)),'CP, Curs, Sem'!C11,"") | T12: =IF(C12<>"",IF(COUNTIF(E12:S12,"a")<>0,COUNTIF(E12:S12,"a")*2,""),"") | V12: =IF(NOT(ISBLANK(B12)),B12,"") | W12: =IF(NOT(ISBLANK(C12)),C12,"") | AL12: =IF(NOT(ISBLANK('CP, Curs, Sem'!C11)),IF(ABS(Y12+AA12+AC12+AE12+AG12+AI12+AK12)<>0,ABS(Y12+AA12+AC12+AE12+AG12+AI12+AK12),""),"") | AM12: =IF(NOT(ISBLANK('CP, Curs, Sem'!C11)),IFERROR(SUM(X12,Z12,AB12,AD12,AF12,AH12,AJ12)/COUNT(X12,Z12,AB12,AD12,AF12,AH12,AJ12),""),"")
B13: =IF(NOT(ISBLANK('CP, Curs, Sem'!B12)),'CP, Curs, Sem'!B12,"") | C13: =IF(NOT(ISBLANK('CP, Curs, Sem'!C12)),'CP, Curs, Sem'!C12,"") | T13: =IF(C13<>"",IF(COUNTIF(E13:S13,"a")<>0,COUNTIF(E13:S13,"a")*2,""),"") | V13: =IF(NOT(ISBLANK(B13)),B13,"") | W13: =IF(NOT(ISBLANK(C13)),C13,"") | AL13: =IF(NOT(ISBLANK('CP, Curs, Sem'!C12)),IF(ABS(Y13+AA13+AC13+AE13+AG13+AI13+AK13)<>0,ABS(Y13+AA13+AC13+AE13+AG13+AI13+AK13),""),"") | AM13: =IF(NOT(ISBLANK('CP, Curs, Sem'!C12)),IFERROR(SUM(X13,Z13,AB13,AD13,AF13,AH13,AJ13)/COUNT(X13,Z13,AB13,AD13,AF13,AH13,AJ13),""),"")
B14: =IF(NOT(ISBLANK('CP, Curs, Sem'!B13)),'CP, Curs, Sem'!B13,"") | C14: =IF(NOT(ISBLANK('CP, Curs, Sem'!C13)),'CP, Curs, Sem'!C13,"") | T14: =IF(C14<>"",IF(COUNTIF(E14:S14,"a")<>0,COUNTIF(E14:S14,"a")*2,""),"") | V14: =IF(NOT(ISBLANK(B14)),B14,"") | W14: =IF(NOT(ISBLANK(C14)),C14,"") | AL14: =IF(NOT(ISBLANK('CP, Curs, Sem'!C13)),IF(ABS(Y14+AA14+AC14+AE14+AG14+AI14+AK14)<>0,ABS(Y14+AA14+AC14+AE14+AG14+AI14+AK14),""),"") | AM14: =IF(NOT(ISBLANK('CP, Curs, Sem'!C13)),IFERROR(SUM(X14,Z14,AB14,AD14,AF14,AH14,AJ14)/COUNT(X14,Z14,AB14,AD14,AF14,AH14,AJ14),""),"")
B15: =IF(NOT(ISBLANK('CP, Curs, Sem'!B14)),'CP, Curs, Sem'!B14,"") | C15: =IF(NOT(ISBLANK('CP, Curs, Sem'!C14)),'CP, Curs, Sem'!C14,"") | T15: =IF(C15<>"",IF(COUNTIF(E15:S15,"a")<>0,COUNTIF(E15:S15,"a")*2,""),"") | V15: =IF(NOT(ISBLANK(B15)),B15,"") | W15: =IF(NOT(ISBLANK(C15)),C15,"") | AL15: =IF(NOT(ISBLANK('CP, Curs, Sem'!C14)),IF(ABS(Y15+AA15+AC15+AE15+AG15+AI15+AK15)<>0,ABS(Y15+AA15+AC15+AE15+AG15+AI15+AK15),""),"") | AM15: =IF(NOT(ISBLANK('CP, Curs, Sem'!C14)),IFERROR(SUM(X15,Z15,AB15,AD15,AF15,AH15,AJ15)/COUNT(X15,Z15,AB15,AD15,AF15,AH15,AJ15),""),"")
B16: =IF(NOT(ISBLANK('CP, Curs, Sem'!B15)),'CP, Curs, Sem'!B15,"") | C16: =IF(NOT(ISBLANK('CP, Curs, Sem'!C15)),'CP, Curs, Sem'!C15,"") | T16: =IF(C16<>"",IF(COUNTIF(E16:S16,"a")<>0,COUNTIF(E16:S16,"a")*2,""),"") | V16: =IF(NOT(ISBLANK(B16)),B16,"") | W16: =IF(NOT(ISBLANK(C16)),C16,"") | AL16: =IF(NOT(ISBLANK('CP, Curs, Sem'!C15)),IF(ABS(Y16+AA16+AC16+AE16+AG16+AI16+AK16)<>0,ABS(Y16+AA16+AC16+AE16+AG16+AI16+AK16),""),"") | AM16: =IF(NOT(ISBLANK('CP, Curs, Sem'!C15)),IFERROR(SUM(X16,Z16,AB16,AD16,AF16,AH16,AJ16)/COUNT(X16,Z16,AB16,AD16,AF16,AH16,AJ16),""),"")
B17: =IF(NOT(ISBLANK('CP, Curs, Sem'!B16)),'CP, Curs, Sem'!B16,"") | C17: =IF(NOT(ISBLANK('CP, Curs, Sem'!C16)),'CP, Curs, Sem'!C16,"") | T17: =IF(C17<>"",IF(COUNTIF(E17:S17,"a")<>0,COUNTIF(E17:S17,"a")*2,""),"") | V17: =IF(NOT(ISBLANK(B17)),B17,"") | W17: =IF(NOT(ISBLANK(C17)),C17,"") | AL17: =IF(NOT(ISBLANK('CP, Curs, Sem'!C16)),IF(ABS(Y17+AA17+AC17+AE17+AG17+AI17+AK17)<>0,ABS(Y17+AA17+AC17+AE17+AG17+AI17+AK17),""),"") | AM17: =IF(NOT(ISBLANK('CP, Curs, Sem'!C16)),IFERROR(SUM(X17,Z17,AB17,AD17,AF17,AH17,AJ17)/COUNT(X17,Z17,AB17,AD17,AF17,AH17,AJ17),""),"")
B18: =IF(NOT(ISBLANK('CP, Curs, Sem'!B17)),'CP, Curs, Sem'!B17,"") | C18: =IF(NOT(ISBLANK('CP, Curs, Sem'!C17)),'CP, Curs, Sem'!C17,"") | T18: =IF(C18<>"",IF(COUNTIF(E18:S18,"a")<>0,COUNTIF(E18:S18,"a")*2,""),"") | V18: =IF(NOT(ISBLANK(B18)),B18,"") | W18: =IF(NOT(ISBLANK(C18)),C18,"") | AL18: =IF(NOT(ISBLANK('CP, Curs, Sem'!C17)),IF(ABS(Y18+AA18+AC18+AE18+AG18+AI18+AK18)<>0,ABS(Y18+AA18+AC18+AE18+AG18+AI18+AK18),""),"") | AM18: =IF(NOT(ISBLANK('CP, Curs, Sem'!C17)),IFERROR(SUM(X18,Z18,AB18,AD18,AF18,AH18,AJ18)/COUNT(X18,Z18,AB18,AD18,AF18,AH18,AJ18),""),"")
B19: =IF(NOT(ISBLANK('CP, Curs, Sem'!B18)),'CP, Curs, Sem'!B18,"") | C19: =IF(NOT(ISBLANK('CP, Curs, Sem'!C18)),'CP, Curs, Sem'!C18,"") | T19: =IF(C19<>"",IF(COUNTIF(E19:S19,"a")<>0,COUNTIF(E19:S19,"a")*2,""),"") | V19: =IF(NOT(ISBLANK(B19)),B19,"") | W19: =IF(NOT(ISBLANK(C19)),C19,"") | AL19: =IF(NOT(ISBLANK('CP, Curs, Sem'!C18)),IF(ABS(Y19+AA19+AC19+AE19+AG19+AI19+AK19)<>0,ABS(Y19+AA19+AC19+AE19+AG19+AI19+AK19),""),"") | AM19: =IF(NOT(ISBLANK('CP, Curs, Sem'!C18)),IFERROR(SUM(X19,Z19,AB19,AD19,AF19,AH19,AJ19)/COUNT(X19,Z19,AB19,AD19,AF19,AH19,AJ19),""),"")
B20: =IF(NOT(ISBLANK('CP, Curs, Sem'!B19)),'CP, Curs, Sem'!B19,"") | C20: =IF(NOT(ISBLANK('CP, Curs, Sem'!C19)),'CP, Curs, Sem'!C19,"") | T20: =IF(C20<>"",IF(COUNTIF(E20:S20,"a")<>0,COUNTIF(E20:S20,"a")*2,""),"") | V20: =IF(NOT(ISBLANK(B20)),B20,"") | W20: =IF(NOT(ISBLANK(C20)),C20,"") | AL20: =IF(NOT(ISBLANK('CP, Curs, Sem'!C19)),IF(ABS(Y20+AA20+AC20+AE20+AG20+AI20+AK20)<>0,ABS(Y20+AA20+AC20+AE20+AG20+AI20+AK20),""),"") | AM20: =IF(NOT(ISBLANK('CP, Curs, Sem'!C19)),IFERROR(SUM(X20,Z20,AB20,AD20,AF20,AH20,AJ20)/COUNT(X20,Z20,AB20,AD20,AF20,AH20,AJ20),""),"")
... B106: =IF(NOT(ISBLANK('CP, Curs, Sem'!B105)),'CP, Curs, Sem'!B105,"") | C106: =IF(NOT(ISBLANK('CP, Curs, Sem'!C105)),'CP, Curs, Sem'!C105,"") | T106: =IF(C106<>"",IF(COUNTIF(E106:S106,"a")<>0,COUNTIF(E106:S106,"a")*2,""),"") | V106: =IF(NOT(ISBLANK(B106)),B106,"") | W106: =IF(NOT(ISBLANK(C106)),C106,"") | AL106: =IF(NOT(ISBLANK('CP, Curs, Sem'!C105)),IF(ABS(Y106+AA106+AC106+AE106+AG106+AI106+AK106)<>0,ABS(Y106+AA106+AC106+AE106+AG106+AI106+AK106),""),"") | AM106: =IF(NOT(ISBLANK('CP, Curs, Sem'!C105)),IFERROR(SUM(X106,Z106,AB106,AD106,AF106,AH106,AJ106)/COUNT(X106,Z106,AB106,AD106,AF106,AH106,AJ106),""),"")

Sheet Lab Fizica
B2: Prezența | V2: Evaluarea activităților
C4: Nr. Subgrupe - | D4: 2 | X4: L1 | Z4: L2 | AB4: L3 | AD4: L4 | AF4: L5 | AH4: L6 | AJ4: L7 | AL4: Total
E5: L1 | G5: L2 | I5: L3 | K5: L4 | M5: L5 | O5: L6 | Q5: L7 | W5: Data susținerii--
B6: Nr. | C6: Nume, Prenume | D6: Varianta | E6: 31.01 | T6: Ore absentate | V6: Nr. | W6: Nume, Prenume | X6: Teor | Y6: Pract | Z6: Teor | AA6: Pract | AB6: Teor | AC6: Pract | AD6: Teor | AE6: Pract | AF6: Teor | AG6: Pract | AH6: Teor | AI6: Pract | AJ6: Teor | AK6: Pract | AL6: Teor | AM6: Pract | AN6: Examen (Admis, N/A)
B7: =IF(NOT(ISBLANK('CP, Curs, Sem'!B6)),'CP, Curs, Sem'!B6,"") -> 1 | C7: =IF(NOT(ISBLANK('CP, Curs, Sem'!C6)),'CP, Curs, Sem'!C6,"") -> Nume, Prenume | T7: =IF(C7<>"",IF(COUNTIF(E7:S7,"a")<>0,COUNTIF(E7:S7,"a")*2,""),"") | V7: =IF(NOT(ISBLANK(B7)),B7,"") -> 1 | W7: =IF(NOT(ISBLANK(C7)),C7,"") -> Nume, Prenume | AL7: =IF(NOT(ISBLANK('CP, Curs, Sem'!B6)),IFERROR(SUM(X7,Z7,AB7,AD7,AF7,AH7,AJ7)/COUNT(X7,Z7,AB7,AD7,AF7,AH7,AJ7),""),"") | AM7: =IF(NOT(ISBLANK('CP, Curs, Sem'!C6)),IFERROR(SUM(Y7,AA7,AC7,AE7,AG7,AI7,AK7)/COUNT(Y7,AA7,AC7,AE7,AG7,AI7,AK7),""),"")
B8: =IF(NOT(ISBLANK('CP, Curs, Sem'!B7)),'CP, Curs, Sem'!B7,"") | C8: =IF(NOT(ISBLANK('CP, Curs, Sem'!C7)),'CP, Curs, Sem'!C7,"") | T8: =IF(C8<>"",IF(COUNTIF(E8:S8,"a")<>0,COUNTIF(E8:S8,"a")*2,""),"") | V8: =IF(NOT(ISBLANK(B8)),B8,"") | W8: =IF(NOT(ISBLANK(C8)),C8,"")
B9: =IF(NOT(ISBLANK('CP, Curs, Sem'!B8)),'CP, Curs, Sem'!B8,"") | C9: =IF(NOT(ISBLANK('CP, Curs, Sem'!C8)),'CP, Curs, Sem'!C8,"") | T9: =IF(C9<>"",IF(COUNTIF(E9:S9,"a")<>0,COUNTIF(E9:S9,"a")*2,""),"") | V9: =IF(NOT(ISBLANK(B9)),B9,"") | W9: =IF(NOT(ISBLANK(C9)),C9,"") | AL9: =IF(NOT(ISBLANK('CP, Curs, Sem'!B8)),IFERROR(SUM(X9,Z9,AB9,AD9,AF9,AH9,AJ9)/COUNT(X9,Z9,AB9,AD9,AF9,AH9,AJ9),""),"") | AM9: =IF(NOT(ISBLANK('CP, Curs, Sem'!C8)),IFERROR(SUM(Y9,AA9,AC9,AE9,AG9,AI9,AK9)/COUNT(Y9,AA9,AC9,AE9,AG9,AI9,AK9),""),"")
B10: =IF(NOT(ISBLANK('CP, Curs, Sem'!B9)),'CP, Curs, Sem'!B9,"") | C10: =IF(NOT(ISBLANK('CP, Curs, Sem'!C9)),'CP, Curs, Sem'!C9,"") | T10: =IF(C10<>"",IF(COUNTIF(E10:S10,"a")<>0,COUNTIF(E10:S10,"a")*2,""),"") | V10: =IF(NOT(ISBLANK(B10)),B10,"") | W10: =IF(NOT(ISBLANK(C10)),C10,"") | AL10: =IF(NOT(ISBLANK('CP, Curs, Sem'!B9)),IFERROR(SUM(X10,Z10,AB10,AD10,AF10,AH10,AJ10)/COUNT(X10,Z10,AB10,AD10,AF10,AH10,AJ10),""),"") | AM10: =IF(NOT(ISBLANK('CP, Curs, Sem'!C9)),IFERROR(SUM(Y10,AA10,AC10,AE10,AG10,AI10,AK10)/COUNT(Y10,AA10,AC10,AE10,AG10,AI10,AK10),""),"")
B11: =IF(NOT(ISBLANK('CP, Curs, Sem'!B10)),'CP, Curs, Sem'!B10,"") | C11: =IF(NOT(ISBLANK('CP, Curs, Sem'!C10)),'CP, Curs, Sem'!C10,"") | T11: =IF(C11<>"",IF(COUNTIF(E11:S11,"a")<>0,COUNTIF(E11:S11,"a")*2,""),"") | V11: =IF(NOT(ISBLANK(B11)),B11,"") | W11: =IF(NOT(ISBLANK(C11)),C11,"") | AL11: =IF(NOT(ISBLANK('CP, Curs, Sem'!B10)),IFERROR(SUM(X11,Z11,AB11,AD11,AF11,AH11,AJ11)/COUNT(X11,Z11,AB11,AD11,AF11,AH11,AJ11),""),"") | AM11: =IF(NOT(ISBLANK('CP, Curs, Sem'!C10)),IFERROR(SUM(Y11,AA11,AC11,AE11,AG11,AI11,AK11)/COUNT(Y11,AA11,AC11,AE11,AG11,AI11,AK11),""),"")
B12: =IF(NOT(ISBLANK('CP, Curs, Sem'!B11)),'CP, Curs, Sem'!B11,"") | C12: =IF(NOT(ISBLANK('CP, Curs, Sem'!C11)),'CP, Curs, Sem'!C11,"") | T12: =IF(C12<>"",IF(COUNTIF(E12:S12,"a")<>0,COUNTIF(E12:S12,"a")*2,""),"") | V12: =IF(NOT(ISBLANK(B12)),B12,"") | W12: =IF(NOT(ISBLANK(C12)),C12,"") | AL12: =IF(NOT(ISBLANK('CP, Curs, Sem'!B11)),IFERROR(SUM(X12,Z12,AB12,AD12,AF12,AH12,AJ12)/COUNT(X12,Z12,AB12,AD12,AF12,AH12,AJ12),""),"") | AM12: =IF(NOT(ISBLANK('CP, Curs, Sem'!C11)),IFERROR(SUM(Y12,AA12,AC12,AE12,AG12,AI12,AK12)/COUNT(Y12,AA12,AC12,AE12,AG12,AI12,AK12),""),"")
B13: =IF(NOT(ISBLANK('CP, Curs, Sem'!B12)),'CP, Curs, Sem'!B12,"") | C13: =IF(NOT(ISBLANK('CP, Curs, Sem'!C12)),'CP, Curs, Sem'!C12,"") | T13: =IF(C13<>"",IF(COUNTIF(E13:S13,"a")<>0,COUNTIF(E13:S13,"a")*2,""),"") | V13: =IF(NOT(ISBLANK(B13)),B13,"") | W13: =IF(NOT(ISBLANK(C13)),C13,"") | AL13: =IF(NOT(ISBLANK('CP, Curs, Sem'!B12)),IFERROR(SUM(X13,Z13,AB13,AD13,AF13,AH13,AJ13)/COUNT(X13,Z13,AB13,AD13,AF13,AH13,AJ13),""),"") | AM13: =IF(NOT(ISBLANK('CP, Curs, Sem'!C12)),IFERROR(SUM(Y13,AA13,AC13,AE13,AG13,AI13,AK13)/COUNT(Y13,AA13,AC13,AE13,AG13,AI13,AK13),""),"")
B14: =IF(NOT(ISBLANK('CP, Curs, Sem'!B13)),'CP, Curs, Sem'!B13,"") | C14: =IF(NOT(ISBLANK('CP, Curs, Sem'!C13)),'CP, Curs, Sem'!C13,"") | T14: =IF(C14<>"",IF(COUNTIF(E14:S14,"a")<>0,COUNTIF(E14:S14,"a")*2,""),"") | V14: =IF(NOT(ISBLANK(B14)),B14,"") | W14: =IF(NOT(ISBLANK(C14)),C14,"") | AL14: =IF(NOT(ISBLANK('CP, Curs, Sem'!B13)),IFERROR(SUM(X14,Z14,AB14,AD14,AF14,AH14,AJ14)/COUNT(X14,Z14,AB14,AD14,AF14,AH14,AJ14),""),"") | AM14: =IF(NOT(ISBLANK('CP, Curs, Sem'!C13)),IFERROR(SUM(Y14,AA14,AC14,AE14,AG14,AI14,AK14)/COUNT(Y14,AA14,AC14,AE14,AG14,AI14,AK14),""),"")
B15: =IF(NOT(ISBLANK('CP, Curs, Sem'!B14)),'CP, Curs, Sem'!B14,"") | C15: =IF(NOT(ISBLANK('CP, Curs, Sem'!C14)),'CP, Curs, Sem'!C14,"") | T15: =IF(C15<>"",IF(COUNTIF(E15:S15,"a")<>0,COUNTIF(E15:S15,"a")*2,""),"") | V15: =IF(NOT(ISBLANK(B15)),B15,"") | W15: =IF(NOT(ISBLANK(C15)),C15,"") | AL15: =IF(NOT(ISBLANK('CP, Curs, Sem'!B14)),IFERROR(SUM(X15,Z15,AB15,AD15,AF15,AH15,AJ15)/COUNT(X15,Z15,AB15,AD15,AF15,AH15,AJ15),""),"") | AM15: =IF(NOT(ISBLANK('CP, Curs, Sem'!C14)),IFERROR(SUM(Y15,AA15,AC15,AE15,AG15,AI15,AK15)/COUNT(Y15,AA15,AC15,AE15,AG15,AI15,AK15),""),"")
B16: =IF(NOT(ISBLANK('CP, Curs, Sem'!B15)),'CP, Curs, Sem'!B15,"") | C16: =IF(NOT(ISBLANK('CP, Curs, Sem'!C15)),'CP, Curs, Sem'!C15,"") | T16: =IF(C16<>"",IF(COUNTIF(E16:S16,"a")<>0,COUNTIF(E16:S16,"a")*2,""),"") | V16: =IF(NOT(ISBLANK(B16)),B16,"") | W16: =IF(NOT(ISBLANK(C16)),C16,"") | AL16: =IF(NOT(ISBLANK('CP, Curs, Sem'!B15)),IFERROR(SUM(X16,Z16,AB16,AD16,AF16,AH16,AJ16)/COUNT(X16,Z16,AB16,AD16,AF16,AH16,AJ16),""),"") | AM16: =IF(NOT(ISBLANK('CP, Curs, Sem'!C15)),IFERROR(SUM(Y16,AA16,AC16,AE16,AG16,AI16,AK16)/COUNT(Y16,AA16,AC16,AE16,AG16,AI16,AK16),""),"")
B17: =IF(NOT(ISBLANK('CP, Curs, Sem'!B16)),'CP, Curs, Sem'!B16,"") | C17: =IF(NOT(ISBLANK('CP, Curs, Sem'!C16)),'CP, Curs, Sem'!C16,"") | T17: =IF(C17<>"",IF(COUNTIF(E17:S17,"a")<>0,COUNTIF(E17:S17,"a")*2,""),"") | V17: =IF(NOT(ISBLANK(B17)),B17,"") | W17: =IF(NOT(ISBLANK(C17)),C17,"") | AL17: =IF(NOT(ISBLANK('CP, Curs, Sem'!B16)),IFERROR(SUM(X17,Z17,AB17,AD17,AF17,AH17,AJ17)/COUNT(X17,Z17,AB17,AD17,AF17,AH17,AJ17),""),"") | AM17: =IF(NOT(ISBLANK('CP, Curs, Sem'!C16)),IFERROR(SUM(Y17,AA17,AC17,AE17,AG17,AI17,AK17)/COUNT(Y17,AA17,AC17,AE17,AG17,AI17,AK17),""),"")
B18: =IF(NOT(ISBLANK('CP, Curs, Sem'!B17)),'CP, Curs, Sem'!B17,"") | C18: =IF(NOT(ISBLANK('CP, Curs, Sem'!C17)),'CP, Curs, Sem'!C17,"") | T18: =IF(C18<>"",IF(COUNTIF(E18:S18,"a")<>0,COUNTIF(E18:S18,"a")*2,""),"") | V18: =IF(NOT(ISBLANK(B18)),B18,"") | W18: =IF(NOT(ISBLANK(C18)),C18,"") | AL18: =IF(NOT(ISBLANK('CP, Curs, Sem'!B17)),IFERROR(SUM(X18,Z18,AB18,AD18,AF18,AH18,AJ18)/COUNT(X18,Z18,AB18,AD18,AF18,AH18,AJ18),""),"") | AM18: =IF(NOT(ISBLANK('CP, Curs, Sem'!C17)),IFERROR(SUM(Y18,AA18,AC18,AE18,AG18,AI18,AK18)/COUNT(Y18,AA18,AC18,AE18,AG18,AI18,AK18),""),"")
B19: =IF(NOT(ISBLANK('CP, Curs, Sem'!B18)),'CP, Curs, Sem'!B18,"") | C19: =IF(NOT(ISBLANK('CP, Curs, Sem'!C18)),'CP, Curs, Sem'!C18,"") | T19: =IF(C19<>"",IF(COUNTIF(E19:S19,"a")<>0,COUNTIF(E19:S19,"a")*2,""),"") | V19: =IF(NOT(ISBLANK(B19)),B19,"") | W19: =IF(NOT(ISBLANK(C19)),C19,"") | AL19: =IF(NOT(ISBLANK('CP, Curs, Sem'!B18)),IFERROR(SUM(X19,Z19,AB19,AD19,AF19,AH19,AJ19)/COUNT(X19,Z19,AB19,AD19,AF19,AH19,AJ19),""),"") | AM19: =IF(NOT(ISBLANK('CP, Curs, Sem'!C18)),IFERROR(SUM(Y19,AA19,AC19,AE19,AG19,AI19,AK19)/COUNT(Y19,AA19,AC19,AE19,AG19,AI19,AK19),""),"")
B20: =IF(NOT(ISBLANK('CP, Curs, Sem'!B19)),'CP, Curs, Sem'!B19,"") | C20: =IF(NOT(ISBLANK('CP, Curs, Sem'!C19)),'CP, Curs, Sem'!C19,"") | T20: =IF(C20<>"",IF(COUNTIF(E20:S20,"a")<>0,COUNTIF(E20:S20,"a")*2,""),"") | V20: =IF(NOT(ISBLANK(B20)),B20,"") | W20: =IF(NOT(ISBLANK(C20)),C20,"") | AL20: =IF(NOT(ISBLANK('CP, Curs, Sem'!B19)),IFERROR(SUM(X20,Z20,AB20,AD20,AF20,AH20,AJ20)/COUNT(X20,Z20,AB20,AD20,AF20,AH20,AJ20),""),"") | AM20: =IF(NOT(ISBLANK('CP, Curs, Sem'!C19)),IFERROR(SUM(Y20,AA20,AC20,AE20,AG20,AI20,AK20)/COUNT(Y20,AA20,AC20,AE20,AG20,AI20,AK20),""),"")
... B106: =IF(NOT(ISBLANK('CP, Curs, Sem'!B105)),'CP, Curs, Sem'!B105,"") | C106: =IF(NOT(ISBLANK('CP, Curs, Sem'!C105)),'CP, Curs, Sem'!C105,"") | T106: =IF(C106<>"",IF(COUNTIF(E106:S106,"a")<>0,COUNTIF(E106:S106,"a")*2,""),"") | V106: =IF(NOT(ISBLANK(B106)),B106,"") | W106: =IF(NOT(ISBLANK(C106)),C106,"") | AL106: =IF(NOT(ISBLANK('CP, Curs, Sem'!B105)),IFERROR(SUM(X106,Z106,AB106,AD106,AF106,AH106,AJ106)/COUNT(X106,Z106,AB106,AD106,AF106,AH106,AJ106),""),"") | AM106: =IF(NOT(ISBLANK('CP, Curs, Sem'!C105)),IFERROR(SUM(Y106,AA106,AC106,AE106,AG106,AI106,AK106)/COUNT(Y106,AA106,AC106,AE106,AG106,AI106,AK106),""),"")

Sheet Teste curente
A1: Nr. | B1: Nume, Prenume | C1: Test 1 | D1: Test 2 | E1: Nota | G1: Statistica
A2: =IF(NOT(ISBLANK('CP, Curs, Sem'!B6)),'CP, Curs, Sem'!B6,"") -> 1 | B2: =IF(NOT(ISBLANK('CP, Curs, Sem'!C6)),'CP, Curs, Sem'!C6,"") -> Nume, Prenume | E2: =IF(NOT(ISBLANK('CP, Curs, Sem'!C6)), IF(AND(NOT(ISBLANK(C2)),NOT(ISBLANK(D2)),C2>=5,D2>=5),ROUND(AVERAGE(C2:D2),0),"n/p"), "") -> n/p | G2: Nota | H2: Nr de note
A3: =IF(NOT(ISBLANK('CP, Curs, Sem'!B7)),'CP, Curs, Sem'!B7,"") | B3: =IF(NOT(ISBLANK('CP, Curs, Sem'!C7)),'CP, Curs, Sem'!C7,"") | E3: =IF(NOT(ISBLANK('CP, Curs, Sem'!C7)), IF(AND(NOT(ISBLANK(C3)),NOT(ISBLANK(D3)),C3>=5,D3>=5),ROUND(AVERAGE(C3:D3),0),"n/p"), "") | G3: 1 | H3: =COUNTIF($E$2:$E$101,G3) -> 0
A4: =IF(NOT(ISBLANK('CP, Curs, Sem'!B8)),'CP, Curs, Sem'!B8,"") | B4: =IF(NOT(ISBLANK('CP, Curs, Sem'!C8)),'CP, Curs, Sem'!C8,"") | E4: =IF(NOT(ISBLANK('CP, Curs, Sem'!C8)), IF(AND(NOT(ISBLANK(C4)),NOT(ISBLANK(D4)),C4>=5,D4>=5),ROUND(AVERAGE(C4:D4),0),"n/p"), "") | G4: 2 | H4: =COUNTIF($E$2:$E$101,G4) -> 0
A5: =IF(NOT(ISBLANK('CP, Curs, Sem'!B9)),'CP, Curs, Sem'!B9,"") | B5: =IF(NOT(ISBLANK('CP, Curs, Sem'!C9)),'CP, Curs, Sem'!C9,"") | E5: =IF(NOT(ISBLANK('CP, Curs, Sem'!C9)), IF(AND(NOT(ISBLANK(C5)),NOT(ISBLANK(D5)),C5>=5,D5>=5),ROUND(AVERAGE(C5:D5),0),"n/p"), "") | G5: 3 | H5: =COUNTIF($E$2:$E$101,G5) -> 0
A6: =IF(NOT(ISBLANK('CP, Curs, Sem'!B10)),'CP, Curs, Sem'!B10,"") | B6: =IF(NOT(ISBLANK('CP, Curs, Sem'!C10)),'CP, Curs, Sem'!C10,"") | E6: =IF(NOT(ISBLANK('CP, Curs, Sem'!C10)), IF(AND(NOT(ISBLANK(C6)),NOT(ISBLANK(D6)),C6>=5,D6>=5),ROUND(AVERAGE(C6:D6),0),"n/p"), "") | G6: 4 | H6: =COUNTIF($E$2:$E$101,G6) -> 0
A7: =IF(NOT(ISBLANK('CP, Curs, Sem'!B11)),'CP, Curs, Sem'!B11,"") | B7: =IF(NOT(ISBLANK('CP, Curs, Sem'!C11)),'CP, Curs, Sem'!C11,"") | E7: =IF(NOT(ISBLANK('CP, Curs, Sem'!C11)), IF(AND(NOT(ISBLANK(C7)),NOT(ISBLANK(D7)),C7>=5,D7>=5),ROUND(AVERAGE(C7:D7),0),"n/p"), "") | G7: 5 | H7: =COUNTIF($E$2:$E$101,G7) -> 0
A8: =IF(NOT(ISBLANK('CP, Curs, Sem'!B12)),'CP, Curs, Sem'!B12,"") | B8: =IF(NOT(ISBLANK('CP, Curs, Sem'!C12)),'CP, Curs, Sem'!C12,"") | E8: =IF(NOT(ISBLANK('CP, Curs, Sem'!C12)), IF(AND(NOT(ISBLANK(C8)),NOT(ISBLANK(D8)),C8>=5,D8>=5),ROUND(AVERAGE(C8:D8),0),"n/p"), "") | G8: 6 | H8: =COUNTIF($E$2:$E$101,G8) -> 0
A9: =IF(NOT(ISBLANK('CP, Curs, Sem'!B13)),'CP, Curs, Sem'!B13,"") | B9: =IF(NOT(ISBLANK('CP, Curs, Sem'!C13)),'CP, Curs, Sem'!C13,"") | E9: =IF(NOT(ISBLANK('CP, Curs, Sem'!C13)), IF(AND(NOT(ISBLANK(C9)),NOT(ISBLANK(D9)),C9>=5,D9>=5),ROUND(AVERAGE(C9:D9),0),"n/p"), "") | G9: 7 | H9: =COUNTIF($E$2:$E$101,G9) -> 0
A10: =IF(NOT(ISBLANK('CP, Curs, Sem'!B14)),'CP, Curs, Sem'!B14,"") | B10: =IF(NOT(ISBLANK('CP, Curs, Sem'!C14)),'CP, Curs, Sem'!C14,"") | E10: =IF(NOT(ISBLANK('CP, Curs, Sem'!C14)), IF(AND(NOT(ISBLANK(C10)),NOT(ISBLANK(D10)),C10>=5,D10>=5),ROUND(AVERAGE(C10:D10),0),"n/p"), "") | G10: 8 | H10: =COUNTIF($E$2:$E$101,G10) -> 0
A11: =IF(NOT(ISBLANK('CP, Curs, Sem'!B15)),'CP, Curs, Sem'!B15,"") | B11: =IF(NOT(ISBLANK('CP, Curs, Sem'!C15)),'CP, Curs, Sem'!C15,"") | E11: =IF(NOT(ISBLANK('CP, Curs, Sem'!C15)), IF(AND(NOT(ISBLANK(C11)),NOT(ISBLANK(D11)),C11>=5,D11>=5),ROUND(AVERAGE(C11:D11),0),"n/p"), "") | G11: 9 | H11: =COUNTIF($E$2:$E$101,G11) -> 0
A12: =IF(NOT(ISBLANK('CP, Curs, Sem'!B16)),'CP, Curs, Sem'!B16,"") | B12: =IF(NOT(ISBLANK('CP, Curs, Sem'!C16)),'CP, Curs, Sem'!C16,"") | E12: =IF(NOT(ISBLANK('CP, Curs, Sem'!C16)), IF(AND(NOT(ISBLANK(C12)),NOT(ISBLANK(D12)),C12>=5,D12>=5),ROUND(AVERAGE(C12:D12),0),"n/p"), "") | G12: 10 | H12: =COUNTIF($E$2:$E$101,G12) -> 0
A13: =IF(NOT(ISBLANK('CP, Curs, Sem'!B17)),'CP, Curs, Sem'!B17,"") | B13: =IF(NOT(ISBLANK('CP, Curs, Sem'!C17)),'CP, Curs, Sem'!C17,"") | E13: =IF(NOT(ISBLANK('CP, Curs, Sem'!C17)), IF(AND(NOT(ISBLANK(C13)),NOT(ISBLANK(D13)),C13>=5,D13>=5),ROUND(AVERAGE(C13:D13),0),"n/p"), "") | G13: n/p | H13: =COUNTIF($E$2:$E$102,G13) -> 1
