Workbook

Sheet Curs
C2: Mecanica Teoretică. Anul de studii: Titular: Grupa: Șeful grupei: | V2: Rezultate atestări și sesiune | AH2: Nota semestrială | AM2: Ev.finală (0.4) | AN2: Nota finală | AR2: Examen:
E3: Curs | V3: Atestarea Nr.1 | Y3: Atestarea Nr.2 | AB3: Sesiunea | AH3: Componente | AL3: Media trunchiată (0.6) | AN3: în sist.național, trunchiată | AP3: Conform ECTS | AR3: Borderou | AS3: Prezenti | AT3: Admisi | AU3: Eliberati | AW3: A | AX3: B | AY3: C | AZ3: D | BA3: E | BB3: FX | BC3: F | BD3: n/p | BE3: n/a | BG3: Reușita din nr. total, % | BH3: Reușita din nr. prez., %
E4: C1 | F4: C2 | G4: C3 | H4: C4 | I4: C5 | J4: C6 | K4: C7 | L4: C8 | M4: C9 | N4: C10 | O4: C11 | P4: C12 | Q4: C13 | R4: C14 | S4: C15 | T4: Ore absentate | V4: Atest.1.1 | W4: Atest.1.2 | X4: Atest.1.3 | Y4: Atest.2.1 | Z4: Atest.2.2 | AA4: Atest.2.3 | AB4: Examen | AC4: Reexam | AD4: Puncte activ. suplim | AE4: Puncte utilizate | AF4: Exam | AH4: Ev.periodice (Atestările) | AJ4: Evaluarea curentă | AK4: Lucrul individual
B5: Nr. | C5: Nume, Prenume | D5: e-mail | E5: 29.01 | F5: 5.02 | G5: 12.02 | H5: 19.02 | I5: 26.02 | J5: 4.03 | K5: 11.03 | L5: 18.03 | M5: 25.03 | N5: 1.04 | O5: 8.04 | P5: 15.04 | Q5: 22.04 | R5: 29.04 | S5: 13.05 | V5: 18.03 | W5: 04.04 | Y5: 22.04 | AF5: Prezenta | AG5: Eliberati | AH5: nr.1 | AI5: nr.2 | AR5: =COUNTA(C6:C105) -> 1 | AS5: =AR5-COUNTIFS(B6:B105,">0",AF6:AF105,"a") -> 1 | AT5: =AR5-COUNTIF(AM6:AM105,"n/a") -> 0 | AU5: =COUNTA(AG6:AG105) -> 0 | AW5: =COUNTIF($AP$6:$AP$105,AW3) -> 0 | AX5: =COUNTIF($AP$6:$AP$105,AX3) -> 0 | AY5: =COUNTIF($AP$6:$AP$105,AY3) -> 0 | AZ5: =COUNTIF($AP$6:$AP$105,AZ3) -> 0 | BA5: =COUNTIF($AP$6:$AP$105,BA3) -> 0 | BB5: =COUNTIF($AP$6:$AP$105,BB3) -> 0 | BC5: =COUNTIF($AP$6:$AP$105,BC3) -> 0 | BD5: =COUNTIF($AM$6:$AM$105,BD3) -> 0 | BE5: =COUNTIF($AM$6:$AM$105,BE3) -> 1 | BG5: =SUM(AW5:BA5)/AR5 -> 0 | BH5: =SUM(AW5:BA5)/AS5 -> 0
B6: =IF(NOT(ISBLANK(C6)),COUNTA($C$6:C6),"") -> 1 | C6: Nume, Prenume | D6: student@mt.utm.md | T6: =IF(NOT(ISBLANK(C6)),IF(COUNTIF(E6:S6,"a")<>0,COUNTIF(E6:S6,"a")*2,""),"") | V6: ='Atest. Nr.1_1'!I2 -> n/p | W6: ='Atest. Nr.1_2'!H2 -> n/p | X6: ='Atest. Nr.1_3'!H2 -> n/p | Y6: ='Atest. Nr.2_1'!I2 -> n/p | Z6: ='Atest. Nr.2_2'!I2 -> n/p | AA6: ='Atest. Nr.2_3'!I2 -> n/p | AB6: =Examen!G2 -> n/p | AC6: =ReExaminare!G2 -> n/p | AD6: =IF(NOT(ISBLANK(B6)), IF(SUM(E6:S6)+SUM(Laborator!E7:R7)<>0,SUM(E6:S6)+SUM(Laborator!E7:R7),""), "") | AH6: =IF(NOT(ISBLANK(C6)), IF(COUNT(MAX(AVERAGE(V6:X6),0)),MAX(V6:X6),"n/p"), "") -> n/p | AI6: =IF(NOT(ISBLANK(C6)), IF(COUNT(MAX(AVERAGE(Y6:AA6),0)),MAX(Y6:AA6),"n/p"), "") -> n/p | AJ6: =IF(NOT(ISBLANK(C6)), IF(Laborator!AN7="Admis",ROUND(Laborator!AM7,0),"n/p"),"") -> n/p | AK6: =IF(NOT(ISBLANK(C6)), IF('Lucrari grafice'!F2<>"n/p",'Lucrari grafice'!F2,"n/p"),"") -> n/p | AL6: =IF(NOT(ISBLANK(C6)), IF(OR(AH6="n/p",AI6="n/p",AJ6="n/p",AK6="n/p",AH6<5,AI6<5,AJ6<5,AK6<5)," ",TRUNC(SUM(AH6:AK6)/4,2)), "") | AM6: =IF(NOT(ISBLANK(C6)), IF(AL6=" ","n/a", IF(AG6,AG6, IF(COUNT(MAX(AVERAGE(AB6:AC6),0)),MAX(AB6:AC6),"n/p"))), "") -> n/a | AN6: =IF(NOT(ISBLANK(C6)), IF(OR(AM6="n/a",AM6="n/p")," ", IF(AM6<5,AM6,TRUNC(AL6*0.6+AM6*0.4,2))), "") | AO6: =IF(NOT(ISBLANK(C6)), IF(AN6=" "," ", IF(AND(AN6>=1,AN6<2),"(unu, "&ROUNDUP(MOD(AN6*100,100),0)&")", IF(AND(AN6>=2,AN6<3),"(doi, "&ROUNDUP(MOD(AN6*100,100),0)&")", IF(AND(AN6>=3,AN6<4),"(trei, "&ROUNDUP(MOD(AN6*100,100),0)&")", IF(AND(AN6>=4,AN6<5),"(patru, "&ROUNDUP(MOD(AN6*100,100),0)&")", IF(AND(AN6>=5,AN6<6),"(cinci, "&ROUNDUP(MOD(AN6*100,100),0)&")", IF(AND(AN6>=6,AN6<7),"(şase, "&ROUNDUP(MOD(AN6*100,100),0)&")", IF(AND(AN6>=7,AN6<8),"(şapte, "&ROUNDUP(MOD(AN6*100,100),0)&")", IF(AND(AN6>=8,AN6<9),"(opt, "&ROUNDUP(MOD(AN6*100,100),0)&")", IF(AND(AN6>=9,AN6<10),"(nouă, "&ROUNDUP(MOD(AN6*100,100),0)&")", IF(AN6=10,"(zece, 00)", ))))))))))),"") | AP6: =IF(NOT(ISBLANK(C6)), IF(AN6=" "," ", IF(AND(AN6>=1,AN6<=3),"F", IF(AND(AN6>3,AN6<5),"FX", IF(AND(AN6>=5,AN6<=6),"E", IF(AND(AN6>6,AN6<=7),"D", IF(AND(AN6>7,AN6<=8),"C", IF(AND(AN6>8,AN6<=9),"B", IF(AND(AN6>9,AN6<=10),"A", )))))))),"")
B7: =IF(NOT(ISBLANK(C7)),COUNTA($C$6:C7),"") | T7: =IF(NOT(ISBLANK(C7)),IF(COUNTIF(E7:S7,"a")<>0,COUNTIF(E7:S7,"a")*2,""),"") | V7: ='Atest. Nr.1_1'!I3 | W7: ='Atest. Nr.1_2'!H3 | X7: ='Atest. Nr.1_3'!H3 | Y7: ='Atest. Nr.2_1'!I3 | Z7: ='Atest. Nr.2_2'!I3 | AA7: ='Atest. Nr.2_3'!I3 | AB7: =Examen!G3 | AC7: =ReExaminare!G3 | AD7: =IF(NOT(ISBLANK(B7)), IF(SUM(E7:S7)+SUM(Laborator!E8:R8)<>0,SUM(E7:S7)+SUM(Laborator!E8:R8),""), "") | AH7: =IF(NOT(ISBLANK(C7)), IF(COUNT(MAX(AVERAGE(V7:X7),0)),MAX(V7:X7),"n/p"), "") | AI7: =IF(NOT(ISBLANK(C7)), IF(COUNT(MAX(AVERAGE(Y7:AA7),0)),MAX(Y7:AA7),"n/p"), "") | AJ7: =IF(NOT(ISBLANK(C7)), IF(Laborator!AN8="Admis",ROUND(Laborator!AM8,0),"n/p"),"") | AK7: =IF(NOT(ISBLANK(C7)), IF('Lucrari grafice'!F3<>"n/p",'Lucrari grafice'!F3,"n/p"),"") | AL7: =IF(NOT(ISBLANK(C7)), IF(OR(AH7="n/p",AI7="n/p",AJ7="n/p",AK7="n/p",AH7<5,AI7<5,AJ7<5,AK7<5)," ",TRUNC(SUM(AH7:AK7)/4,2)), "") | AM7: =IF(NOT(ISBLANK(C7)), IF(AL7=" ","n/a", IF(AG7,AG7, IF(COUNT(MAX(AVERAGE(AB7:AC7),0)),MAX(AB7:AC7),"n/p"))), "") | AN7: =IF(NOT(ISBLANK(C7)), IF(OR(AM7="n/a",AM7="n/p")," ", IF(AM7<5,AM7,TRUNC(AL7*0.6+AM7*0.4,2))), "") | AO7: =IF(NOT(ISBLANK(C7)), IF(AN7=" "," ", IF(AND(AN7>=1,AN7<2),"(unu, "&ROUNDUP(MOD(AN7*100,100),0)&")", IF(AND(AN7>=2,AN7<3),"(doi, "&ROUNDUP(MOD(AN7*100,100),0)&")", IF(AND(AN7>=3,AN7<4),"(trei, "&ROUNDUP(MOD(AN7*100,100),0)&")", IF(AND(AN7>=4,AN7<5),"(patru, "&ROUNDUP(MOD(AN7*100,100),0)&")", IF(AND(AN7>=5,AN7<6),"(cinci, "&ROUNDUP(MOD(AN7*100,100),0)&")", IF(AND(AN7>=6,AN7<7),"(şase, "&ROUNDUP(MOD(AN7*100,100),0)&")", IF(AND(AN7>=7,AN7<8),"(şapte, "&ROUNDUP(MOD(AN7*100,100),0)&")", IF(AND(AN7>=8,AN7<9),"(opt, "&ROUNDUP(MOD(AN7*100,100),0)&")", IF(AND(AN7>=9,AN7<10),"(nouă, "&ROUNDUP(MOD(AN7*100,100),0)&")", IF(AN7=10,"(zece, 00)", ))))))))))),"") | AP7: =IF(NOT(ISBLANK(C7)), IF(AN7=" "," ", IF(AND(AN7>=1,AN7<=3),"F", IF(AND(AN7>3,AN7<5),"FX", IF(AND(AN7>=5,AN7<=6),"E", IF(AND(AN7>6,AN7<=7),"D", IF(AND(AN7>7,AN7<=8),"C", IF(AND(AN7>8,AN7<=9),"B", IF(AND(AN7>9,AN7<=10),"A", )))))))),"")
B8: =IF(NOT(ISBLANK(C8)),COUNTA($C$6:C8),"") | T8: =IF(NOT(ISBLANK(C8)),IF(COUNTIF(E8:S8,"a")<>0,COUNTIF(E8:S8,"a")*2,""),"") | V8: ='Atest. Nr.1_1'!I4 | W8: ='Atest. Nr.1_2'!H4 | X8: ='Atest. Nr.1_3'!H4 | Y8: ='Atest. Nr.2_1'!I4 | Z8: ='Atest. Nr.2_2'!I4 | AA8: ='Atest. Nr.2_3'!I4 | AB8: =Examen!G4 | AC8: =ReExaminare!G4 | AD8: =IF(NOT(ISBLANK(B8)), IF(SUM(E8:S8)+SUM(Laborator!E9:R9)<>0,SUM(E8:S8)+SUM(Laborator!E9:R9),""), "") | AH8: =IF(NOT(ISBLANK(C8)), IF(COUNT(MAX(AVERAGE(V8:X8),0)),MAX(V8:X8),"n/p"), "") | AI8: =IF(NOT(ISBLANK(C8)), IF(COUNT(MAX(AVERAGE(Y8:AA8),0)),MAX(Y8:AA8),"n/p"), "") | AJ8: =IF(NOT(ISBLANK(C8)), IF(Laborator!AN9="Admis",ROUND(Laborator!AM9,0),"n/p"),"") | AK8: =IF(NOT(ISBLANK(C8)), IF('Lucrari grafice'!F4<>"n/p",'Lucrari grafice'!F4,"n/p"),"") | AL8: =IF(NOT(ISBLANK(C8)), IF(OR(AH8="n/p",AI8="n/p",AJ8="n/p",AK8="n/p",AH8<5,AI8<5,AJ8<5,AK8<5)," ",TRUNC(SUM(AH8:AK8)/4,2)), "") | AM8: =IF(NOT(ISBLANK(C8)), IF(AL8=" ","n/a", IF(AG8,AG8, IF(COUNT(MAX(AVERAGE(AB8:AC8),0)),MAX(AB8:AC8),"n/p"))), "") | AN8: =IF(NOT(ISBLANK(C8)), IF(OR(AM8="n/a",AM8="n/p")," ", IF(AM8<5,AM8,TRUNC(AL8*0.6+AM8*0.4,2))), "") | AO8: =IF(NOT(ISBLANK(C8)), IF(AN8=" "," ", IF(AND(AN8>=1,AN8<2),"(unu, "&ROUNDUP(MOD(AN8*100,100),0)&")", IF(AND(AN8>=2,AN8<3),"(doi, "&ROUNDUP(MOD(AN8*100,100),0)&")", IF(AND(AN8>=3,AN8<4),"(trei, "&ROUNDUP(MOD(AN8*100,100),0)&")", IF(AND(AN8>=4,AN8<5),"(patru, "&ROUNDUP(MOD(AN8*100,100),0)&")", IF(AND(AN8>=5,AN8<6),"(cinci, "&ROUNDUP(MOD(AN8*100,100),0)&")", IF(AND(AN8>=6,AN8<7),"(şase, "&ROUNDUP(MOD(AN8*100,100),0)&")", IF(AND(AN8>=7,AN8<8),"(şapte, "&ROUNDUP(MOD(AN8*100,100),0)&")", IF(AND(AN8>=8,AN8<9),"(opt, "&ROUNDUP(MOD(AN8*100,100),0)&")", IF(AND(AN8>=9,AN8<10),"(nouă, "&ROUNDUP(MOD(AN8*100,100),0)&")", IF(AN8=10,"(zece, 00)", ))))))))))),"") | AP8: =IF(NOT(ISBLANK(C8)), IF(AN8=" "," ", IF(AND(AN8>=1,AN8<=3),"F", IF(AND(AN8>3,AN8<5),"FX", IF(AND(AN8>=5,AN8<=6),"E", IF(AND(AN8>6,AN8<=7),"D", IF(AND(AN8>7,AN8<=8),"C", IF(AND(AN8>8,AN8<=9),"B", IF(AND(AN8>9,AN8<=10),"A", )))))))),"")
B9: =IF(NOT(ISBLANK(C9)),COUNTA($C$6:C9),"") | T9: =IF(NOT(ISBLANK(C9)),IF(COUNTIF(E9:S9,"a")<>0,COUNTIF(E9:S9,"a")*2,""),"") | V9: ='Atest. Nr.1_1'!I5 | W9: ='Atest. Nr.1_2'!H5 | X9: ='Atest. Nr.1_3'!H5 | Y9: ='Atest. Nr.2_1'!I5 | Z9: ='Atest. Nr.2_2'!I5 | AA9: ='Atest. Nr.2_3'!I5 | AB9: =Examen!G5 | AC9: =ReExaminare!G5 | AD9: =IF(NOT(ISBLANK(B9)), IF(SUM(E9:S9)+SUM(Laborator!E10:R10)<>0,SUM(E9:S9)+SUM(Laborator!E10:R10),""), "") | AH9: =IF(NOT(ISBLANK(C9)), IF(COUNT(MAX(AVERAGE(V9:X9),0)),MAX(V9:X9),"n/p"), "") | AI9: =IF(NOT(ISBLANK(C9)), IF(COUNT(MAX(AVERAGE(Y9:AA9),0)),MAX(Y9:AA9),"n/p"), "") | AJ9: =IF(NOT(ISBLANK(C9)), IF(Laborator!AN10="Admis",ROUND(Laborator!AM10,0),"n/p"),"") | AK9: =IF(NOT(ISBLANK(C9)), IF('Lucrari grafice'!F5<>"n/p",'Lucrari grafice'!F5,"n/p"),"") | AL9: =IF(NOT(ISBLANK(C9)), IF(OR(AH9="n/p",AI9="n/p",AJ9="n/p",AK9="n/p",AH9<5,AI9<5,AJ9<5,AK9<5)," ",TRUNC(SUM(AH9:AK9)/4,2)), "") | AM9: =IF(NOT(ISBLANK(C9)), IF(AL9=" ","n/a", IF(AG9,AG9, IF(COUNT(MAX(AVERAGE(AB9:AC9),0)),MAX(AB9:AC9),"n/p"))), "") | AN9: =IF(NOT(ISBLANK(C9)), IF(OR(AM9="n/a",AM9="n/p")," ", IF(AM9<5,AM9,TRUNC(AL9*0.6+AM9*0.4,2))), "") | AO9: =IF(NOT(ISBLANK(C9)), IF(AN9=" "," ", IF(AND(AN9>=1,AN9<2),"(unu, "&ROUNDUP(MOD(AN9*100,100),0)&")", IF(AND(AN9>=2,AN9<3),"(doi, "&ROUNDUP(MOD(AN9*100,100),0)&")", IF(AND(AN9>=3,AN9<4),"(trei, "&ROUNDUP(MOD(AN9*100,100),0)&")", IF(AND(AN9>=4,AN9<5),"(patru, "&ROUNDUP(MOD(AN9*100,100),0)&")", IF(AND(AN9>=5,AN9<6),"(cinci, "&ROUNDUP(MOD(AN9*100,100),0)&")", IF(AND(AN9>=6,AN9<7),"(şase, "&ROUNDUP(MOD(AN9*100,100),0)&")", IF(AND(AN9>=7,AN9<8),"(şapte, "&ROUNDUP(MOD(AN9*100,100),0)&")", IF(AND(AN9>=8,AN9<9),"(opt, "&ROUNDUP(MOD(AN9*100,100),0)&")", IF(AND(AN9>=9,AN9<10),"(nouă, "&ROUNDUP(MOD(AN9*100,100),0)&")", IF(AN9=10,"(zece, 00)", ))))))))))),"") | AP9: =IF(NOT(ISBLANK(C9)), IF(AN9=" "," ", IF(AND(AN9>=1,AN9<=3),"F", IF(AND(AN9>3,AN9<5),"FX", IF(AND(AN9>=5,AN9<=6),"E", IF(AND(AN9>6,AN9<=7),"D", IF(AND(AN9>7,AN9<=8),"C", IF(AND(AN9>8,AN9<=9),"B", IF(AND(AN9>9,AN9<=10),"A", )))))))),"") | AT9: Evaluarea periodică Nr.1 | BG9: Reușita din nr. total, %
B10: =IF(NOT(ISBLANK(C10)),COUNTA($C$6:C10),"") | T10: =IF(NOT(ISBLANK(C10)),IF(COUNTIF(E10:S10,"a")<>0,COUNTIF(E10:S10,"a")*2,""),"") | V10: ='Atest. Nr.1_1'!I6 | W10: ='Atest. Nr.1_2'!H6 | X10: ='Atest. Nr.1_3'!H6 | Y10: ='Atest. Nr.2_1'!I6 | Z10: ='Atest. Nr.2_2'!I6 | AA10: ='Atest. Nr.2_3'!I6 | AB10: =Examen!G6 | AC10: =ReExaminare!G6 | AD10: =IF(NOT(ISBLANK(B10)), IF(SUM(E10:S10)+SUM(Laborator!E11:R11)<>0,SUM(E10:S10)+SUM(Laborator!E11:R11),""), "") | AH10: =IF(NOT(ISBLANK(C10)), IF(COUNT(MAX(AVERAGE(V10:X10),0)),MAX(V10:X10),"n/p"), "") | AI10: =IF(NOT(ISBLANK(C10)), IF(COUNT(MAX(AVERAGE(Y10:AA10),0)),MAX(Y10:AA10),"n/p"), "") | AJ10: =IF(NOT(ISBLANK(C10)), IF(Laborator!AN11="Admis",ROUND(Laborator!AM11,0),"n/p"),"") | AK10: =IF(NOT(ISBLANK(C10)), IF('Lucrari grafice'!F6<>"n/p",'Lucrari grafice'!F6,"n/p"),"") | AL10: =IF(NOT(ISBLANK(C10)), IF(OR(AH10="n/p",AI10="n/p",AJ10="n/p",AK10="n/p",AH10<5,AI10<5,AJ10<5,AK10<5)," ",TRUNC(SUM(AH10:AK10)/4,2)), "") | AM10: =IF(NOT(ISBLANK(C10)), IF(AL10=" ","n/a", IF(AG10,AG10, IF(COUNT(MAX(AVERAGE(AB10:AC10),0)),MAX(AB10:AC10),"n/p"))), "") | AN10: =IF(NOT(ISBLANK(C10)), IF(OR(AM10="n/a",AM10="n/p")," ", IF(AM10<5,AM10,TRUNC(AL10*0.6+AM10*0.4,2))), "") | AO10: =IF(NOT(ISBLANK(C10)), IF(AN10=" "," ", IF(AND(AN10>=1,AN10<2),"(unu, "&ROUNDUP(MOD(AN10*100,100),0)&")", IF(AND(AN10>=2,AN10<3),"(doi, "&ROUNDUP(MOD(AN10*100,100),0)&")", IF(AND(AN10>=3,AN10<4),"(trei, "&ROUNDUP(MOD(AN10*100,100),0)&")", IF(AND(AN10>=4,AN10<5),"(patru, "&ROUNDUP(MOD(AN10*100,100),0)&")", IF(AND(AN10>=5,AN10<6),"(cinci, "&ROUNDUP(MOD(AN10*100,100),0)&")", IF(AND(AN10>=6,AN10<7),"(şase, "&ROUNDUP(MOD(AN10*100,100),0)&")", IF(AND(AN10>=7,AN10<8),"(şapte, "&ROUNDUP(MOD(AN10*100,100),0)&")", IF(AND(AN10>=8,AN10<9),"(opt, "&ROUNDUP(MOD(AN10*100,100),0)&")", IF(AND(AN10>=9,AN10<10),"(nouă, "&ROUNDUP(MOD(AN10*100,100),0)&")", IF(AN10=10,"(zece, 00)", ))))))))))),"") | AP10: =IF(NOT(ISBLANK(C10)), IF(AN10=" "," ", IF(AND(AN10>=1,AN10<=3),"F", IF(AND(AN10>3,AN10<5),"FX", IF(AND(AN10>=5,AN10<=6),"E", IF(AND(AN10>6,AN10<=7),"D", IF(AND(AN10>7,AN10<=8),"C", IF(AND(AN10>8,AN10<=9),"B", IF(AND(AN10>9,AN10<=10),"A", )))))))),"")
B11: =IF(NOT(ISBLANK(C11)),COUNTA($C$6:C11),"") | T11: =IF(NOT(ISBLANK(C11)),IF(COUNTIF(E11:S11,"a")<>0,COUNTIF(E11:S11,"a")*2,""),"") | V11: ='Atest. Nr.1_1'!I7 | W11: ='Atest. Nr.1_2'!H7 | X11: ='Atest. Nr.1_3'!H7 | Y11: ='Atest. Nr.2_1'!I7 | Z11: ='Atest. Nr.2_2'!I7 | AA11: ='Atest. Nr.2_3'!I7 | AB11: =Examen!G7 | AC11: =ReExaminare!G7 | AD11: =IF(NOT(ISBLANK(B11)), IF(SUM(E11:S11)+SUM(Laborator!E12:R12)<>0,SUM(E11:S11)+SUM(Laborator!E12:R12),""), "") | AH11: =IF(NOT(ISBLANK(C11)), IF(COUNT(MAX(AVERAGE(V11:X11),0)),MAX(V11:X11),"n/p"), "") | AI11: =IF(NOT(ISBLANK(C11)), IF(COUNT(MAX(AVERAGE(Y11:AA11),0)),MAX(Y11:AA11),"n/p"), "") | AJ11: =IF(NOT(ISBLANK(C11)), IF(Laborator!AN12="Admis",ROUND(Laborator!AM12,0),"n/p"),"") | AK11: =IF(NOT(ISBLANK(C11)), IF('Lucrari grafice'!F7<>"n/p",'Lucrari grafice'!F7,"n/p"),"") | AL11: =IF(NOT(ISBLANK(C11)), IF(OR(AH11="n/p",AI11="n/p",AJ11="n/p",AK11="n/p",AH11<5,AI11<5,AJ11<5,AK11<5)," ",TRUNC(SUM(AH11:AK11)/4,2)), "") | AM11: =IF(NOT(ISBLANK(C11)), IF(AL11=" ","n/a", IF(AG11,AG11, IF(COUNT(MAX(AVERAGE(AB11:AC11),0)),MAX(AB11:AC11),"n/p"))), "") | AN11: =IF(NOT(ISBLANK(C11)), IF(OR(AM11="n/a",AM11="n/p")," ", IF(AM11<5,AM11,TRUNC(AL11*0.6+AM11*0.4,2))), "") | AO11: =IF(NOT(ISBLANK(C11)), IF(AN11=" "," ", IF(AND(AN11>=1,AN11<2),"(unu, "&ROUNDUP(MOD(AN11*100,100),0)&")", IF(AND(AN11>=2,AN11<3),"(doi, "&ROUNDUP(MOD(AN11*100,100),0)&")", IF(AND(AN11>=3,AN11<4),"(trei, "&ROUNDUP(MOD(AN11*100,100),0)&")", IF(AND(AN11>=4,AN11<5),"(patru, "&ROUNDUP(MOD(AN11*100,100),0)&")", IF(AND(AN11>=5,AN11<6),"(cinci, "&ROUNDUP(MOD(AN11*100,100),0)&")", IF(AND(AN11>=6,AN11<7),"(şase, "&ROUNDUP(MOD(AN11*100,100),0)&")", IF(AND(AN11>=7,AN11<8),"(şapte, "&ROUNDUP(MOD(AN11*100,100),0)&")", IF(AND(AN11>=8,AN11<9),"(opt, "&ROUNDUP(MOD(AN11*100,100),0)&")", IF(AND(AN11>=9,AN11<10),"(nouă, "&ROUNDUP(MOD(AN11*100,100),0)&")", IF(AN11=10,"(zece, 00)", ))))))))))),"") | AP11: =IF(NOT(ISBLANK(C11)), IF(AN11=" "," ", IF(AND(AN11>=1,AN11<=3),"F", IF(AND(AN11>3,AN11<5),"FX", IF(AND(AN11>=5,AN11<=6),"E", IF(AND(AN11>6,AN11<=7),"D", IF(AND(AN11>7,AN11<=8),"C", IF(AND(AN11>8,AN11<=9),"B", IF(AND(AN11>9,AN11<=10),"A", )))))))),"") | AT11: Nr. stud | AU11: n/p | AV11: 1 | AW11: 2 | AX11: 3 | AY11: 4 | AZ11: 5 | BA11: 6 | BB11: 7 | BC11: 8 | BD11: 9 | BE11: 10
B12: =IF(NOT(ISBLANK(C12)),COUNTA($C$6:C12),"") | T12: =IF(NOT(ISBLANK(C12)),IF(COUNTIF(E12:S12,"a")<>0,COUNTIF(E12:S12,"a")*2,""),"") | V12: ='Atest. Nr.1_1'!I8 | W12: ='Atest. Nr.1_2'!H8 | X12: ='Atest. Nr.1_3'!H8 | Y12: ='Atest. Nr.2_1'!I8 | Z12: ='Atest. Nr.2_2'!I8 | AA12: ='Atest. Nr.2_3'!I8 | AB12: =Examen!G8 | AC12: =ReExaminare!G8 | AD12: =IF(NOT(ISBLANK(B12)), IF(SUM(E12:S12)+SUM(Laborator!E13:R13)<>0,SUM(E12:S12)+SUM(Laborator!E13:R13),""), "") | AH12: =IF(NOT(ISBLANK(C12)), IF(COUNT(MAX(AVERAGE(V12:X12),0)),MAX(V12:X12),"n/p"), "") | AI12: =IF(NOT(ISBLANK(C12)), IF(COUNT(MAX(AVERAGE(Y12:AA12),0)),MAX(Y12:AA12),"n/p"), "") | AJ12: =IF(NOT(ISBLANK(C12)), IF(Laborator!AN13="Admis",ROUND(Laborator!AM13,0),"n/p"),"") | AK12: =IF(NOT(ISBLANK(C12)), IF('Lucrari grafice'!F8<>"n/p",'Lucrari grafice'!F8,"n/p"),"") | AL12: =IF(NOT(ISBLANK(C12)), IF(OR(AH12="n/p",AI12="n/p",AJ12="n/p",AK12="n/p",AH12<5,AI12<5,AJ12<5,AK12<5)," ",TRUNC(SUM(AH12:AK12)/4,2)), "") | AM12: =IF(NOT(ISBLANK(C12)), IF(AL12=" ","n/a", IF(AG12,AG12, IF(COUNT(MAX(AVERAGE(AB12:AC12),0)),MAX(AB12:AC12),"n/p"))), "") | AN12: =IF(NOT(ISBLANK(C12)), IF(OR(AM12="n/a",AM12="n/p")," ", IF(AM12<5,AM12,TRUNC(AL12*0.6+AM12*0.4,2))), "") | AO12: =IF(NOT(ISBLANK(C12)), IF(AN12=" "," ", IF(AND(AN12>=1,AN12<2),"(unu, "&ROUNDUP(MOD(AN12*100,100),0)&")", IF(AND(AN12>=2,AN12<3),"(doi, "&ROUNDUP(MOD(AN12*100,100),0)&")", IF(AND(AN12>=3,AN12<4),"(trei, "&ROUNDUP(MOD(AN12*100,100),0)&")", IF(AND(AN12>=4,AN12<5),"(patru, "&ROUNDUP(MOD(AN12*100,100),0)&")", IF(AND(AN12>=5,AN12<6),"(cinci, "&ROUNDUP(MOD(AN12*100,100),0)&")", IF(AND(AN12>=6,AN12<7),"(şase, "&ROUNDUP(MOD(AN12*100,100),0)&")", IF(AND(AN12>=7,AN12<8),"(şapte, "&ROUNDUP(MOD(AN12*100,100),0)&")", IF(AND(AN12>=8,AN12<9),"(opt, "&ROUNDUP(MOD(AN12*100,100),0)&")", IF(AND(AN12>=9,AN12<10),"(nouă, "&ROUNDUP(MOD(AN12*100,100),0)&")", IF(AN12=10,"(zece, 00)", ))))))))))),"") | AP12: =IF(NOT(ISBLANK(C12)), IF(AN12=" "," ", IF(AND(AN12>=1,AN12<=3),"F", IF(AND(AN12>3,AN12<5),"FX", IF(AND(AN12>=5,AN12<=6),"E", IF(AND(AN12>6,AN12<=7),"D", IF(AND(AN12>7,AN12<=8),"C", IF(AND(AN12>8,AN12<=9),"B", IF(AND(AN12>9,AN12<=10),"A", )))))))),"")
B13: =IF(NOT(ISBLANK(C13)),COUNTA($C$6:C13),"") | T13: =IF(NOT(ISBLANK(C13)),IF(COUNTIF(E13:S13,"a")<>0,COUNTIF(E13:S13,"a")*2,""),"") | V13: ='Atest. Nr.1_1'!I9 | W13: ='Atest. Nr.1_2'!H9 | X13: ='Atest. Nr.1_3'!H9 | Y13: ='Atest. Nr.2_1'!I9 | Z13: ='Atest. Nr.2_2'!I9 | AA13: ='Atest. Nr.2_3'!I9 | AB13: =Examen!G9 | AC13: =ReExaminare!G9 | AD13: =IF(NOT(ISBLANK(B13)), IF(SUM(E13:S13)+SUM(Laborator!E14:R14)<>0,SUM(E13:S13)+SUM(Laborator!E14:R14),""), "") | AH13: =IF(NOT(ISBLANK(C13)), IF(COUNT(MAX(AVERAGE(V13:X13),0)),MAX(V13:X13),"n/p"), "") | AI13: =IF(NOT(ISBLANK(C13)), IF(COUNT(MAX(AVERAGE(Y13:AA13),0)),MAX(Y13:AA13),"n/p"), "") | AJ13: =IF(NOT(ISBLANK(C13)), IF(Laborator!AN14="Admis",ROUND(Laborator!AM14,0),"n/p"),"") | AK13: =IF(NOT(ISBLANK(C13)), IF('Lucrari grafice'!F9<>"n/p",'Lucrari grafice'!F9,"n/p"),"") | AL13: =IF(NOT(ISBLANK(C13)), IF(OR(AH13="n/p",AI13="n/p",AJ13="n/p",AK13="n/p",AH13<5,AI13<5,AJ13<5,AK13<5)," ",TRUNC(SUM(AH13:AK13)/4,2)), "") | AM13: =IF(NOT(ISBLANK(C13)), IF(AL13=" ","n/a", IF(AG13,AG13, IF(COUNT(MAX(AVERAGE(AB13:AC13),0)),MAX(AB13:AC13),"n/p"))), "") | AN13: =IF(NOT(ISBLANK(C13)), IF(OR(AM13="n/a",AM13="n/p")," ", IF(AM13<5,AM13,TRUNC(AL13*0.6+AM13*0.4,2))), "") | AO13: =IF(NOT(ISBLANK(C13)), IF(AN13=" "," ", IF(AND(AN13>=1,AN13<2),"(unu, "&ROUNDUP(MOD(AN13*100,100),0)&")", IF(AND(AN13>=2,AN13<3),"(doi, "&ROUNDUP(MOD(AN13*100,100),0)&")", IF(AND(AN13>=3,AN13<4),"(trei, "&ROUNDUP(MOD(AN13*100,100),0)&")", IF(AND(AN13>=4,AN13<5),"(patru, "&ROUNDUP(MOD(AN13*100,100),0)&")", IF(AND(AN13>=5,AN13<6),"(cinci, "&ROUNDUP(MOD(AN13*100,100),0)&")", IF(AND(AN13>=6,AN13<7),"(şase, "&ROUNDUP(MOD(AN13*100,100),0)&")", IF(AND(AN13>=7,AN13<8),"(şapte, "&ROUNDUP(MOD(AN13*100,100),0)&")", IF(AND(AN13>=8,AN13<9),"(opt, "&ROUNDUP(MOD(AN13*100,100),0)&")", IF(AND(AN13>=9,AN13<10),"(nouă, "&ROUNDUP(MOD(AN13*100,100),0)&")", IF(AN13=10,"(zece, 00)", ))))))))))),"") | AP13: =IF(NOT(ISBLANK(C13)), IF(AN13=" "," ", IF(AND(AN13>=1,AN13<=3),"F", IF(AND(AN13>3,AN13<5),"FX", IF(AND(AN13>=5,AN13<=6),"E", IF(AND(AN13>6,AN13<=7),"D", IF(AND(AN13>7,AN13<=8),"C", IF(AND(AN13>8,AN13<=9),"B", IF(AND(AN13>9,AN13<=10),"A", )))))))),"") | AT13: =COUNTA(C6:C105) -> 1 | AU13: =COUNTIF($AH$6:$AH$105,AU11) -> 1 | AV13: =COUNTIF($AH$6:$AH$105,AV11) -> 0 | AW13: =COUNTIF($AH$6:$AH$105,AW11) -> 0 | AX13: =COUNTIF($AH$6:$AH$105,AX11) -> 0 | AY13: =COUNTIF($AH$6:$AH$105,AY11) -> 0 | AZ13: =COUNTIF($AH$6:$AH$105,AZ11) -> 0 | BA13: =COUNTIF($AH$6:$AH$105,BA11) -> 0 | BB13: =COUNTIF($AH$6:$AH$105,BB11) -> 0 | ... BE13: =COUNTIF($AH$6:$AH$105,BE11) -> 0 | BG13: =SUM(AZ13:BE14)/AT13 -> 0
B14: =IF(NOT(ISBLANK(C14)),COUNTA($C$6:C14),"") | T14: =IF(NOT(ISBLANK(C14)),IF(COUNTIF(E14:S14,"a")<>0,COUNTIF(E14:S14,"a")*2,""),"") | V14: ='Atest. Nr.1_1'!I10 | W14: ='Atest. Nr.1_2'!H10 | X14: ='Atest. Nr.1_3'!H10 | Y14: ='Atest. Nr.2_1'!I10 | Z14: ='Atest. Nr.2_2'!I10 | AA14: ='Atest. Nr.2_3'!I10 | AB14: =Examen!G10 | AC14: =ReExaminare!G10 | AD14: =IF(NOT(ISBLANK(B14)), IF(SUM(E14:S14)+SUM(Laborator!E15:R15)<>0,SUM(E14:S14)+SUM(Laborator!E15:R15),""), "") | AH14: =IF(NOT(ISBLANK(C14)), IF(COUNT(MAX(AVERAGE(V14:X14),0)),MAX(V14:X14),"n/p"), "") | AI14: =IF(NOT(ISBLANK(C14)), IF(COUNT(MAX(AVERAGE(Y14:AA14),0)),MAX(Y14:AA14),"n/p"), "") | AJ14: =IF(NOT(ISBLANK(C14)), IF(Laborator!AN15="Admis",ROUND(Laborator!AM15,0),"n/p"),"") | AK14: =IF(NOT(ISBLANK(C14)), IF('Lucrari grafice'!F10<>"n/p",'Lucrari grafice'!F10,"n/p"),"") | AL14: =IF(NOT(ISBLANK(C14)), IF(OR(AH14="n/p",AI14="n/p",AJ14="n/p",AK14="n/p",AH14<5,AI14<5,AJ14<5,AK14<5)," ",TRUNC(SUM(AH14:AK14)/4,2)), "") | AM14: =IF(NOT(ISBLANK(C14)), IF(AL14=" ","n/a", IF(AG14,AG14, IF(COUNT(MAX(AVERAGE(AB14:AC14),0)),MAX(AB14:AC14),"n/p"))), "") | AN14: =IF(NOT(ISBLANK(C14)), IF(OR(AM14="n/a",AM14="n/p")," ", IF(AM14<5,AM14,TRUNC(AL14*0.6+AM14*0.4,2))), "") | AO14: =IF(NOT(ISBLANK(C14)), IF(AN14=" "," ", IF(AND(AN14>=1,AN14<2),"(unu, "&ROUNDUP(MOD(AN14*100,100),0)&")", IF(AND(AN14>=2,AN14<3),"(doi, "&ROUNDUP(MOD(AN14*100,100),0)&")", IF(AND(AN14>=3,AN14<4),"(trei, "&ROUNDUP(MOD(AN14*100,100),0)&")", IF(AND(AN14>=4,AN14<5),"(patru, "&ROUNDUP(MOD(AN14*100,100),0)&")", IF(AND(AN14>=5,AN14<6),"(cinci, "&ROUNDUP(MOD(AN14*100,100),0)&")", IF(AND(AN14>=6,AN14<7),"(şase, "&ROUNDUP(MOD(AN14*100,100),0)&")", IF(AND(AN14>=7,AN14<8),"(şapte, "&ROUNDUP(MOD(AN14*100,100),0)&")", IF(AND(AN14>=8,AN14<9),"(opt, "&ROUNDUP(MOD(AN14*100,100),0)&")", IF(AND(AN14>=9,AN14<10),"(nouă, "&ROUNDUP(MOD(AN14*100,100),0)&")", IF(AN14=10,"(zece, 00)", ))))))))))),"") | AP14: =IF(NOT(ISBLANK(C14)), IF(AN14=" "," ", IF(AND(AN14>=1,AN14<=3),"F", IF(AND(AN14>3,AN14<5),"FX", IF(AND(AN14>=5,AN14<=6),"E", IF(AND(AN14>6,AN14<=7),"D", IF(AND(AN14>7,AN14<=8),"C", IF(AND(AN14>8,AN14<=9),"B", IF(AND(AN14>9,AN14<=10),"A", )))))))),"")
B15: =IF(NOT(ISBLANK(C15)),COUNTA($C$6:C15),"") | T15: =IF(NOT(ISBLANK(C15)),IF(COUNTIF(E15:S15,"a")<>0,COUNTIF(E15:S15,"a")*2,""),"") | V15: ='Atest. Nr.1_1'!I11 | W15: ='Atest. Nr.1_2'!H11 | X15: ='Atest. Nr.1_3'!H11 | Y15: ='Atest. Nr.2_1'!I11 | Z15: ='Atest. Nr.2_2'!I11 | AA15: ='Atest. Nr.2_3'!I11 | AB15: =Examen!G11 | AC15: =ReExaminare!G11 | AD15: =IF(NOT(ISBLANK(B15)), IF(SUM(E15:S15)+SUM(Laborator!E16:R16)<>0,SUM(E15:S15)+SUM(Laborator!E16:R16),""), "") | AH15: =IF(NOT(ISBLANK(C15)), IF(COUNT(MAX(AVERAGE(V15:X15),0)),MAX(V15:X15),"n/p"), "") | AI15: =IF(NOT(ISBLANK(C15)), IF(COUNT(MAX(AVERAGE(Y15:AA15),0)),MAX(Y15:AA15),"n/p"), "") | AJ15: =IF(NOT(ISBLANK(C15)), IF(Laborator!AN16="Admis",ROUND(Laborator!AM16,0),"n/p"),"") | AK15: =IF(NOT(ISBLANK(C15)), IF('Lucrari grafice'!F11<>"n/p",'Lucrari grafice'!F11,"n/p"),"") | AL15: =IF(NOT(ISBLANK(C15)), IF(OR(AH15="n/p",AI15="n/p",AJ15="n/p",AK15="n/p",AH15<5,AI15<5,AJ15<5,AK15<5)," ",TRUNC(SUM(AH15:AK15)/4,2)), "") | AM15: =IF(NOT(ISBLANK(C15)), IF(AL15=" ","n/a", IF(AG15,AG15, IF(COUNT(MAX(AVERAGE(AB15:AC15),0)),MAX(AB15:AC15),"n/p"))), "") | AN15: =IF(NOT(ISBLANK(C15)), IF(OR(AM15="n/a",AM15="n/p")," ", IF(AM15<5,AM15,TRUNC(AL15*0.6+AM15*0.4,2))), "") | AO15: =IF(NOT(ISBLANK(C15)), IF(AN15=" "," ", IF(AND(AN15>=1,AN15<2),"(unu, "&ROUNDUP(MOD(AN15*100,100),0)&")", IF(AND(AN15>=2,AN15<3),"(doi, "&ROUNDUP(MOD(AN15*100,100),0)&")", IF(AND(AN15>=3,AN15<4),"(trei, "&ROUNDUP(MOD(AN15*100,100),0)&")", IF(AND(AN15>=4,AN15<5),"(patru, "&ROUNDUP(MOD(AN15*100,100),0)&")", IF(AND(AN15>=5,AN15<6),"(cinci, "&ROUNDUP(MOD(AN15*100,100),0)&")", IF(AND(AN15>=6,AN15<7),"(şase, "&ROUNDUP(MOD(AN15*100,100),0)&")", IF(AND(AN15>=7,AN15<8),"(şapte, "&ROUNDUP(MOD(AN15*100,100),0)&")", IF(AND(AN15>=8,AN15<9),"(opt, "&ROUNDUP(MOD(AN15*100,100),0)&")", IF(AND(AN15>=9,AN15<10),"(nouă, "&ROUNDUP(MOD(AN15*100,100),0)&")", IF(AN15=10,"(zece, 00)", ))))))))))),"") | AP15: =IF(NOT(ISBLANK(C15)), IF(AN15=" "," ", IF(AND(AN15>=1,AN15<=3),"F", IF(AND(AN15>3,AN15<5),"FX", IF(AND(AN15>=5,AN15<=6),"E", IF(AND(AN15>6,AN15<=7),"D", IF(AND(AN15>7,AN15<=8),"C", IF(AND(AN15>8,AN15<=9),"B", IF(AND(AN15>9,AN15<=10),"A", )))))))),"")
B16: =IF(NOT(ISBLANK(C16)),COUNTA($C$6:C16),"") | T16: =IF(NOT(ISBLANK(C16)),IF(COUNTIF(E16:S16,"a")<>0,COUNTIF(E16:S16,"a")*2,""),"") | V16: ='Atest. Nr.1_1'!I12 | W16: ='Atest. Nr.1_2'!H12 | X16: ='Atest. Nr.1_3'!H12 | Y16: ='Atest. Nr.2_1'!I12 | Z16: ='Atest. Nr.2_2'!I12 | AA16: ='Atest. Nr.2_3'!I12 | AB16: =Examen!G12 | AC16: =ReExaminare!G12 | AD16: =IF(NOT(ISBLANK(B16)), IF(SUM(E16:S16)+SUM(Laborator!E17:R17)<>0,SUM(E16:S16)+SUM(Laborator!E17:R17),""), "") | AH16: =IF(NOT(ISBLANK(C16)), IF(COUNT(MAX(AVERAGE(V16:X16),0)),MAX(V16:X16),"n/p"), "") | AI16: =IF(NOT(ISBLANK(C16)), IF(COUNT(MAX(AVERAGE(Y16:AA16),0)),MAX(Y16:AA16),"n/p"), "") | AJ16: =IF(NOT(ISBLANK(C16)), IF(Laborator!AN17="Admis",ROUND(Laborator!AM17,0),"n/p"),"") | AK16: =IF(NOT(ISBLANK(C16)), IF('Lucrari grafice'!F12<>"n/p",'Lucrari grafice'!F12,"n/p"),"") | AL16: =IF(NOT(ISBLANK(C16)), IF(OR(AH16="n/p",AI16="n/p",AJ16="n/p",AK16="n/p",AH16<5,AI16<5,AJ16<5,AK16<5)," ",TRUNC(SUM(AH16:AK16)/4,2)), "") | AM16: =IF(NOT(ISBLANK(C16)), IF(AL16=" ","n/a", IF(AG16,AG16, IF(COUNT(MAX(AVERAGE(AB16:AC16),0)),MAX(AB16:AC16),"n/p"))), "") | AN16: =IF(NOT(ISBLANK(C16)), IF(OR(AM16="n/a",AM16="n/p")," ", IF(AM16<5,AM16,TRUNC(AL16*0.6+AM16*0.4,2))), "") | AO16: =IF(NOT(ISBLANK(C16)), IF(AN16=" "," ", IF(AND(AN16>=1,AN16<2),"(unu, "&ROUNDUP(MOD(AN16*100,100),0)&")", IF(AND(AN16>=2,AN16<3),"(doi, "&ROUNDUP(MOD(AN16*100,100),0)&")", IF(AND(AN16>=3,AN16<4),"(trei, "&ROUNDUP(MOD(AN16*100,100),0)&")", IF(AND(AN16>=4,AN16<5),"(patru, "&ROUNDUP(MOD(AN16*100,100),0)&")", IF(AND(AN16>=5,AN16<6),"(cinci, "&ROUNDUP(MOD(AN16*100,100),0)&")", IF(AND(AN16>=6,AN16<7),"(şase, "&ROUNDUP(MOD(AN16*100,100),0)&")", IF(AND(AN16>=7,AN16<8),"(şapte, "&ROUNDUP(MOD(AN16*100,100),0)&")", IF(AND(AN16>=8,AN16<9),"(opt, "&ROUNDUP(MOD(AN16*100,100),0)&")", IF(AND(AN16>=9,AN16<10),"(nouă, "&ROUNDUP(MOD(AN16*100,100),0)&")", IF(AN16=10,"(zece, 00)", ))))))))))),"") | AP16: =IF(NOT(ISBLANK(C16)), IF(AN16=" "," ", IF(AND(AN16>=1,AN16<=3),"F", IF(AND(AN16>3,AN16<5),"FX", IF(AND(AN16>=5,AN16<=6),"E", IF(AND(AN16>6,AN16<=7),"D", IF(AND(AN16>7,AN16<=8),"C", IF(AND(AN16>8,AN16<=9),"B", IF(AND(AN16>9,AN16<=10),"A", )))))))),"")
B17: =IF(NOT(ISBLANK(C17)),COUNTA($C$6:C17),"") | T17: =IF(NOT(ISBLANK(C17)),IF(COUNTIF(E17:S17,"a")<>0,COUNTIF(E17:S17,"a")*2,""),"") | V17: ='Atest. Nr.1_1'!I13 | W17: ='Atest. Nr.1_2'!H13 | X17: ='Atest. Nr.1_3'!H13 | Y17: ='Atest. Nr.2_1'!I13 | Z17: ='Atest. Nr.2_2'!I13 | AA17: ='Atest. Nr.2_3'!I13 | AB17: =Examen!G13 | AC17: =ReExaminare!G13 | AD17: =IF(NOT(ISBLANK(B17)), IF(SUM(E17:S17)+SUM(Laborator!E18:R18)<>0,SUM(E17:S17)+SUM(Laborator!E18:R18),""), "") | AH17: =IF(NOT(ISBLANK(C17)), IF(COUNT(MAX(AVERAGE(V17:X17),0)),MAX(V17:X17),"n/p"), "") | AI17: =IF(NOT(ISBLANK(C17)), IF(COUNT(MAX(AVERAGE(Y17:AA17),0)),MAX(Y17:AA17),"n/p"), "") | AJ17: =IF(NOT(ISBLANK(C17)), IF(Laborator!AN18="Admis",ROUND(Laborator!AM18,0),"n/p"),"") | AK17: =IF(NOT(ISBLANK(C17)), IF('Lucrari grafice'!F13<>"n/p",'Lucrari grafice'!F13,"n/p"),"") | AL17: =IF(NOT(ISBLANK(C17)), IF(OR(AH17="n/p",AI17="n/p",AJ17="n/p",AK17="n/p",AH17<5,AI17<5,AJ17<5,AK17<5)," ",TRUNC(SUM(AH17:AK17)/4,2)), "") | AM17: =IF(NOT(ISBLANK(C17)), IF(AL17=" ","n/a", IF(AG17,AG17, IF(COUNT(MAX(AVERAGE(AB17:AC17),0)),MAX(AB17:AC17),"n/p"))), "") | AN17: =IF(NOT(ISBLANK(C17)), IF(OR(AM17="n/a",AM17="n/p")," ", IF(AM17<5,AM17,TRUNC(AL17*0.6+AM17*0.4,2))), "") | AO17: =IF(NOT(ISBLANK(C17)), IF(AN17=" "," ", IF(AND(AN17>=1,AN17<2),"(unu, "&ROUNDUP(MOD(AN17*100,100),0)&")", IF(AND(AN17>=2,AN17<3),"(doi, "&ROUNDUP(MOD(AN17*100,100),0)&")", IF(AND(AN17>=3,AN17<4),"(trei, "&ROUNDUP(MOD(AN17*100,100),0)&")", IF(AND(AN17>=4,AN17<5),"(patru, "&ROUNDUP(MOD(AN17*100,100),0)&")", IF(AND(AN17>=5,AN17<6),"(cinci, "&ROUNDUP(MOD(AN17*100,100),0)&")", IF(AND(AN17>=6,AN17<7),"(şase, "&ROUNDUP(MOD(AN17*100,100),0)&")", IF(AND(AN17>=7,AN17<8),"(şapte, "&ROUNDUP(MOD(AN17*100,100),0)&")", IF(AND(AN17>=8,AN17<9),"(opt, "&ROUNDUP(MOD(AN17*100,100),0)&")", IF(AND(AN17>=9,AN17<10),"(nouă, "&ROUNDUP(MOD(AN17*100,100),0)&")", IF(AN17=10,"(zece, 00)", ))))))))))),"") | AP17: =IF(NOT(ISBLANK(C17)), IF(AN17=" "," ", IF(AND(AN17>=1,AN17<=3),"F", IF(AND(AN17>3,AN17<5),"FX", IF(AND(AN17>=5,AN17<=6),"E", IF(AND(AN17>6,AN17<=7),"D", IF(AND(AN17>7,AN17<=8),"C", IF(AND(AN17>8,AN17<=9),"B", IF(AND(AN17>9,AN17<=10),"A", )))))))),"")
B18: =IF(NOT(ISBLANK(C18)),COUNTA($C$6:C18),"") | T18: =IF(NOT(ISBLANK(C18)),IF(COUNTIF(E18:S18,"a")<>0,COUNTIF(E18:S18,"a")*2,""),"") | V18: ='Atest. Nr.1_1'!I14 | W18: ='Atest. Nr.1_2'!H14 | X18: ='Atest. Nr.1_3'!H14 | Y18: ='Atest. Nr.2_1'!I14 | Z18: ='Atest. Nr.2_2'!I14 | AA18: ='Atest. Nr.2_3'!I14 | AB18: =Examen!G14 | AC18: =ReExaminare!G14 | AD18: =IF(NOT(ISBLANK(B18)), IF(SUM(E18:S18)+SUM(Laborator!E19:R19)<>0,SUM(E18:S18)+SUM(Laborator!E19:R19),""), "") | AH18: =IF(NOT(ISBLANK(C18)), IF(COUNT(MAX(AVERAGE(V18:X18),0)),MAX(V18:X18),"n/p"), "") | AI18: =IF(NOT(ISBLANK(C18)), IF(COUNT(MAX(AVERAGE(Y18:AA18),0)),MAX(Y18:AA18),"n/p"), "") | AJ18: =IF(NOT(ISBLANK(C18)), IF(Laborator!AN19="Admis",ROUND(Laborator!AM19,0),"n/p"),"") | AK18: =IF(NOT(ISBLANK(C18)), IF('Lucrari grafice'!F14<>"n/p",'Lucrari grafice'!F14,"n/p"),"") | AL18: =IF(NOT(ISBLANK(C18)), IF(OR(AH18="n/p",AI18="n/p",AJ18="n/p",AK18="n/p",AH18<5,AI18<5,AJ18<5,AK18<5)," ",TRUNC(SUM(AH18:AK18)/4,2)), "") | AM18: =IF(NOT(ISBLANK(C18)), IF(AL18=" ","n/a", IF(AG18,AG18, IF(COUNT(MAX(AVERAGE(AB18:AC18),0)),MAX(AB18:AC18),"n/p"))), "") | AN18: =IF(NOT(ISBLANK(C18)), IF(OR(AM18="n/a",AM18="n/p")," ", IF(AM18<5,AM18,TRUNC(AL18*0.6+AM18*0.4,2))), "") | AO18: =IF(NOT(ISBLANK(C18)), IF(AN18=" "," ", IF(AND(AN18>=1,AN18<2),"(unu, "&ROUNDUP(MOD(AN18*100,100),0)&")", IF(AND(AN18>=2,AN18<3),"(doi, "&ROUNDUP(MOD(AN18*100,100),0)&")", IF(AND(AN18>=3,AN18<4),"(trei, "&ROUNDUP(MOD(AN18*100,100),0)&")", IF(AND(AN18>=4,AN18<5),"(patru, "&ROUNDUP(MOD(AN18*100,100),0)&")", IF(AND(AN18>=5,AN18<6),"(cinci, "&ROUNDUP(MOD(AN18*100,100),0)&")", IF(AND(AN18>=6,AN18<7),"(şase, "&ROUNDUP(MOD(AN18*100,100),0)&")", IF(AND(AN18>=7,AN18<8),"(şapte, "&ROUNDUP(MOD(AN18*100,100),0)&")", IF(AND(AN18>=8,AN18<9),"(opt, "&ROUNDUP(MOD(AN18*100,100),0)&")", IF(AND(AN18>=9,AN18<10),"(nouă, "&ROUNDUP(MOD(AN18*100,100),0)&")", IF(AN18=10,"(zece, 00)", ))))))))))),"") | AP18: =IF(NOT(ISBLANK(C18)), IF(AN18=" "," ", IF(AND(AN18>=1,AN18<=3),"F", IF(AND(AN18>3,AN18<5),"FX", IF(AND(AN18>=5,AN18<=6),"E", IF(AND(AN18>6,AN18<=7),"D", IF(AND(AN18>7,AN18<=8),"C", IF(AND(AN18>8,AN18<=9),"B", IF(AND(AN18>9,AN18<=10),"A", )))))))),"") | AT18: Evaluarea periodică Nr.2 | BG18: Reușita din nr. total, %
B19: =IF(NOT(ISBLANK(C19)),COUNTA($C$6:C19),"") | T19: =IF(NOT(ISBLANK(C19)),IF(COUNTIF(E19:S19,"a")<>0,COUNTIF(E19:S19,"a")*2,""),"") | V19: ='Atest. Nr.1_1'!I15 | W19: ='Atest. Nr.1_2'!H15 | X19: ='Atest. Nr.1_3'!H15 | Y19: ='Atest. Nr.2_1'!I15 | Z19: ='Atest. Nr.2_2'!I15 | AA19: ='Atest. Nr.2_3'!I15 | AB19: =Examen!G15 | AC19: =ReExaminare!G15 | AD19: =IF(NOT(ISBLANK(B19)), IF(SUM(E19:S19)+SUM(Laborator!E20:R20)<>0,SUM(E19:S19)+SUM(Laborator!E20:R20),""), "") | AH19: =IF(NOT(ISBLANK(C19)), IF(COUNT(MAX(AVERAGE(V19:X19),0)),MAX(V19:X19),"n/p"), "") | AI19: =IF(NOT(ISBLANK(C19)), IF(COUNT(MAX(AVERAGE(Y19:AA19),0)),MAX(Y19:AA19),"n/p"), "") | AJ19: =IF(NOT(ISBLANK(C19)), IF(Laborator!AN20="Admis",ROUND(Laborator!AM20,0),"n/p"),"") | AK19: =IF(NOT(ISBLANK(C19)), IF('Lucrari grafice'!F15<>"n/p",'Lucrari grafice'!F15,"n/p"),"") | AL19: =IF(NOT(ISBLANK(C19)), IF(OR(AH19="n/p",AI19="n/p",AJ19="n/p",AK19="n/p",AH19<5,AI19<5,AJ19<5,AK19<5)," ",TRUNC(SUM(AH19:AK19)/4,2)), "") | AM19: =IF(NOT(ISBLANK(C19)), IF(AL19=" ","n/a", IF(AG19,AG19, IF(COUNT(MAX(AVERAGE(AB19:AC19),0)),MAX(AB19:AC19),"n/p"))), "") | AN19: =IF(NOT(ISBLANK(C19)), IF(OR(AM19="n/a",AM19="n/p")," ", IF(AM19<5,AM19,TRUNC(AL19*0.6+AM19*0.4,2))), "") | AO19: =IF(NOT(ISBLANK(C19)), IF(AN19=" "," ", IF(AND(AN19>=1,AN19<2),"(unu, "&ROUNDUP(MOD(AN19*100,100),0)&")", IF(AND(AN19>=2,AN19<3),"(doi, "&ROUNDUP(MOD(AN19*100,100),0)&")", IF(AND(AN19>=3,AN19<4),"(trei, "&ROUNDUP(MOD(AN19*100,100),0)&")", IF(AND(AN19>=4,AN19<5),"(patru, "&ROUNDUP(MOD(AN19*100,100),0)&")", IF(AND(AN19>=5,AN19<6),"(cinci, "&ROUNDUP(MOD(AN19*100,100),0)&")", IF(AND(AN19>=6,AN19<7),"(şase, "&ROUNDUP(MOD(AN19*100,100),0)&")", IF(AND(AN19>=7,AN19<8),"(şapte, "&ROUNDUP(MOD(AN19*100,100),0)&")", IF(AND(AN19>=8,AN19<9),"(opt, "&ROUNDUP(MOD(AN19*100,100),0)&")", IF(AND(AN19>=9,AN19<10),"(nouă, "&ROUNDUP(MOD(AN19*100,100),0)&")", IF(AN19=10,"(zece, 00)", ))))))))))),"") | AP19: =IF(NOT(ISBLANK(C19)), IF(AN19=" "," ", IF(AND(AN19>=1,AN19<=3),"F", IF(AND(AN19>3,AN19<5),"FX", IF(AND(AN19>=5,AN19<=6),"E", IF(AND(AN19>6,AN19<=7),"D", IF(AND(AN19>7,AN19<=8),"C", IF(AND(AN19>8,AN19<=9),"B", IF(AND(AN19>9,AN19<=10),"A", )))))))),"")
B20: =IF(NOT(ISBLANK(C20)),COUNTA($C$6:C20),"") | T20: =IF(NOT(ISBLANK(C20)),IF(COUNTIF(E20:S20,"a")<>0,COUNTIF(E20:S20,"a")*2,""),"") | V20: ='Atest. Nr.1_1'!I16 | W20: ='Atest. Nr.1_2'!H16 | X20: ='Atest. Nr.1_3'!H16 | Y20: ='Atest. Nr.2_1'!I16 | Z20: ='Atest. Nr.2_2'!I16 | AA20: ='Atest. Nr.2_3'!I16 | AB20: =Examen!G16 | AC20: =ReExaminare!G16 | AD20: =IF(NOT(ISBLANK(B20)), IF(SUM(E20:S20)+SUM(Laborator!E21:R21)<>0,SUM(E20:S20)+SUM(Laborator!E21:R21),""), "") | AH20: =IF(NOT(ISBLANK(C20)), IF(COUNT(MAX(AVERAGE(V20:X20),0)),MAX(V20:X20),"n/p"), "") | AI20: =IF(NOT(ISBLANK(C20)), IF(COUNT(MAX(AVERAGE(Y20:AA20),0)),MAX(Y20:AA20),"n/p"), "") | AJ20: =IF(NOT(ISBLANK(C20)), IF(Laborator!AN21="Admis",ROUND(Laborator!AM21,0),"n/p"),"") | AK20: =IF(NOT(ISBLANK(C20)), IF('Lucrari grafice'!F16<>"n/p",'Lucrari grafice'!F16,"n/p"),"") | AL20: =IF(NOT(ISBLANK(C20)), IF(OR(AH20="n/p",AI20="n/p",AJ20="n/p",AK20="n/p",AH20<5,AI20<5,AJ20<5,AK20<5)," ",TRUNC(SUM(AH20:AK20)/4,2)), "") | AM20: =IF(NOT(ISBLANK(C20)), IF(AL20=" ","n/a", IF(AG20,AG20, IF(COUNT(MAX(AVERAGE(AB20:AC20),0)),MAX(AB20:AC20),"n/p"))), "") | AN20: =IF(NOT(ISBLANK(C20)), IF(OR(AM20="n/a",AM20="n/p")," ", IF(AM20<5,AM20,TRUNC(AL20*0.6+AM20*0.4,2))), "") | AO20: =IF(NOT(ISBLANK(C20)), IF(AN20=" "," ", IF(AND(AN20>=1,AN20<2),"(unu, "&ROUNDUP(MOD(AN20*100,100),0)&")", IF(AND(AN20>=2,AN20<3),"(doi, "&ROUNDUP(MOD(AN20*100,100),0)&")", IF(AND(AN20>=3,AN20<4),"(trei, "&ROUNDUP(MOD(AN20*100,100),0)&")", IF(AND(AN20>=4,AN20<5),"(patru, "&ROUNDUP(MOD(AN20*100,100),0)&")", IF(AND(AN20>=5,AN20<6),"(cinci, "&ROUNDUP(MOD(AN20*100,100),0)&")", IF(AND(AN20>=6,AN20<7),"(şase, "&ROUNDUP(MOD(AN20*100,100),0)&")", IF(AND(AN20>=7,AN20<8),"(şapte, "&ROUNDUP(MOD(AN20*100,100),0)&")", IF(AND(AN20>=8,AN20<9),"(opt, "&ROUNDUP(MOD(AN20*100,100),0)&")", IF(AND(AN20>=9,AN20<10),"(nouă, "&ROUNDUP(MOD(AN20*100,100),0)&")", IF(AN20=10,"(zece, 00)", ))))))))))),"") | AP20: =IF(NOT(ISBLANK(C20)), IF(AN20=" "," ", IF(AND(AN20>=1,AN20<=3),"F", IF(AND(AN20>3,AN20<5),"FX", IF(AND(AN20>=5,AN20<=6),"E", IF(AND(AN20>6,AN20<=7),"D", IF(AND(AN20>7,AN20<=8),"C", IF(AND(AN20>8,AN20<=9),"B", IF(AND(AN20>9,AN20<=10),"A", )))))))),"") | AT20: Nr. stud | AU20: n/p | AV20: 1 | AW20: 2 | AX20: 3 | AY20: 4 | AZ20: 5 | BA20: 6 | BB20: 7 | BC20: 8 | BD20: 9 | BE20: 10
B21: =IF(NOT(ISBLANK(C21)),COUNTA($C$6:C21),"") | T21: =IF(NOT(ISBLANK(C21)),IF(COUNTIF(E21:S21,"a")<>0,COUNTIF(E21:S21,"a")*2,""),"") | V21: ='Atest. Nr.1_1'!I17 | W21: ='Atest. Nr.1_2'!H17 | X21: ='Atest. Nr.1_3'!H17 | Y21: ='Atest. Nr.2_1'!I17 | Z21: ='Atest. Nr.2_2'!I17 | AA21: ='Atest. Nr.2_3'!I17 | AB21: =Examen!G17 | AC21: =ReExaminare!G17 | AD21: =IF(NOT(ISBLANK(B21)), IF(SUM(E21:S21)+SUM(Laborator!E22:R22)<>0,SUM(E21:S21)+SUM(Laborator!E22:R22),""), "") | AH21: =IF(NOT(ISBLANK(C21)), IF(COUNT(MAX(AVERAGE(V21:X21),0)),MAX(V21:X21),"n/p"), "") | AI21: =IF(NOT(ISBLANK(C21)), IF(COUNT(MAX(AVERAGE(Y21:AA21),0)),MAX(Y21:AA21),"n/p"), "") | AJ21: =IF(NOT(ISBLANK(C21)), IF(Laborator!AN22="Admis",ROUND(Laborator!AM22,0),"n/p"),"") | AK21: =IF(NOT(ISBLANK(C21)), IF('Lucrari grafice'!F17<>"n/p",'Lucrari grafice'!F17,"n/p"),"") | AL21: =IF(NOT(ISBLANK(C21)), IF(OR(AH21="n/p",AI21="n/p",AJ21="n/p",AK21="n/p",AH21<5,AI21<5,AJ21<5,AK21<5)," ",TRUNC(SUM(AH21:AK21)/4,2)), "") | AM21: =IF(NOT(ISBLANK(C21)), IF(AL21=" ","n/a", IF(AG21,AG21, IF(COUNT(MAX(AVERAGE(AB21:AC21),0)),MAX(AB21:AC21),"n/p"))), "") | AN21: =IF(NOT(ISBLANK(C21)), IF(OR(AM21="n/a",AM21="n/p")," ", IF(AM21<5,AM21,TRUNC(AL21*0.6+AM21*0.4,2))), "") | AO21: =IF(NOT(ISBLANK(C21)), IF(AN21=" "," ", IF(AND(AN21>=1,AN21<2),"(unu, "&ROUNDUP(MOD(AN21*100,100),0)&")", IF(AND(AN21>=2,AN21<3),"(doi, "&ROUNDUP(MOD(AN21*100,100),0)&")", IF(AND(AN21>=3,AN21<4),"(trei, "&ROUNDUP(MOD(AN21*100,100),0)&")", IF(AND(AN21>=4,AN21<5),"(patru, "&ROUNDUP(MOD(AN21*100,100),0)&")", IF(AND(AN21>=5,AN21<6),"(cinci, "&ROUNDUP(MOD(AN21*100,100),0)&")", IF(AND(AN21>=6,AN21<7),"(şase, "&ROUNDUP(MOD(AN21*100,100),0)&")", IF(AND(AN21>=7,AN21<8),"(şapte, "&ROUNDUP(MOD(AN21*100,100),0)&")", IF(AND(AN21>=8,AN21<9),"(opt, "&ROUNDUP(MOD(AN21*100,100),0)&")", IF(AND(AN21>=9,AN21<10),"(nouă, "&ROUNDUP(MOD(AN21*100,100),0)&")", IF(AN21=10,"(zece, 00)", ))))))))))),"") | AP21: =IF(NOT(ISBLANK(C21)), IF(AN21=" "," ", IF(AND(AN21>=1,AN21<=3),"F", IF(AND(AN21>3,AN21<5),"FX", IF(AND(AN21>=5,AN21<=6),"E", IF(AND(AN21>6,AN21<=7),"D", IF(AND(AN21>7,AN21<=8),"C", IF(AND(AN21>8,AN21<=9),"B", IF(AND(AN21>9,AN21<=10),"A", )))))))),"")
B22: =IF(NOT(ISBLANK(C22)),COUNTA($C$6:C22),"") | T22: =IF(NOT(ISBLANK(C22)),IF(COUNTIF(E22:S22,"a")<>0,COUNTIF(E22:S22,"a")*2,""),"") | V22: ='Atest. Nr.1_1'!I18 | W22: ='Atest. Nr.1_2'!H18 | X22: ='Atest. Nr.1_3'!H18 | Y22: ='Atest. Nr.2_1'!I18 | Z22: ='Atest. Nr.2_2'!I18 | AA22: ='Atest. Nr.2_3'!I18 | AB22: =Examen!G18 | AC22: =ReExaminare!G18 | AD22: =IF(NOT(ISBLANK(B22)), IF(SUM(E22:S22)+SUM(Laborator!E23:R23)<>0,SUM(E22:S22)+SUM(Laborator!E23:R23),""), "") | AH22: =IF(NOT(ISBLANK(C22)), IF(COUNT(MAX(AVERAGE(V22:X22),0)),MAX(V22:X22),"n/p"), "") | AI22: =IF(NOT(ISBLANK(C22)), IF(COUNT(MAX(AVERAGE(Y22:AA22),0)),MAX(Y22:AA22),"n/p"), "") | AJ22: =IF(NOT(ISBLANK(C22)), IF(Laborator!AN23="Admis",ROUND(Laborator!AM23,0),"n/p"),"") | AK22: =IF(NOT(ISBLANK(C22)), IF('Lucrari grafice'!F18<>"n/p",'Lucrari grafice'!F18,"n/p"),"") | AL22: =IF(NOT(ISBLANK(C22)), IF(OR(AH22="n/p",AI22="n/p",AJ22="n/p",AK22="n/p",AH22<5,AI22<5,AJ22<5,AK22<5)," ",TRUNC(SUM(AH22:AK22)/4,2)), "") | AM22: =IF(NOT(ISBLANK(C22)), IF(AL22=" ","n/a", IF(AG22,AG22, IF(COUNT(MAX(AVERAGE(AB22:AC22),0)),MAX(AB22:AC22),"n/p"))), "") | AN22: =IF(NOT(ISBLANK(C22)), IF(OR(AM22="n/a",AM22="n/p")," ", IF(AM22<5,AM22,TRUNC(AL22*0.6+AM22*0.4,2))), "") | AO22: =IF(NOT(ISBLANK(C22)), IF(AN22=" "," ", IF(AND(AN22>=1,AN22<2),"(unu, "&ROUNDUP(MOD(AN22*100,100),0)&")", IF(AND(AN22>=2,AN22<3),"(doi, "&ROUNDUP(MOD(AN22*100,100),0)&")", IF(AND(AN22>=3,AN22<4),"(trei, "&ROUNDUP(MOD(AN22*100,100),0)&")", IF(AND(AN22>=4,AN22<5),"(patru, "&ROUNDUP(MOD(AN22*100,100),0)&")", IF(AND(AN22>=5,AN22<6),"(cinci, "&ROUNDUP(MOD(AN22*100,100),0)&")", IF(AND(AN22>=6,AN22<7),"(şase, "&ROUNDUP(MOD(AN22*100,100),0)&")", IF(AND(AN22>=7,AN22<8),"(şapte, "&ROUNDUP(MOD(AN22*100,100),0)&")", IF(AND(AN22>=8,AN22<9),"(opt, "&ROUNDUP(MOD(AN22*100,100),0)&")", IF(AND(AN22>=9,AN22<10),"(nouă, "&ROUNDUP(MOD(AN22*100,100),0)&")", IF(AN22=10,"(zece, 00)", ))))))))))),"") | AP22: =IF(NOT(ISBLANK(C22)), IF(AN22=" "," ", IF(AND(AN22>=1,AN22<=3),"F", IF(AND(AN22>3,AN22<5),"FX", IF(AND(AN22>=5,AN22<=6),"E", IF(AND(AN22>6,AN22<=7),"D", IF(AND(AN22>7,AN22<=8),"C", IF(AND(AN22>8,AN22<=9),"B", IF(AND(AN22>9,AN22<=10),"A", )))))))),"") | AT22: =COUNTA(C6:C105) -> 1 | AU22: =COUNTIF($AI$6:$AI$105,AU20) -> 1 | AV22: =COUNTIF($AI$6:$AI$105,AV20) -> 0 | AW22: =COUNTIF($AI$6:$AI$105,AW20) -> 0 | AX22: =COUNTIF($AI$6:$AI$105,AX20) -> 0 | AY22: =COUNTIF($AI$6:$AI$105,AY20) -> 0 | AZ22: =COUNTIF($AI$6:$AI$105,AZ20) -> 0 | BA22: =COUNTIF($AI$6:$AI$105,BA20) -> 0 | BB22: =COUNTIF($AI$6:$AI$105,BB20) -> 0 | ... BE22: =COUNTIF($AI$6:$AI$105,BE20) -> 0 | BG22: =SUM(AZ22:BE23)/AT22 -> 0
B23: =IF(NOT(ISBLANK(C23)),COUNTA($C$6:C23),"") | T23: =IF(NOT(ISBLANK(C23)),IF(COUNTIF(E23:S23,"a")<>0,COUNTIF(E23:S23,"a")*2,""),"") | V23: ='Atest. Nr.1_1'!I19 | W23: ='Atest. Nr.1_2'!H19 | X23: ='Atest. Nr.1_3'!H19 | Y23: ='Atest. Nr.2_1'!I19 | Z23: ='Atest. Nr.2_2'!I19 | AA23: ='Atest. Nr.2_3'!I19 | AB23: =Examen!G19 | AC23: =ReExaminare!G19 | AD23: =IF(NOT(ISBLANK(B23)), IF(SUM(E23:S23)+SUM(Laborator!E24:R24)<>0,SUM(E23:S23)+SUM(Laborator!E24:R24),""), "") | AH23: =IF(NOT(ISBLANK(C23)), IF(COUNT(MAX(AVERAGE(V23:X23),0)),MAX(V23:X23),"n/p"), "") | AI23: =IF(NOT(ISBLANK(C23)), IF(COUNT(MAX(AVERAGE(Y23:AA23),0)),MAX(Y23:AA23),"n/p"), "") | AJ23: =IF(NOT(ISBLANK(C23)), IF(Laborator!AN24="Admis",ROUND(Laborator!AM24,0),"n/p"),"") | AK23: =IF(NOT(ISBLANK(C23)), IF('Lucrari grafice'!F19<>"n/p",'Lucrari grafice'!F19,"n/p"),"") | AL23: =IF(NOT(ISBLANK(C23)), IF(OR(AH23="n/p",AI23="n/p",AJ23="n/p",AK23="n/p",AH23<5,AI23<5,AJ23<5,AK23<5)," ",TRUNC(SUM(AH23:AK23)/4,2)), "") | AM23: =IF(NOT(ISBLANK(C23)), IF(AL23=" ","n/a", IF(AG23,AG23, IF(COUNT(MAX(AVERAGE(AB23:AC23),0)),MAX(AB23:AC23),"n/p"))), "") | AN23: =IF(NOT(ISBLANK(C23)), IF(OR(AM23="n/a",AM23="n/p")," ", IF(AM23<5,AM23,TRUNC(AL23*0.6+AM23*0.4,2))), "") | AO23: =IF(NOT(ISBLANK(C23)), IF(AN23=" "," ", IF(AND(AN23>=1,AN23<2),"(unu, "&ROUNDUP(MOD(AN23*100,100),0)&")", IF(AND(AN23>=2,AN23<3),"(doi, "&ROUNDUP(MOD(AN23*100,100),0)&")", IF(AND(AN23>=3,AN23<4),"(trei, "&ROUNDUP(MOD(AN23*100,100),0)&")", IF(AND(AN23>=4,AN23<5),"(patru, "&ROUNDUP(MOD(AN23*100,100),0)&")", IF(AND(AN23>=5,AN23<6),"(cinci, "&ROUNDUP(MOD(AN23*100,100),0)&")", IF(AND(AN23>=6,AN23<7),"(şase, "&ROUNDUP(MOD(AN23*100,100),0)&")", IF(AND(AN23>=7,AN23<8),"(şapte, "&ROUNDUP(MOD(AN23*100,100),0)&")", IF(AND(AN23>=8,AN23<9),"(opt, "&ROUNDUP(MOD(AN23*100,100),0)&")", IF(AND(AN23>=9,AN23<10),"(nouă, "&ROUNDUP(MOD(AN23*100,100),0)&")", IF(AN23=10,"(zece, 00)", ))))))))))),"") | AP23: =IF(NOT(ISBLANK(C23)), IF(AN23=" "," ", IF(AND(AN23>=1,AN23<=3),"F", IF(AND(AN23>3,AN23<5),"FX", IF(AND(AN23>=5,AN23<=6),"E", IF(AND(AN23>6,AN23<=7),"D", IF(AND(AN23>7,AN23<=8),"C", IF(AND(AN23>8,AN23<=9),"B", IF(AND(AN23>9,AN23<=10),"A", )))))))),"")
B24: =IF(NOT(ISBLANK(C24)),COUNTA($C$6:C24),"") | T24: =IF(NOT(ISBLANK(C24)),IF(COUNTIF(E24:S24,"a")<>0,COUNTIF(E24:S24,"a")*2,""),"") | V24: ='Atest. Nr.1_1'!I20 | W24: ='Atest. Nr.1_2'!H20 | X24: ='Atest. Nr.1_3'!H20 | Y24: ='Atest. Nr.2_1'!I20 | Z24: ='Atest. Nr.2_2'!I20 | AA24: ='Atest. Nr.2_3'!I20 | AB24: =Examen!G20 | AC24: =ReExaminare!G20 | AD24: =IF(NOT(ISBLANK(B24)), IF(SUM(E24:S24)+SUM(Laborator!E25:R25)<>0,SUM(E24:S24)+SUM(Laborator!E25:R25),""), "") | AH24: =IF(NOT(ISBLANK(C24)), IF(COUNT(MAX(AVERAGE(V24:X24),0)),MAX(V24:X24),"n/p"), "") | AI24: =IF(NOT(ISBLANK(C24)), IF(COUNT(MAX(AVERAGE(Y24:AA24),0)),MAX(Y24:AA24),"n/p"), "") | AJ24: =IF(NOT(ISBLANK(C24)), IF(Laborator!AN25="Admis",ROUND(Laborator!AM25,0),"n/p"),"") | AK24: =IF(NOT(ISBLANK(C24)), IF('Lucrari grafice'!F20<>"n/p",'Lucrari grafice'!F20,"n/p"),"") | AL24: =IF(NOT(ISBLANK(C24)), IF(OR(AH24="n/p",AI24="n/p",AJ24="n/p",AK24="n/p",AH24<5,AI24<5,AJ24<5,AK24<5)," ",TRUNC(SUM(AH24:AK24)/4,2)), "") | AM24: =IF(NOT(ISBLANK(C24)), IF(AL24=" ","n/a", IF(AG24,AG24, IF(COUNT(MAX(AVERAGE(AB24:AC24),0)),MAX(AB24:AC24),"n/p"))), "") | AN24: =IF(NOT(ISBLANK(C24)), IF(OR(AM24="n/a",AM24="n/p")," ", IF(AM24<5,AM24,TRUNC(AL24*0.6+AM24*0.4,2))), "") | AO24: =IF(NOT(ISBLANK(C24)), IF(AN24=" "," ", IF(AND(AN24>=1,AN24<2),"(unu, "&ROUNDUP(MOD(AN24*100,100),0)&")", IF(AND(AN24>=2,AN24<3),"(doi, "&ROUNDUP(MOD(AN24*100,100),0)&")", IF(AND(AN24>=3,AN24<4),"(trei, "&ROUNDUP(MOD(AN24*100,100),0)&")", IF(AND(AN24>=4,AN24<5),"(patru, "&ROUNDUP(MOD(AN24*100,100),0)&")", IF(AND(AN24>=5,AN24<6),"(cinci, "&ROUNDUP(MOD(AN24*100,100),0)&")", IF(AND(AN24>=6,AN24<7),"(şase, "&ROUNDUP(MOD(AN24*100,100),0)&")", IF(AND(AN24>=7,AN24<8),"(şapte, "&ROUNDUP(MOD(AN24*100,100),0)&")", IF(AND(AN24>=8,AN24<9),"(opt, "&ROUNDUP(MOD(AN24*100,100),0)&")", IF(AND(AN24>=9,AN24<10),"(nouă, "&ROUNDUP(MOD(AN24*100,100),0)&")", IF(AN24=10,"(zece, 00)", ))))))))))),"") | AP24: =IF(NOT(ISBLANK(C24)), IF(AN24=" "," ", IF(AND(AN24>=1,AN24<=3),"F", IF(AND(AN24>3,AN24<5),"FX", IF(AND(AN24>=5,AN24<=6),"E", IF(AND(AN24>6,AN24<=7),"D", IF(AND(AN24>7,AN24<=8),"C", IF(AND(AN24>8,AN24<=9),"B", IF(AND(AN24>9,AN24<=10),"A", )))))))),"")
B25: =IF(NOT(ISBLANK(C25)),COUNTA($C$6:C25),"") | T25: =IF(NOT(ISBLANK(C25)),IF(COUNTIF(E25:S25,"a")<>0,COUNTIF(E25:S25,"a")*2,""),"") | V25: ='Atest. Nr.1_1'!I21 | W25: ='Atest. Nr.1_2'!H21 | X25: ='Atest. Nr.1_3'!H21 | Y25: ='Atest. Nr.2_1'!I21 | Z25: ='Atest. Nr.2_2'!I21 | AA25: ='Atest. Nr.2_3'!I21 | AB25: =Examen!G21 | AC25: =ReExaminare!G21 | AD25: =IF(NOT(ISBLANK(B25)), IF(SUM(E25:S25)+SUM(Laborator!E26:R26)<>0,SUM(E25:S25)+SUM(Laborator!E26:R26),""), "") | AH25: =IF(NOT(ISBLANK(C25)), IF(COUNT(MAX(AVERAGE(V25:X25),0)),MAX(V25:X25),"n/p"), "") | AI25: =IF(NOT(ISBLANK(C25)), IF(COUNT(MAX(AVERAGE(Y25:AA25),0)),MAX(Y25:AA25),"n/p"), "") | AJ25: =IF(NOT(ISBLANK(C25)), IF(Laborator!AN26="Admis",ROUND(Laborator!AM26,0),"n/p"),"") | AK25: =IF(NOT(ISBLANK(C25)), IF('Lucrari grafice'!F21<>"n/p",'Lucrari grafice'!F21,"n/p"),"") | AL25: =IF(NOT(ISBLANK(C25)), IF(OR(AH25="n/p",AI25="n/p",AJ25="n/p",AK25="n/p",AH25<5,AI25<5,AJ25<5,AK25<5)," ",TRUNC(SUM(AH25:AK25)/4,2)), "") | AM25: =IF(NOT(ISBLANK(C25)), IF(AL25=" ","n/a", IF(AG25,AG25, IF(COUNT(MAX(AVERAGE(AB25:AC25),0)),MAX(AB25:AC25),"n/p"))), "") | AN25: =IF(NOT(ISBLANK(C25)), IF(OR(AM25="n/a",AM25="n/p")," ", IF(AM25<5,AM25,TRUNC(AL25*0.6+AM25*0.4,2))), "") | AO25: =IF(NOT(ISBLANK(C25)), IF(AN25=" "," ", IF(AND(AN25>=1,AN25<2),"(unu, "&ROUNDUP(MOD(AN25*100,100),0)&")", IF(AND(AN25>=2,AN25<3),"(doi, "&ROUNDUP(MOD(AN25*100,100),0)&")", IF(AND(AN25>=3,AN25<4),"(trei, "&ROUNDUP(MOD(AN25*100,100),0)&")", IF(AND(AN25>=4,AN25<5),"(patru, "&ROUNDUP(MOD(AN25*100,100),0)&")", IF(AND(AN25>=5,AN25<6),"(cinci, "&ROUNDUP(MOD(AN25*100,100),0)&")", IF(AND(AN25>=6,AN25<7),"(şase, "&ROUNDUP(MOD(AN25*100,100),0)&")", IF(AND(AN25>=7,AN25<8),"(şapte, "&ROUNDUP(MOD(AN25*100,100),0)&")", IF(AND(AN25>=8,AN25<9),"(opt, "&ROUNDUP(MOD(AN25*100,100),0)&")", IF(AND(AN25>=9,AN25<10),"(nouă, "&ROUNDUP(MOD(AN25*100,100),0)&")", IF(AN25=10,"(zece, 00)", ))))))))))),"") | AP25: =IF(NOT(ISBLANK(C25)), IF(AN25=" "," ", IF(AND(AN25>=1,AN25<=3),"F", IF(AND(AN25>3,AN25<5),"FX", IF(AND(AN25>=5,AN25<=6),"E", IF(AND(AN25>6,AN25<=7),"D", IF(AND(AN25>7,AN25<=8),"C", IF(AND(AN25>8,AN25<=9),"B", IF(AND(AN25>9,AN25<=10),"A", )))))))),"")
B26: =IF(NOT(ISBLANK(C26)),COUNTA($C$6:C26),"") | T26: =IF(NOT(ISBLANK(C26)),IF(COUNTIF(E26:S26,"a")<>0,COUNTIF(E26:S26,"a")*2,""),"") | V26: ='Atest. Nr.1_1'!I22 | W26: ='Atest. Nr.1_2'!H22 | X26: ='Atest. Nr.1_3'!H22 | Y26: ='Atest. Nr.2_1'!I22 | Z26: ='Atest. Nr.2_2'!I22 | AA26: ='Atest. Nr.2_3'!I22 | AB26: =Examen!G22 | AC26: =ReExaminare!G22 | AD26: =IF(NOT(ISBLANK(B26)), IF(SUM(E26:S26)+SUM(Laborator!E27:R27)<>0,SUM(E26:S26)+SUM(Laborator!E27:R27),""), "") | AH26: =IF(NOT(ISBLANK(C26)), IF(COUNT(MAX(AVERAGE(V26:X26),0)),MAX(V26:X26),"n/p"), "") | AI26: =IF(NOT(ISBLANK(C26)), IF(COUNT(MAX(AVERAGE(Y26:AA26),0)),MAX(Y26:AA26),"n/p"), "") | AJ26: =IF(NOT(ISBLANK(C26)), IF(Laborator!AN27="Admis",ROUND(Laborator!AM27,0),"n/p"),"") | AK26: =IF(NOT(ISBLANK(C26)), IF('Lucrari grafice'!F22<>"n/p",'Lucrari grafice'!F22,"n/p"),"") | AL26: =IF(NOT(ISBLANK(C26)), IF(OR(AH26="n/p",AI26="n/p",AJ26="n/p",AK26="n/p",AH26<5,AI26<5,AJ26<5,AK26<5)," ",TRUNC(SUM(AH26:AK26)/4,2)), "") | AM26: =IF(NOT(ISBLANK(C26)), IF(AL26=" ","n/a", IF(AG26,AG26, IF(COUNT(MAX(AVERAGE(AB26:AC26),0)),MAX(AB26:AC26),"n/p"))), "") | AN26: =IF(NOT(ISBLANK(C26)), IF(OR(AM26="n/a",AM26="n/p")," ", IF(AM26<5,AM26,TRUNC(AL26*0.6+AM26*0.4,2))), "") | AO26: =IF(NOT(ISBLANK(C26)), IF(AN26=" "," ", IF(AND(AN26>=1,AN26<2),"(unu, "&ROUNDUP(MOD(AN26*100,100),0)&")", IF(AND(AN26>=2,AN26<3),"(doi, "&ROUNDUP(MOD(AN26*100,100),0)&")", IF(AND(AN26>=3,AN26<4),"(trei, "&ROUNDUP(MOD(AN26*100,100),0)&")", IF(AND(AN26>=4,AN26<5),"(patru, "&ROUNDUP(MOD(AN26*100,100),0)&")", IF(AND(AN26>=5,AN26<6),"(cinci, "&ROUNDUP(MOD(AN26*100,100),0)&")", IF(AND(AN26>=6,AN26<7),"(şase, "&ROUNDUP(MOD(AN26*100,100),0)&")", IF(AND(AN26>=7,AN26<8),"(şapte, "&ROUNDUP(MOD(AN26*100,100),0)&")", IF(AND(AN26>=8,AN26<9),"(opt, "&ROUNDUP(MOD(AN26*100,100),0)&")", IF(AND(AN26>=9,AN26<10),"(nouă, "&ROUNDUP(MOD(AN26*100,100),0)&")", IF(AN26=10,"(zece, 00)", ))))))))))),"") | AP26: =IF(NOT(ISBLANK(C26)), IF(AN26=" "," ", IF(AND(AN26>=1,AN26<=3),"F", IF(AND(AN26>3,AN26<5),"FX", IF(AND(AN26>=5,AN26<=6),"E", IF(AND(AN26>6,AN26<=7),"D", IF(AND(AN26>7,AN26<=8),"C", IF(AND(AN26>8,AN26<=9),"B", IF(AND(AN26>9,AN26<=10),"A", )))))))),"")
B27: =IF(NOT(ISBLANK(C27)),COUNTA($C$6:C27),"") | T27: =IF(NOT(ISBLANK(C27)),IF(COUNTIF(E27:S27,"a")<>0,COUNTIF(E27:S27,"a")*2,""),"") | V27: ='Atest. Nr.1_1'!I23 | W27: ='Atest. Nr.1_2'!H23 | X27: ='Atest. Nr.1_3'!H23 | Y27: ='Atest. Nr.2_1'!I23 | Z27: ='Atest. Nr.2_2'!I23 | AA27: ='Atest. Nr.2_3'!I23 | AB27: =Examen!G23 | AC27: =ReExaminare!G23 | AD27: =IF(NOT(ISBLANK(B27)), IF(SUM(E27:S27)+SUM(Laborator!E28:R28)<>0,SUM(E27:S27)+SUM(Laborator!E28:R28),""), "") | AH27: =IF(NOT(ISBLANK(C27)), IF(COUNT(MAX(AVERAGE(V27:X27),0)),MAX(V27:X27),"n/p"), "") | AI27: =IF(NOT(ISBLANK(C27)), IF(COUNT(MAX(AVERAGE(Y27:AA27),0)),MAX(Y27:AA27),"n/p"), "") | AJ27: =IF(NOT(ISBLANK(C27)), IF(Laborator!AN28="Admis",ROUND(Laborator!AM28,0),"n/p"),"") | AK27: =IF(NOT(ISBLANK(C27)), IF('Lucrari grafice'!F23<>"n/p",'Lucrari grafice'!F23,"n/p"),"") | AL27: =IF(NOT(ISBLANK(C27)), IF(OR(AH27="n/p",AI27="n/p",AJ27="n/p",AK27="n/p",AH27<5,AI27<5,AJ27<5,AK27<5)," ",TRUNC(SUM(AH27:AK27)/4,2)), "") | AM27: =IF(NOT(ISBLANK(C27)), IF(AL27=" ","n/a", IF(AG27,AG27, IF(COUNT(MAX(AVERAGE(AB27:AC27),0)),MAX(AB27:AC27),"n/p"))), "") | AN27: =IF(NOT(ISBLANK(C27)), IF(OR(AM27="n/a",AM27="n/p")," ", IF(AM27<5,AM27,TRUNC(AL27*0.6+AM27*0.4,2))), "") | AO27: =IF(NOT(ISBLANK(C27)), IF(AN27=" "," ", IF(AND(AN27>=1,AN27<2),"(unu, "&ROUNDUP(MOD(AN27*100,100),0)&")", IF(AND(AN27>=2,AN27<3),"(doi, "&ROUNDUP(MOD(AN27*100,100),0)&")", IF(AND(AN27>=3,AN27<4),"(trei, "&ROUNDUP(MOD(AN27*100,100),0)&")", IF(AND(AN27>=4,AN27<5),"(patru, "&ROUNDUP(MOD(AN27*100,100),0)&")", IF(AND(AN27>=5,AN27<6),"(cinci, "&ROUNDUP(MOD(AN27*100,100),0)&")", IF(AND(AN27>=6,AN27<7),"(şase, "&ROUNDUP(MOD(AN27*100,100),0)&")", IF(AND(AN27>=7,AN27<8),"(şapte, "&ROUNDUP(MOD(AN27*100,100),0)&")", IF(AND(AN27>=8,AN27<9),"(opt, "&ROUNDUP(MOD(AN27*100,100),0)&")", IF(AND(AN27>=9,AN27<10),"(nouă, "&ROUNDUP(MOD(AN27*100,100),0)&")", IF(AN27=10,"(zece, 00)", ))))))))))),"") | AP27: =IF(NOT(ISBLANK(C27)), IF(AN27=" "," ", IF(AND(AN27>=1,AN27<=3),"F", IF(AND(AN27>3,AN27<5),"FX", IF(AND(AN27>=5,AN27<=6),"E", IF(AND(AN27>6,AN27<=7),"D", IF(AND(AN27>7,AN27<=8),"C", IF(AND(AN27>8,AN27<=9),"B", IF(AND(AN27>9,AN27<=10),"A", )))))))),"")
B28: =IF(NOT(ISBLANK(C28)),COUNTA($C$6:C28),"") | T28: =IF(NOT(ISBLANK(C28)),IF(COUNTIF(E28:S28,"a")<>0,COUNTIF(E28:S28,"a")*2,""),"") | V28: ='Atest. Nr.1_1'!I24 | W28: ='Atest. Nr.1_2'!H24 | X28: ='Atest. Nr.1_3'!H24 | Y28: ='Atest. Nr.2_1'!I24 | Z28: ='Atest. Nr.2_2'!I24 | AA28: ='Atest. Nr.2_3'!I24 | AB28: =Examen!G24 | AC28: =ReExaminare!G24 | AD28: =IF(NOT(ISBLANK(B28)), IF(SUM(E28:S28)+SUM(Laborator!E29:R29)<>0,SUM(E28:S28)+SUM(Laborator!E29:R29),""), "") | AH28: =IF(NOT(ISBLANK(C28)), IF(COUNT(MAX(AVERAGE(V28:X28),0)),MAX(V28:X28),"n/p"), "") | AI28: =IF(NOT(ISBLANK(C28)), IF(COUNT(MAX(AVERAGE(Y28:AA28),0)),MAX(Y28:AA28),"n/p"), "") | AJ28: =IF(NOT(ISBLANK(C28)), IF(Laborator!AN29="Admis",ROUND(Laborator!AM29,0),"n/p"),"") | AK28: =IF(NOT(ISBLANK(C28)), IF('Lucrari grafice'!F24<>"n/p",'Lucrari grafice'!F24,"n/p"),"") | AL28: =IF(NOT(ISBLANK(C28)), IF(OR(AH28="n/p",AI28="n/p",AJ28="n/p",AK28="n/p",AH28<5,AI28<5,AJ28<5,AK28<5)," ",TRUNC(SUM(AH28:AK28)/4,2)), "") | AM28: =IF(NOT(ISBLANK(C28)), IF(AL28=" ","n/a", IF(AG28,AG28, IF(COUNT(MAX(AVERAGE(AB28:AC28),0)),MAX(AB28:AC28),"n/p"))), "") | AN28: =IF(NOT(ISBLANK(C28)), IF(OR(AM28="n/a",AM28="n/p")," ", IF(AM28<5,AM28,TRUNC(AL28*0.6+AM28*0.4,2))), "") | AO28: =IF(NOT(ISBLANK(C28)), IF(AN28=" "," ", IF(AND(AN28>=1,AN28<2),"(unu, "&ROUNDUP(MOD(AN28*100,100),0)&")", IF(AND(AN28>=2,AN28<3),"(doi, "&ROUNDUP(MOD(AN28*100,100),0)&")", IF(AND(AN28>=3,AN28<4),"(trei, "&ROUNDUP(MOD(AN28*100,100),0)&")", IF(AND(AN28>=4,AN28<5),"(patru, "&ROUNDUP(MOD(AN28*100,100),0)&")", IF(AND(AN28>=5,AN28<6),"(cinci, "&ROUNDUP(MOD(AN28*100,100),0)&")", IF(AND(AN28>=6,AN28<7),"(şase, "&ROUNDUP(MOD(AN28*100,100),0)&")", IF(AND(AN28>=7,AN28<8),"(şapte, "&ROUNDUP(MOD(AN28*100,100),0)&")", IF(AND(AN28>=8,AN28<9),"(opt, "&ROUNDUP(MOD(AN28*100,100),0)&")", IF(AND(AN28>=9,AN28<10),"(nouă, "&ROUNDUP(MOD(AN28*100,100),0)&")", IF(AN28=10,"(zece, 00)", ))))))))))),"") | AP28: =IF(NOT(ISBLANK(C28)), IF(AN28=" "," ", IF(AND(AN28>=1,AN28<=3),"F", IF(AND(AN28>3,AN28<5),"FX", IF(AND(AN28>=5,AN28<=6),"E", IF(AND(AN28>6,AN28<=7),"D", IF(AND(AN28>7,AN28<=8),"C", IF(AND(AN28>8,AN28<=9),"B", IF(AND(AN28>9,AN28<=10),"A", )))))))),"")
B29: =IF(NOT(ISBLANK(C29)),COUNTA($C$6:C29),"") | T29: =IF(NOT(ISBLANK(C29)),IF(COUNTIF(E29:S29,"a")<>0,COUNTIF(E29:S29,"a")*2,""),"") | V29: ='Atest. Nr.1_1'!I25 | W29: ='Atest. Nr.1_2'!H25 | X29: ='Atest. Nr.1_3'!H25 | Y29: ='Atest. Nr.2_1'!I25 | Z29: ='Atest. Nr.2_2'!I25 | AA29: ='Atest. Nr.2_3'!I25 | AB29: =Examen!G25 | AC29: =ReExaminare!G25 | AD29: =IF(NOT(ISBLANK(B29)), IF(SUM(E29:S29)+SUM(Laborator!E30:R30)<>0,SUM(E29:S29)+SUM(Laborator!E30:R30),""), "") | AH29: =IF(NOT(ISBLANK(C29)), IF(COUNT(MAX(AVERAGE(V29:X29),0)),MAX(V29:X29),"n/p"), "") | AI29: =IF(NOT(ISBLANK(C29)), IF(COUNT(MAX(AVERAGE(Y29:AA29),0)),MAX(Y29:AA29),"n/p"), "") | AJ29: =IF(NOT(ISBLANK(C29)), IF(Laborator!AN30="Admis",ROUND(Laborator!AM30,0),"n/p"),"") | AK29: =IF(NOT(ISBLANK(C29)), IF('Lucrari grafice'!F25<>"n/p",'Lucrari grafice'!F25,"n/p"),"") | AL29: =IF(NOT(ISBLANK(C29)), IF(OR(AH29="n/p",AI29="n/p",AJ29="n/p",AK29="n/p",AH29<5,AI29<5,AJ29<5,AK29<5)," ",TRUNC(SUM(AH29:AK29)/4,2)), "") | AM29: =IF(NOT(ISBLANK(C29)), IF(AL29=" ","n/a", IF(AG29,AG29, IF(COUNT(MAX(AVERAGE(AB29:AC29),0)),MAX(AB29:AC29),"n/p"))), "") | AN29: =IF(NOT(ISBLANK(C29)), IF(OR(AM29="n/a",AM29="n/p")," ", IF(AM29<5,AM29,TRUNC(AL29*0.6+AM29*0.4,2))), "") | AO29: =IF(NOT(ISBLANK(C29)), IF(AN29=" "," ", IF(AND(AN29>=1,AN29<2),"(unu, "&ROUNDUP(MOD(AN29*100,100),0)&")", IF(AND(AN29>=2,AN29<3),"(doi, "&ROUNDUP(MOD(AN29*100,100),0)&")", IF(AND(AN29>=3,AN29<4),"(trei, "&ROUNDUP(MOD(AN29*100,100),0)&")", IF(AND(AN29>=4,AN29<5),"(patru, "&ROUNDUP(MOD(AN29*100,100),0)&")", IF(AND(AN29>=5,AN29<6),"(cinci, "&ROUNDUP(MOD(AN29*100,100),0)&")", IF(AND(AN29>=6,AN29<7),"(şase, "&ROUNDUP(MOD(AN29*100,100),0)&")", IF(AND(AN29>=7,AN29<8),"(şapte, "&ROUNDUP(MOD(AN29*100,100),0)&")", IF(AND(AN29>=8,AN29<9),"(opt, "&ROUNDUP(MOD(AN29*100,100),0)&")", IF(AND(AN29>=9,AN29<10),"(nouă, "&ROUNDUP(MOD(AN29*100,100),0)&")", IF(AN29=10,"(zece, 00)", ))))))))))),"") | AP29: =IF(NOT(ISBLANK(C29)), IF(AN29=" "," ", IF(AND(AN29>=1,AN29<=3),"F", IF(AND(AN29>3,AN29<5),"FX", IF(AND(AN29>=5,AN29<=6),"E", IF(AND(AN29>6,AN29<=7),"D", IF(AND(AN29>7,AN29<=8),"C", IF(AND(AN29>8,AN29<=9),"B", IF(AND(AN29>9,AN29<=10),"A", )))))))),"")
B30: =IF(NOT(ISBLANK(C30)),COUNTA($C$6:C30),"") | T30: =IF(NOT(ISBLANK(C30)),IF(COUNTIF(E30:S30,"a")<>0,COUNTIF(E30:S30,"a")*2,""),"") | V30: ='Atest. Nr.1_1'!I26 | W30: ='Atest. Nr.1_2'!H26 | X30: ='Atest. Nr.1_3'!H26 | Y30: ='Atest. Nr.2_1'!I26 | Z30: ='Atest. Nr.2_2'!I26 | AA30: ='Atest. Nr.2_3'!I26 | AB30: =Examen!G26 | AC30: =ReExaminare!G26 | AD30: =IF(NOT(ISBLANK(B30)), IF(SUM(E30:S30)+SUM(Laborator!E31:R31)<>0,SUM(E30:S30)+SUM(Laborator!E31:R31),""), "") | AH30: =IF(NOT(ISBLANK(C30)), IF(COUNT(MAX(AVERAGE(V30:X30),0)),MAX(V30:X30),"n/p"), "") | AI30: =IF(NOT(ISBLANK(C30)), IF(COUNT(MAX(AVERAGE(Y30:AA30),0)),MAX(Y30:AA30),"n/p"), "") | AJ30: =IF(NOT(ISBLANK(C30)), IF(Laborator!AN31="Admis",ROUND(Laborator!AM31,0),"n/p"),"") | AK30: =IF(NOT(ISBLANK(C30)), IF('Lucrari grafice'!F26<>"n/p",'Lucrari grafice'!F26,"n/p"),"") | AL30: =IF(NOT(ISBLANK(C30)), IF(OR(AH30="n/p",AI30="n/p",AJ30="n/p",AK30="n/p",AH30<5,AI30<5,AJ30<5,AK30<5)," ",TRUNC(SUM(AH30:AK30)/4,2)), "") | AM30: =IF(NOT(ISBLANK(C30)), IF(AL30=" ","n/a", IF(AG30,AG30, IF(COUNT(MAX(AVERAGE(AB30:AC30),0)),MAX(AB30:AC30),"n/p"))), "") | AN30: =IF(NOT(ISBLANK(C30)), IF(OR(AM30="n/a",AM30="n/p")," ", IF(AM30<5,AM30,TRUNC(AL30*0.6+AM30*0.4,2))), "") | AO30: =IF(NOT(ISBLANK(C30)), IF(AN30=" "," ", IF(AND(AN30>=1,AN30<2),"(unu, "&ROUNDUP(MOD(AN30*100,100),0)&")", IF(AND(AN30>=2,AN30<3),"(doi, "&ROUNDUP(MOD(AN30*100,100),0)&")", IF(AND(AN30>=3,AN30<4),"(trei, "&ROUNDUP(MOD(AN30*100,100),0)&")", IF(AND(AN30>=4,AN30<5),"(patru, "&ROUNDUP(MOD(AN30*100,100),0)&")", IF(AND(AN30>=5,AN30<6),"(cinci, "&ROUNDUP(MOD(AN30*100,100),0)&")", IF(AND(AN30>=6,AN30<7),"(şase, "&ROUNDUP(MOD(AN30*100,100),0)&")", IF(AND(AN30>=7,AN30<8),"(şapte, "&ROUNDUP(MOD(AN30*100,100),0)&")", IF(AND(AN30>=8,AN30<9),"(opt, "&ROUNDUP(MOD(AN30*100,100),0)&")", IF(AND(AN30>=9,AN30<10),"(nouă, "&ROUNDUP(MOD(AN30*100,100),0)&")", IF(AN30=10,"(zece, 00)", ))))))))))),"") | AP30: =IF(NOT(ISBLANK(C30)), IF(AN30=" "," ", IF(AND(AN30>=1,AN30<=3),"F", IF(AND(AN30>3,AN30<5),"FX", IF(AND(AN30>=5,AN30<=6),"E", IF(AND(AN30>6,AN30<=7),"D", IF(AND(AN30>7,AN30<=8),"C", IF(AND(AN30>8,AN30<=9),"B", IF(AND(AN30>9,AN30<=10),"A", )))))))),"")
B31: =IF(NOT(ISBLANK(C31)),COUNTA($C$6:C31),"") | T31: =IF(NOT(ISBLANK(C31)),IF(COUNTIF(E31:S31,"a")<>0,COUNTIF(E31:S31,"a")*2,""),"") | V31: ='Atest. Nr.1_1'!I27 | W31: ='Atest. Nr.1_2'!H27 | X31: ='Atest. Nr.1_3'!H27 | Y31: ='Atest. Nr.2_1'!I27 | Z31: ='Atest. Nr.2_2'!I27 | AA31: ='Atest. Nr.2_3'!I27 | AB31: =Examen!G27 | AC31: =ReExaminare!G27 | AD31: =IF(NOT(ISBLANK(B31)), IF(SUM(E31:S31)+SUM(Laborator!E32:R32)<>0,SUM(E31:S31)+SUM(Laborator!E32:R32),""), "") | AH31: =IF(NOT(ISBLANK(C31)), IF(COUNT(MAX(AVERAGE(V31:X31),0)),MAX(V31:X31),"n/p"), "") | AI31: =IF(NOT(ISBLANK(C31)), IF(COUNT(MAX(AVERAGE(Y31:AA31),0)),MAX(Y31:AA31),"n/p"), "") | AJ31: =IF(NOT(ISBLANK(C31)), IF(Laborator!AN32="Admis",ROUND(Laborator!AM32,0),"n/p"),"") | AK31: =IF(NOT(ISBLANK(C31)), IF('Lucrari grafice'!F27<>"n/p",'Lucrari grafice'!F27,"n/p"),"") | AL31: =IF(NOT(ISBLANK(C31)), IF(OR(AH31="n/p",AI31="n/p",AJ31="n/p",AK31="n/p",AH31<5,AI31<5,AJ31<5,AK31<5)," ",TRUNC(SUM(AH31:AK31)/4,2)), "") | AM31: =IF(NOT(ISBLANK(C31)), IF(AL31=" ","n/a", IF(AG31,AG31, IF(COUNT(MAX(AVERAGE(AB31:AC31),0)),MAX(AB31:AC31),"n/p"))), "") | AN31: =IF(NOT(ISBLANK(C31)), IF(OR(AM31="n/a",AM31="n/p")," ", IF(AM31<5,AM31,TRUNC(AL31*0.6+AM31*0.4,2))), "") | AO31: =IF(NOT(ISBLANK(C31)), IF(AN31=" "," ", IF(AND(AN31>=1,AN31<2),"(unu, "&ROUNDUP(MOD(AN31*100,100),0)&")", IF(AND(AN31>=2,AN31<3),"(doi, "&ROUNDUP(MOD(AN31*100,100),0)&")", IF(AND(AN31>=3,AN31<4),"(trei, "&ROUNDUP(MOD(AN31*100,100),0)&")", IF(AND(AN31>=4,AN31<5),"(patru, "&ROUNDUP(MOD(AN31*100,100),0)&")", IF(AND(AN31>=5,AN31<6),"(cinci, "&ROUNDUP(MOD(AN31*100,100),0)&")", IF(AND(AN31>=6,AN31<7),"(şase, "&ROUNDUP(MOD(AN31*100,100),0)&")", IF(AND(AN31>=7,AN31<8),"(şapte, "&ROUNDUP(MOD(AN31*100,100),0)&")", IF(AND(AN31>=8,AN31<9),"(opt, "&ROUNDUP(MOD(AN31*100,100),0)&")", IF(AND(AN31>=9,AN31<10),"(nouă, "&ROUNDUP(MOD(AN31*100,100),0)&")", IF(AN31=10,"(zece, 00)", ))))))))))),"") | AP31: =IF(NOT(ISBLANK(C31)), IF(AN31=" "," ", IF(AND(AN31>=1,AN31<=3),"F", IF(AND(AN31>3,AN31<5),"FX", IF(AND(AN31>=5,AN31<=6),"E", IF(AND(AN31>6,AN31<=7),"D", IF(AND(AN31>7,AN31<=8),"C", IF(AND(AN31>8,AN31<=9),"B", IF(AND(AN31>9,AN31<=10),"A", )))))))),"")
