Workbook

Sheet Curs
C2: Mecanica Teoretică. Anul de studii: Titular: Grupa: Șeful grupei: Nume, Prenume, telefon | S2: Nota semestrială | V2: Ev.finală (0.5) | W2: Nota finală | AA2: Examen:
E3: Curs | M3: Sesiunea | S3: Componente | U3: Media trunchiată (0.5) | W3: în sist.național, trunchiată | Y3: Conform ECTS | AA3: Borderou | AB3: Prezenti | AC3: Admisi | AD3: Eliberati
E4: C1 | F4: C2 | G4: C3 | H4: C4 | I4: C5 | J4: C6 | K4: Ore absentate | M4: Examen | N4: Reexam | O4: Puncte activ. suplim | P4: Puncte utilizate | Q4: Exam | S4: Evaluarea curentă | T4: Lucrul individual | AF4: A | AG4: B | AH4: C | AI4: D | AJ4: E | AK4: FX | AL4: F | AM4: n/p | AN4: n/a
B5: Nr. | C5: Nume, Prenume | D5: e-mail | E5: 30.01 | F5: 6.02 | G5: 13.02 | H5: 20.02 | I5: 27.02 | J5: 6.03 | Q5: Prezenta | R5: Eliberati | AA5: =COUNTA(C6:C105) -> 1 | AB5: =AA5-COUNTIFS(B6:B105,">0",Q6:Q105,"a") -> 1 | AC5: =AA5-COUNTIF(V6:V105,"n/a") -> 0 | AD5: =COUNTA(R6:R105) -> 0 | AF5: =COUNTIF($Y$6:$Y$105,AF4) -> 0 | AG5: =COUNTIF($Y$6:$Y$105,AG4) -> 0 | AH5: =COUNTIF($Y$6:$Y$105,AH4) -> 0 | AI5: =COUNTIF($Y$6:$Y$105,AI4) -> 0 | AJ5: =COUNTIF($Y$6:$Y$105,AJ4) -> 0 | AK5: =COUNTIF($Y$6:$Y$105,AK4) -> 0 | AL5: =COUNTIF($Y$6:$Y$105,AL4) -> 0 | AM5: =COUNTIF($V$6:$V$105,AM4) -> 0 | AN5: =COUNTIF($V$6:$V$105,AN4) -> 1
B6: =IF(NOT(ISBLANK(C6)),COUNTA($C$6:C6),"") -> 1 | C6: Nume, Prenume | D6: example@mail.com | K6: =IF(NOT(ISBLANK(C6)),IF(COUNTIF(E6:J6,"a")<>0,COUNTIF(E6:J6,"a")*2,""),"") | M6: =Examen!G2 -> n/p | O6: =IF(NOT(ISBLANK(B6)), IF(SUM(E6:J6)+SUM(Laborator!E7:J7)<>0,SUM(E6:J6)+SUM(Laborator!E7:J7),""), "") | S6: =IF(NOT(ISBLANK(C6)),IF(ISNUMBER(Laborator!AD7),Laborator!AD7,"n/p"),"") -> n/p | T6: ='Lucru Individual'!G2 -> n/p | U6: =IF(NOT(ISBLANK(C6)), IF(OR(S6="n/p",T6="n/p",S6<5,T6<5)," ",TRUNC(SUM(S6:T6)/2,2)), "") | V6: =IF(NOT(ISBLANK(C6)), IF(U6=" ","n/a", IF(R6,R6, IF(COUNT(MAX(AVERAGE(M6:N6),0)),MAX(M6:N6),"n/p"))), "") -> n/a | W6: =IF(NOT(ISBLANK(C6)), IF(OR(V6="n/a",V6="n/p")," ", IF(V6<5,V6,TRUNC(U6*0.5+V6*0.5,2))), "") | X6: =IF(NOT(ISBLANK(C6)), IF(W6=" "," ", IF(AND(W6>=1,W6<2),"(unu, "&ROUNDUP(MOD(W6*100,100),0)&")", IF(AND(W6>=2,W6<3),"(doi, "&ROUNDUP(MOD(W6*100,100),0)&")", IF(AND(W6>=3,W6<4),"(trei, "&ROUNDUP(MOD(W6*100,100),0)&")", IF(AND(W6>=4,W6<5),"(patru, "&ROUNDUP(MOD(W6*100,100),0)&")", IF(AND(W6>=5,W6<6),"(cinci, "&ROUNDUP(MOD(W6*100,100),0)&")", IF(AND(W6>=6,W6<7),"(şase, "&ROUNDUP(MOD(W6*100,100),0)&")", IF(AND(W6>=7,W6<8),"(şapte, "&ROUNDUP(MOD(W6*100,100),0)&")", IF(AND(W6>=8,W6<9),"(opt, "&ROUNDUP(MOD(W6*100,100),0)&")", IF(AND(W6>=9,W6<10),"(nouă, "&ROUNDUP(MOD(W6*100,100),0)&")", IF(W6=10,"(zece, 00)", ))))))))))),"") | Y6: =IF(NOT(ISBLANK(C6)), IF(W6=" "," ", IF(AND(W6>=1,W6<=3),"F", IF(AND(W6>3,W6<5),"FX", IF(AND(W6>=5,W6<=6),"E", IF(AND(W6>6,W6<=7),"D", IF(AND(W6>7,W6<=8),"C", IF(AND(W6>8,W6<=9),"B", IF(AND(W6>9,W6<=10),"A", )))))))),"")
B7: =IF(NOT(ISBLANK(C7)),COUNTA($C$6:C7),"") | K7: =IF(NOT(ISBLANK(C7)),IF(COUNTIF(E7:J7,"a")<>0,COUNTIF(E7:J7,"a")*2,""),"") | M7: =Examen!G3 | O7: =IF(NOT(ISBLANK(B7)), IF(SUM(E7:J7)+SUM(Laborator!E8:J8)<>0,SUM(E7:J7)+SUM(Laborator!E8:J8),""), "") | S7: =IF(NOT(ISBLANK(C7)),IF(ISNUMBER(Laborator!AD8),Laborator!AD8,"n/p"),"") | T7: ='Lucru Individual'!G3 | U7: =IF(NOT(ISBLANK(C7)), IF(OR(S7="n/p",T7="n/p",S7<5,T7<5)," ",TRUNC(SUM(S7:T7)/2,2)), "") | V7: =IF(NOT(ISBLANK(C7)), IF(U7=" ","n/a", IF(R7,R7, IF(COUNT(MAX(AVERAGE(M7:N7),0)),MAX(M7:N7),"n/p"))), "") | W7: =IF(NOT(ISBLANK(C7)), IF(OR(V7="n/a",V7="n/p")," ", IF(V7<5,V7,TRUNC(U7*0.5+V7*0.5,2))), "") | X7: =IF(NOT(ISBLANK(C7)), IF(W7=" "," ", IF(AND(W7>=1,W7<2),"(unu, "&ROUNDUP(MOD(W7*100,100),0)&")", IF(AND(W7>=2,W7<3),"(doi, "&ROUNDUP(MOD(W7*100,100),0)&")", IF(AND(W7>=3,W7<4),"(trei, "&ROUNDUP(MOD(W7*100,100),0)&")", IF(AND(W7>=4,W7<5),"(patru, "&ROUNDUP(MOD(W7*100,100),0)&")", IF(AND(W7>=5,W7<6),"(cinci, "&ROUNDUP(MOD(W7*100,100),0)&")", IF(AND(W7>=6,W7<7),"(şase, "&ROUNDUP(MOD(W7*100,100),0)&")", IF(AND(W7>=7,W7<8),"(şapte, "&ROUNDUP(MOD(W7*100,100),0)&")", IF(AND(W7>=8,W7<9),"(opt, "&ROUNDUP(MOD(W7*100,100),0)&")", IF(AND(W7>=9,W7<10),"(nouă, "&ROUNDUP(MOD(W7*100,100),0)&")", IF(W7=10,"(zece, 00)", ))))))))))),"") | Y7: =IF(NOT(ISBLANK(C7)), IF(W7=" "," ", IF(AND(W7>=1,W7<=3),"F", IF(AND(W7>3,W7<5),"FX", IF(AND(W7>=5,W7<=6),"E", IF(AND(W7>6,W7<=7),"D", IF(AND(W7>7,W7<=8),"C", IF(AND(W7>8,W7<=9),"B", IF(AND(W7>9,W7<=10),"A", )))))))),"")
B8: =IF(NOT(ISBLANK(C8)),COUNTA($C$6:C8),"") | K8: =IF(NOT(ISBLANK(C8)),IF(COUNTIF(E8:J8,"a")<>0,COUNTIF(E8:J8,"a")*2,""),"") | M8: =Examen!G4 | O8: =IF(NOT(ISBLANK(B8)), IF(SUM(E8:J8)+SUM(Laborator!E9:J9)<>0,SUM(E8:J8)+SUM(Laborator!E9:J9),""), "") | S8: =IF(NOT(ISBLANK(C8)),IF(ISNUMBER(Laborator!AD9),Laborator!AD9,"n/p"),"") | T8: ='Lucru Individual'!G4 | U8: =IF(NOT(ISBLANK(C8)), IF(OR(S8="n/p",T8="n/p",S8<5,T8<5)," ",TRUNC(SUM(S8:T8)/2,2)), "") | V8: =IF(NOT(ISBLANK(C8)), IF(U8=" ","n/a", IF(R8,R8, IF(COUNT(MAX(AVERAGE(M8:N8),0)),MAX(M8:N8),"n/p"))), "") | W8: =IF(NOT(ISBLANK(C8)), IF(OR(V8="n/a",V8="n/p")," ", IF(V8<5,V8,TRUNC(U8*0.5+V8*0.5,2))), "") | X8: =IF(NOT(ISBLANK(C8)), IF(W8=" "," ", IF(AND(W8>=1,W8<2),"(unu, "&ROUNDUP(MOD(W8*100,100),0)&")", IF(AND(W8>=2,W8<3),"(doi, "&ROUNDUP(MOD(W8*100,100),0)&")", IF(AND(W8>=3,W8<4),"(trei, "&ROUNDUP(MOD(W8*100,100),0)&")", IF(AND(W8>=4,W8<5),"(patru, "&ROUNDUP(MOD(W8*100,100),0)&")", IF(AND(W8>=5,W8<6),"(cinci, "&ROUNDUP(MOD(W8*100,100),0)&")", IF(AND(W8>=6,W8<7),"(şase, "&ROUNDUP(MOD(W8*100,100),0)&")", IF(AND(W8>=7,W8<8),"(şapte, "&ROUNDUP(MOD(W8*100,100),0)&")", IF(AND(W8>=8,W8<9),"(opt, "&ROUNDUP(MOD(W8*100,100),0)&")", IF(AND(W8>=9,W8<10),"(nouă, "&ROUNDUP(MOD(W8*100,100),0)&")", IF(W8=10,"(zece, 00)", ))))))))))),"") | Y8: =IF(NOT(ISBLANK(C8)), IF(W8=" "," ", IF(AND(W8>=1,W8<=3),"F", IF(AND(W8>3,W8<5),"FX", IF(AND(W8>=5,W8<=6),"E", IF(AND(W8>6,W8<=7),"D", IF(AND(W8>7,W8<=8),"C", IF(AND(W8>8,W8<=9),"B", IF(AND(W8>9,W8<=10),"A", )))))))),"")
B9: =IF(NOT(ISBLANK(C9)),COUNTA($C$6:C9),"") | K9: =IF(NOT(ISBLANK(C9)),IF(COUNTIF(E9:J9,"a")<>0,COUNTIF(E9:J9,"a")*2,""),"") | M9: =Examen!G5 | O9: =IF(NOT(ISBLANK(B9)), IF(SUM(E9:J9)+SUM(Laborator!E10:J10)<>0,SUM(E9:J9)+SUM(Laborator!E10:J10),""), "") | S9: =IF(NOT(ISBLANK(C9)),IF(ISNUMBER(Laborator!AD10),Laborator!AD10,"n/p"),"") | T9: ='Lucru Individual'!G5 | U9: =IF(NOT(ISBLANK(C9)), IF(OR(S9="n/p",T9="n/p",S9<5,T9<5)," ",TRUNC(SUM(S9:T9)/2,2)), "") | V9: =IF(NOT(ISBLANK(C9)), IF(U9=" ","n/a", IF(R9,R9, IF(COUNT(MAX(AVERAGE(M9:N9),0)),MAX(M9:N9),"n/p"))), "") | W9: =IF(NOT(ISBLANK(C9)), IF(OR(V9="n/a",V9="n/p")," ", IF(V9<5,V9,TRUNC(U9*0.5+V9*0.5,2))), "") | X9: =IF(NOT(ISBLANK(C9)), IF(W9=" "," ", IF(AND(W9>=1,W9<2),"(unu, "&ROUNDUP(MOD(W9*100,100),0)&")", IF(AND(W9>=2,W9<3),"(doi, "&ROUNDUP(MOD(W9*100,100),0)&")", IF(AND(W9>=3,W9<4),"(trei, "&ROUNDUP(MOD(W9*100,100),0)&")", IF(AND(W9>=4,W9<5),"(patru, "&ROUNDUP(MOD(W9*100,100),0)&")", IF(AND(W9>=5,W9<6),"(cinci, "&ROUNDUP(MOD(W9*100,100),0)&")", IF(AND(W9>=6,W9<7),"(şase, "&ROUNDUP(MOD(W9*100,100),0)&")", IF(AND(W9>=7,W9<8),"(şapte, "&ROUNDUP(MOD(W9*100,100),0)&")", IF(AND(W9>=8,W9<9),"(opt, "&ROUNDUP(MOD(W9*100,100),0)&")", IF(AND(W9>=9,W9<10),"(nouă, "&ROUNDUP(MOD(W9*100,100),0)&")", IF(W9=10,"(zece, 00)", ))))))))))),"") | Y9: =IF(NOT(ISBLANK(C9)), IF(W9=" "," ", IF(AND(W9>=1,W9<=3),"F", IF(AND(W9>3,W9<5),"FX", IF(AND(W9>=5,W9<=6),"E", IF(AND(W9>6,W9<=7),"D", IF(AND(W9>7,W9<=8),"C", IF(AND(W9>8,W9<=9),"B", IF(AND(W9>9,W9<=10),"A", )))))))),"")
B10: =IF(NOT(ISBLANK(C10)),COUNTA($C$6:C10),"") | K10: =IF(NOT(ISBLANK(C10)),IF(COUNTIF(E10:J10,"a")<>0,COUNTIF(E10:J10,"a")*2,""),"") | M10: =Examen!G6 | O10: =IF(NOT(ISBLANK(B10)), IF(SUM(E10:J10)+SUM(Laborator!E11:J11)<>0,SUM(E10:J10)+SUM(Laborator!E11:J11),""), "") | S10: =IF(NOT(ISBLANK(C10)),IF(ISNUMBER(Laborator!AD11),Laborator!AD11,"n/p"),"") | T10: ='Lucru Individual'!G6 | U10: =IF(NOT(ISBLANK(C10)), IF(OR(S10="n/p",T10="n/p",S10<5,T10<5)," ",TRUNC(SUM(S10:T10)/2,2)), "") | V10: =IF(NOT(ISBLANK(C10)), IF(U10=" ","n/a", IF(R10,R10, IF(COUNT(MAX(AVERAGE(M10:N10),0)),MAX(M10:N10),"n/p"))), "") | W10: =IF(NOT(ISBLANK(C10)), IF(OR(V10="n/a",V10="n/p")," ", IF(V10<5,V10,TRUNC(U10*0.5+V10*0.5,2))), "") | X10: =IF(NOT(ISBLANK(C10)), IF(W10=" "," ", IF(AND(W10>=1,W10<2),"(unu, "&ROUNDUP(MOD(W10*100,100),0)&")", IF(AND(W10>=2,W10<3),"(doi, "&ROUNDUP(MOD(W10*100,100),0)&")", IF(AND(W10>=3,W10<4),"(trei, "&ROUNDUP(MOD(W10*100,100),0)&")", IF(AND(W10>=4,W10<5),"(patru, "&ROUNDUP(MOD(W10*100,100),0)&")", IF(AND(W10>=5,W10<6),"(cinci, "&ROUNDUP(MOD(W10*100,100),0)&")", IF(AND(W10>=6,W10<7),"(şase, "&ROUNDUP(MOD(W10*100,100),0)&")", IF(AND(W10>=7,W10<8),"(şapte, "&ROUNDUP(MOD(W10*100,100),0)&")", IF(AND(W10>=8,W10<9),"(opt, "&ROUNDUP(MOD(W10*100,100),0)&")", IF(AND(W10>=9,W10<10),"(nouă, "&ROUNDUP(MOD(W10*100,100),0)&")", IF(W10=10,"(zece, 00)", ))))))))))),"") | Y10: =IF(NOT(ISBLANK(C10)), IF(W10=" "," ", IF(AND(W10>=1,W10<=3),"F", IF(AND(W10>3,W10<5),"FX", IF(AND(W10>=5,W10<=6),"E", IF(AND(W10>6,W10<=7),"D", IF(AND(W10>7,W10<=8),"C", IF(AND(W10>8,W10<=9),"B", IF(AND(W10>9,W10<=10),"A", )))))))),"")
B11: =IF(NOT(ISBLANK(C11)),COUNTA($C$6:C11),"") | K11: =IF(NOT(ISBLANK(C11)),IF(COUNTIF(E11:J11,"a")<>0,COUNTIF(E11:J11,"a")*2,""),"") | M11: =Examen!G7 | O11: =IF(NOT(ISBLANK(B11)), IF(SUM(E11:J11)+SUM(Laborator!E12:J12)<>0,SUM(E11:J11)+SUM(Laborator!E12:J12),""), "") | S11: =IF(NOT(ISBLANK(C11)),IF(ISNUMBER(Laborator!AD12),Laborator!AD12,"n/p"),"") | T11: ='Lucru Individual'!G7 | U11: =IF(NOT(ISBLANK(C11)), IF(OR(S11="n/p",T11="n/p",S11<5,T11<5)," ",TRUNC(SUM(S11:T11)/2,2)), "") | V11: =IF(NOT(ISBLANK(C11)), IF(U11=" ","n/a", IF(R11,R11, IF(COUNT(MAX(AVERAGE(M11:N11),0)),MAX(M11:N11),"n/p"))), "") | W11: =IF(NOT(ISBLANK(C11)), IF(OR(V11="n/a",V11="n/p")," ", IF(V11<5,V11,TRUNC(U11*0.5+V11*0.5,2))), "") | X11: =IF(NOT(ISBLANK(C11)), IF(W11=" "," ", IF(AND(W11>=1,W11<2),"(unu, "&ROUNDUP(MOD(W11*100,100),0)&")", IF(AND(W11>=2,W11<3),"(doi, "&ROUNDUP(MOD(W11*100,100),0)&")", IF(AND(W11>=3,W11<4),"(trei, "&ROUNDUP(MOD(W11*100,100),0)&")", IF(AND(W11>=4,W11<5),"(patru, "&ROUNDUP(MOD(W11*100,100),0)&")", IF(AND(W11>=5,W11<6),"(cinci, "&ROUNDUP(MOD(W11*100,100),0)&")", IF(AND(W11>=6,W11<7),"(şase, "&ROUNDUP(MOD(W11*100,100),0)&")", IF(AND(W11>=7,W11<8),"(şapte, "&ROUNDUP(MOD(W11*100,100),0)&")", IF(AND(W11>=8,W11<9),"(opt, "&ROUNDUP(MOD(W11*100,100),0)&")", IF(AND(W11>=9,W11<10),"(nouă, "&ROUNDUP(MOD(W11*100,100),0)&")", IF(W11=10,"(zece, 00)", ))))))))))),"") | Y11: =IF(NOT(ISBLANK(C11)), IF(W11=" "," ", IF(AND(W11>=1,W11<=3),"F", IF(AND(W11>3,W11<5),"FX", IF(AND(W11>=5,W11<=6),"E", IF(AND(W11>6,W11<=7),"D", IF(AND(W11>7,W11<=8),"C", IF(AND(W11>8,W11<=9),"B", IF(AND(W11>9,W11<=10),"A", )))))))),"")
B12: =IF(NOT(ISBLANK(C12)),COUNTA($C$6:C12),"") | K12: =IF(NOT(ISBLANK(C12)),IF(COUNTIF(E12:J12,"a")<>0,COUNTIF(E12:J12,"a")*2,""),"") | M12: =Examen!G8 | O12: =IF(NOT(ISBLANK(B12)), IF(SUM(E12:J12)+SUM(Laborator!E13:J13)<>0,SUM(E12:J12)+SUM(Laborator!E13:J13),""), "") | S12: =IF(NOT(ISBLANK(C12)),IF(ISNUMBER(Laborator!AD13),Laborator!AD13,"n/p"),"") | T12: ='Lucru Individual'!G8 | U12: =IF(NOT(ISBLANK(C12)), IF(OR(S12="n/p",T12="n/p",S12<5,T12<5)," ",TRUNC(SUM(S12:T12)/2,2)), "") | V12: =IF(NOT(ISBLANK(C12)), IF(U12=" ","n/a", IF(R12,R12, IF(COUNT(MAX(AVERAGE(M12:N12),0)),MAX(M12:N12),"n/p"))), "") | W12: =IF(NOT(ISBLANK(C12)), IF(OR(V12="n/a",V12="n/p")," ", IF(V12<5,V12,TRUNC(U12*0.5+V12*0.5,2))), "") | X12: =IF(NOT(ISBLANK(C12)), IF(W12=" "," ", IF(AND(W12>=1,W12<2),"(unu, "&ROUNDUP(MOD(W12*100,100),0)&")", IF(AND(W12>=2,W12<3),"(doi, "&ROUNDUP(MOD(W12*100,100),0)&")", IF(AND(W12>=3,W12<4),"(trei, "&ROUNDUP(MOD(W12*100,100),0)&")", IF(AND(W12>=4,W12<5),"(patru, "&ROUNDUP(MOD(W12*100,100),0)&")", IF(AND(W12>=5,W12<6),"(cinci, "&ROUNDUP(MOD(W12*100,100),0)&")", IF(AND(W12>=6,W12<7),"(şase, "&ROUNDUP(MOD(W12*100,100),0)&")", IF(AND(W12>=7,W12<8),"(şapte, "&ROUNDUP(MOD(W12*100,100),0)&")", IF(AND(W12>=8,W12<9),"(opt, "&ROUNDUP(MOD(W12*100,100),0)&")", IF(AND(W12>=9,W12<10),"(nouă, "&ROUNDUP(MOD(W12*100,100),0)&")", IF(W12=10,"(zece, 00)", ))))))))))),"") | Y12: =IF(NOT(ISBLANK(C12)), IF(W12=" "," ", IF(AND(W12>=1,W12<=3),"F", IF(AND(W12>3,W12<5),"FX", IF(AND(W12>=5,W12<=6),"E", IF(AND(W12>6,W12<=7),"D", IF(AND(W12>7,W12<=8),"C", IF(AND(W12>8,W12<=9),"B", IF(AND(W12>9,W12<=10),"A", )))))))),"")
B13: =IF(NOT(ISBLANK(C13)),COUNTA($C$6:C13),"") | K13: =IF(NOT(ISBLANK(C13)),IF(COUNTIF(E13:J13,"a")<>0,COUNTIF(E13:J13,"a")*2,""),"") | M13: =Examen!G9 | O13: =IF(NOT(ISBLANK(B13)), IF(SUM(E13:J13)+SUM(Laborator!E14:J14)<>0,SUM(E13:J13)+SUM(Laborator!E14:J14),""), "") | S13: =IF(NOT(ISBLANK(C13)),IF(ISNUMBER(Laborator!AD14),Laborator!AD14,"n/p"),"") | T13: ='Lucru Individual'!G9 | U13: =IF(NOT(ISBLANK(C13)), IF(OR(S13="n/p",T13="n/p",S13<5,T13<5)," ",TRUNC(SUM(S13:T13)/2,2)), "") | V13: =IF(NOT(ISBLANK(C13)), IF(U13=" ","n/a", IF(R13,R13, IF(COUNT(MAX(AVERAGE(M13:N13),0)),MAX(M13:N13),"n/p"))), "") | W13: =IF(NOT(ISBLANK(C13)), IF(OR(V13="n/a",V13="n/p")," ", IF(V13<5,V13,TRUNC(U13*0.5+V13*0.5,2))), "") | X13: =IF(NOT(ISBLANK(C13)), IF(W13=" "," ", IF(AND(W13>=1,W13<2),"(unu, "&ROUNDUP(MOD(W13*100,100),0)&")", IF(AND(W13>=2,W13<3),"(doi, "&ROUNDUP(MOD(W13*100,100),0)&")", IF(AND(W13>=3,W13<4),"(trei, "&ROUNDUP(MOD(W13*100,100),0)&")", IF(AND(W13>=4,W13<5),"(patru, "&ROUNDUP(MOD(W13*100,100),0)&")", IF(AND(W13>=5,W13<6),"(cinci, "&ROUNDUP(MOD(W13*100,100),0)&")", IF(AND(W13>=6,W13<7),"(şase, "&ROUNDUP(MOD(W13*100,100),0)&")", IF(AND(W13>=7,W13<8),"(şapte, "&ROUNDUP(MOD(W13*100,100),0)&")", IF(AND(W13>=8,W13<9),"(opt, "&ROUNDUP(MOD(W13*100,100),0)&")", IF(AND(W13>=9,W13<10),"(nouă, "&ROUNDUP(MOD(W13*100,100),0)&")", IF(W13=10,"(zece, 00)", ))))))))))),"") | Y13: =IF(NOT(ISBLANK(C13)), IF(W13=" "," ", IF(AND(W13>=1,W13<=3),"F", IF(AND(W13>3,W13<5),"FX", IF(AND(W13>=5,W13<=6),"E", IF(AND(W13>6,W13<=7),"D", IF(AND(W13>7,W13<=8),"C", IF(AND(W13>8,W13<=9),"B", IF(AND(W13>9,W13<=10),"A", )))))))),"")
B14: =IF(NOT(ISBLANK(C14)),COUNTA($C$6:C14),"") | K14: =IF(NOT(ISBLANK(C14)),IF(COUNTIF(E14:J14,"a")<>0,COUNTIF(E14:J14,"a")*2,""),"") | M14: =Examen!G10 | O14: =IF(NOT(ISBLANK(B14)), IF(SUM(E14:J14)+SUM(Laborator!E15:J15)<>0,SUM(E14:J14)+SUM(Laborator!E15:J15),""), "") | S14: =IF(NOT(ISBLANK(C14)),IF(ISNUMBER(Laborator!AD15),Laborator!AD15,"n/p"),"") | T14: ='Lucru Individual'!G10 | U14: =IF(NOT(ISBLANK(C14)), IF(OR(S14="n/p",T14="n/p",S14<5,T14<5)," ",TRUNC(SUM(S14:T14)/2,2)), "") | V14: =IF(NOT(ISBLANK(C14)), IF(U14=" ","n/a", IF(R14,R14, IF(COUNT(MAX(AVERAGE(M14:N14),0)),MAX(M14:N14),"n/p"))), "") | W14: =IF(NOT(ISBLANK(C14)), IF(OR(V14="n/a",V14="n/p")," ", IF(V14<5,V14,TRUNC(U14*0.5+V14*0.5,2))), "") | X14: =IF(NOT(ISBLANK(C14)), IF(W14=" "," ", IF(AND(W14>=1,W14<2),"(unu, "&ROUNDUP(MOD(W14*100,100),0)&")", IF(AND(W14>=2,W14<3),"(doi, "&ROUNDUP(MOD(W14*100,100),0)&")", IF(AND(W14>=3,W14<4),"(trei, "&ROUNDUP(MOD(W14*100,100),0)&")", IF(AND(W14>=4,W14<5),"(patru, "&ROUNDUP(MOD(W14*100,100),0)&")", IF(AND(W14>=5,W14<6),"(cinci, "&ROUNDUP(MOD(W14*100,100),0)&")", IF(AND(W14>=6,W14<7),"(şase, "&ROUNDUP(MOD(W14*100,100),0)&")", IF(AND(W14>=7,W14<8),"(şapte, "&ROUNDUP(MOD(W14*100,100),0)&")", IF(AND(W14>=8,W14<9),"(opt, "&ROUNDUP(MOD(W14*100,100),0)&")", IF(AND(W14>=9,W14<10),"(nouă, "&ROUNDUP(MOD(W14*100,100),0)&")", IF(W14=10,"(zece, 00)", ))))))))))),"") | Y14: =IF(NOT(ISBLANK(C14)), IF(W14=" "," ", IF(AND(W14>=1,W14<=3),"F", IF(AND(W14>3,W14<5),"FX", IF(AND(W14>=5,W14<=6),"E", IF(AND(W14>6,W14<=7),"D", IF(AND(W14>7,W14<=8),"C", IF(AND(W14>8,W14<=9),"B", IF(AND(W14>9,W14<=10),"A", )))))))),"")
B15: =IF(NOT(ISBLANK(C15)),COUNTA($C$6:C15),"") | K15: =IF(NOT(ISBLANK(C15)),IF(COUNTIF(E15:J15,"a")<>0,COUNTIF(E15:J15,"a")*2,""),"") | M15: =Examen!G11 | O15: =IF(NOT(ISBLANK(B15)), IF(SUM(E15:J15)+SUM(Laborator!E16:J16)<>0,SUM(E15:J15)+SUM(Laborator!E16:J16),""), "") | S15: =IF(NOT(ISBLANK(C15)),IF(ISNUMBER(Laborator!AD16),Laborator!AD16,"n/p"),"") | T15: ='Lucru Individual'!G11 | U15: =IF(NOT(ISBLANK(C15)), IF(OR(S15="n/p",T15="n/p",S15<5,T15<5)," ",TRUNC(SUM(S15:T15)/2,2)), "") | V15: =IF(NOT(ISBLANK(C15)), IF(U15=" ","n/a", IF(R15,R15, IF(COUNT(MAX(AVERAGE(M15:N15),0)),MAX(M15:N15),"n/p"))), "") | W15: =IF(NOT(ISBLANK(C15)), IF(OR(V15="n/a",V15="n/p")," ", IF(V15<5,V15,TRUNC(U15*0.5+V15*0.5,2))), "") | X15: =IF(NOT(ISBLANK(C15)), IF(W15=" "," ", IF(AND(W15>=1,W15<2),"(unu, "&ROUNDUP(MOD(W15*100,100),0)&")", IF(AND(W15>=2,W15<3),"(doi, "&ROUNDUP(MOD(W15*100,100),0)&")", IF(AND(W15>=3,W15<4),"(trei, "&ROUNDUP(MOD(W15*100,100),0)&")", IF(AND(W15>=4,W15<5),"(patru, "&ROUNDUP(MOD(W15*100,100),0)&")", IF(AND(W15>=5,W15<6),"(cinci, "&ROUNDUP(MOD(W15*100,100),0)&")", IF(AND(W15>=6,W15<7),"(şase, "&ROUNDUP(MOD(W15*100,100),0)&")", IF(AND(W15>=7,W15<8),"(şapte, "&ROUNDUP(MOD(W15*100,100),0)&")", IF(AND(W15>=8,W15<9),"(opt, "&ROUNDUP(MOD(W15*100,100),0)&")", IF(AND(W15>=9,W15<10),"(nouă, "&ROUNDUP(MOD(W15*100,100),0)&")", IF(W15=10,"(zece, 00)", ))))))))))),"") | Y15: =IF(NOT(ISBLANK(C15)), IF(W15=" "," ", IF(AND(W15>=1,W15<=3),"F", IF(AND(W15>3,W15<5),"FX", IF(AND(W15>=5,W15<=6),"E", IF(AND(W15>6,W15<=7),"D", IF(AND(W15>7,W15<=8),"C", IF(AND(W15>8,W15<=9),"B", IF(AND(W15>9,W15<=10),"A", )))))))),"")
B16: =IF(NOT(ISBLANK(C16)),COUNTA($C$6:C16),"") | K16: =IF(NOT(ISBLANK(C16)),IF(COUNTIF(E16:J16,"a")<>0,COUNTIF(E16:J16,"a")*2,""),"") | M16: =Examen!G12 | O16: =IF(NOT(ISBLANK(B16)), IF(SUM(E16:J16)+SUM(Laborator!E17:J17)<>0,SUM(E16:J16)+SUM(Laborator!E17:J17),""), "") | S16: =IF(NOT(ISBLANK(C16)),IF(ISNUMBER(Laborator!AD17),Laborator!AD17,"n/p"),"") | T16: ='Lucru Individual'!G12 | U16: =IF(NOT(ISBLANK(C16)), IF(OR(S16="n/p",T16="n/p",S16<5,T16<5)," ",TRUNC(SUM(S16:T16)/2,2)), "") | V16: =IF(NOT(ISBLANK(C16)), IF(U16=" ","n/a", IF(R16,R16, IF(COUNT(MAX(AVERAGE(M16:N16),0)),MAX(M16:N16),"n/p"))), "") | W16: =IF(NOT(ISBLANK(C16)), IF(OR(V16="n/a",V16="n/p")," ", IF(V16<5,V16,TRUNC(U16*0.5+V16*0.5,2))), "") | X16: =IF(NOT(ISBLANK(C16)), IF(W16=" "," ", IF(AND(W16>=1,W16<2),"(unu, "&ROUNDUP(MOD(W16*100,100),0)&")", IF(AND(W16>=2,W16<3),"(doi, "&ROUNDUP(MOD(W16*100,100),0)&")", IF(AND(W16>=3,W16<4),"(trei, "&ROUNDUP(MOD(W16*100,100),0)&")", IF(AND(W16>=4,W16<5),"(patru, "&ROUNDUP(MOD(W16*100,100),0)&")", IF(AND(W16>=5,W16<6),"(cinci, "&ROUNDUP(MOD(W16*100,100),0)&")", IF(AND(W16>=6,W16<7),"(şase, "&ROUNDUP(MOD(W16*100,100),0)&")", IF(AND(W16>=7,W16<8),"(şapte, "&ROUNDUP(MOD(W16*100,100),0)&")", IF(AND(W16>=8,W16<9),"(opt, "&ROUNDUP(MOD(W16*100,100),0)&")", IF(AND(W16>=9,W16<10),"(nouă, "&ROUNDUP(MOD(W16*100,100),0)&")", IF(W16=10,"(zece, 00)", ))))))))))),"") | Y16: =IF(NOT(ISBLANK(C16)), IF(W16=" "," ", IF(AND(W16>=1,W16<=3),"F", IF(AND(W16>3,W16<5),"FX", IF(AND(W16>=5,W16<=6),"E", IF(AND(W16>6,W16<=7),"D", IF(AND(W16>7,W16<=8),"C", IF(AND(W16>8,W16<=9),"B", IF(AND(W16>9,W16<=10),"A", )))))))),"")
B17: =IF(NOT(ISBLANK(C17)),COUNTA($C$6:C17),"") | K17: =IF(NOT(ISBLANK(C17)),IF(COUNTIF(E17:J17,"a")<>0,COUNTIF(E17:J17,"a")*2,""),"") | M17: =Examen!G13 | O17: =IF(NOT(ISBLANK(B17)), IF(SUM(E17:J17)+SUM(Laborator!E18:J18)<>0,SUM(E17:J17)+SUM(Laborator!E18:J18),""), "") | S17: =IF(NOT(ISBLANK(C17)),IF(ISNUMBER(Laborator!AD18),Laborator!AD18,"n/p"),"") | T17: ='Lucru Individual'!G13 | U17: =IF(NOT(ISBLANK(C17)), IF(OR(S17="n/p",T17="n/p",S17<5,T17<5)," ",TRUNC(SUM(S17:T17)/2,2)), "") | V17: =IF(NOT(ISBLANK(C17)), IF(U17=" ","n/a", IF(R17,R17, IF(COUNT(MAX(AVERAGE(M17:N17),0)),MAX(M17:N17),"n/p"))), "") | W17: =IF(NOT(ISBLANK(C17)), IF(OR(V17="n/a",V17="n/p")," ", IF(V17<5,V17,TRUNC(U17*0.5+V17*0.5,2))), "") | X17: =IF(NOT(ISBLANK(C17)), IF(W17=" "," ", IF(AND(W17>=1,W17<2),"(unu, "&ROUNDUP(MOD(W17*100,100),0)&")", IF(AND(W17>=2,W17<3),"(doi, "&ROUNDUP(MOD(W17*100,100),0)&")", IF(AND(W17>=3,W17<4),"(trei, "&ROUNDUP(MOD(W17*100,100),0)&")", IF(AND(W17>=4,W17<5),"(patru, "&ROUNDUP(MOD(W17*100,100),0)&")", IF(AND(W17>=5,W17<6),"(cinci, "&ROUNDUP(MOD(W17*100,100),0)&")", IF(AND(W17>=6,W17<7),"(şase, "&ROUNDUP(MOD(W17*100,100),0)&")", IF(AND(W17>=7,W17<8),"(şapte, "&ROUNDUP(MOD(W17*100,100),0)&")", IF(AND(W17>=8,W17<9),"(opt, "&ROUNDUP(MOD(W17*100,100),0)&")", IF(AND(W17>=9,W17<10),"(nouă, "&ROUNDUP(MOD(W17*100,100),0)&")", IF(W17=10,"(zece, 00)", ))))))))))),"") | Y17: =IF(NOT(ISBLANK(C17)), IF(W17=" "," ", IF(AND(W17>=1,W17<=3),"F", IF(AND(W17>3,W17<5),"FX", IF(AND(W17>=5,W17<=6),"E", IF(AND(W17>6,W17<=7),"D", IF(AND(W17>7,W17<=8),"C", IF(AND(W17>8,W17<=9),"B", IF(AND(W17>9,W17<=10),"A", )))))))),"")
B18: =IF(NOT(ISBLANK(C18)),COUNTA($C$6:C18),"") | K18: =IF(NOT(ISBLANK(C18)),IF(COUNTIF(E18:J18,"a")<>0,COUNTIF(E18:J18,"a")*2,""),"") | M18: =Examen!G14 | O18: =IF(NOT(ISBLANK(B18)), IF(SUM(E18:J18)+SUM(Laborator!E19:J19)<>0,SUM(E18:J18)+SUM(Laborator!E19:J19),""), "") | S18: =IF(NOT(ISBLANK(C18)),IF(ISNUMBER(Laborator!AD19),Laborator!AD19,"n/p"),"") | T18: ='Lucru Individual'!G14 | U18: =IF(NOT(ISBLANK(C18)), IF(OR(S18="n/p",T18="n/p",S18<5,T18<5)," ",TRUNC(SUM(S18:T18)/2,2)), "") | V18: =IF(NOT(ISBLANK(C18)), IF(U18=" ","n/a", IF(R18,R18, IF(COUNT(MAX(AVERAGE(M18:N18),0)),MAX(M18:N18),"n/p"))), "") | W18: =IF(NOT(ISBLANK(C18)), IF(OR(V18="n/a",V18="n/p")," ", IF(V18<5,V18,TRUNC(U18*0.5+V18*0.5,2))), "") | X18: =IF(NOT(ISBLANK(C18)), IF(W18=" "," ", IF(AND(W18>=1,W18<2),"(unu, "&ROUNDUP(MOD(W18*100,100),0)&")", IF(AND(W18>=2,W18<3),"(doi, "&ROUNDUP(MOD(W18*100,100),0)&")", IF(AND(W18>=3,W18<4),"(trei, "&ROUNDUP(MOD(W18*100,100),0)&")", IF(AND(W18>=4,W18<5),"(patru, "&ROUNDUP(MOD(W18*100,100),0)&")", IF(AND(W18>=5,W18<6),"(cinci, "&ROUNDUP(MOD(W18*100,100),0)&")", IF(AND(W18>=6,W18<7),"(şase, "&ROUNDUP(MOD(W18*100,100),0)&")", IF(AND(W18>=7,W18<8),"(şapte, "&ROUNDUP(MOD(W18*100,100),0)&")", IF(AND(W18>=8,W18<9),"(opt, "&ROUNDUP(MOD(W18*100,100),0)&")", IF(AND(W18>=9,W18<10),"(nouă, "&ROUNDUP(MOD(W18*100,100),0)&")", IF(W18=10,"(zece, 00)", ))))))))))),"") | Y18: =IF(NOT(ISBLANK(C18)), IF(W18=" "," ", IF(AND(W18>=1,W18<=3),"F", IF(AND(W18>3,W18<5),"FX", IF(AND(W18>=5,W18<=6),"E", IF(AND(W18>6,W18<=7),"D", IF(AND(W18>7,W18<=8),"C", IF(AND(W18>8,W18<=9),"B", IF(AND(W18>9,W18<=10),"A", )))))))),"")
... B105: =IF(NOT(ISBLANK(C105)),COUNTA($C$6:C105),"") | K105: =IF(NOT(ISBLANK(C105)),IF(COUNTIF(E105:J105,"a")<>0,COUNTIF(E105:J105,"a")*2,""),"") | M105: =Examen!G101 | O105: =IF(NOT(ISBLANK(B105)), IF(SUM(E105:J105)+SUM(Laborator!E106:J106)<>0,SUM(E105:J105)+SUM(Laborator!E106:J106),""), "") | S105: =IF(NOT(ISBLANK(C105)),IF(ISNUMBER(Laborator!AD106),Laborator!AD106,"n/p"),"") | T105: ='Lucru Individual'!G101 | U105: =IF(NOT(ISBLANK(C105)), IF(OR(S105="n/p",T105="n/p",S105<5,T105<5)," ",TRUNC(SUM(S105:T105)/2,2)), "") | V105: =IF(NOT(ISBLANK(C105)), IF(U105=" ","n/a", IF(R105,R105, IF(COUNT(MAX(AVERAGE(M105:N105),0)),MAX(M105:N105),"n/p"))), "") | W105: =IF(NOT(ISBLANK(C105)), IF(OR(V105="n/a",V105="n/p")," ", IF(V105<5,V105,TRUNC(U105*0.5+V105*0.5,2))), "") | X105: =IF(NOT(ISBLANK(C105)), IF(W105=" "," ", IF(AND(W105>=1,W105<2),"(unu, "&ROUNDUP(MOD(W105*100,100),0)&")", IF(AND(W105>=2,W105<3),"(doi, "&ROUNDUP(MOD(W105*100,100),0)&")", IF(AND(W105>=3,W105<4),"(trei, "&ROUNDUP(MOD(W105*100,100),0)&")", IF(AND(W105>=4,W105<5),"(patru, "&ROUNDUP(MOD(W105*100,100),0)&")", IF(AND(W105>=5,W105<6),"(cinci, "&ROUNDUP(MOD(W105*100,100),0)&")", IF(AND(W105>=6,W105<7),"(şase, "&ROUNDUP(MOD(W105*100,100),0)&")", IF(AND(W105>=7,W105<8),"(şapte, "&ROUNDUP(MOD(W105*100,100),0)&")", IF(AND(W105>=8,W105<9),"(opt, "&ROUNDUP(MOD(W105*100,100),0)&")", IF(AND(W105>=9,W105<10),"(nouă, "&ROUNDUP(MOD(W105*100,100),0)&")", IF(W105=10,"(zece, 00)", ))))))))))),"") | Y105: =IF(NOT(ISBLANK(C105)), IF(W105=" "," ", IF(AND(W105>=1,W105<=3),"F", IF(AND(W105>3,W105<5),"FX", IF(AND(W105>=5,W105<=6),"E", IF(AND(W105>6,W105<=7),"D", IF(AND(W105>7,W105<=8),"C", IF(AND(W105>8,W105<=9),"B", IF(AND(W105>9,W105<=10),"A", )))))))),"")
Y106: =IF(NOT(ISBLANK(C106)), IF(W106=" "," ", IF(AND(W106>=1,W106<=3),"F", IF(AND(W106>3,W106<5),"FX", IF(AND(W106>=5,W106<=6),"E", IF(AND(W106>6,W106<=7),"D", IF(AND(W106>7,W106<=8),"C", IF(AND(W106>8,W106<=9),"B", IF(AND(W106>9,W106<=10),"A", )))))))),"")

Sheet Laborator
B2: Prezența | M2: Evaluarea activităților
C4: Nr. Subgrupe - | D4: 1 | O4: L1 | Q4: L2 | S4: L3 | U4: L4 | W4: L5 | Y4: L6 | AA4: L7 | AC4: Total
E5: L1 | F5: L2 | G5: L3 | H5: L4 | I5: L5 | J5: L6 | N5: Data susținerii-- | O5: 11.02 18.02 | Q5: 25.02 4.03 | S5: 11.03 18.03 | U5: 25.03 1.04 | W5: 8.04 15.04 | Y5: 22.04 6.05 | AA5: 13.05
B6: Nr. | C6: Nume, Prenume | D6: Varianta | E6: 28.01 | F6: 11.02/ 18.02 | G6: 25.02/ 4.03 | H6: 11.03/ 18.03 | I6: 25.03/ 1.04 | J6: 8.04/ 15.04 | K6: Ore absentate | M6: Nr. | N6: Nume, Prenume | O6: Nota | P6: Penalit | Q6: Nota | R6: Penalit | S6: Nota | T6: Penalit | U6: Nota | V6: Penalit | W6: Nota | X6: Penalit | Y6: Nota | Z6: Penalit | AA6: Nota | AB6: Penalit | AC6: Penalități | AD6: Nota medie
B7: =IF(NOT(ISBLANK(Curs!B6)),Curs!B6,"") -> 1 | C7: =IF(NOT(ISBLANK(Curs!C6)),Curs!C6,"") -> Nume, Prenume | K7: =IF(C7<>"",IF(COUNTIF(E7:J7,"a")<>0,COUNTIF(E7:J7,"a")*2,""),"") | M7: =IF(NOT(ISBLANK(B7)),B7,"") -> 1 | N7: =IF(NOT(ISBLANK(C7)),C7,"") -> Nume, Prenume | AD7: =IF(NOT(ISBLANK(Curs!C6)),IFERROR(SUM(O7,Q7,S7,U7,W7,Y7,AA7)/COUNT(O7,Q7,S7,U7,W7,Y7,AA7),""),"")
B8: =IF(NOT(ISBLANK(Curs!B7)),Curs!B7,"") | C8: =IF(NOT(ISBLANK(Curs!C7)),Curs!C7,"") | K8: =IF(C8<>"",IF(COUNTIF(E8:J8,"a")<>0,COUNTIF(E8:J8,"a")*2,""),"") | M8: =IF(NOT(ISBLANK(B8)),B8,"") | N8: =IF(NOT(ISBLANK(C8)),C8,"") | AD8: =IF(NOT(ISBLANK(Curs!C7)),IFERROR(SUM(O8,Q8,S8,U8,W8,Y8,AA8)/COUNT(O8,Q8,S8,U8,W8,Y8,AA8),""),"")
B9: =IF(NOT(ISBLANK(Curs!B8)),Curs!B8,"") | C9: =IF(NOT(ISBLANK(Curs!C8)),Curs!C8,"") | K9: =IF(C9<>"",IF(COUNTIF(E9:J9,"a")<>0,COUNTIF(E9:J9,"a")*2,""),"") | M9: =IF(NOT(ISBLANK(B9)),B9,"") | N9: =IF(NOT(ISBLANK(C9)),C9,"") | AD9: =IF(NOT(ISBLANK(Curs!C8)),IFERROR(SUM(O9,Q9,S9,U9,W9,Y9,AA9)/COUNT(O9,Q9,S9,U9,W9,Y9,AA9),""),"")
B10: =IF(NOT(ISBLANK(Curs!B9)),Curs!B9,"") | C10: =IF(NOT(ISBLANK(Curs!C9)),Curs!C9,"") | K10: =IF(C10<>"",IF(COUNTIF(E10:J10,"a")<>0,COUNTIF(E10:J10,"a")*2,""),"") | M10: =IF(NOT(ISBLANK(B10)),B10,"") | N10: =IF(NOT(ISBLANK(C10)),C10,"") | AD10: =IF(NOT(ISBLANK(Curs!C9)),IFERROR(SUM(O10,Q10,S10,U10,W10,Y10,AA10)/COUNT(O10,Q10,S10,U10,W10,Y10,AA10),""),"")
B11: =IF(NOT(ISBLANK(Curs!B10)),Curs!B10,"") | C11: =IF(NOT(ISBLANK(Curs!C10)),Curs!C10,"") | K11: =IF(C11<>"",IF(COUNTIF(E11:J11,"a")<>0,COUNTIF(E11:J11,"a")*2,""),"") | M11: =IF(NOT(ISBLANK(B11)),B11,"") | N11: =IF(NOT(ISBLANK(C11)),C11,"") | AC11: =IF(NOT(ISBLANK(Curs!C10)),IF(ABS(P11+R11+T11+V11+X11+Z11+AB11)<>0,ABS(P11+R11+T11+V11+X11+Z11+AB11),""),"") | AD11: =IF(NOT(ISBLANK(Curs!C10)),IFERROR(SUM(O11,Q11,S11,U11,W11,Y11,AA11)/COUNT(O11,Q11,S11,U11,W11,Y11,AA11),""),"")
B12: =IF(NOT(ISBLANK(Curs!B11)),Curs!B11,"") | C12: =IF(NOT(ISBLANK(Curs!C11)),Curs!C11,"") | K12: =IF(C12<>"",IF(COUNTIF(E12:J12,"a")<>0,COUNTIF(E12:J12,"a")*2,""),"") | M12: =IF(NOT(ISBLANK(B12)),B12,"") | N12: =IF(NOT(ISBLANK(C12)),C12,"") | AC12: =IF(NOT(ISBLANK(Curs!C11)),IF(ABS(P12+R12+T12+V12+X12+Z12+AB12)<>0,ABS(P12+R12+T12+V12+X12+Z12+AB12),""),"") | AD12: =IF(NOT(ISBLANK(Curs!C11)),IFERROR(SUM(O12,Q12,S12,U12,W12,Y12,AA12)/COUNT(O12,Q12,S12,U12,W12,Y12,AA12),""),"")
B13: =IF(NOT(ISBLANK(Curs!B12)),Curs!B12,"") | C13: =IF(NOT(ISBLANK(Curs!C12)),Curs!C12,"") | K13: =IF(C13<>"",IF(COUNTIF(E13:J13,"a")<>0,COUNTIF(E13:J13,"a")*2,""),"") | M13: =IF(NOT(ISBLANK(B13)),B13,"") | N13: =IF(NOT(ISBLANK(C13)),C13,"") | AC13: =IF(NOT(ISBLANK(Curs!C12)),IF(ABS(P13+R13+T13+V13+X13+Z13+AB13)<>0,ABS(P13+R13+T13+V13+X13+Z13+AB13),""),"") | AD13: =IF(NOT(ISBLANK(Curs!C12)),IFERROR(SUM(O13,Q13,S13,U13,W13,Y13,AA13)/COUNT(O13,Q13,S13,U13,W13,Y13,AA13),""),"")
B14: =IF(NOT(ISBLANK(Curs!B13)),Curs!B13,"") | C14: =IF(NOT(ISBLANK(Curs!C13)),Curs!C13,"") | K14: =IF(C14<>"",IF(COUNTIF(E14:J14,"a")<>0,COUNTIF(E14:J14,"a")*2,""),"") | M14: =IF(NOT(ISBLANK(B14)),B14,"") | N14: =IF(NOT(ISBLANK(C14)),C14,"") | AC14: =IF(NOT(ISBLANK(Curs!C13)),IF(ABS(P14+R14+T14+V14+X14+Z14+AB14)<>0,ABS(P14+R14+T14+V14+X14+Z14+AB14),""),"") | AD14: =IF(NOT(ISBLANK(Curs!C13)),IFERROR(SUM(O14,Q14,S14,U14,W14,Y14,AA14)/COUNT(O14,Q14,S14,U14,W14,Y14,AA14),""),"")
B15: =IF(NOT(ISBLANK(Curs!B14)),Curs!B14,"") | C15: =IF(NOT(ISBLANK(Curs!C14)),Curs!C14,"") | K15: =IF(C15<>"",IF(COUNTIF(E15:J15,"a")<>0,COUNTIF(E15:J15,"a")*2,""),"") | M15: =IF(NOT(ISBLANK(B15)),B15,"") | N15: =IF(NOT(ISBLANK(C15)),C15,"") | AC15: =IF(NOT(ISBLANK(Curs!C14)),IF(ABS(P15+R15+T15+V15+X15+Z15+AB15)<>0,ABS(P15+R15+T15+V15+X15+Z15+AB15),""),"") | AD15: =IF(NOT(ISBLANK(Curs!C14)),IFERROR(SUM(O15,Q15,S15,U15,W15,Y15,AA15)/COUNT(O15,Q15,S15,U15,W15,Y15,AA15),""),"")
B16: =IF(NOT(ISBLANK(Curs!B15)),Curs!B15,"") | C16: =IF(NOT(ISBLANK(Curs!C15)),Curs!C15,"") | K16: =IF(C16<>"",IF(COUNTIF(E16:J16,"a")<>0,COUNTIF(E16:J16,"a")*2,""),"") | M16: =IF(NOT(ISBLANK(B16)),B16,"") | N16: =IF(NOT(ISBLANK(C16)),C16,"") | AC16: =IF(NOT(ISBLANK(Curs!C15)),IF(ABS(P16+R16+T16+V16+X16+Z16+AB16)<>0,ABS(P16+R16+T16+V16+X16+Z16+AB16),""),"") | AD16: =IF(NOT(ISBLANK(Curs!C15)),IFERROR(SUM(O16,Q16,S16,U16,W16,Y16,AA16)/COUNT(O16,Q16,S16,U16,W16,Y16,AA16),""),"")
B17: =IF(NOT(ISBLANK(Curs!B16)),Curs!B16,"") | C17: =IF(NOT(ISBLANK(Curs!C16)),Curs!C16,"") | K17: =IF(C17<>"",IF(COUNTIF(E17:J17,"a")<>0,COUNTIF(E17:J17,"a")*2,""),"") | M17: =IF(NOT(ISBLANK(B17)),B17,"") | N17: =IF(NOT(ISBLANK(C17)),C17,"") | AC17: =IF(NOT(ISBLANK(Curs!C16)),IF(ABS(P17+R17+T17+V17+X17+Z17+AB17)<>0,ABS(P17+R17+T17+V17+X17+Z17+AB17),""),"") | AD17: =IF(NOT(ISBLANK(Curs!C16)),IFERROR(SUM(O17,Q17,S17,U17,W17,Y17,AA17)/COUNT(O17,Q17,S17,U17,W17,Y17,AA17),""),"")
B18: =IF(NOT(ISBLANK(Curs!B17)),Curs!B17,"") | C18: =IF(NOT(ISBLANK(Curs!C17)),Curs!C17,"") | K18: =IF(C18<>"",IF(COUNTIF(E18:J18,"a")<>0,COUNTIF(E18:J18,"a")*2,""),"") | M18: =IF(NOT(ISBLANK(B18)),B18,"") | N18: =IF(NOT(ISBLANK(C18)),C18,"") | AC18: =IF(NOT(ISBLANK(Curs!C17)),IF(ABS(P18+R18+T18+V18+X18+Z18+AB18)<>0,ABS(P18+R18+T18+V18+X18+Z18+AB18),""),"") | AD18: =IF(NOT(ISBLANK(Curs!C17)),IFERROR(SUM(O18,Q18,S18,U18,W18,Y18,AA18)/COUNT(O18,Q18,S18,U18,W18,Y18,AA18),""),"")
B19: =IF(NOT(ISBLANK(Curs!B18)),Curs!B18,"") | C19: =IF(NOT(ISBLANK(Curs!C18)),Curs!C18,"") | K19: =IF(C19<>"",IF(COUNTIF(E19:J19,"a")<>0,COUNTIF(E19:J19,"a")*2,""),"") | M19: =IF(NOT(ISBLANK(B19)),B19,"") | N19: =IF(NOT(ISBLANK(C19)),C19,"") | AC19: =IF(NOT(ISBLANK(Curs!C18)),IF(ABS(P19+R19+T19+V19+X19+Z19+AB19)<>0,ABS(P19+R19+T19+V19+X19+Z19+AB19),""),"") | AD19: =IF(NOT(ISBLANK(Curs!C18)),IFERROR(SUM(O19,Q19,S19,U19,W19,Y19,AA19)/COUNT(O19,Q19,S19,U19,W19,Y19,AA19),""),"")
B20: =IF(NOT(ISBLANK(Curs!B19)),Curs!B19,"") | C20: =IF(NOT(ISBLANK(Curs!C19)),Curs!C19,"") | K20: =IF(C20<>"",IF(COUNTIF(E20:J20,"a")<>0,COUNTIF(E20:J20,"a")*2,""),"") | M20: =IF(NOT(ISBLANK(B20)),B20,"") | N20: =IF(NOT(ISBLANK(C20)),C20,"") | AC20: =IF(NOT(ISBLANK(Curs!C19)),IF(ABS(P20+R20+T20+V20+X20+Z20+AB20)<>0,ABS(P20+R20+T20+V20+X20+Z20+AB20),""),"") | AD20: =IF(NOT(ISBLANK(Curs!C19)),IFERROR(SUM(O20,Q20,S20,U20,W20,Y20,AA20)/COUNT(O20,Q20,S20,U20,W20,Y20,AA20),""),"")
B21: =IF(NOT(ISBLANK(Curs!B20)),Curs!B20,"") | C21: =IF(NOT(ISBLANK(Curs!C20)),Curs!C20,"") | K21: =IF(C21<>"",IF(COUNTIF(E21:J21,"a")<>0,COUNTIF(E21:J21,"a")*2,""),"") | M21: =IF(NOT(ISBLANK(B21)),B21,"") | N21: =IF(NOT(ISBLANK(C21)),C21,"") | AC21: =IF(NOT(ISBLANK(Curs!C20)),IF(ABS(P21+R21+T21+V21+X21+Z21+AB21)<>0,ABS(P21+R21+T21+V21+X21+Z21+AB21),""),"") | AD21: =IF(NOT(ISBLANK(Curs!C20)),IFERROR(SUM(O21,Q21,S21,U21,W21,Y21,AA21)/COUNT(O21,Q21,S21,U21,W21,Y21,AA21),""),"")
B22: =IF(NOT(ISBLANK(Curs!B21)),Curs!B21,"") | C22: =IF(NOT(ISBLANK(Curs!C21)),Curs!C21,"") | K22: =IF(C22<>"",IF(COUNTIF(E22:J22,"a")<>0,COUNTIF(E22:J22,"a")*2,""),"") | M22: =IF(NOT(ISBLANK(B22)),B22,"") | N22: =IF(NOT(ISBLANK(C22)),C22,"") | AC22: =IF(NOT(ISBLANK(Curs!C21)),IF(ABS(P22+R22+T22+V22+X22+Z22+AB22)<>0,ABS(P22+R22+T22+V22+X22+Z22+AB22),""),"") | AD22: =IF(NOT(ISBLANK(Curs!C21)),IFERROR(SUM(O22,Q22,S22,U22,W22,Y22,AA22)/COUNT(O22,Q22,S22,U22,W22,Y22,AA22),""),"")
... B106: =IF(NOT(ISBLANK(Curs!B105)),Curs!B105,"") | C106: =IF(NOT(ISBLANK(Curs!C105)),Curs!C105,"") | K106: =IF(C106<>"",IF(COUNTIF(E106:J106,"a")<>0,COUNTIF(E106:J106,"a")*2,""),"") | M106: =IF(NOT(ISBLANK(B106)),B106,"") | N106: =IF(NOT(ISBLANK(C106)),C106,"") | AC106: =IF(NOT(ISBLANK(Curs!C105)),IF(ABS(P106+R106+T106+V106+X106+Z106+AB106)<>0,ABS(P106+R106+T106+V106+X106+Z106+AB106),""),"") | AD106: =IF(NOT(ISBLANK(Curs!C105)),IFERROR(SUM(O106,Q106,S106,U106,W106,Y106,AA106)/COUNT(O106,Q106,S106,U106,W106,Y106,AA106),""),"")

Sheet Lucru Individual
A1: Nr. | B1: Nume, Prenume | C1: Var | D1: C1 | E1: C2 | F1: D1 | G1: Nota | I1: Statistica
A2: =IF(NOT(ISBLANK(Curs!B6)),Curs!B6,"") -> 1 | B2: =IF(NOT(ISBLANK(Curs!C6)),Curs!C6,"") -> Nume, Prenume | C2: 01 | G2: =IF(NOT(ISBLANK(Curs!C6)),IF(AND(NOT(ISBLANK(D2)),NOT(ISBLANK(F2)),D2>=5,F2>=5),ROUND(AVERAGE(D2:F2),0),"n/p"),"") -> n/p | I2: Nota | J2: Nr de note
A3: =IF(NOT(ISBLANK(Curs!B7)),Curs!B7,"") | B3: =IF(NOT(ISBLANK(Curs!C7)),Curs!C7,"") | G3: =IF(NOT(ISBLANK(Curs!C7)),IF(AND(NOT(ISBLANK(D3)),NOT(ISBLANK(F3)),D3>=5,F3>=5),ROUND(AVERAGE(D3:F3),0),"n/p"),"") | I3: 1 | J3: =COUNTIF($G$2:$G$101,I3) -> 0
A4: =IF(NOT(ISBLANK(Curs!B8)),Curs!B8,"") | B4: =IF(NOT(ISBLANK(Curs!C8)),Curs!C8,"") | G4: =IF(NOT(ISBLANK(Curs!C8)),IF(AND(NOT(ISBLANK(D4)),NOT(ISBLANK(F4)),D4>=5,F4>=5),ROUND(AVERAGE(D4:F4),0),"n/p"),"") | I4: 2 | J4: =COUNTIF($G$2:$G$101,I4) -> 0
A5: =IF(NOT(ISBLANK(Curs!B9)),Curs!B9,"") | B5: =IF(NOT(ISBLANK(Curs!C9)),Curs!C9,"") | G5: =IF(NOT(ISBLANK(Curs!C9)),IF(AND(NOT(ISBLANK(D5)),NOT(ISBLANK(F5)),D5>=5,F5>=5),ROUND(AVERAGE(D5:F5),0),"n/p"),"") | I5: 3 | J5: =COUNTIF($G$2:$G$101,I5) -> 0
A6: =IF(NOT(ISBLANK(Curs!B10)),Curs!B10,"") | B6: =IF(NOT(ISBLANK(Curs!C10)),Curs!C10,"") | G6: =IF(NOT(ISBLANK(Curs!C10)),IF(AND(NOT(ISBLANK(D6)),NOT(ISBLANK(F6)),D6>=5,F6>=5),ROUND(AVERAGE(D6:F6),0),"n/p"),"") | I6: 4 | J6: =COUNTIF($G$2:$G$101,I6) -> 0
A7: =IF(NOT(ISBLANK(Curs!B11)),Curs!B11,"") | B7: =IF(NOT(ISBLANK(Curs!C11)),Curs!C11,"") | G7: =IF(NOT(ISBLANK(Curs!C11)),IF(AND(NOT(ISBLANK(D7)),NOT(ISBLANK(F7)),D7>=5,F7>=5),ROUND(AVERAGE(D7:F7),0),"n/p"),"") | I7: 5 | J7: =COUNTIF($G$2:$G$101,I7) -> 0
A8: =IF(NOT(ISBLANK(Curs!B12)),Curs!B12,"") | B8: =IF(NOT(ISBLANK(Curs!C12)),Curs!C12,"") | G8: =IF(NOT(ISBLANK(Curs!C12)),IF(AND(NOT(ISBLANK(D8)),NOT(ISBLANK(F8)),D8>=5,F8>=5),ROUND(AVERAGE(D8:F8),0),"n/p"),"") | I8: 6 | J8: =COUNTIF($G$2:$G$101,I8) -> 0
A9: =IF(NOT(ISBLANK(Curs!B13)),Curs!B13,"") | B9: =IF(NOT(ISBLANK(Curs!C13)),Curs!C13,"") | G9: =IF(NOT(ISBLANK(Curs!C13)),IF(AND(NOT(ISBLANK(D9)),NOT(ISBLANK(F9)),D9>=5,F9>=5),ROUND(AVERAGE(D9:F9),0),"n/p"),"") | I9: 7 | J9: =COUNTIF($G$2:$G$101,I9) -> 0
A10: =IF(NOT(ISBLANK(Curs!B14)),Curs!B14,"") | B10: =IF(NOT(ISBLANK(Curs!C14)),Curs!C14,"") | G10: =IF(NOT(ISBLANK(Curs!C14)),IF(AND(NOT(ISBLANK(D10)),NOT(ISBLANK(F10)),D10>=5,F10>=5),ROUND(AVERAGE(D10:F10),0),"n/p"),"") | I10: 8 | J10: =COUNTIF($G$2:$G$101,I10) -> 0
A11: =IF(NOT(ISBLANK(Curs!B15)),Curs!B15,"") | B11: =IF(NOT(ISBLANK(Curs!C15)),Curs!C15,"") | G11: =IF(NOT(ISBLANK(Curs!C15)),IF(AND(NOT(ISBLANK(D11)),NOT(ISBLANK(F11)),D11>=5,F11>=5),ROUND(AVERAGE(D11:F11),0),"n/p"),"") | I11: 9 | J11: =COUNTIF($G$2:$G$101,I11) -> 0
A12: =IF(NOT(ISBLANK(Curs!B16)),Curs!B16,"") | B12: =IF(NOT(ISBLANK(Curs!C16)),Curs!C16,"") | G12: =IF(NOT(ISBLANK(Curs!C16)),IF(AND(NOT(ISBLANK(D12)),NOT(ISBLANK(F12)),D12>=5,F12>=5),ROUND(AVERAGE(D12:F12),0),"n/p"),"") | I12: 10 | J12: =COUNTIF($G$2:$G$101,I12) -> 0
A13: =IF(NOT(ISBLANK(Curs!B17)),Curs!B17,"") | B13: =IF(NOT(ISBLANK(Curs!C17)),Curs!C17,"") | G13: =IF(NOT(ISBLANK(Curs!C17)),IF(AND(NOT(ISBLANK(D13)),NOT(ISBLANK(F13)),D13>=5,F13>=5),ROUND(AVERAGE(D13:F13),0),"n/p"),"") | I13: n/p | J13: =COUNTIF($G$2:$G$101,I13) -> 1
A14: =IF(NOT(ISBLANK(Curs!B18)),Curs!B18,"") | B14: =IF(NOT(ISBLANK(Curs!C18)),Curs!C18,"") | G14: =IF(NOT(ISBLANK(Curs!C18)),IF(AND(NOT(ISBLANK(D14)),NOT(ISBLANK(F14)),D14>=5,F14>=5),ROUND(AVERAGE(D14:F14),0),"n/p"),"")
A15: =IF(NOT(ISBLANK(Curs!B19)),Curs!B19,"") | B15: =IF(NOT(ISBLANK(Curs!C19)),Curs!C19,"") | G15: =IF(NOT(ISBLANK(Curs!C19)),IF(AND(NOT(ISBLANK(D15)),NOT(ISBLANK(F15)),D15>=5,F15>=5),ROUND(AVERAGE(D15:F15),0),"n/p"),"")
A16: =IF(NOT(ISBLANK(Curs!B20)),Curs!B20,"") | B16: =IF(NOT(ISBLANK(Curs!C20)),Curs!C20,"") | G16: =IF(NOT(ISBLANK(Curs!C20)),IF(AND(NOT(ISBLANK(D16)),NOT(ISBLANK(F16)),D16>=5,F16>=5),ROUND(AVERAGE(D16:F16),0),"n/p"),"")
A17: =IF(NOT(ISBLANK(Curs!B21)),Curs!B21,"") | B17: =IF(NOT(ISBLANK(Curs!C21)),Curs!C21,"") | G17: =IF(NOT(ISBLANK(Curs!C21)),IF(AND(NOT(ISBLANK(D17)),NOT(ISBLANK(F17)),D17>=5,F17>=5),ROUND(AVERAGE(D17:F17),0),"n/p"),"")
A18: =IF(NOT(ISBLANK(Curs!B22)),Curs!B22,"") | B18: =IF(NOT(ISBLANK(Curs!C22)),Curs!C22,"") | G18: =IF(NOT(ISBLANK(Curs!C22)),IF(AND(NOT(ISBLANK(D18)),NOT(ISBLANK(F18)),D18>=5,F18>=5),ROUND(AVERAGE(D18:F18),0),"n/p"),"")
A19: =IF(NOT(ISBLANK(Curs!B23)),Curs!B23,"") | B19: =IF(NOT(ISBLANK(Curs!C23)),Curs!C23,"") | G19: =IF(NOT(ISBLANK(Curs!C23)),IF(AND(NOT(ISBLANK(D19)),NOT(ISBLANK(F19)),D19>=5,F19>=5),ROUND(AVERAGE(D19:F19),0),"n/p"),"")
A20: =IF(NOT(ISBLANK(Curs!B24)),Curs!B24,"") | B20: =IF(NOT(ISBLANK(Curs!C24)),Curs!C24,"") | G20: =IF(NOT(ISBLANK(Curs!C24)),IF(AND(NOT(ISBLANK(D20)),NOT(ISBLANK(F20)),D20>=5,F20>=5),ROUND(AVERAGE(D20:F20),0),"n/p"),"")
A21: =IF(NOT(ISBLANK(Curs!B25)),Curs!B25,"") | B21: =IF(NOT(ISBLANK(Curs!C25)),Curs!C25,"") | G21: =IF(NOT(ISBLANK(Curs!C25)),IF(AND(NOT(ISBLANK(D21)),NOT(ISBLANK(F21)),D21>=5,F21>=5),ROUND(AVERAGE(D21:F21),0),"n/p"),"")
A22: =IF(NOT(ISBLANK(Curs!B26)),Curs!B26,"") | B22: =IF(NOT(ISBLANK(Curs!C26)),Curs!C26,"") | G22: =IF(NOT(ISBLANK(Curs!C26)),IF(AND(NOT(ISBLANK(D22)),NOT(ISBLANK(F22)),D22>=5,F22>=5),ROUND(AVERAGE(D22:F22),0),"n/p"),"")
A23: =IF(NOT(ISBLANK(Curs!B27)),Curs!B27,"") | B23: =IF(NOT(ISBLANK(Curs!C27)),Curs!C27,"") | G23: =IF(NOT(ISBLANK(Curs!C27)),IF(AND(NOT(ISBLANK(D23)),NOT(ISBLANK(F23)),D23>=5,F23>=5),ROUND(AVERAGE(D23:F23),0),"n/p"),"")
A24: =IF(NOT(ISBLANK(Curs!B28)),Curs!B28,"") | B24: =IF(NOT(ISBLANK(Curs!C28)),Curs!C28,"") | G24: =IF(NOT(ISBLANK(Curs!C28)),IF(AND(NOT(ISBLANK(D24)),NOT(ISBLANK(F24)),D24>=5,F24>=5),ROUND(AVERAGE(D24:F24),0),"n/p"),"")
A25: =IF(NOT(ISBLANK(Curs!B29)),Curs!B29,"") | B25: =IF(NOT(ISBLANK(Curs!C29)),Curs!C29,"") | G25: =IF(NOT(ISBLANK(Curs!C29)),IF(AND(NOT(ISBLANK(D25)),NOT(ISBLANK(F25)),D25>=5,F25>=5),ROUND(AVERAGE(D25:F25),0),"n/p"),"")
... A101: =IF(NOT(ISBLANK(Curs!B105)),Curs!B105,"") | B101: =IF(NOT(ISBLANK(Curs!C105)),Curs!C105,"") | G101: =IF(NOT(ISBLANK(Curs!C105)),IF(AND(NOT(ISBLANK(D101)),NOT(ISBLANK(F101)),D101>=5,F101>=5),ROUND(AVERAGE(D101:F101),0),"n/p"),"")
G102: =IF(NOT(ISBLANK(Curs!C106)),IF(AND(NOT(ISBLANK(D102)),NOT(ISBLANK(F102))),ROUND(AVERAGE(D102:F102),0),"n/p"),"")
G103: =IF(NOT(ISBLANK(Curs!C107)),IF(AND(NOT(ISBLANK(D103)),NOT(ISBLANK(F103))),ROUND(AVERAGE(D103:F103),0),"n/p"),"")
G104: =IF(NOT(ISBLANK(Curs!C108)),IF(AND(NOT(ISBLANK(D104)),NOT(ISBLANK(F104))),ROUND(AVERAGE(D104:F104),0),"n/p"),"")

Sheet Examen
A1: Nr. | B1: Nume, Prenume | C1: item 1 6 p | D1: item 2 10 p | E1: item 3 14 p | F1: Pctj Total | G1: Nota | H1: Baremul de evaluare | K1: Statistica
A2: =IF(NOT(ISBLANK(Curs!B6)),Curs!B6,"") -> 1 | B2: =IF(NOT(ISBLANK(Curs!C6)),Curs!C6,"") -> Nume, Prenume | F2: =IF(NOT(ISBLANK(Curs!C6)), IF(Curs!R6,"Eliberat", ROUND(SUM(C2:E2),0)), "") -> 0 | G2: =IF(NOT(ISBLANK(Curs!C6)), IF(Curs!R6,Curs!R6, IF(F2=0,"n/p", IF(AND(F2>=$H$3,F2<=$I$3),$J$3, IF(AND(F2>=$H$4,F2<=$I$4),$J$4, IF(AND(F2>=$H$5,F2<=$I$5),$J$5, IF(AND(F2>=$H$6,F2<=$I$6),$J$6, IF(AND(F2>=$H$7,F2<=$I$7),$J$7, IF(AND(F2>=$H$8,F2<=$I$8),$J$8, IF(AND(F2>=$H$9,F2<=$I$9),$J$9, IF(AND(F2>=$H$10,F2<=$I$10),$J$10, IF(AND(F2>=$H$11,F2<=$I$11),$J$11))))))))))), "") -> n/p | H2: Punctajul acumulat | J2: Nota | K2: Nota | L2: Nr de note
A3: =IF(NOT(ISBLANK(Curs!B7)),Curs!B7,"") | B3: =IF(NOT(ISBLANK(Curs!C7)),Curs!C7,"") | F3: =IF(NOT(ISBLANK(Curs!C7)), IF(Curs!R7,"Eliberat", ROUND(SUM(C3:E3),0)), "") | G3: =IF(NOT(ISBLANK(Curs!C7)), IF(Curs!R7,Curs!R7, IF(F3=0,"n/p", IF(AND(F3>=$H$3,F3<=$I$3),$J$3, IF(AND(F3>=$H$4,F3<=$I$4),$J$4, IF(AND(F3>=$H$5,F3<=$I$5),$J$5, IF(AND(F3>=$H$6,F3<=$I$6),$J$6, IF(AND(F3>=$H$7,F3<=$I$7),$J$7, IF(AND(F3>=$H$8,F3<=$I$8),$J$8, IF(AND(F3>=$H$9,F3<=$I$9),$J$9, IF(AND(F3>=$H$10,F3<=$I$10),$J$10, IF(AND(F3>=$H$11,F3<=$I$11),$J$11))))))))))), "") | H3: 0 | I3: 3 | J3: 2 | K3: 1 | L3: =COUNTIF($G$2:$G101,K3) -> 0
A4: =IF(NOT(ISBLANK(Curs!B8)),Curs!B8,"") | B4: =IF(NOT(ISBLANK(Curs!C8)),Curs!C8,"") | F4: =IF(NOT(ISBLANK(Curs!C8)), IF(Curs!R8,"Eliberat", ROUND(SUM(C4:E4),0)), "") | G4: =IF(NOT(ISBLANK(Curs!C8)), IF(Curs!R8,Curs!R8, IF(F4=0,"n/p", IF(AND(F4>=$H$3,F4<=$I$3),$J$3, IF(AND(F4>=$H$4,F4<=$I$4),$J$4, IF(AND(F4>=$H$5,F4<=$I$5),$J$5, IF(AND(F4>=$H$6,F4<=$I$6),$J$6, IF(AND(F4>=$H$7,F4<=$I$7),$J$7, IF(AND(F4>=$H$8,F4<=$I$8),$J$8, IF(AND(F4>=$H$9,F4<=$I$9),$J$9, IF(AND(F4>=$H$10,F4<=$I$10),$J$10, IF(AND(F4>=$H$11,F4<=$I$11),$J$11))))))))))), "") | H4: 4 | I4: 7 | J4: 3 | K4: 2 | L4: =COUNTIF($G$2:$G102,K4) -> 0
A5: =IF(NOT(ISBLANK(Curs!B9)),Curs!B9,"") | B5: =IF(NOT(ISBLANK(Curs!C9)),Curs!C9,"") | F5: =IF(NOT(ISBLANK(Curs!C9)), IF(Curs!R9,"Eliberat", ROUND(SUM(C5:E5),0)), "") | G5: =IF(NOT(ISBLANK(Curs!C9)), IF(Curs!R9,Curs!R9, IF(F5=0,"n/p", IF(AND(F5>=$H$3,F5<=$I$3),$J$3, IF(AND(F5>=$H$4,F5<=$I$4),$J$4, IF(AND(F5>=$H$5,F5<=$I$5),$J$5, IF(AND(F5>=$H$6,F5<=$I$6),$J$6, IF(AND(F5>=$H$7,F5<=$I$7),$J$7, IF(AND(F5>=$H$8,F5<=$I$8),$J$8, IF(AND(F5>=$H$9,F5<=$I$9),$J$9, IF(AND(F5>=$H$10,F5<=$I$10),$J$10, IF(AND(F5>=$H$11,F5<=$I$11),$J$11))))))))))), "") | H5: 8 | I5: 12 | J5: 4 | K5: 3 | L5: =COUNTIF($G$2:$G103,K5) -> 0
A6: =IF(NOT(ISBLANK(Curs!B10)),Curs!B10,"") | B6: =IF(NOT(ISBLANK(Curs!C10)),Curs!C10,"") | F6: =IF(NOT(ISBLANK(Curs!C10)), IF(Curs!R10,"Eliberat", ROUND(SUM(C6:E6),0)), "") | G6: =IF(NOT(ISBLANK(Curs!C10)), IF(Curs!R10,Curs!R10, IF(F6=0,"n/p", IF(AND(F6>=$H$3,F6<=$I$3),$J$3, IF(AND(F6>=$H$4,F6<=$I$4),$J$4, IF(AND(F6>=$H$5,F6<=$I$5),$J$5, IF(AND(F6>=$H$6,F6<=$I$6),$J$6, IF(AND(F6>=$H$7,F6<=$I$7),$J$7, IF(AND(F6>=$H$8,F6<=$I$8),$J$8, IF(AND(F6>=$H$9,F6<=$I$9),$J$9, IF(AND(F6>=$H$10,F6<=$I$10),$J$10, IF(AND(F6>=$H$11,F6<=$I$11),$J$11))))))))))), "") | H6: 13 | I6: 15 | J6: 5 | K6: 4 | L6: =COUNTIF($G$2:$G104,K6) -> 0
A7: =IF(NOT(ISBLANK(Curs!B11)),Curs!B11,"") | B7: =IF(NOT(ISBLANK(Curs!C11)),Curs!C11,"") | F7: =IF(NOT(ISBLANK(Curs!C11)), IF(Curs!R11,"Eliberat", ROUND(SUM(C7:E7),0)), "") | G7: =IF(NOT(ISBLANK(Curs!C11)), IF(Curs!R11,Curs!R11, IF(F7=0,"n/p", IF(AND(F7>=$H$3,F7<=$I$3),$J$3, IF(AND(F7>=$H$4,F7<=$I$4),$J$4, IF(AND(F7>=$H$5,F7<=$I$5),$J$5, IF(AND(F7>=$H$6,F7<=$I$6),$J$6, IF(AND(F7>=$H$7,F7<=$I$7),$J$7, IF(AND(F7>=$H$8,F7<=$I$8),$J$8, IF(AND(F7>=$H$9,F7<=$I$9),$J$9, IF(AND(F7>=$H$10,F7<=$I$10),$J$10, IF(AND(F7>=$H$11,F7<=$I$11),$J$11))))))))))), "") | H7: 16 | I7: 18 | J7: 6 | K7: 5 | L7: =COUNTIF($G$2:$G105,K7) -> 0
A8: =IF(NOT(ISBLANK(Curs!B12)),Curs!B12,"") | B8: =IF(NOT(ISBLANK(Curs!C12)),Curs!C12,"") | F8: =IF(NOT(ISBLANK(Curs!C12)), IF(Curs!R12,"Eliberat", ROUND(SUM(C8:E8),0)), "") | G8: =IF(NOT(ISBLANK(Curs!C12)), IF(Curs!R12,Curs!R12, IF(F8=0,"n/p", IF(AND(F8>=$H$3,F8<=$I$3),$J$3, IF(AND(F8>=$H$4,F8<=$I$4),$J$4, IF(AND(F8>=$H$5,F8<=$I$5),$J$5, IF(AND(F8>=$H$6,F8<=$I$6),$J$6, IF(AND(F8>=$H$7,F8<=$I$7),$J$7, IF(AND(F8>=$H$8,F8<=$I$8),$J$8, IF(AND(F8>=$H$9,F8<=$I$9),$J$9, IF(AND(F8>=$H$10,F8<=$I$10),$J$10, IF(AND(F8>=$H$11,F8<=$I$11),$J$11))))))))))), "") | H8: 19 | I8: 21 | J8: 7 | K8: 6 | L8: =COUNTIF($G$2:$G106,K8) -> 0
A9: =IF(NOT(ISBLANK(Curs!B13)),Curs!B13,"") | B9: =IF(NOT(ISBLANK(Curs!C13)),Curs!C13,"") | F9: =IF(NOT(ISBLANK(Curs!C13)), IF(Curs!R13,"Eliberat", ROUND(SUM(C9:E9),0)), "") | G9: =IF(NOT(ISBLANK(Curs!C13)), IF(Curs!R13,Curs!R13, IF(F9=0,"n/p", IF(AND(F9>=$H$3,F9<=$I$3),$J$3, IF(AND(F9>=$H$4,F9<=$I$4),$J$4, IF(AND(F9>=$H$5,F9<=$I$5),$J$5, IF(AND(F9>=$H$6,F9<=$I$6),$J$6, IF(AND(F9>=$H$7,F9<=$I$7),$J$7, IF(AND(F9>=$H$8,F9<=$I$8),$J$8, IF(AND(F9>=$H$9,F9<=$I$9),$J$9, IF(AND(F9>=$H$10,F9<=$I$10),$J$10, IF(AND(F9>=$H$11,F9<=$I$11),$J$11))))))))))), "") | H9: 22 | I9: 24 | J9: 8 | K9: 7 | L9: =COUNTIF($G$2:$G107,K9) -> 0
A10: =IF(NOT(ISBLANK(Curs!B14)),Curs!B14,"") | B10: =IF(NOT(ISBLANK(Curs!C14)),Curs!C14,"") | F10: =IF(NOT(ISBLANK(Curs!C14)), IF(Curs!R14,"Eliberat", ROUND(SUM(C10:E10),0)), "") | G10: =IF(NOT(ISBLANK(Curs!C14)), IF(Curs!R14,Curs!R14, IF(F10=0,"n/p", IF(AND(F10>=$H$3,F10<=$I$3),$J$3, IF(AND(F10>=$H$4,F10<=$I$4),$J$4, IF(AND(F10>=$H$5,F10<=$I$5),$J$5, IF(AND(F10>=$H$6,F10<=$I$6),$J$6, IF(AND(F10>=$H$7,F10<=$I$7),$J$7, IF(AND(F10>=$H$8,F10<=$I$8),$J$8, IF(AND(F10>=$H$9,F10<=$I$9),$J$9, IF(AND(F10>=$H$10,F10<=$I$10),$J$10, IF(AND(F10>=$H$11,F10<=$I$11),$J$11))))))))))), "") | H10: 25 | I10: 27 | J10: 9 | K10: 8 | L10: =COUNTIF($G$2:$G108,K10) -> 0
A11: =IF(NOT(ISBLANK(Curs!B15)),Curs!B15,"") | B11: =IF(NOT(ISBLANK(Curs!C15)),Curs!C15,"") | F11: =IF(NOT(ISBLANK(Curs!C15)), IF(Curs!R15,"Eliberat", ROUND(SUM(C11:E11),0)), "") | G11: =IF(NOT(ISBLANK(Curs!C15)), IF(Curs!R15,Curs!R15, IF(F11=0,"n/p", IF(AND(F11>=$H$3,F11<=$I$3),$J$3, IF(AND(F11>=$H$4,F11<=$I$4),$J$4, IF(AND(F11>=$H$5,F11<=$I$5),$J$5, IF(AND(F11>=$H$6,F11<=$I$6),$J$6, IF(AND(F11>=$H$7,F11<=$I$7),$J$7, IF(AND(F11>=$H$8,F11<=$I$8),$J$8, IF(AND(F11>=$H$9,F11<=$I$9),$J$9, IF(AND(F11>=$H$10,F11<=$I$10),$J$10, IF(AND(F11>=$H$11,F11<=$I$11),$J$11))))))))))), "") | H11: 28 | I11: 30 | J11: 10 | K11: 9 | L11: =COUNTIF($G$2:$G109,K11) -> 0
A12: =IF(NOT(ISBLANK(Curs!B16)),Curs!B16,"") | B12: =IF(NOT(ISBLANK(Curs!C16)),Curs!C16,"") | F12: =IF(NOT(ISBLANK(Curs!C16)), IF(Curs!R16,"Eliberat", ROUND(SUM(C12:E12),0)), "") | G12: =IF(NOT(ISBLANK(Curs!C16)), IF(Curs!R16,Curs!R16, IF(F12=0,"n/p", IF(AND(F12>=$H$3,F12<=$I$3),$J$3, IF(AND(F12>=$H$4,F12<=$I$4),$J$4, IF(AND(F12>=$H$5,F12<=$I$5),$J$5, IF(AND(F12>=$H$6,F12<=$I$6),$J$6, IF(AND(F12>=$H$7,F12<=$I$7),$J$7, IF(AND(F12>=$H$8,F12<=$I$8),$J$8, IF(AND(F12>=$H$9,F12<=$I$9),$J$9, IF(AND(F12>=$H$10,F12<=$I$10),$J$10, IF(AND(F12>=$H$11,F12<=$I$11),$J$11))))))))))), "") | K12: 10 | L12: =COUNTIF($G$2:$G110,K12) -> 0
A13: =IF(NOT(ISBLANK(Curs!B17)),Curs!B17,"") | B13: =IF(NOT(ISBLANK(Curs!C17)),Curs!C17,"") | F13: =IF(NOT(ISBLANK(Curs!C17)), IF(Curs!R17,"Eliberat", ROUND(SUM(C13:E13),0)), "") | G13: =IF(NOT(ISBLANK(Curs!C17)), IF(Curs!R17,Curs!R17, IF(F13=0,"n/p", IF(AND(F13>=$H$3,F13<=$I$3),$J$3, IF(AND(F13>=$H$4,F13<=$I$4),$J$4, IF(AND(F13>=$H$5,F13<=$I$5),$J$5, IF(AND(F13>=$H$6,F13<=$I$6),$J$6, IF(AND(F13>=$H$7,F13<=$I$7),$J$7, IF(AND(F13>=$H$8,F13<=$I$8),$J$8, IF(AND(F13>=$H$9,F13<=$I$9),$J$9, IF(AND(F13>=$H$10,F13<=$I$10),$J$10, IF(AND(F13>=$H$11,F13<=$I$11),$J$11))))))))))), "") | K13: n/p | L13: =COUNTIF($G$2:$G111,K13) -> 1
A14: =IF(NOT(ISBLANK(Curs!B18)),Curs!B18,"") | B14: =IF(NOT(ISBLANK(Curs!C18)),Curs!C18,"") | F14: =IF(NOT(ISBLANK(Curs!C18)), IF(Curs!R18,"Eliberat", ROUND(SUM(C14:E14),0)), "") | G14: =IF(NOT(ISBLANK(Curs!C18)), IF(Curs!R18,Curs!R18, IF(F14=0,"n/p", IF(AND(F14>=$H$3,F14<=$I$3),$J$3, IF(AND(F14>=$H$4,F14<=$I$4),$J$4, IF(AND(F14>=$H$5,F14<=$I$5),$J$5, IF(AND(F14>=$H$6,F14<=$I$6),$J$6, IF(AND(F14>=$H$7,F14<=$I$7),$J$7, IF(AND(F14>=$H$8,F14<=$I$8),$J$8, IF(AND(F14>=$H$9,F14<=$I$9),$J$9, IF(AND(F14>=$H$10,F14<=$I$10),$J$10, IF(AND(F14>=$H$11,F14<=$I$11),$J$11))))))))))), "")
A15: =IF(NOT(ISBLANK(Curs!B19)),Curs!B19,"") | B15: =IF(NOT(ISBLANK(Curs!C19)),Curs!C19,"") | F15: =IF(NOT(ISBLANK(Curs!C19)), IF(Curs!R19,"Eliberat", ROUND(SUM(C15:E15),0)), "") | G15: =IF(NOT(ISBLANK(Curs!C19)), IF(Curs!R19,Curs!R19, IF(F15=0,"n/p", IF(AND(F15>=$H$3,F15<=$I$3),$J$3, IF(AND(F15>=$H$4,F15<=$I$4),$J$4, IF(AND(F15>=$H$5,F15<=$I$5),$J$5, IF(AND(F15>=$H$6,F15<=$I$6),$J$6, IF(AND(F15>=$H$7,F15<=$I$7),$J$7, IF(AND(F15>=$H$8,F15<=$I$8),$J$8, IF(AND(F15>=$H$9,F15<=$I$9),$J$9, IF(AND(F15>=$H$10,F15<=$I$10),$J$10, IF(AND(F15>=$H$11,F15<=$I$11),$J$11))))))))))), "")
A16: =IF(NOT(ISBLANK(Curs!B20)),Curs!B20,"") | B16: =IF(NOT(ISBLANK(Curs!C20)),Curs!C20,"") | F16: =IF(NOT(ISBLANK(Curs!C20)), IF(Curs!R20,"Eliberat", ROUND(SUM(C16:E16),0)), "") | G16: =IF(NOT(ISBLANK(Curs!C20)), IF(Curs!R20,Curs!R20, IF(F16=0,"n/p", IF(AND(F16>=$H$3,F16<=$I$3),$J$3, IF(AND(F16>=$H$4,F16<=$I$4),$J$4, IF(AND(F16>=$H$5,F16<=$I$5),$J$5, IF(AND(F16>=$H$6,F16<=$I$6),$J$6, IF(AND(F16>=$H$7,F16<=$I$7),$J$7, IF(AND(F16>=$H$8,F16<=$I$8),$J$8, IF(AND(F16>=$H$9,F16<=$I$9),$J$9, IF(AND(F16>=$H$10,F16<=$I$10),$J$10, IF(AND(F16>=$H$11,F16<=$I$11),$J$11))))))))))), "")
A17: =IF(NOT(ISBLANK(Curs!B21)),Curs!B21,"") | B17: =IF(NOT(ISBLANK(Curs!C21)),Curs!C21,"") | F17: =IF(NOT(ISBLANK(Curs!C21)), IF(Curs!R21,"Eliberat", ROUND(SUM(C17:E17),0)), "") | G17: =IF(NOT(ISBLANK(Curs!C21)), IF(Curs!R21,Curs!R21, IF(F17=0,"n/p", IF(AND(F17>=$H$3,F17<=$I$3),$J$3, IF(AND(F17>=$H$4,F17<=$I$4),$J$4, IF(AND(F17>=$H$5,F17<=$I$5),$J$5, IF(AND(F17>=$H$6,F17<=$I$6),$J$6, IF(AND(F17>=$H$7,F17<=$I$7),$J$7, IF(AND(F17>=$H$8,F17<=$I$8),$J$8, IF(AND(F17>=$H$9,F17<=$I$9),$J$9, IF(AND(F17>=$H$10,F17<=$I$10),$J$10, IF(AND(F17>=$H$11,F17<=$I$11),$J$11))))))))))), "")
A18: =IF(NOT(ISBLANK(Curs!B22)),Curs!B22,"") | B18: =IF(NOT(ISBLANK(Curs!C22)),Curs!C22,"") | F18: =IF(NOT(ISBLANK(Curs!C22)), IF(Curs!R22,"Eliberat", ROUND(SUM(C18:E18),0)), "") | G18: =IF(NOT(ISBLANK(Curs!C22)), IF(Curs!R22,Curs!R22, IF(F18=0,"n/p", IF(AND(F18>=$H$3,F18<=$I$3),$J$3, IF(AND(F18>=$H$4,F18<=$I$4),$J$4, IF(AND(F18>=$H$5,F18<=$I$5),$J$5, IF(AND(F18>=$H$6,F18<=$I$6),$J$6, IF(AND(F18>=$H$7,F18<=$I$7),$J$7, IF(AND(F18>=$H$8,F18<=$I$8),$J$8, IF(AND(F18>=$H$9,F18<=$I$9),$J$9, IF(AND(F18>=$H$10,F18<=$I$10),$J$10, IF(AND(F18>=$H$11,F18<=$I$11),$J$11))))))))))), "")
A19: =IF(NOT(ISBLANK(Curs!B23)),Curs!B23,"") | B19: =IF(NOT(ISBLANK(Curs!C23)),Curs!C23,"") | F19: =IF(NOT(ISBLANK(Curs!C23)), IF(Curs!R23,"Eliberat", ROUND(SUM(C19:E19),0)), "") | G19: =IF(NOT(ISBLANK(Curs!C23)), IF(Curs!R23,Curs!R23, IF(F19=0,"n/p", IF(AND(F19>=$H$3,F19<=$I$3),$J$3, IF(AND(F19>=$H$4,F19<=$I$4),$J$4, IF(AND(F19>=$H$5,F19<=$I$5),$J$5, IF(AND(F19>=$H$6,F19<=$I$6),$J$6, IF(AND(F19>=$H$7,F19<=$I$7),$J$7, IF(AND(F19>=$H$8,F19<=$I$8),$J$8, IF(AND(F19>=$H$9,F19<=$I$9),$J$9, IF(AND(F19>=$H$10,F19<=$I$10),$J$10, IF(AND(F19>=$H$11,F19<=$I$11),$J$11))))))))))), "")
A20: =IF(NOT(ISBLANK(Curs!B24)),Curs!B24,"") | B20: =IF(NOT(ISBLANK(Curs!C24)),Curs!C24,"") | F20: =IF(NOT(ISBLANK(Curs!C24)), IF(Curs!R24,"Eliberat", ROUND(SUM(C20:E20),0)), "") | G20: =IF(NOT(ISBLANK(Curs!C24)), IF(Curs!R24,Curs!R24, IF(F20=0,"n/p", IF(AND(F20>=$H$3,F20<=$I$3),$J$3, IF(AND(F20>=$H$4,F20<=$I$4),$J$4, IF(AND(F20>=$H$5,F20<=$I$5),$J$5, IF(AND(F20>=$H$6,F20<=$I$6),$J$6, IF(AND(F20>=$H$7,F20<=$I$7),$J$7, IF(AND(F20>=$H$8,F20<=$I$8),$J$8, IF(AND(F20>=$H$9,F20<=$I$9),$J$9, IF(AND(F20>=$H$10,F20<=$I$10),$J$10, IF(AND(F20>=$H$11,F20<=$I$11),$J$11))))))))))), "")
A21: =IF(NOT(ISBLANK(Curs!B25)),Curs!B25,"") | B21: =IF(NOT(ISBLANK(Curs!C25)),Curs!C25,"") | F21: =IF(NOT(ISBLANK(Curs!C25)), IF(Curs!R25,"Eliberat", ROUND(SUM(C21:E21),0)), "") | G21: =IF(NOT(ISBLANK(Curs!C25)), IF(Curs!R25,Curs!R25, IF(F21=0,"n/p", IF(AND(F21>=$H$3,F21<=$I$3),$J$3, IF(AND(F21>=$H$4,F21<=$I$4),$J$4, IF(AND(F21>=$H$5,F21<=$I$5),$J$5, IF(AND(F21>=$H$6,F21<=$I$6),$J$6, IF(AND(F21>=$H$7,F21<=$I$7),$J$7, IF(AND(F21>=$H$8,F21<=$I$8),$J$8, IF(AND(F21>=$H$9,F21<=$I$9),$J$9, IF(AND(F21>=$H$10,F21<=$I$10),$J$10, IF(AND(F21>=$H$11,F21<=$I$11),$J$11))))))))))), "")
A22: =IF(NOT(ISBLANK(Curs!B26)),Curs!B26,"") | B22: =IF(NOT(ISBLANK(Curs!C26)),Curs!C26,"") | F22: =IF(NOT(ISBLANK(Curs!C26)), IF(Curs!R26,"Eliberat", ROUND(SUM(C22:E22),0)), "") | G22: =IF(NOT(ISBLANK(Curs!C26)), IF(Curs!R26,Curs!R26, IF(F22=0,"n/p", IF(AND(F22>=$H$3,F22<=$I$3),$J$3, IF(AND(F22>=$H$4,F22<=$I$4),$J$4, IF(AND(F22>=$H$5,F22<=$I$5),$J$5, IF(AND(F22>=$H$6,F22<=$I$6),$J$6, IF(AND(F22>=$H$7,F22<=$I$7),$J$7, IF(AND(F22>=$H$8,F22<=$I$8),$J$8, IF(AND(F22>=$H$9,F22<=$I$9),$J$9, IF(AND(F22>=$H$10,F22<=$I$10),$J$10, IF(AND(F22>=$H$11,F22<=$I$11),$J$11))))))))))), "")
A23: =IF(NOT(ISBLANK(Curs!B27)),Curs!B27,"") | B23: =IF(NOT(ISBLANK(Curs!C27)),Curs!C27,"") | F23: =IF(NOT(ISBLANK(Curs!C27)), IF(Curs!R27,"Eliberat", ROUND(SUM(C23:E23),0)), "") | G23: =IF(NOT(ISBLANK(Curs!C27)), IF(Curs!R27,Curs!R27, IF(F23=0,"n/p", IF(AND(F23>=$H$3,F23<=$I$3),$J$3, IF(AND(F23>=$H$4,F23<=$I$4),$J$4, IF(AND(F23>=$H$5,F23<=$I$5),$J$5, IF(AND(F23>=$H$6,F23<=$I$6),$J$6, IF(AND(F23>=$H$7,F23<=$I$7),$J$7, IF(AND(F23>=$H$8,F23<=$I$8),$J$8, IF(AND(F23>=$H$9,F23<=$I$9),$J$9, IF(AND(F23>=$H$10,F23<=$I$10),$J$10, IF(AND(F23>=$H$11,F23<=$I$11),$J$11))))))))))), "")
A24: =IF(NOT(ISBLANK(Curs!B28)),Curs!B28,"") | B24: =IF(NOT(ISBLANK(Curs!C28)),Curs!C28,"") | F24: =IF(NOT(ISBLANK(Curs!C28)), IF(Curs!R28,"Eliberat", ROUND(SUM(C24:E24),0)), "") | G24: =IF(NOT(ISBLANK(Curs!C28)), IF(Curs!R28,Curs!R28, IF(F24=0,"n/p", IF(AND(F24>=$H$3,F24<=$I$3),$J$3, IF(AND(F24>=$H$4,F24<=$I$4),$J$4, IF(AND(F24>=$H$5,F24<=$I$5),$J$5, IF(AND(F24>=$H$6,F24<=$I$6),$J$6, IF(AND(F24>=$H$7,F24<=$I$7),$J$7, IF(AND(F24>=$H$8,F24<=$I$8),$J$8, IF(AND(F24>=$H$9,F24<=$I$9),$J$9, IF(AND(F24>=$H$10,F24<=$I$10),$J$10, IF(AND(F24>=$H$11,F24<=$I$11),$J$11))))))))))), "")
A25: =IF(NOT(ISBLANK(Curs!B29)),Curs!B29,"") | B25: =IF(NOT(ISBLANK(Curs!C29)),Curs!C29,"") | F25: =IF(NOT(ISBLANK(Curs!C29)), IF(Curs!R29,"Eliberat", ROUND(SUM(C25:E25),0)), "") | G25: =IF(NOT(ISBLANK(Curs!C29)), IF(Curs!R29,Curs!R29, IF(F25=0,"n/p", IF(AND(F25>=$H$3,F25<=$I$3),$J$3, IF(AND(F25>=$H$4,F25<=$I$4),$J$4, IF(AND(F25>=$H$5,F25<=$I$5),$J$5, IF(AND(F25>=$H$6,F25<=$I$6),$J$6, IF(AND(F25>=$H$7,F25<=$I$7),$J$7, IF(AND(F25>=$H$8,F25<=$I$8),$J$8, IF(AND(F25>=$H$9,F25<=$I$9),$J$9, IF(AND(F25>=$H$10,F25<=$I$10),$J$10, IF(AND(F25>=$H$11,F25<=$I$11),$J$11))))))))))), "")
... A101: =IF(NOT(ISBLANK(Curs!B105)),Curs!B105,"") | B101: =IF(NOT(ISBLANK(Curs!C105)),Curs!C105,"") | F101: =IF(NOT(ISBLANK(Curs!C105)), IF(Curs!R105,"Eliberat", ROUND(SUM(C101:E101),0)), "") | G101: =IF(NOT(ISBLANK(Curs!C105)), IF(Curs!R105,Curs!R105, IF(F101=0,"n/p", IF(AND(F101>=$H$3,F101<=$I$3),$J$3, IF(AND(F101>=$H$4,F101<=$I$4),$J$4, IF(AND(F101>=$H$5,F101<=$I$5),$J$5, IF(AND(F101>=$H$6,F101<=$I$6),$J$6, IF(AND(F101>=$H$7,F101<=$I$7),$J$7, IF(AND(F101>=$H$8,F101<=$I$8),$J$8, IF(AND(F101>=$H$9,F101<=$I$9),$J$9, IF(AND(F101>=$H$10,F101<=$I$10),$J$10, IF(AND(F101>=$H$11,F101<=$I$11),$J$11))))))))))), "")

Sheet Registru
AJ1: Evidenţa îndeplinirii planului de învăţământ
AI2: Denumirea disciplinei __Mecanica Teoretică____
B3: Evidenţa frecvenţei, reuşitei curente, evaluării curente a studenţilor | AI3: Forma de studii ___prelegeri, lucrări de laborator____ (prelegeri, lucrări practice / seminarii, lucrări de laborator)
C4: =Curs!E3 -> Curs | K4: Laborator | AI4: Cadrul didactic:
A5: Nr. crt. | B5: Numele, prenumele | C5: =IF(Curs!E5<>"",Curs!E5,"") -> 30.01 | D5: =IF(Curs!F5<>"",Curs!F5,"") -> 6.02 | E5: =IF(Curs!G5<>"",Curs!G5,"") -> 13.02 | F5: =IF(Curs!H5<>"",Curs!H5,"") -> 20.02 | G5: =IF(Curs!I5<>"",Curs!I5,"") -> 27.02 | H5: =IF(Curs!J5<>"",Curs!J5,"") -> 6.03 | K5: =Laborator!E6 -> 28.01 | L5: =Laborator!F6 -> 11.02/ 18.02 | M5: =Laborator!G6 -> 25.02/ 4.03 | N5: =Laborator!H6 -> 11.03/ 18.03 | O5: =Laborator!I6 -> 25.03/ 1.04 | P5: =Laborator!J6 -> 8.04/ 15.04 | AE5: Evaluare curentă | AI5: Data | AJ5: Temele de studii | AK5: Nr. de ore | AL5: Semnătura cadrului didactic
AE6: nr.1 | AF6: nr.2 | AG6: Proiect / teză de an
A7: =Curs!B6 -> 1 | B7: =IF(NOT(ISBLANK(Curs!C6)),Curs!C6,"") -> Nume, Prenume | C7: =IF(Curs!E6<>"a","",Curs!E6) | D7: =IF(Curs!F6<>"a","",Curs!F6) | E7: =IF(Curs!G6<>"a","",Curs!G6) | F7: =IF(Curs!H6<>"a","",Curs!H6) | G7: =IF(Curs!I6<>"a","",Curs!I6) | H7: =IF(Curs!J6<>"a","",Curs!J6) | K7: =IF(Laborator!E7<>"a","",Curs!#REF!) | L7: =IF(Laborator!F7<>"a","",Curs!#REF!) | M7: =IF(Laborator!G7<>"a","",Curs!#REF!) | N7: =IF(Laborator!H7<>"a","",Curs!#REF!) | O7: =IF(Laborator!I7<>"a","",Curs!#REF!) | P7: =IF(Laborator!J7<>"a","",Curs!#REF!) | AI7: =C5 -> 30.01 | AJ7: Tema 1. | AK7: 2
A8: =Curs!B7 | B8: =IF(NOT(ISBLANK(Curs!C7)),Curs!C7,"") | C8: =IF(Curs!E7<>"a","",Curs!E7) | D8: =IF(Curs!F7<>"a","",Curs!F7) | E8: =IF(Curs!G7<>"a","",Curs!G7) | F8: =IF(Curs!H7<>"a","",Curs!H7) | G8: =IF(Curs!I7<>"a","",Curs!I7) | H8: =IF(Curs!J7<>"a","",Curs!J7) | K8: =IF(Laborator!E8<>"a","",Curs!#REF!) | L8: =IF(Laborator!F8<>"a","",Curs!#REF!) | M8: =IF(Laborator!G8<>"a","",Curs!#REF!) | N8: =IF(Laborator!H8<>"a","",Curs!#REF!) | O8: =IF(Laborator!I8<>"a","",Curs!#REF!) | P8: =IF(Laborator!J8<>"a","",Curs!#REF!) | AI8: =D5 -> 6.02 | AJ8: Tema 2.
A9: =Curs!B8 | B9: =IF(NOT(ISBLANK(Curs!C8)),Curs!C8,"") | C9: =IF(Curs!E8<>"a","",Curs!E8) | D9: =IF(Curs!F8<>"a","",Curs!F8) | E9: =IF(Curs!G8<>"a","",Curs!G8) | F9: =IF(Curs!H8<>"a","",Curs!H8) | G9: =IF(Curs!I8<>"a","",Curs!I8) | H9: =IF(Curs!J8<>"a","",Curs!J8) | K9: =IF(Laborator!E9<>"a","",Curs!#REF!) | L9: =IF(Laborator!F9<>"a","",Curs!#REF!) | M9: =IF(Laborator!G9<>"a","",Curs!#REF!) | N9: =IF(Laborator!H9<>"a","",Curs!#REF!) | O9: =IF(Laborator!I9<>"a","",Curs!#REF!) | P9: =IF(Laborator!J9<>"a","",Curs!#REF!) | AI9: =E5 -> 13.02 | AJ9: Tema 3.
A10: =Curs!B9 | B10: =IF(NOT(ISBLANK(Curs!C9)),Curs!C9,"") | C10: =IF(Curs!E9<>"a","",Curs!E9) | D10: =IF(Curs!F9<>"a","",Curs!F9) | E10: =IF(Curs!G9<>"a","",Curs!G9) | F10: =IF(Curs!H9<>"a","",Curs!H9) | G10: =IF(Curs!I9<>"a","",Curs!I9) | H10: =IF(Curs!J9<>"a","",Curs!J9) | K10: =IF(Laborator!E10<>"a","",Curs!#REF!) | L10: =IF(Laborator!F10<>"a","",Curs!#REF!) | M10: =IF(Laborator!G10<>"a","",Curs!#REF!) | N10: =IF(Laborator!H10<>"a","",Curs!#REF!) | O10: =IF(Laborator!I10<>"a","",Curs!#REF!) | P10: =IF(Laborator!J10<>"a","",Curs!#REF!) | AI10: =F5 -> 20.02 | AJ10: Tema 4.
A11: =Curs!B10 | B11: =IF(NOT(ISBLANK(Curs!C10)),Curs!C10,"") | C11: =IF(Curs!E10<>"a","",Curs!E10) | D11: =IF(Curs!F10<>"a","",Curs!F10) | E11: =IF(Curs!G10<>"a","",Curs!G10) | F11: =IF(Curs!H10<>"a","",Curs!H10) | G11: =IF(Curs!I10<>"a","",Curs!I10) | H11: =IF(Curs!J10<>"a","",Curs!J10) | K11: =IF(Laborator!E11<>"a","",Curs!#REF!) | L11: =IF(Laborator!F11<>"a","",Curs!#REF!) | M11: =IF(Laborator!G11<>"a","",Curs!#REF!) | N11: =IF(Laborator!H11<>"a","",Curs!#REF!) | O11: =IF(Laborator!I11<>"a","",Curs!#REF!) | P11: =IF(Laborator!J11<>"a","",Curs!#REF!) | AI11: =G5 -> 27.02 | AJ11: Tema 5.
A12: =Curs!B11 | B12: =IF(NOT(ISBLANK(Curs!C11)),Curs!C11,"") | C12: =IF(Curs!E11<>"a","",Curs!E11) | D12: =IF(Curs!F11<>"a","",Curs!F11) | E12: =IF(Curs!G11<>"a","",Curs!G11) | F12: =IF(Curs!H11<>"a","",Curs!H11) | G12: =IF(Curs!I11<>"a","",Curs!I11) | H12: =IF(Curs!J11<>"a","",Curs!J11) | K12: =IF(Laborator!E12<>"a","",Curs!#REF!) | L12: =IF(Laborator!F12<>"a","",Curs!#REF!) | M12: =IF(Laborator!G12<>"a","",Curs!#REF!) | N12: =IF(Laborator!H12<>"a","",Curs!#REF!) | O12: =IF(Laborator!I12<>"a","",Curs!#REF!) | P12: =IF(Laborator!J12<>"a","",Curs!#REF!) | AI12: =H5 -> 6.03 | AJ12: Tema 6.
A13: =Curs!B12 | B13: =IF(NOT(ISBLANK(Curs!C12)),Curs!C12,"") | C13: =IF(Curs!E12<>"a","",Curs!E12) | D13: =IF(Curs!F12<>"a","",Curs!F12) | E13: =IF(Curs!G12<>"a","",Curs!G12) | F13: =IF(Curs!H12<>"a","",Curs!H12) | G13: =IF(Curs!I12<>"a","",Curs!I12) | H13: =IF(Curs!J12<>"a","",Curs!J12) | K13: =IF(Laborator!E13<>"a","",Curs!#REF!) | L13: =IF(Laborator!F13<>"a","",Curs!#REF!) | M13: =IF(Laborator!G13<>"a","",Curs!#REF!) | N13: =IF(Laborator!H13<>"a","",Curs!#REF!) | O13: =IF(Laborator!I13<>"a","",Curs!#REF!) | P13: =IF(Laborator!J13<>"a","",Curs!#REF!) | AJ13: Total Plan | AK13: 12
