Workbook

Sheet Curs, Seminar
C2: Mecanica Teoretică. Anul de studii: Titular: Grupa: Șeful grupei: Nume, Prenume, telefon | AM2: Rezultate atestări și sesiune | AY2: Nota semestrială | BD2: Ev.finală (0.4) | BE2: Nota finală | BI2: Examen:
E3: Curs | U3: Seminar | AM3: Atestarea Nr.1 | AP3: Atestarea Nr.2 | AS3: Sesiunea | AY3: Componente | BC3: Media trunchiată (0.6) | BE3: în sist.național, trunchiată | BG3: Conform ECTS | BI3: Borderou | BJ3: Prezenti | BK3: Admisi | BL3: Eliberati | BN3: A | BO3: B | BP3: C | BQ3: D | BR3: E | BS3: FX | BT3: F | BU3: n/p | BV3: n/a | BX3: Reușita din nr. total, % | BY3: Reușita din nr. prez., %
E4: C1 | F4: C2 | G4: C3 | H4: C4 | I4: C5 | J4: C6 | K4: C7 | L4: C8 | M4: C9 | N4: C10 | O4: C11 | P4: C12 | Q4: C13 | R4: C14 | S4: C15 | T4: Ore absențe Curs | U4: S1 | V4: S2 | W4: S3 | X4: S4 | Y4: S5 | Z4: S6 | AA4: S7 | AB4: S8 | AC4: S9 | AD4: S10 | AE4: S11 | AF4: S12 | AG4: S13 | AH4: S14 | AI4: S15 | AJ4: Ore absențe Sem | AK4: Ore absențe total | AM4: Atest.1.1 | AN4: Atest.1.2 | AO4: Atest.1.3 | AP4: Atest.2.1 | AQ4: Atest.2.2 | AR4: Atest.2.3 | AS4: Examen | AT4: Reexam | AU4: Puncte activ. suplim | AV4: Puncte utilizate | AW4: Exam | AY4: Ev.periodică | BA4: Evaluarea curentă | BB4: Lucrul individual
B5: Nr. | C5: Nume, Prenume | D5: e-mail | E5: 4.09 | F5: 4.09 | G5: 11.09 | H5: 11.09 | S5: fin curs | U5: 6.09 | V5: 7.09 | AI5: fin sem | AK5: Frecventa | AW5: Prezenta | AX5: Eliberati | AY5: nr.1 | AZ5: nr.2 | BI5: =COUNTA(C6:C105) -> 1 | BJ5: =BI5-COUNTIF(AW6:AW105,"a") -> 1 | BK5: =BI5-COUNTIF(BD6:BD105,"n/a") -> 0 | BL5: =COUNTA(AX6:AX105) -> 0 | BN5: =COUNTIF($BG$6:$BG$105,BN3) -> 0 | BO5: =COUNTIF($BG$6:$BG$105,BO3) -> 0 | BP5: =COUNTIF($BG$6:$BG$105,BP3) -> 0 | BQ5: =COUNTIF($BG$6:$BG$105,BQ3) -> 0 | BR5: =COUNTIF($BG$6:$BG$105,BR3) -> 0 | BS5: =COUNTIF($BG$6:$BG$105,BS3) -> 0 | BT5: =COUNTIF($BG$6:$BG$105,BT3) -> 0 | BU5: =COUNTIF($BD$6:$BD$105,BU3) -> 0 | BV5: =COUNTIF($BD$6:$BD$105,BV3) -> 1 | BX5: =SUM(BN5:BR5)/BI5 -> 0 | BY5: =SUM(BN5:BR5)/BJ5 -> 0
B6: =IF(NOT(ISBLANK(C6)),COUNTA($C$6:C6),"") -> 1 | C6: Nume, Prenume | T6: =IF(NOT(ISBLANK(C6)),IF(COUNTIF(E6:S6,"a")<>0,COUNTIF(E6:S6,"a")*2,""),"") | AJ6: =IF(NOT(ISBLANK(B6)),IF(COUNTIF(U6:AI6,"a")<>0,COUNTIF(U6:AI6,"a")*2,""),"") | AK6: =IF(NOT(ISBLANK(C6)),IF(COUNTIF(E6:AI6,"a")<>0,COUNTIF(E6:AI6,"a")*2,""),"") | AM6: ='Atest. Nr.1_1'!I2 -> n/p | AN6: ='Atest. Nr.1_2'!I2 -> n/p | AO6: ='Atest. Nr.1_3'!I2 -> n/p | AP6: ='Atest. Nr.2_1'!I2 -> n/p | AQ6: ='Atest. Nr.2_2'!I2 -> n/p | AR6: ='Atest. Nr.2_3'!I2 -> n/p | AS6: =Examen!G2 -> n/p | AT6: =ReExaminare!G2 -> n/p | AU6: =IF(NOT(ISBLANK(B6)), IF(SUM(E6:S6,U6:AI6)<>0,SUM(E6:S6,U6:AI6),""), "") | AY6: =IF(NOT(ISBLANK(C6)), IF(COUNT(MAX(AVERAGE(AM6:AO6),0)),MAX(AM6:AO6),"n/p"), "") -> n/p | AZ6: =IF(NOT(ISBLANK(C6)), IF(COUNT(MAX(AVERAGE(AP6:AR6),0)),MAX(AP6:AR6),"n/p"), "") -> n/p | BA6: ='Ev. Curenta'!I2 -> n/p | BB6: =IF(NOT(ISBLANK(C6)), IF('L. Indiv.'!G2<>"n/p",'L. Indiv.'!G2,"n/p"), "") -> n/p | BC6: =IF(NOT(ISBLANK(C6)), IF(OR(AY6="n/p",AZ6="n/p",BA6="n/p",BB6="n/p",AY6<5,AZ6<5,BA6<5,BB6<5)," ",TRUNC(SUM(AY6:BB6)/4,2)), "") | BD6: =IF(NOT(ISBLANK(C6)), IF(BC6=" ","n/a", IF(AX6,AX6, IF(COUNT(MAX(AVERAGE(AS6:AT6),0)),MAX(AS6:AT6),"n/p"))), "") -> n/a | BE6: =IF(NOT(ISBLANK(C6)), IF(OR(BD6="n/a",BD6="n/p")," ", IF(BD6<5,BD6,TRUNC(BC6*0.6+BD6*0.4,2))), "") | BF6: =IF(NOT(ISBLANK(C6)), IF(BE6=" "," ", IF(AND(BE6>=1,BE6<2),"(unu, "&ROUNDUP(MOD(BE6*100,100),0)&")", IF(AND(BE6>=2,BE6<3),"(doi, "&ROUNDUP(MOD(BE6*100,100),0)&")", IF(AND(BE6>=3,BE6<4),"(trei, "&ROUNDUP(MOD(BE6*100,100),0)&")", IF(AND(BE6>=4,BE6<5),"(patru, "&ROUNDUP(MOD(BE6*100,100),0)&")", IF(AND(BE6>=5,BE6<6),"(cinci, "&ROUNDUP(MOD(BE6*100,100),0)&")", IF(AND(BE6>=6,BE6<7),"(şase, "&ROUNDUP(MOD(BE6*100,100),0)&")", IF(AND(BE6>=7,BE6<8),"(şapte, "&ROUNDUP(MOD(BE6*100,100),0)&")", IF(AND(BE6>=8,BE6<9),"(opt, "&ROUNDUP(MOD(BE6*100,100),0)&")", IF(AND(BE6>=9,BE6<10),"(nouă, "&ROUNDUP(MOD(BE6*100,100),0)&")", IF(BE6=10,"(zece, 00)", ))))))))))),"") | BG6: =IF(NOT(ISBLANK(C6)), IF(BE6=" "," ", IF(AND(BE6>=1,BE6<=3),"F", IF(AND(BE6>3,BE6<5),"FX", IF(AND(BE6>=5,BE6<=6),"E", IF(AND(BE6>6,BE6<=7),"D", IF(AND(BE6>7,BE6<=8),"C", IF(AND(BE6>8,BE6<=9),"B", IF(AND(BE6>9,BE6<=10),"A", )))))))),"")
B7: =IF(NOT(ISBLANK(C7)),COUNTA($C$6:C7),"") | T7: =IF(NOT(ISBLANK(C7)),IF(COUNTIF(E7:S7,"a")<>0,COUNTIF(E7:S7,"a")*2,""),"") | AJ7: =IF(NOT(ISBLANK(B7)),IF(COUNTIF(U7:AI7,"a")<>0,COUNTIF(U7:AI7,"a")*2,""),"") | AK7: =IF(NOT(ISBLANK(C7)),IF(COUNTIF(E7:AI7,"a")<>0,COUNTIF(E7:AI7,"a")*2,""),"") | AM7: ='Atest. Nr.1_1'!I3 | AN7: ='Atest. Nr.1_2'!I3 | AO7: ='Atest. Nr.1_3'!I3 | AP7: ='Atest. Nr.2_1'!I3 | AQ7: ='Atest. Nr.2_2'!I3 | AR7: ='Atest. Nr.2_3'!I3 | AS7: =Examen!G3 | AT7: =ReExaminare!G3 | AU7: =IF(NOT(ISBLANK(B7)), IF(SUM(E7:S7,U7:AI7)<>0,SUM(E7:S7,U7:AI7),""), "") | AY7: =IF(NOT(ISBLANK(C7)), IF(COUNT(MAX(AVERAGE(AM7:AO7),0)),MAX(AM7:AO7),"n/p"), "") | AZ7: =IF(NOT(ISBLANK(C7)), IF(COUNT(MAX(AVERAGE(AP7:AR7),0)),MAX(AP7:AR7),"n/p"), "") | BA7: ='Ev. Curenta'!I3 | BB7: =IF(NOT(ISBLANK(C7)), IF('L. Indiv.'!G3<>"n/p",'L. Indiv.'!G3,"n/p"), "") | BC7: =IF(NOT(ISBLANK(C7)), IF(OR(AY7="n/p",AZ7="n/p",BA7="n/p",BB7="n/p",AY7<5,AZ7<5,BA7<5,BB7<5)," ",TRUNC(SUM(AY7:BB7)/4,2)), "") | BD7: =IF(NOT(ISBLANK(C7)), IF(BC7=" ","n/a", IF(AX7,AX7, IF(COUNT(MAX(AVERAGE(AS7:AT7),0)),MAX(AS7:AT7),"n/p"))), "") | BE7: =IF(NOT(ISBLANK(C7)), IF(OR(BD7="n/a",BD7="n/p")," ", IF(BD7<5,BD7,TRUNC(BC7*0.6+BD7*0.4,2))), "") | BF7: =IF(NOT(ISBLANK(C7)), IF(BE7=" "," ", IF(AND(BE7>=1,BE7<2),"(unu, "&ROUNDUP(MOD(BE7*100,100),0)&")", IF(AND(BE7>=2,BE7<3),"(doi, "&ROUNDUP(MOD(BE7*100,100),0)&")", IF(AND(BE7>=3,BE7<4),"(trei, "&ROUNDUP(MOD(BE7*100,100),0)&")", IF(AND(BE7>=4,BE7<5),"(patru, "&ROUNDUP(MOD(BE7*100,100),0)&")", IF(AND(BE7>=5,BE7<6),"(cinci, "&ROUNDUP(MOD(BE7*100,100),0)&")", IF(AND(BE7>=6,BE7<7),"(şase, "&ROUNDUP(MOD(BE7*100,100),0)&")", IF(AND(BE7>=7,BE7<8),"(şapte, "&ROUNDUP(MOD(BE7*100,100),0)&")", IF(AND(BE7>=8,BE7<9),"(opt, "&ROUNDUP(MOD(BE7*100,100),0)&")", IF(AND(BE7>=9,BE7<10),"(nouă, "&ROUNDUP(MOD(BE7*100,100),0)&")", IF(BE7=10,"(zece, 00)", ))))))))))),"") | BG7: =IF(NOT(ISBLANK(C7)), IF(BE7=" "," ", IF(AND(BE7>=1,BE7<=3),"F", IF(AND(BE7>3,BE7<5),"FX", IF(AND(BE7>=5,BE7<=6),"E", IF(AND(BE7>6,BE7<=7),"D", IF(AND(BE7>7,BE7<=8),"C", IF(AND(BE7>8,BE7<=9),"B", IF(AND(BE7>9,BE7<=10),"A", )))))))),"")
B8: =IF(NOT(ISBLANK(C8)),COUNTA($C$6:C8),"") | T8: =IF(NOT(ISBLANK(C8)),IF(COUNTIF(E8:S8,"a")<>0,COUNTIF(E8:S8,"a")*2,""),"") | AJ8: =IF(NOT(ISBLANK(B8)),IF(COUNTIF(U8:AI8,"a")<>0,COUNTIF(U8:AI8,"a")*2,""),"") | AK8: =IF(NOT(ISBLANK(C8)),IF(COUNTIF(E8:AI8,"a")<>0,COUNTIF(E8:AI8,"a")*2,""),"") | AM8: ='Atest. Nr.1_1'!I4 | AN8: ='Atest. Nr.1_2'!I4 | AO8: ='Atest. Nr.1_3'!I4 | AP8: ='Atest. Nr.2_1'!I4 | AQ8: ='Atest. Nr.2_2'!I4 | AR8: ='Atest. Nr.2_3'!I4 | AS8: =Examen!G4 | AT8: =ReExaminare!G4 | AU8: =IF(NOT(ISBLANK(B8)), IF(SUM(E8:S8,U8:AI8)<>0,SUM(E8:S8,U8:AI8),""), "") | AY8: =IF(NOT(ISBLANK(C8)), IF(COUNT(MAX(AVERAGE(AM8:AO8),0)),MAX(AM8:AO8),"n/p"), "") | AZ8: =IF(NOT(ISBLANK(C8)), IF(COUNT(MAX(AVERAGE(AP8:AR8),0)),MAX(AP8:AR8),"n/p"), "") | BA8: ='Ev. Curenta'!I4 | BB8: =IF(NOT(ISBLANK(C8)), IF('L. Indiv.'!G4<>"n/p",'L. Indiv.'!G4,"n/p"), "") | BC8: =IF(NOT(ISBLANK(C8)), IF(OR(AY8="n/p",AZ8="n/p",BA8="n/p",BB8="n/p",AY8<5,AZ8<5,BA8<5,BB8<5)," ",TRUNC(SUM(AY8:BB8)/4,2)), "") | BD8: =IF(NOT(ISBLANK(C8)), IF(BC8=" ","n/a", IF(AX8,AX8, IF(COUNT(MAX(AVERAGE(AS8:AT8),0)),MAX(AS8:AT8),"n/p"))), "") | BE8: =IF(NOT(ISBLANK(C8)), IF(OR(BD8="n/a",BD8="n/p")," ", IF(BD8<5,BD8,TRUNC(BC8*0.6+BD8*0.4,2))), "") | BF8: =IF(NOT(ISBLANK(C8)), IF(BE8=" "," ", IF(AND(BE8>=1,BE8<2),"(unu, "&ROUNDUP(MOD(BE8*100,100),0)&")", IF(AND(BE8>=2,BE8<3),"(doi, "&ROUNDUP(MOD(BE8*100,100),0)&")", IF(AND(BE8>=3,BE8<4),"(trei, "&ROUNDUP(MOD(BE8*100,100),0)&")", IF(AND(BE8>=4,BE8<5),"(patru, "&ROUNDUP(MOD(BE8*100,100),0)&")", IF(AND(BE8>=5,BE8<6),"(cinci, "&ROUNDUP(MOD(BE8*100,100),0)&")", IF(AND(BE8>=6,BE8<7),"(şase, "&ROUNDUP(MOD(BE8*100,100),0)&")", IF(AND(BE8>=7,BE8<8),"(şapte, "&ROUNDUP(MOD(BE8*100,100),0)&")", IF(AND(BE8>=8,BE8<9),"(opt, "&ROUNDUP(MOD(BE8*100,100),0)&")", IF(AND(BE8>=9,BE8<10),"(nouă, "&ROUNDUP(MOD(BE8*100,100),0)&")", IF(BE8=10,"(zece, 00)", ))))))))))),"") | BG8: =IF(NOT(ISBLANK(C8)), IF(BE8=" "," ", IF(AND(BE8>=1,BE8<=3),"F", IF(AND(BE8>3,BE8<5),"FX", IF(AND(BE8>=5,BE8<=6),"E", IF(AND(BE8>6,BE8<=7),"D", IF(AND(BE8>7,BE8<=8),"C", IF(AND(BE8>8,BE8<=9),"B", IF(AND(BE8>9,BE8<=10),"A", )))))))),"")
B9: =IF(NOT(ISBLANK(C9)),COUNTA($C$6:C9),"") | T9: =IF(NOT(ISBLANK(C9)),IF(COUNTIF(E9:S9,"a")<>0,COUNTIF(E9:S9,"a")*2,""),"") | AJ9: =IF(NOT(ISBLANK(B9)),IF(COUNTIF(U9:AI9,"a")<>0,COUNTIF(U9:AI9,"a")*2,""),"") | AK9: =IF(NOT(ISBLANK(C9)),IF(COUNTIF(E9:AI9,"a")<>0,COUNTIF(E9:AI9,"a")*2,""),"") | AM9: ='Atest. Nr.1_1'!I5 | AN9: ='Atest. Nr.1_2'!I5 | AO9: ='Atest. Nr.1_3'!I5 | AP9: ='Atest. Nr.2_1'!I5 | AQ9: ='Atest. Nr.2_2'!I5 | AR9: ='Atest. Nr.2_3'!I5 | AS9: =Examen!G5 | AT9: =ReExaminare!G5 | AU9: =IF(NOT(ISBLANK(B9)), IF(SUM(E9:S9,U9:AI9)<>0,SUM(E9:S9,U9:AI9),""), "") | AY9: =IF(NOT(ISBLANK(C9)), IF(COUNT(MAX(AVERAGE(AM9:AO9),0)),MAX(AM9:AO9),"n/p"), "") | AZ9: =IF(NOT(ISBLANK(C9)), IF(COUNT(MAX(AVERAGE(AP9:AR9),0)),MAX(AP9:AR9),"n/p"), "") | BA9: ='Ev. Curenta'!I5 | BB9: =IF(NOT(ISBLANK(C9)), IF('L. Indiv.'!G5<>"n/p",'L. Indiv.'!G5,"n/p"), "") | BC9: =IF(NOT(ISBLANK(C9)), IF(OR(AY9="n/p",AZ9="n/p",BA9="n/p",BB9="n/p",AY9<5,AZ9<5,BA9<5,BB9<5)," ",TRUNC(SUM(AY9:BB9)/4,2)), "") | BD9: =IF(NOT(ISBLANK(C9)), IF(BC9=" ","n/a", IF(AX9,AX9, IF(COUNT(MAX(AVERAGE(AS9:AT9),0)),MAX(AS9:AT9),"n/p"))), "") | BE9: =IF(NOT(ISBLANK(C9)), IF(OR(BD9="n/a",BD9="n/p")," ", IF(BD9<5,BD9,TRUNC(BC9*0.6+BD9*0.4,2))), "") | BF9: =IF(NOT(ISBLANK(C9)), IF(BE9=" "," ", IF(AND(BE9>=1,BE9<2),"(unu, "&ROUNDUP(MOD(BE9*100,100),0)&")", IF(AND(BE9>=2,BE9<3),"(doi, "&ROUNDUP(MOD(BE9*100,100),0)&")", IF(AND(BE9>=3,BE9<4),"(trei, "&ROUNDUP(MOD(BE9*100,100),0)&")", IF(AND(BE9>=4,BE9<5),"(patru, "&ROUNDUP(MOD(BE9*100,100),0)&")", IF(AND(BE9>=5,BE9<6),"(cinci, "&ROUNDUP(MOD(BE9*100,100),0)&")", IF(AND(BE9>=6,BE9<7),"(şase, "&ROUNDUP(MOD(BE9*100,100),0)&")", IF(AND(BE9>=7,BE9<8),"(şapte, "&ROUNDUP(MOD(BE9*100,100),0)&")", IF(AND(BE9>=8,BE9<9),"(opt, "&ROUNDUP(MOD(BE9*100,100),0)&")", IF(AND(BE9>=9,BE9<10),"(nouă, "&ROUNDUP(MOD(BE9*100,100),0)&")", IF(BE9=10,"(zece, 00)", ))))))))))),"") | BG9: =IF(NOT(ISBLANK(C9)), IF(BE9=" "," ", IF(AND(BE9>=1,BE9<=3),"F", IF(AND(BE9>3,BE9<5),"FX", IF(AND(BE9>=5,BE9<=6),"E", IF(AND(BE9>6,BE9<=7),"D", IF(AND(BE9>7,BE9<=8),"C", IF(AND(BE9>8,BE9<=9),"B", IF(AND(BE9>9,BE9<=10),"A", )))))))),"") | BK9: Evaluarea periodică Nr.1 | BX9: Reușita din nr. total, %
B10: =IF(NOT(ISBLANK(C10)),COUNTA($C$6:C10),"") | T10: =IF(NOT(ISBLANK(C10)),IF(COUNTIF(E10:S10,"a")<>0,COUNTIF(E10:S10,"a")*2,""),"") | AJ10: =IF(NOT(ISBLANK(B10)),IF(COUNTIF(U10:AI10,"a")<>0,COUNTIF(U10:AI10,"a")*2,""),"") | AK10: =IF(NOT(ISBLANK(C10)),IF(COUNTIF(E10:AI10,"a")<>0,COUNTIF(E10:AI10,"a")*2,""),"") | AM10: ='Atest. Nr.1_1'!I6 | AN10: ='Atest. Nr.1_2'!I6 | AO10: ='Atest. Nr.1_3'!I6 | AP10: ='Atest. Nr.2_1'!I6 | AQ10: ='Atest. Nr.2_2'!I6 | AR10: ='Atest. Nr.2_3'!I6 | AS10: =Examen!G6 | AT10: =ReExaminare!G6 | AU10: =IF(NOT(ISBLANK(B10)), IF(SUM(E10:S10,U10:AI10)<>0,SUM(E10:S10,U10:AI10),""), "") | AY10: =IF(NOT(ISBLANK(C10)), IF(COUNT(MAX(AVERAGE(AM10:AO10),0)),MAX(AM10:AO10),"n/p"), "") | AZ10: =IF(NOT(ISBLANK(C10)), IF(COUNT(MAX(AVERAGE(AP10:AR10),0)),MAX(AP10:AR10),"n/p"), "") | BA10: ='Ev. Curenta'!I6 | BB10: =IF(NOT(ISBLANK(C10)), IF('L. Indiv.'!G6<>"n/p",'L. Indiv.'!G6,"n/p"), "") | BC10: =IF(NOT(ISBLANK(C10)), IF(OR(AY10="n/p",AZ10="n/p",BA10="n/p",BB10="n/p",AY10<5,AZ10<5,BA10<5,BB10<5)," ",TRUNC(SUM(AY10:BB10)/4,2)), "") | BD10: =IF(NOT(ISBLANK(C10)), IF(BC10=" ","n/a", IF(AX10,AX10, IF(COUNT(MAX(AVERAGE(AS10:AT10),0)),MAX(AS10:AT10),"n/p"))), "") | BE10: =IF(NOT(ISBLANK(C10)), IF(OR(BD10="n/a",BD10="n/p")," ", IF(BD10<5,BD10,TRUNC(BC10*0.6+BD10*0.4,2))), "") | BF10: =IF(NOT(ISBLANK(C10)), IF(BE10=" "," ", IF(AND(BE10>=1,BE10<2),"(unu, "&ROUNDUP(MOD(BE10*100,100),0)&")", IF(AND(BE10>=2,BE10<3),"(doi, "&ROUNDUP(MOD(BE10*100,100),0)&")", IF(AND(BE10>=3,BE10<4),"(trei, "&ROUNDUP(MOD(BE10*100,100),0)&")", IF(AND(BE10>=4,BE10<5),"(patru, "&ROUNDUP(MOD(BE10*100,100),0)&")", IF(AND(BE10>=5,BE10<6),"(cinci, "&ROUNDUP(MOD(BE10*100,100),0)&")", IF(AND(BE10>=6,BE10<7),"(şase, "&ROUNDUP(MOD(BE10*100,100),0)&")", IF(AND(BE10>=7,BE10<8),"(şapte, "&ROUNDUP(MOD(BE10*100,100),0)&")", IF(AND(BE10>=8,BE10<9),"(opt, "&ROUNDUP(MOD(BE10*100,100),0)&")", IF(AND(BE10>=9,BE10<10),"(nouă, "&ROUNDUP(MOD(BE10*100,100),0)&")", IF(BE10=10,"(zece, 00)", ))))))))))),"") | BG10: =IF(NOT(ISBLANK(C10)), IF(BE10=" "," ", IF(AND(BE10>=1,BE10<=3),"F", IF(AND(BE10>3,BE10<5),"FX", IF(AND(BE10>=5,BE10<=6),"E", IF(AND(BE10>6,BE10<=7),"D", IF(AND(BE10>7,BE10<=8),"C", IF(AND(BE10>8,BE10<=9),"B", IF(AND(BE10>9,BE10<=10),"A", )))))))),"")
B11: =IF(NOT(ISBLANK(C11)),COUNTA($C$6:C11),"") | T11: =IF(NOT(ISBLANK(C11)),IF(COUNTIF(E11:S11,"a")<>0,COUNTIF(E11:S11,"a")*2,""),"") | AJ11: =IF(NOT(ISBLANK(B11)),IF(COUNTIF(U11:AI11,"a")<>0,COUNTIF(U11:AI11,"a")*2,""),"") | AK11: =IF(NOT(ISBLANK(C11)),IF(COUNTIF(E11:AI11,"a")<>0,COUNTIF(E11:AI11,"a")*2,""),"") | AM11: ='Atest. Nr.1_1'!I7 | AN11: ='Atest. Nr.1_2'!I7 | AO11: ='Atest. Nr.1_3'!I7 | AP11: ='Atest. Nr.2_1'!I7 | AQ11: ='Atest. Nr.2_2'!I7 | AR11: ='Atest. Nr.2_3'!I7 | AS11: =Examen!G7 | AT11: =ReExaminare!G7 | AU11: =IF(NOT(ISBLANK(B11)), IF(SUM(E11:S11,U11:AI11)<>0,SUM(E11:S11,U11:AI11),""), "") | AY11: =IF(NOT(ISBLANK(C11)), IF(COUNT(MAX(AVERAGE(AM11:AO11),0)),MAX(AM11:AO11),"n/p"), "") | AZ11: =IF(NOT(ISBLANK(C11)), IF(COUNT(MAX(AVERAGE(AP11:AR11),0)),MAX(AP11:AR11),"n/p"), "") | BA11: ='Ev. Curenta'!I7 | BB11: =IF(NOT(ISBLANK(C11)), IF('L. Indiv.'!G7<>"n/p",'L. Indiv.'!G7,"n/p"), "") | BC11: =IF(NOT(ISBLANK(C11)), IF(OR(AY11="n/p",AZ11="n/p",BA11="n/p",BB11="n/p",AY11<5,AZ11<5,BA11<5,BB11<5)," ",TRUNC(SUM(AY11:BB11)/4,2)), "") | BD11: =IF(NOT(ISBLANK(C11)), IF(BC11=" ","n/a", IF(AX11,AX11, IF(COUNT(MAX(AVERAGE(AS11:AT11),0)),MAX(AS11:AT11),"n/p"))), "") | BE11: =IF(NOT(ISBLANK(C11)), IF(OR(BD11="n/a",BD11="n/p")," ", IF(BD11<5,BD11,TRUNC(BC11*0.6+BD11*0.4,2))), "") | BF11: =IF(NOT(ISBLANK(C11)), IF(BE11=" "," ", IF(AND(BE11>=1,BE11<2),"(unu, "&ROUNDUP(MOD(BE11*100,100),0)&")", IF(AND(BE11>=2,BE11<3),"(doi, "&ROUNDUP(MOD(BE11*100,100),0)&")", IF(AND(BE11>=3,BE11<4),"(trei, "&ROUNDUP(MOD(BE11*100,100),0)&")", IF(AND(BE11>=4,BE11<5),"(patru, "&ROUNDUP(MOD(BE11*100,100),0)&")", IF(AND(BE11>=5,BE11<6),"(cinci, "&ROUNDUP(MOD(BE11*100,100),0)&")", IF(AND(BE11>=6,BE11<7),"(şase, "&ROUNDUP(MOD(BE11*100,100),0)&")", IF(AND(BE11>=7,BE11<8),"(şapte, "&ROUNDUP(MOD(BE11*100,100),0)&")", IF(AND(BE11>=8,BE11<9),"(opt, "&ROUNDUP(MOD(BE11*100,100),0)&")", IF(AND(BE11>=9,BE11<10),"(nouă, "&ROUNDUP(MOD(BE11*100,100),0)&")", IF(BE11=10,"(zece, 00)", ))))))))))),"") | BG11: =IF(NOT(ISBLANK(C11)), IF(BE11=" "," ", IF(AND(BE11>=1,BE11<=3),"F", IF(AND(BE11>3,BE11<5),"FX", IF(AND(BE11>=5,BE11<=6),"E", IF(AND(BE11>6,BE11<=7),"D", IF(AND(BE11>7,BE11<=8),"C", IF(AND(BE11>8,BE11<=9),"B", IF(AND(BE11>9,BE11<=10),"A", )))))))),"") | BK11: Nr. stud | BL11: n/p | BM11: 1 | BN11: 2 | BO11: 3 | BP11: 4 | BQ11: 5 | BR11: 6 | BS11: 7 | BT11: 8 | BU11: 9 | BV11: 10
B12: =IF(NOT(ISBLANK(C12)),COUNTA($C$6:C12),"") | T12: =IF(NOT(ISBLANK(C12)),IF(COUNTIF(E12:S12,"a")<>0,COUNTIF(E12:S12,"a")*2,""),"") | AJ12: =IF(NOT(ISBLANK(B12)),IF(COUNTIF(U12:AI12,"a")<>0,COUNTIF(U12:AI12,"a")*2,""),"") | AK12: =IF(NOT(ISBLANK(C12)),IF(COUNTIF(E12:AI12,"a")<>0,COUNTIF(E12:AI12,"a")*2,""),"") | AM12: ='Atest. Nr.1_1'!I8 | AN12: ='Atest. Nr.1_2'!I8 | AO12: ='Atest. Nr.1_3'!I8 | AP12: ='Atest. Nr.2_1'!I8 | AQ12: ='Atest. Nr.2_2'!I8 | AR12: ='Atest. Nr.2_3'!I8 | AS12: =Examen!G8 | AT12: =ReExaminare!G8 | AU12: =IF(NOT(ISBLANK(B12)), IF(SUM(E12:S12,U12:AI12)<>0,SUM(E12:S12,U12:AI12),""), "") | AY12: =IF(NOT(ISBLANK(C12)), IF(COUNT(MAX(AVERAGE(AM12:AO12),0)),MAX(AM12:AO12),"n/p"), "") | AZ12: =IF(NOT(ISBLANK(C12)), IF(COUNT(MAX(AVERAGE(AP12:AR12),0)),MAX(AP12:AR12),"n/p"), "") | BA12: ='Ev. Curenta'!I8 | BB12: =IF(NOT(ISBLANK(C12)), IF('L. Indiv.'!G8<>"n/p",'L. Indiv.'!G8,"n/p"), "") | BC12: =IF(NOT(ISBLANK(C12)), IF(OR(AY12="n/p",AZ12="n/p",BA12="n/p",BB12="n/p",AY12<5,AZ12<5,BA12<5,BB12<5)," ",TRUNC(SUM(AY12:BB12)/4,2)), "") | BD12: =IF(NOT(ISBLANK(C12)), IF(BC12=" ","n/a", IF(AX12,AX12, IF(COUNT(MAX(AVERAGE(AS12:AT12),0)),MAX(AS12:AT12),"n/p"))), "") | BE12: =IF(NOT(ISBLANK(C12)), IF(OR(BD12="n/a",BD12="n/p")," ", IF(BD12<5,BD12,TRUNC(BC12*0.6+BD12*0.4,2))), "") | BF12: =IF(NOT(ISBLANK(C12)), IF(BE12=" "," ", IF(AND(BE12>=1,BE12<2),"(unu, "&ROUNDUP(MOD(BE12*100,100),0)&")", IF(AND(BE12>=2,BE12<3),"(doi, "&ROUNDUP(MOD(BE12*100,100),0)&")", IF(AND(BE12>=3,BE12<4),"(trei, "&ROUNDUP(MOD(BE12*100,100),0)&")", IF(AND(BE12>=4,BE12<5),"(patru, "&ROUNDUP(MOD(BE12*100,100),0)&")", IF(AND(BE12>=5,BE12<6),"(cinci, "&ROUNDUP(MOD(BE12*100,100),0)&")", IF(AND(BE12>=6,BE12<7),"(şase, "&ROUNDUP(MOD(BE12*100,100),0)&")", IF(AND(BE12>=7,BE12<8),"(şapte, "&ROUNDUP(MOD(BE12*100,100),0)&")", IF(AND(BE12>=8,BE12<9),"(opt, "&ROUNDUP(MOD(BE12*100,100),0)&")", IF(AND(BE12>=9,BE12<10),"(nouă, "&ROUNDUP(MOD(BE12*100,100),0)&")", IF(BE12=10,"(zece, 00)", ))))))))))),"") | BG12: =IF(NOT(ISBLANK(C12)), IF(BE12=" "," ", IF(AND(BE12>=1,BE12<=3),"F", IF(AND(BE12>3,BE12<5),"FX", IF(AND(BE12>=5,BE12<=6),"E", IF(AND(BE12>6,BE12<=7),"D", IF(AND(BE12>7,BE12<=8),"C", IF(AND(BE12>8,BE12<=9),"B", IF(AND(BE12>9,BE12<=10),"A", )))))))),"")
B13: =IF(NOT(ISBLANK(C13)),COUNTA($C$6:C13),"") | T13: =IF(NOT(ISBLANK(C13)),IF(COUNTIF(E13:S13,"a")<>0,COUNTIF(E13:S13,"a")*2,""),"") | AJ13: =IF(NOT(ISBLANK(B13)),IF(COUNTIF(U13:AI13,"a")<>0,COUNTIF(U13:AI13,"a")*2,""),"") | AK13: =IF(NOT(ISBLANK(C13)),IF(COUNTIF(E13:AI13,"a")<>0,COUNTIF(E13:AI13,"a")*2,""),"") | AM13: ='Atest. Nr.1_1'!I9 | AN13: ='Atest. Nr.1_2'!I9 | AO13: ='Atest. Nr.1_3'!I9 | AP13: ='Atest. Nr.2_1'!I9 | AQ13: ='Atest. Nr.2_2'!I9 | AR13: ='Atest. Nr.2_3'!I9 | AS13: =Examen!G9 | AT13: =ReExaminare!G9 | AU13: =IF(NOT(ISBLANK(B13)), IF(SUM(E13:S13,U13:AI13)<>0,SUM(E13:S13,U13:AI13),""), "") | AY13: =IF(NOT(ISBLANK(C13)), IF(COUNT(MAX(AVERAGE(AM13:AO13),0)),MAX(AM13:AO13),"n/p"), "") | AZ13: =IF(NOT(ISBLANK(C13)), IF(COUNT(MAX(AVERAGE(AP13:AR13),0)),MAX(AP13:AR13),"n/p"), "") | BA13: ='Ev. Curenta'!I9 | BB13: =IF(NOT(ISBLANK(C13)), IF('L. Indiv.'!G9<>"n/p",'L. Indiv.'!G9,"n/p"), "") | BC13: =IF(NOT(ISBLANK(C13)), IF(OR(AY13="n/p",AZ13="n/p",BA13="n/p",BB13="n/p",AY13<5,AZ13<5,BA13<5,BB13<5)," ",TRUNC(SUM(AY13:BB13)/4,2)), "") | BD13: =IF(NOT(ISBLANK(C13)), IF(BC13=" ","n/a", IF(AX13,AX13, IF(COUNT(MAX(AVERAGE(AS13:AT13),0)),MAX(AS13:AT13),"n/p"))), "") | BE13: =IF(NOT(ISBLANK(C13)), IF(OR(BD13="n/a",BD13="n/p")," ", IF(BD13<5,BD13,TRUNC(BC13*0.6+BD13*0.4,2))), "") | BF13: =IF(NOT(ISBLANK(C13)), IF(BE13=" "," ", IF(AND(BE13>=1,BE13<2),"(unu, "&ROUNDUP(MOD(BE13*100,100),0)&")", IF(AND(BE13>=2,BE13<3),"(doi, "&ROUNDUP(MOD(BE13*100,100),0)&")", IF(AND(BE13>=3,BE13<4),"(trei, "&ROUNDUP(MOD(BE13*100,100),0)&")", IF(AND(BE13>=4,BE13<5),"(patru, "&ROUNDUP(MOD(BE13*100,100),0)&")", IF(AND(BE13>=5,BE13<6),"(cinci, "&ROUNDUP(MOD(BE13*100,100),0)&")", IF(AND(BE13>=6,BE13<7),"(şase, "&ROUNDUP(MOD(BE13*100,100),0)&")", IF(AND(BE13>=7,BE13<8),"(şapte, "&ROUNDUP(MOD(BE13*100,100),0)&")", IF(AND(BE13>=8,BE13<9),"(opt, "&ROUNDUP(MOD(BE13*100,100),0)&")", IF(AND(BE13>=9,BE13<10),"(nouă, "&ROUNDUP(MOD(BE13*100,100),0)&")", IF(BE13=10,"(zece, 00)", ))))))))))),"") | BG13: =IF(NOT(ISBLANK(C13)), IF(BE13=" "," ", IF(AND(BE13>=1,BE13<=3),"F", IF(AND(BE13>3,BE13<5),"FX", IF(AND(BE13>=5,BE13<=6),"E", IF(AND(BE13>6,BE13<=7),"D", IF(AND(BE13>7,BE13<=8),"C", IF(AND(BE13>8,BE13<=9),"B", IF(AND(BE13>9,BE13<=10),"A", )))))))),"") | BK13: =COUNTA(T6:T105) -> 100 | BL13: =COUNTIF($AH$6:$AH$105,BL11) -> 0 | BM13: =COUNTIF($AH$6:$AH$105,BM11) -> 0 | BN13: =COUNTIF($AH$6:$AH$105,BN11) -> 0 | BO13: =COUNTIF($AH$6:$AH$105,BO11) -> 0 | BP13: =COUNTIF($AH$6:$AH$105,BP11) -> 0 | BQ13: =COUNTIF($AH$6:$AH$105,BQ11) -> 0 | BR13: =COUNTIF($AH$6:$AH$105,BR11) -> 0 | BS13: =COUNTIF($AH$6:$AH$105,BS11) -> 0 | ... BV13: =COUNTIF($AH$6:$AH$105,BV11) -> 0 | BX13: =SUM(BQ13:BV14)/BK13 -> 0
B14: =IF(NOT(ISBLANK(C14)),COUNTA($C$6:C14),"") | T14: =IF(NOT(ISBLANK(C14)),IF(COUNTIF(E14:S14,"a")<>0,COUNTIF(E14:S14,"a")*2,""),"") | AJ14: =IF(NOT(ISBLANK(B14)),IF(COUNTIF(U14:AI14,"a")<>0,COUNTIF(U14:AI14,"a")*2,""),"") | AK14: =IF(NOT(ISBLANK(C14)),IF(COUNTIF(E14:AI14,"a")<>0,COUNTIF(E14:AI14,"a")*2,""),"") | AM14: ='Atest. Nr.1_1'!I10 | AN14: ='Atest. Nr.1_2'!I10 | AO14: ='Atest. Nr.1_3'!I10 | AP14: ='Atest. Nr.2_1'!I10 | AQ14: ='Atest. Nr.2_2'!I10 | AR14: ='Atest. Nr.2_3'!I10 | AS14: =Examen!G10 | AT14: =ReExaminare!G10 | AU14: =IF(NOT(ISBLANK(B14)), IF(SUM(E14:S14,U14:AI14)<>0,SUM(E14:S14,U14:AI14),""), "") | AY14: =IF(NOT(ISBLANK(C14)), IF(COUNT(MAX(AVERAGE(AM14:AO14),0)),MAX(AM14:AO14),"n/p"), "") | AZ14: =IF(NOT(ISBLANK(C14)), IF(COUNT(MAX(AVERAGE(AP14:AR14),0)),MAX(AP14:AR14),"n/p"), "") | BA14: ='Ev. Curenta'!I10 | BB14: =IF(NOT(ISBLANK(C14)), IF('L. Indiv.'!G10<>"n/p",'L. Indiv.'!G10,"n/p"), "") | BC14: =IF(NOT(ISBLANK(C14)), IF(OR(AY14="n/p",AZ14="n/p",BA14="n/p",BB14="n/p",AY14<5,AZ14<5,BA14<5,BB14<5)," ",TRUNC(SUM(AY14:BB14)/4,2)), "") | BD14: =IF(NOT(ISBLANK(C14)), IF(BC14=" ","n/a", IF(AX14,AX14, IF(COUNT(MAX(AVERAGE(AS14:AT14),0)),MAX(AS14:AT14),"n/p"))), "") | BE14: =IF(NOT(ISBLANK(C14)), IF(OR(BD14="n/a",BD14="n/p")," ", IF(BD14<5,BD14,TRUNC(BC14*0.6+BD14*0.4,2))), "") | BF14: =IF(NOT(ISBLANK(C14)), IF(BE14=" "," ", IF(AND(BE14>=1,BE14<2),"(unu, "&ROUNDUP(MOD(BE14*100,100),0)&")", IF(AND(BE14>=2,BE14<3),"(doi, "&ROUNDUP(MOD(BE14*100,100),0)&")", IF(AND(BE14>=3,BE14<4),"(trei, "&ROUNDUP(MOD(BE14*100,100),0)&")", IF(AND(BE14>=4,BE14<5),"(patru, "&ROUNDUP(MOD(BE14*100,100),0)&")", IF(AND(BE14>=5,BE14<6),"(cinci, "&ROUNDUP(MOD(BE14*100,100),0)&")", IF(AND(BE14>=6,BE14<7),"(şase, "&ROUNDUP(MOD(BE14*100,100),0)&")", IF(AND(BE14>=7,BE14<8),"(şapte, "&ROUNDUP(MOD(BE14*100,100),0)&")", IF(AND(BE14>=8,BE14<9),"(opt, "&ROUNDUP(MOD(BE14*100,100),0)&")", IF(AND(BE14>=9,BE14<10),"(nouă, "&ROUNDUP(MOD(BE14*100,100),0)&")", IF(BE14=10,"(zece, 00)", ))))))))))),"") | BG14: =IF(NOT(ISBLANK(C14)), IF(BE14=" "," ", IF(AND(BE14>=1,BE14<=3),"F", IF(AND(BE14>3,BE14<5),"FX", IF(AND(BE14>=5,BE14<=6),"E", IF(AND(BE14>6,BE14<=7),"D", IF(AND(BE14>7,BE14<=8),"C", IF(AND(BE14>8,BE14<=9),"B", IF(AND(BE14>9,BE14<=10),"A", )))))))),"")
B15: =IF(NOT(ISBLANK(C15)),COUNTA($C$6:C15),"") | T15: =IF(NOT(ISBLANK(C15)),IF(COUNTIF(E15:S15,"a")<>0,COUNTIF(E15:S15,"a")*2,""),"") | AJ15: =IF(NOT(ISBLANK(B15)),IF(COUNTIF(U15:AI15,"a")<>0,COUNTIF(U15:AI15,"a")*2,""),"") | AK15: =IF(NOT(ISBLANK(C15)),IF(COUNTIF(E15:AI15,"a")<>0,COUNTIF(E15:AI15,"a")*2,""),"") | AM15: ='Atest. Nr.1_1'!I11 | AN15: ='Atest. Nr.1_2'!I11 | AO15: ='Atest. Nr.1_3'!I11 | AP15: ='Atest. Nr.2_1'!I11 | AQ15: ='Atest. Nr.2_2'!I11 | AR15: ='Atest. Nr.2_3'!I11 | AS15: =Examen!G11 | AT15: =ReExaminare!G11 | AU15: =IF(NOT(ISBLANK(B15)), IF(SUM(E15:S15,U15:AI15)<>0,SUM(E15:S15,U15:AI15),""), "") | AY15: =IF(NOT(ISBLANK(C15)), IF(COUNT(MAX(AVERAGE(AM15:AO15),0)),MAX(AM15:AO15),"n/p"), "") | AZ15: =IF(NOT(ISBLANK(C15)), IF(COUNT(MAX(AVERAGE(AP15:AR15),0)),MAX(AP15:AR15),"n/p"), "") | BA15: ='Ev. Curenta'!I11 | BB15: =IF(NOT(ISBLANK(C15)), IF('L. Indiv.'!G11<>"n/p",'L. Indiv.'!G11,"n/p"), "") | BC15: =IF(NOT(ISBLANK(C15)), IF(OR(AY15="n/p",AZ15="n/p",BA15="n/p",BB15="n/p",AY15<5,AZ15<5,BA15<5,BB15<5)," ",TRUNC(SUM(AY15:BB15)/4,2)), "") | BD15: =IF(NOT(ISBLANK(C15)), IF(BC15=" ","n/a", IF(AX15,AX15, IF(COUNT(MAX(AVERAGE(AS15:AT15),0)),MAX(AS15:AT15),"n/p"))), "") | BE15: =IF(NOT(ISBLANK(C15)), IF(OR(BD15="n/a",BD15="n/p")," ", IF(BD15<5,BD15,TRUNC(BC15*0.6+BD15*0.4,2))), "") | BF15: =IF(NOT(ISBLANK(C15)), IF(BE15=" "," ", IF(AND(BE15>=1,BE15<2),"(unu, "&ROUNDUP(MOD(BE15*100,100),0)&")", IF(AND(BE15>=2,BE15<3),"(doi, "&ROUNDUP(MOD(BE15*100,100),0)&")", IF(AND(BE15>=3,BE15<4),"(trei, "&ROUNDUP(MOD(BE15*100,100),0)&")", IF(AND(BE15>=4,BE15<5),"(patru, "&ROUNDUP(MOD(BE15*100,100),0)&")", IF(AND(BE15>=5,BE15<6),"(cinci, "&ROUNDUP(MOD(BE15*100,100),0)&")", IF(AND(BE15>=6,BE15<7),"(şase, "&ROUNDUP(MOD(BE15*100,100),0)&")", IF(AND(BE15>=7,BE15<8),"(şapte, "&ROUNDUP(MOD(BE15*100,100),0)&")", IF(AND(BE15>=8,BE15<9),"(opt, "&ROUNDUP(MOD(BE15*100,100),0)&")", IF(AND(BE15>=9,BE15<10),"(nouă, "&ROUNDUP(MOD(BE15*100,100),0)&")", IF(BE15=10,"(zece, 00)", ))))))))))),"") | BG15: =IF(NOT(ISBLANK(C15)), IF(BE15=" "," ", IF(AND(BE15>=1,BE15<=3),"F", IF(AND(BE15>3,BE15<5),"FX", IF(AND(BE15>=5,BE15<=6),"E", IF(AND(BE15>6,BE15<=7),"D", IF(AND(BE15>7,BE15<=8),"C", IF(AND(BE15>8,BE15<=9),"B", IF(AND(BE15>9,BE15<=10),"A", )))))))),"")
B16: =IF(NOT(ISBLANK(C16)),COUNTA($C$6:C16),"") | T16: =IF(NOT(ISBLANK(C16)),IF(COUNTIF(E16:S16,"a")<>0,COUNTIF(E16:S16,"a")*2,""),"") | AJ16: =IF(NOT(ISBLANK(B16)),IF(COUNTIF(U16:AI16,"a")<>0,COUNTIF(U16:AI16,"a")*2,""),"") | AK16: =IF(NOT(ISBLANK(C16)),IF(COUNTIF(E16:AI16,"a")<>0,COUNTIF(E16:AI16,"a")*2,""),"") | AM16: ='Atest. Nr.1_1'!I12 | AN16: ='Atest. Nr.1_2'!I12 | AO16: ='Atest. Nr.1_3'!I12 | AP16: ='Atest. Nr.2_1'!I12 | AQ16: ='Atest. Nr.2_2'!I12 | AR16: ='Atest. Nr.2_3'!I12 | AS16: =Examen!G12 | AT16: =ReExaminare!G12 | AU16: =IF(NOT(ISBLANK(B16)), IF(SUM(E16:S16,U16:AI16)<>0,SUM(E16:S16,U16:AI16),""), "") | AY16: =IF(NOT(ISBLANK(C16)), IF(COUNT(MAX(AVERAGE(AM16:AO16),0)),MAX(AM16:AO16),"n/p"), "") | AZ16: =IF(NOT(ISBLANK(C16)), IF(COUNT(MAX(AVERAGE(AP16:AR16),0)),MAX(AP16:AR16),"n/p"), "") | BA16: ='Ev. Curenta'!I12 | BB16: =IF(NOT(ISBLANK(C16)), IF('L. Indiv.'!G12<>"n/p",'L. Indiv.'!G12,"n/p"), "") | BC16: =IF(NOT(ISBLANK(C16)), IF(OR(AY16="n/p",AZ16="n/p",BA16="n/p",BB16="n/p",AY16<5,AZ16<5,BA16<5,BB16<5)," ",TRUNC(SUM(AY16:BB16)/4,2)), "") | BD16: =IF(NOT(ISBLANK(C16)), IF(BC16=" ","n/a", IF(AX16,AX16, IF(COUNT(MAX(AVERAGE(AS16:AT16),0)),MAX(AS16:AT16),"n/p"))), "") | BE16: =IF(NOT(ISBLANK(C16)), IF(OR(BD16="n/a",BD16="n/p")," ", IF(BD16<5,BD16,TRUNC(BC16*0.6+BD16*0.4,2))), "") | BF16: =IF(NOT(ISBLANK(C16)), IF(BE16=" "," ", IF(AND(BE16>=1,BE16<2),"(unu, "&ROUNDUP(MOD(BE16*100,100),0)&")", IF(AND(BE16>=2,BE16<3),"(doi, "&ROUNDUP(MOD(BE16*100,100),0)&")", IF(AND(BE16>=3,BE16<4),"(trei, "&ROUNDUP(MOD(BE16*100,100),0)&")", IF(AND(BE16>=4,BE16<5),"(patru, "&ROUNDUP(MOD(BE16*100,100),0)&")", IF(AND(BE16>=5,BE16<6),"(cinci, "&ROUNDUP(MOD(BE16*100,100),0)&")", IF(AND(BE16>=6,BE16<7),"(şase, "&ROUNDUP(MOD(BE16*100,100),0)&")", IF(AND(BE16>=7,BE16<8),"(şapte, "&ROUNDUP(MOD(BE16*100,100),0)&")", IF(AND(BE16>=8,BE16<9),"(opt, "&ROUNDUP(MOD(BE16*100,100),0)&")", IF(AND(BE16>=9,BE16<10),"(nouă, "&ROUNDUP(MOD(BE16*100,100),0)&")", IF(BE16=10,"(zece, 00)", ))))))))))),"") | BG16: =IF(NOT(ISBLANK(C16)), IF(BE16=" "," ", IF(AND(BE16>=1,BE16<=3),"F", IF(AND(BE16>3,BE16<5),"FX", IF(AND(BE16>=5,BE16<=6),"E", IF(AND(BE16>6,BE16<=7),"D", IF(AND(BE16>7,BE16<=8),"C", IF(AND(BE16>8,BE16<=9),"B", IF(AND(BE16>9,BE16<=10),"A", )))))))),"")
B17: =IF(NOT(ISBLANK(C17)),COUNTA($C$6:C17),"") | T17: =IF(NOT(ISBLANK(C17)),IF(COUNTIF(E17:S17,"a")<>0,COUNTIF(E17:S17,"a")*2,""),"") | AJ17: =IF(NOT(ISBLANK(B17)),IF(COUNTIF(U17:AI17,"a")<>0,COUNTIF(U17:AI17,"a")*2,""),"") | AK17: =IF(NOT(ISBLANK(C17)),IF(COUNTIF(E17:AI17,"a")<>0,COUNTIF(E17:AI17,"a")*2,""),"") | AM17: ='Atest. Nr.1_1'!I13 | AN17: ='Atest. Nr.1_2'!I13 | AO17: ='Atest. Nr.1_3'!I13 | AP17: ='Atest. Nr.2_1'!I13 | AQ17: ='Atest. Nr.2_2'!I13 | AR17: ='Atest. Nr.2_3'!I13 | AS17: =Examen!G13 | AT17: =ReExaminare!G13 | AU17: =IF(NOT(ISBLANK(B17)), IF(SUM(E17:S17,U17:AI17)<>0,SUM(E17:S17,U17:AI17),""), "") | AY17: =IF(NOT(ISBLANK(C17)), IF(COUNT(MAX(AVERAGE(AM17:AO17),0)),MAX(AM17:AO17),"n/p"), "") | AZ17: =IF(NOT(ISBLANK(C17)), IF(COUNT(MAX(AVERAGE(AP17:AR17),0)),MAX(AP17:AR17),"n/p"), "") | BA17: ='Ev. Curenta'!I13 | BB17: =IF(NOT(ISBLANK(C17)), IF('L. Indiv.'!G13<>"n/p",'L. Indiv.'!G13,"n/p"), "") | BC17: =IF(NOT(ISBLANK(C17)), IF(OR(AY17="n/p",AZ17="n/p",BA17="n/p",BB17="n/p",AY17<5,AZ17<5,BA17<5,BB17<5)," ",TRUNC(SUM(AY17:BB17)/4,2)), "") | BD17: =IF(NOT(ISBLANK(C17)), IF(BC17=" ","n/a", IF(AX17,AX17, IF(COUNT(MAX(AVERAGE(AS17:AT17),0)),MAX(AS17:AT17),"n/p"))), "") | BE17: =IF(NOT(ISBLANK(C17)), IF(OR(BD17="n/a",BD17="n/p")," ", IF(BD17<5,BD17,TRUNC(BC17*0.6+BD17*0.4,2))), "") | BF17: =IF(NOT(ISBLANK(C17)), IF(BE17=" "," ", IF(AND(BE17>=1,BE17<2),"(unu, "&ROUNDUP(MOD(BE17*100,100),0)&")", IF(AND(BE17>=2,BE17<3),"(doi, "&ROUNDUP(MOD(BE17*100,100),0)&")", IF(AND(BE17>=3,BE17<4),"(trei, "&ROUNDUP(MOD(BE17*100,100),0)&")", IF(AND(BE17>=4,BE17<5),"(patru, "&ROUNDUP(MOD(BE17*100,100),0)&")", IF(AND(BE17>=5,BE17<6),"(cinci, "&ROUNDUP(MOD(BE17*100,100),0)&")", IF(AND(BE17>=6,BE17<7),"(şase, "&ROUNDUP(MOD(BE17*100,100),0)&")", IF(AND(BE17>=7,BE17<8),"(şapte, "&ROUNDUP(MOD(BE17*100,100),0)&")", IF(AND(BE17>=8,BE17<9),"(opt, "&ROUNDUP(MOD(BE17*100,100),0)&")", IF(AND(BE17>=9,BE17<10),"(nouă, "&ROUNDUP(MOD(BE17*100,100),0)&")", IF(BE17=10,"(zece, 00)", ))))))))))),"") | BG17: =IF(NOT(ISBLANK(C17)), IF(BE17=" "," ", IF(AND(BE17>=1,BE17<=3),"F", IF(AND(BE17>3,BE17<5),"FX", IF(AND(BE17>=5,BE17<=6),"E", IF(AND(BE17>6,BE17<=7),"D", IF(AND(BE17>7,BE17<=8),"C", IF(AND(BE17>8,BE17<=9),"B", IF(AND(BE17>9,BE17<=10),"A", )))))))),"")
B18: =IF(NOT(ISBLANK(C18)),COUNTA($C$6:C18),"") | T18: =IF(NOT(ISBLANK(C18)),IF(COUNTIF(E18:S18,"a")<>0,COUNTIF(E18:S18,"a")*2,""),"") | AJ18: =IF(NOT(ISBLANK(B18)),IF(COUNTIF(U18:AI18,"a")<>0,COUNTIF(U18:AI18,"a")*2,""),"") | AK18: =IF(NOT(ISBLANK(C18)),IF(COUNTIF(E18:AI18,"a")<>0,COUNTIF(E18:AI18,"a")*2,""),"") | AM18: ='Atest. Nr.1_1'!I14 | AN18: ='Atest. Nr.1_2'!I14 | AO18: ='Atest. Nr.1_3'!I14 | AP18: ='Atest. Nr.2_1'!I14 | AQ18: ='Atest. Nr.2_2'!I14 | AR18: ='Atest. Nr.2_3'!I14 | AS18: =Examen!G14 | AT18: =ReExaminare!G14 | AU18: =IF(NOT(ISBLANK(B18)), IF(SUM(E18:S18,U18:AI18)<>0,SUM(E18:S18,U18:AI18),""), "") | AY18: =IF(NOT(ISBLANK(C18)), IF(COUNT(MAX(AVERAGE(AM18:AO18),0)),MAX(AM18:AO18),"n/p"), "") | AZ18: =IF(NOT(ISBLANK(C18)), IF(COUNT(MAX(AVERAGE(AP18:AR18),0)),MAX(AP18:AR18),"n/p"), "") | BA18: ='Ev. Curenta'!I14 | BB18: =IF(NOT(ISBLANK(C18)), IF('L. Indiv.'!G14<>"n/p",'L. Indiv.'!G14,"n/p"), "") | BC18: =IF(NOT(ISBLANK(C18)), IF(OR(AY18="n/p",AZ18="n/p",BA18="n/p",BB18="n/p",AY18<5,AZ18<5,BA18<5,BB18<5)," ",TRUNC(SUM(AY18:BB18)/4,2)), "") | BD18: =IF(NOT(ISBLANK(C18)), IF(BC18=" ","n/a", IF(AX18,AX18, IF(COUNT(MAX(AVERAGE(AS18:AT18),0)),MAX(AS18:AT18),"n/p"))), "") | BE18: =IF(NOT(ISBLANK(C18)), IF(OR(BD18="n/a",BD18="n/p")," ", IF(BD18<5,BD18,TRUNC(BC18*0.6+BD18*0.4,2))), "") | BF18: =IF(NOT(ISBLANK(C18)), IF(BE18=" "," ", IF(AND(BE18>=1,BE18<2),"(unu, "&ROUNDUP(MOD(BE18*100,100),0)&")", IF(AND(BE18>=2,BE18<3),"(doi, "&ROUNDUP(MOD(BE18*100,100),0)&")", IF(AND(BE18>=3,BE18<4),"(trei, "&ROUNDUP(MOD(BE18*100,100),0)&")", IF(AND(BE18>=4,BE18<5),"(patru, "&ROUNDUP(MOD(BE18*100,100),0)&")", IF(AND(BE18>=5,BE18<6),"(cinci, "&ROUNDUP(MOD(BE18*100,100),0)&")", IF(AND(BE18>=6,BE18<7),"(şase, "&ROUNDUP(MOD(BE18*100,100),0)&")", IF(AND(BE18>=7,BE18<8),"(şapte, "&ROUNDUP(MOD(BE18*100,100),0)&")", IF(AND(BE18>=8,BE18<9),"(opt, "&ROUNDUP(MOD(BE18*100,100),0)&")", IF(AND(BE18>=9,BE18<10),"(nouă, "&ROUNDUP(MOD(BE18*100,100),0)&")", IF(BE18=10,"(zece, 00)", ))))))))))),"") | BG18: =IF(NOT(ISBLANK(C18)), IF(BE18=" "," ", IF(AND(BE18>=1,BE18<=3),"F", IF(AND(BE18>3,BE18<5),"FX", IF(AND(BE18>=5,BE18<=6),"E", IF(AND(BE18>6,BE18<=7),"D", IF(AND(BE18>7,BE18<=8),"C", IF(AND(BE18>8,BE18<=9),"B", IF(AND(BE18>9,BE18<=10),"A", )))))))),"") | BK18: Evaluarea periodică Nr.2 | BX18: Reușita din nr. total, %
B19: =IF(NOT(ISBLANK(C19)),COUNTA($C$6:C19),"") | T19: =IF(NOT(ISBLANK(C19)),IF(COUNTIF(E19:S19,"a")<>0,COUNTIF(E19:S19,"a")*2,""),"") | AJ19: =IF(NOT(ISBLANK(B19)),IF(COUNTIF(U19:AI19,"a")<>0,COUNTIF(U19:AI19,"a")*2,""),"") | AK19: =IF(NOT(ISBLANK(C19)),IF(COUNTIF(E19:AI19,"a")<>0,COUNTIF(E19:AI19,"a")*2,""),"") | AM19: ='Atest. Nr.1_1'!I15 | AN19: ='Atest. Nr.1_2'!I15 | AO19: ='Atest. Nr.1_3'!I15 | AP19: ='Atest. Nr.2_1'!I15 | AQ19: ='Atest. Nr.2_2'!I15 | AR19: ='Atest. Nr.2_3'!I15 | AS19: =Examen!G15 | AT19: =ReExaminare!G15 | AU19: =IF(NOT(ISBLANK(B19)), IF(SUM(E19:S19,U19:AI19)<>0,SUM(E19:S19,U19:AI19),""), "") | AY19: =IF(NOT(ISBLANK(C19)), IF(COUNT(MAX(AVERAGE(AM19:AO19),0)),MAX(AM19:AO19),"n/p"), "") | AZ19: =IF(NOT(ISBLANK(C19)), IF(COUNT(MAX(AVERAGE(AP19:AR19),0)),MAX(AP19:AR19),"n/p"), "") | BA19: ='Ev. Curenta'!I15 | BB19: =IF(NOT(ISBLANK(C19)), IF('L. Indiv.'!G15<>"n/p",'L. Indiv.'!G15,"n/p"), "") | BC19: =IF(NOT(ISBLANK(C19)), IF(OR(AY19="n/p",AZ19="n/p",BA19="n/p",BB19="n/p",AY19<5,AZ19<5,BA19<5,BB19<5)," ",TRUNC(SUM(AY19:BB19)/4,2)), "") | BD19: =IF(NOT(ISBLANK(C19)), IF(BC19=" ","n/a", IF(AX19,AX19, IF(COUNT(MAX(AVERAGE(AS19:AT19),0)),MAX(AS19:AT19),"n/p"))), "") | BE19: =IF(NOT(ISBLANK(C19)), IF(OR(BD19="n/a",BD19="n/p")," ", IF(BD19<5,BD19,TRUNC(BC19*0.6+BD19*0.4,2))), "") | BF19: =IF(NOT(ISBLANK(C19)), IF(BE19=" "," ", IF(AND(BE19>=1,BE19<2),"(unu, "&ROUNDUP(MOD(BE19*100,100),0)&")", IF(AND(BE19>=2,BE19<3),"(doi, "&ROUNDUP(MOD(BE19*100,100),0)&")", IF(AND(BE19>=3,BE19<4),"(trei, "&ROUNDUP(MOD(BE19*100,100),0)&")", IF(AND(BE19>=4,BE19<5),"(patru, "&ROUNDUP(MOD(BE19*100,100),0)&")", IF(AND(BE19>=5,BE19<6),"(cinci, "&ROUNDUP(MOD(BE19*100,100),0)&")", IF(AND(BE19>=6,BE19<7),"(şase, "&ROUNDUP(MOD(BE19*100,100),0)&")", IF(AND(BE19>=7,BE19<8),"(şapte, "&ROUNDUP(MOD(BE19*100,100),0)&")", IF(AND(BE19>=8,BE19<9),"(opt, "&ROUNDUP(MOD(BE19*100,100),0)&")", IF(AND(BE19>=9,BE19<10),"(nouă, "&ROUNDUP(MOD(BE19*100,100),0)&")", IF(BE19=10,"(zece, 00)", ))))))))))),"") | BG19: =IF(NOT(ISBLANK(C19)), IF(BE19=" "," ", IF(AND(BE19>=1,BE19<=3),"F", IF(AND(BE19>3,BE19<5),"FX", IF(AND(BE19>=5,BE19<=6),"E", IF(AND(BE19>6,BE19<=7),"D", IF(AND(BE19>7,BE19<=8),"C", IF(AND(BE19>8,BE19<=9),"B", IF(AND(BE19>9,BE19<=10),"A", )))))))),"")
B20: =IF(NOT(ISBLANK(C20)),COUNTA($C$6:C20),"") | T20: =IF(NOT(ISBLANK(C20)),IF(COUNTIF(E20:S20,"a")<>0,COUNTIF(E20:S20,"a")*2,""),"") | AJ20: =IF(NOT(ISBLANK(B20)),IF(COUNTIF(U20:AI20,"a")<>0,COUNTIF(U20:AI20,"a")*2,""),"") | AK20: =IF(NOT(ISBLANK(C20)),IF(COUNTIF(E20:AI20,"a")<>0,COUNTIF(E20:AI20,"a")*2,""),"") | AM20: ='Atest. Nr.1_1'!I16 | AN20: ='Atest. Nr.1_2'!I16 | AO20: ='Atest. Nr.1_3'!I16 | AP20: ='Atest. Nr.2_1'!I16 | AQ20: ='Atest. Nr.2_2'!I16 | AR20: ='Atest. Nr.2_3'!I16 | AS20: =Examen!G16 | AT20: =ReExaminare!G16 | AU20: =IF(NOT(ISBLANK(B20)), IF(SUM(E20:S20,U20:AI20)<>0,SUM(E20:S20,U20:AI20),""), "") | AY20: =IF(NOT(ISBLANK(C20)), IF(COUNT(MAX(AVERAGE(AM20:AO20),0)),MAX(AM20:AO20),"n/p"), "") | AZ20: =IF(NOT(ISBLANK(C20)), IF(COUNT(MAX(AVERAGE(AP20:AR20),0)),MAX(AP20:AR20),"n/p"), "") | BA20: ='Ev. Curenta'!I16 | BB20: =IF(NOT(ISBLANK(C20)), IF('L. Indiv.'!G16<>"n/p",'L. Indiv.'!G16,"n/p"), "") | BC20: =IF(NOT(ISBLANK(C20)), IF(OR(AY20="n/p",AZ20="n/p",BA20="n/p",BB20="n/p",AY20<5,AZ20<5,BA20<5,BB20<5)," ",TRUNC(SUM(AY20:BB20)/4,2)), "") | BD20: =IF(NOT(ISBLANK(C20)), IF(BC20=" ","n/a", IF(AX20,AX20, IF(COUNT(MAX(AVERAGE(AS20:AT20),0)),MAX(AS20:AT20),"n/p"))), "") | BE20: =IF(NOT(ISBLANK(C20)), IF(OR(BD20="n/a",BD20="n/p")," ", IF(BD20<5,BD20,TRUNC(BC20*0.6+BD20*0.4,2))), "") | BF20: =IF(NOT(ISBLANK(C20)), IF(BE20=" "," ", IF(AND(BE20>=1,BE20<2),"(unu, "&ROUNDUP(MOD(BE20*100,100),0)&")", IF(AND(BE20>=2,BE20<3),"(doi, "&ROUNDUP(MOD(BE20*100,100),0)&")", IF(AND(BE20>=3,BE20<4),"(trei, "&ROUNDUP(MOD(BE20*100,100),0)&")", IF(AND(BE20>=4,BE20<5),"(patru, "&ROUNDUP(MOD(BE20*100,100),0)&")", IF(AND(BE20>=5,BE20<6),"(cinci, "&ROUNDUP(MOD(BE20*100,100),0)&")", IF(AND(BE20>=6,BE20<7),"(şase, "&ROUNDUP(MOD(BE20*100,100),0)&")", IF(AND(BE20>=7,BE20<8),"(şapte, "&ROUNDUP(MOD(BE20*100,100),0)&")", IF(AND(BE20>=8,BE20<9),"(opt, "&ROUNDUP(MOD(BE20*100,100),0)&")", IF(AND(BE20>=9,BE20<10),"(nouă, "&ROUNDUP(MOD(BE20*100,100),0)&")", IF(BE20=10,"(zece, 00)", ))))))))))),"") | BG20: =IF(NOT(ISBLANK(C20)), IF(BE20=" "," ", IF(AND(BE20>=1,BE20<=3),"F", IF(AND(BE20>3,BE20<5),"FX", IF(AND(BE20>=5,BE20<=6),"E", IF(AND(BE20>6,BE20<=7),"D", IF(AND(BE20>7,BE20<=8),"C", IF(AND(BE20>8,BE20<=9),"B", IF(AND(BE20>9,BE20<=10),"A", )))))))),"") | BK20: Nr. stud | BL20: n/p | BM20: 1 | BN20: 2 | BO20: 3 | BP20: 4 | BQ20: 5 | BR20: 6 | BS20: 7 | BT20: 8 | BU20: 9 | BV20: 10
B21: =IF(NOT(ISBLANK(C21)),COUNTA($C$6:C21),"") | T21: =IF(NOT(ISBLANK(C21)),IF(COUNTIF(E21:S21,"a")<>0,COUNTIF(E21:S21,"a")*2,""),"") | AJ21: =IF(NOT(ISBLANK(B21)),IF(COUNTIF(U21:AI21,"a")<>0,COUNTIF(U21:AI21,"a")*2,""),"") | AK21: =IF(NOT(ISBLANK(C21)),IF(COUNTIF(E21:AI21,"a")<>0,COUNTIF(E21:AI21,"a")*2,""),"") | AM21: ='Atest. Nr.1_1'!I17 | AN21: ='Atest. Nr.1_2'!I17 | AO21: ='Atest. Nr.1_3'!I17 | AP21: ='Atest. Nr.2_1'!I17 | AQ21: ='Atest. Nr.2_2'!I17 | AR21: ='Atest. Nr.2_3'!I17 | AS21: =Examen!G17 | AT21: =ReExaminare!G17 | AU21: =IF(NOT(ISBLANK(B21)), IF(SUM(E21:S21,U21:AI21)<>0,SUM(E21:S21,U21:AI21),""), "") | AY21: =IF(NOT(ISBLANK(C21)), IF(COUNT(MAX(AVERAGE(AM21:AO21),0)),MAX(AM21:AO21),"n/p"), "") | AZ21: =IF(NOT(ISBLANK(C21)), IF(COUNT(MAX(AVERAGE(AP21:AR21),0)),MAX(AP21:AR21),"n/p"), "") | BA21: ='Ev. Curenta'!I17 | BB21: =IF(NOT(ISBLANK(C21)), IF('L. Indiv.'!G17<>"n/p",'L. Indiv.'!G17,"n/p"), "") | BC21: =IF(NOT(ISBLANK(C21)), IF(OR(AY21="n/p",AZ21="n/p",BA21="n/p",BB21="n/p",AY21<5,AZ21<5,BA21<5,BB21<5)," ",TRUNC(SUM(AY21:BB21)/4,2)), "") | BD21: =IF(NOT(ISBLANK(C21)), IF(BC21=" ","n/a", IF(AX21,AX21, IF(COUNT(MAX(AVERAGE(AS21:AT21),0)),MAX(AS21:AT21),"n/p"))), "") | BE21: =IF(NOT(ISBLANK(C21)), IF(OR(BD21="n/a",BD21="n/p")," ", IF(BD21<5,BD21,TRUNC(BC21*0.6+BD21*0.4,2))), "") | BF21: =IF(NOT(ISBLANK(C21)), IF(BE21=" "," ", IF(AND(BE21>=1,BE21<2),"(unu, "&ROUNDUP(MOD(BE21*100,100),0)&")", IF(AND(BE21>=2,BE21<3),"(doi, "&ROUNDUP(MOD(BE21*100,100),0)&")", IF(AND(BE21>=3,BE21<4),"(trei, "&ROUNDUP(MOD(BE21*100,100),0)&")", IF(AND(BE21>=4,BE21<5),"(patru, "&ROUNDUP(MOD(BE21*100,100),0)&")", IF(AND(BE21>=5,BE21<6),"(cinci, "&ROUNDUP(MOD(BE21*100,100),0)&")", IF(AND(BE21>=6,BE21<7),"(şase, "&ROUNDUP(MOD(BE21*100,100),0)&")", IF(AND(BE21>=7,BE21<8),"(şapte, "&ROUNDUP(MOD(BE21*100,100),0)&")", IF(AND(BE21>=8,BE21<9),"(opt, "&ROUNDUP(MOD(BE21*100,100),0)&")", IF(AND(BE21>=9,BE21<10),"(nouă, "&ROUNDUP(MOD(BE21*100,100),0)&")", IF(BE21=10,"(zece, 00)", ))))))))))),"") | BG21: =IF(NOT(ISBLANK(C21)), IF(BE21=" "," ", IF(AND(BE21>=1,BE21<=3),"F", IF(AND(BE21>3,BE21<5),"FX", IF(AND(BE21>=5,BE21<=6),"E", IF(AND(BE21>6,BE21<=7),"D", IF(AND(BE21>7,BE21<=8),"C", IF(AND(BE21>8,BE21<=9),"B", IF(AND(BE21>9,BE21<=10),"A", )))))))),"")
B22: =IF(NOT(ISBLANK(C22)),COUNTA($C$6:C22),"") | T22: =IF(NOT(ISBLANK(C22)),IF(COUNTIF(E22:S22,"a")<>0,COUNTIF(E22:S22,"a")*2,""),"") | AJ22: =IF(NOT(ISBLANK(B22)),IF(COUNTIF(U22:AI22,"a")<>0,COUNTIF(U22:AI22,"a")*2,""),"") | AK22: =IF(NOT(ISBLANK(C22)),IF(COUNTIF(E22:AI22,"a")<>0,COUNTIF(E22:AI22,"a")*2,""),"") | AM22: ='Atest. Nr.1_1'!I18 | AN22: ='Atest. Nr.1_2'!I18 | AO22: ='Atest. Nr.1_3'!I18 | AP22: ='Atest. Nr.2_1'!I18 | AQ22: ='Atest. Nr.2_2'!I18 | AR22: ='Atest. Nr.2_3'!I18 | AS22: =Examen!G18 | AT22: =ReExaminare!G18 | AU22: =IF(NOT(ISBLANK(B22)), IF(SUM(E22:S22,U22:AI22)<>0,SUM(E22:S22,U22:AI22),""), "") | AY22: =IF(NOT(ISBLANK(C22)), IF(COUNT(MAX(AVERAGE(AM22:AO22),0)),MAX(AM22:AO22),"n/p"), "") | AZ22: =IF(NOT(ISBLANK(C22)), IF(COUNT(MAX(AVERAGE(AP22:AR22),0)),MAX(AP22:AR22),"n/p"), "") | BA22: ='Ev. Curenta'!I18 | BB22: =IF(NOT(ISBLANK(C22)), IF('L. Indiv.'!G18<>"n/p",'L. Indiv.'!G18,"n/p"), "") | BC22: =IF(NOT(ISBLANK(C22)), IF(OR(AY22="n/p",AZ22="n/p",BA22="n/p",BB22="n/p",AY22<5,AZ22<5,BA22<5,BB22<5)," ",TRUNC(SUM(AY22:BB22)/4,2)), "") | BD22: =IF(NOT(ISBLANK(C22)), IF(BC22=" ","n/a", IF(AX22,AX22, IF(COUNT(MAX(AVERAGE(AS22:AT22),0)),MAX(AS22:AT22),"n/p"))), "") | BE22: =IF(NOT(ISBLANK(C22)), IF(OR(BD22="n/a",BD22="n/p")," ", IF(BD22<5,BD22,TRUNC(BC22*0.6+BD22*0.4,2))), "") | BF22: =IF(NOT(ISBLANK(C22)), IF(BE22=" "," ", IF(AND(BE22>=1,BE22<2),"(unu, "&ROUNDUP(MOD(BE22*100,100),0)&")", IF(AND(BE22>=2,BE22<3),"(doi, "&ROUNDUP(MOD(BE22*100,100),0)&")", IF(AND(BE22>=3,BE22<4),"(trei, "&ROUNDUP(MOD(BE22*100,100),0)&")", IF(AND(BE22>=4,BE22<5),"(patru, "&ROUNDUP(MOD(BE22*100,100),0)&")", IF(AND(BE22>=5,BE22<6),"(cinci, "&ROUNDUP(MOD(BE22*100,100),0)&")", IF(AND(BE22>=6,BE22<7),"(şase, "&ROUNDUP(MOD(BE22*100,100),0)&")", IF(AND(BE22>=7,BE22<8),"(şapte, "&ROUNDUP(MOD(BE22*100,100),0)&")", IF(AND(BE22>=8,BE22<9),"(opt, "&ROUNDUP(MOD(BE22*100,100),0)&")", IF(AND(BE22>=9,BE22<10),"(nouă, "&ROUNDUP(MOD(BE22*100,100),0)&")", IF(BE22=10,"(zece, 00)", ))))))))))),"") | BG22: =IF(NOT(ISBLANK(C22)), IF(BE22=" "," ", IF(AND(BE22>=1,BE22<=3),"F", IF(AND(BE22>3,BE22<5),"FX", IF(AND(BE22>=5,BE22<=6),"E", IF(AND(BE22>6,BE22<=7),"D", IF(AND(BE22>7,BE22<=8),"C", IF(AND(BE22>8,BE22<=9),"B", IF(AND(BE22>9,BE22<=10),"A", )))))))),"") | BK22: =COUNTA(T6:T105) -> 100 | BL22: =COUNTIF($AI$6:$AI$105,BL20) -> 0 | BM22: =COUNTIF($AI$6:$AI$105,BM20) -> 0 | BN22: =COUNTIF($AI$6:$AI$105,BN20) -> 0 | BO22: =COUNTIF($AI$6:$AI$105,BO20) -> 0 | BP22: =COUNTIF($AI$6:$AI$105,BP20) -> 0 | BQ22: =COUNTIF($AI$6:$AI$105,BQ20) -> 0 | BR22: =COUNTIF($AI$6:$AI$105,BR20) -> 0 | BS22: =COUNTIF($AI$6:$AI$105,BS20) -> 0 | ... BV22: =COUNTIF($AI$6:$AI$105,BV20) -> 0 | BX22: =SUM(BQ22:BV23)/BK22 -> 0
B23: =IF(NOT(ISBLANK(C23)),COUNTA($C$6:C23),"") | T23: =IF(NOT(ISBLANK(C23)),IF(COUNTIF(E23:S23,"a")<>0,COUNTIF(E23:S23,"a")*2,""),"") | AJ23: =IF(NOT(ISBLANK(B23)),IF(COUNTIF(U23:AI23,"a")<>0,COUNTIF(U23:AI23,"a")*2,""),"") | AK23: =IF(NOT(ISBLANK(C23)),IF(COUNTIF(E23:AI23,"a")<>0,COUNTIF(E23:AI23,"a")*2,""),"") | AM23: ='Atest. Nr.1_1'!I19 | AN23: ='Atest. Nr.1_2'!I19 | AO23: ='Atest. Nr.1_3'!I19 | AP23: ='Atest. Nr.2_1'!I19 | AQ23: ='Atest. Nr.2_2'!I19 | AR23: ='Atest. Nr.2_3'!I19 | AS23: =Examen!G19 | AT23: =ReExaminare!G19 | AU23: =IF(NOT(ISBLANK(B23)), IF(SUM(E23:S23,U23:AI23)<>0,SUM(E23:S23,U23:AI23),""), "") | AY23: =IF(NOT(ISBLANK(C23)), IF(COUNT(MAX(AVERAGE(AM23:AO23),0)),MAX(AM23:AO23),"n/p"), "") | AZ23: =IF(NOT(ISBLANK(C23)), IF(COUNT(MAX(AVERAGE(AP23:AR23),0)),MAX(AP23:AR23),"n/p"), "") | BA23: ='Ev. Curenta'!I19 | BB23: =IF(NOT(ISBLANK(C23)), IF('L. Indiv.'!G19<>"n/p",'L. Indiv.'!G19,"n/p"), "") | BC23: =IF(NOT(ISBLANK(C23)), IF(OR(AY23="n/p",AZ23="n/p",BA23="n/p",BB23="n/p",AY23<5,AZ23<5,BA23<5,BB23<5)," ",TRUNC(SUM(AY23:BB23)/4,2)), "") | BD23: =IF(NOT(ISBLANK(C23)), IF(BC23=" ","n/a", IF(AX23,AX23, IF(COUNT(MAX(AVERAGE(AS23:AT23),0)),MAX(AS23:AT23),"n/p"))), "") | BE23: =IF(NOT(ISBLANK(C23)), IF(OR(BD23="n/a",BD23="n/p")," ", IF(BD23<5,BD23,TRUNC(BC23*0.6+BD23*0.4,2))), "") | BF23: =IF(NOT(ISBLANK(C23)), IF(BE23=" "," ", IF(AND(BE23>=1,BE23<2),"(unu, "&ROUNDUP(MOD(BE23*100,100),0)&")", IF(AND(BE23>=2,BE23<3),"(doi, "&ROUNDUP(MOD(BE23*100,100),0)&")", IF(AND(BE23>=3,BE23<4),"(trei, "&ROUNDUP(MOD(BE23*100,100),0)&")", IF(AND(BE23>=4,BE23<5),"(patru, "&ROUNDUP(MOD(BE23*100,100),0)&")", IF(AND(BE23>=5,BE23<6),"(cinci, "&ROUNDUP(MOD(BE23*100,100),0)&")", IF(AND(BE23>=6,BE23<7),"(şase, "&ROUNDUP(MOD(BE23*100,100),0)&")", IF(AND(BE23>=7,BE23<8),"(şapte, "&ROUNDUP(MOD(BE23*100,100),0)&")", IF(AND(BE23>=8,BE23<9),"(opt, "&ROUNDUP(MOD(BE23*100,100),0)&")", IF(AND(BE23>=9,BE23<10),"(nouă, "&ROUNDUP(MOD(BE23*100,100),0)&")", IF(BE23=10,"(zece, 00)", ))))))))))),"") | BG23: =IF(NOT(ISBLANK(C23)), IF(BE23=" "," ", IF(AND(BE23>=1,BE23<=3),"F", IF(AND(BE23>3,BE23<5),"FX", IF(AND(BE23>=5,BE23<=6),"E", IF(AND(BE23>6,BE23<=7),"D", IF(AND(BE23>7,BE23<=8),"C", IF(AND(BE23>8,BE23<=9),"B", IF(AND(BE23>9,BE23<=10),"A", )))))))),"")
B24: =IF(NOT(ISBLANK(C24)),COUNTA($C$6:C24),"") | T24: =IF(NOT(ISBLANK(C24)),IF(COUNTIF(E24:S24,"a")<>0,COUNTIF(E24:S24,"a")*2,""),"") | AJ24: =IF(NOT(ISBLANK(B24)),IF(COUNTIF(U24:AI24,"a")<>0,COUNTIF(U24:AI24,"a")*2,""),"") | AK24: =IF(NOT(ISBLANK(C24)),IF(COUNTIF(E24:AI24,"a")<>0,COUNTIF(E24:AI24,"a")*2,""),"") | AM24: ='Atest. Nr.1_1'!I20 | AN24: ='Atest. Nr.1_2'!I20 | AO24: ='Atest. Nr.1_3'!I20 | AP24: ='Atest. Nr.2_1'!I20 | AQ24: ='Atest. Nr.2_2'!I20 | AR24: ='Atest. Nr.2_3'!I20 | AS24: =Examen!G20 | AT24: =ReExaminare!G20 | AU24: =IF(NOT(ISBLANK(B24)), IF(SUM(E24:S24,U24:AI24)<>0,SUM(E24:S24,U24:AI24),""), "") | AY24: =IF(NOT(ISBLANK(C24)), IF(COUNT(MAX(AVERAGE(AM24:AO24),0)),MAX(AM24:AO24),"n/p"), "") | AZ24: =IF(NOT(ISBLANK(C24)), IF(COUNT(MAX(AVERAGE(AP24:AR24),0)),MAX(AP24:AR24),"n/p"), "") | BA24: ='Ev. Curenta'!I20 | BB24: =IF(NOT(ISBLANK(C24)), IF('L. Indiv.'!G20<>"n/p",'L. Indiv.'!G20,"n/p"), "") | BC24: =IF(NOT(ISBLANK(C24)), IF(OR(AY24="n/p",AZ24="n/p",BA24="n/p",BB24="n/p",AY24<5,AZ24<5,BA24<5,BB24<5)," ",TRUNC(SUM(AY24:BB24)/4,2)), "") | BD24: =IF(NOT(ISBLANK(C24)), IF(BC24=" ","n/a", IF(AX24,AX24, IF(COUNT(MAX(AVERAGE(AS24:AT24),0)),MAX(AS24:AT24),"n/p"))), "") | BE24: =IF(NOT(ISBLANK(C24)), IF(OR(BD24="n/a",BD24="n/p")," ", IF(BD24<5,BD24,TRUNC(BC24*0.6+BD24*0.4,2))), "") | BF24: =IF(NOT(ISBLANK(C24)), IF(BE24=" "," ", IF(AND(BE24>=1,BE24<2),"(unu, "&ROUNDUP(MOD(BE24*100,100),0)&")", IF(AND(BE24>=2,BE24<3),"(doi, "&ROUNDUP(MOD(BE24*100,100),0)&")", IF(AND(BE24>=3,BE24<4),"(trei, "&ROUNDUP(MOD(BE24*100,100),0)&")", IF(AND(BE24>=4,BE24<5),"(patru, "&ROUNDUP(MOD(BE24*100,100),0)&")", IF(AND(BE24>=5,BE24<6),"(cinci, "&ROUNDUP(MOD(BE24*100,100),0)&")", IF(AND(BE24>=6,BE24<7),"(şase, "&ROUNDUP(MOD(BE24*100,100),0)&")", IF(AND(BE24>=7,BE24<8),"(şapte, "&ROUNDUP(MOD(BE24*100,100),0)&")", IF(AND(BE24>=8,BE24<9),"(opt, "&ROUNDUP(MOD(BE24*100,100),0)&")", IF(AND(BE24>=9,BE24<10),"(nouă, "&ROUNDUP(MOD(BE24*100,100),0)&")", IF(BE24=10,"(zece, 00)", ))))))))))),"") | BG24: =IF(NOT(ISBLANK(C24)), IF(BE24=" "," ", IF(AND(BE24>=1,BE24<=3),"F", IF(AND(BE24>3,BE24<5),"FX", IF(AND(BE24>=5,BE24<=6),"E", IF(AND(BE24>6,BE24<=7),"D", IF(AND(BE24>7,BE24<=8),"C", IF(AND(BE24>8,BE24<=9),"B", IF(AND(BE24>9,BE24<=10),"A", )))))))),"")
B25: =IF(NOT(ISBLANK(C25)),COUNTA($C$6:C25),"") | T25: =IF(NOT(ISBLANK(C25)),IF(COUNTIF(E25:S25,"a")<>0,COUNTIF(E25:S25,"a")*2,""),"") | AJ25: =IF(NOT(ISBLANK(B25)),IF(COUNTIF(U25:AI25,"a")<>0,COUNTIF(U25:AI25,"a")*2,""),"") | AK25: =IF(NOT(ISBLANK(C25)),IF(COUNTIF(E25:AI25,"a")<>0,COUNTIF(E25:AI25,"a")*2,""),"") | AM25: ='Atest. Nr.1_1'!I21 | AN25: ='Atest. Nr.1_2'!I21 | AO25: ='Atest. Nr.1_3'!I21 | AP25: ='Atest. Nr.2_1'!I21 | AQ25: ='Atest. Nr.2_2'!I21 | AR25: ='Atest. Nr.2_3'!I21 | AS25: =Examen!G21 | AT25: =ReExaminare!G21 | AU25: =IF(NOT(ISBLANK(B25)), IF(SUM(E25:S25,U25:AI25)<>0,SUM(E25:S25,U25:AI25),""), "") | AY25: =IF(NOT(ISBLANK(C25)), IF(COUNT(MAX(AVERAGE(AM25:AO25),0)),MAX(AM25:AO25),"n/p"), "") | AZ25: =IF(NOT(ISBLANK(C25)), IF(COUNT(MAX(AVERAGE(AP25:AR25),0)),MAX(AP25:AR25),"n/p"), "") | BA25: ='Ev. Curenta'!I21 | BB25: =IF(NOT(ISBLANK(C25)), IF('L. Indiv.'!G21<>"n/p",'L. Indiv.'!G21,"n/p"), "") | BC25: =IF(NOT(ISBLANK(C25)), IF(OR(AY25="n/p",AZ25="n/p",BA25="n/p",BB25="n/p",AY25<5,AZ25<5,BA25<5,BB25<5)," ",TRUNC(SUM(AY25:BB25)/4,2)), "") | BD25: =IF(NOT(ISBLANK(C25)), IF(BC25=" ","n/a", IF(AX25,AX25, IF(COUNT(MAX(AVERAGE(AS25:AT25),0)),MAX(AS25:AT25),"n/p"))), "") | BE25: =IF(NOT(ISBLANK(C25)), IF(OR(BD25="n/a",BD25="n/p")," ", IF(BD25<5,BD25,TRUNC(BC25*0.6+BD25*0.4,2))), "") | BF25: =IF(NOT(ISBLANK(C25)), IF(BE25=" "," ", IF(AND(BE25>=1,BE25<2),"(unu, "&ROUNDUP(MOD(BE25*100,100),0)&")", IF(AND(BE25>=2,BE25<3),"(doi, "&ROUNDUP(MOD(BE25*100,100),0)&")", IF(AND(BE25>=3,BE25<4),"(trei, "&ROUNDUP(MOD(BE25*100,100),0)&")", IF(AND(BE25>=4,BE25<5),"(patru, "&ROUNDUP(MOD(BE25*100,100),0)&")", IF(AND(BE25>=5,BE25<6),"(cinci, "&ROUNDUP(MOD(BE25*100,100),0)&")", IF(AND(BE25>=6,BE25<7),"(şase, "&ROUNDUP(MOD(BE25*100,100),0)&")", IF(AND(BE25>=7,BE25<8),"(şapte, "&ROUNDUP(MOD(BE25*100,100),0)&")", IF(AND(BE25>=8,BE25<9),"(opt, "&ROUNDUP(MOD(BE25*100,100),0)&")", IF(AND(BE25>=9,BE25<10),"(nouă, "&ROUNDUP(MOD(BE25*100,100),0)&")", IF(BE25=10,"(zece, 00)", ))))))))))),"") | BG25: =IF(NOT(ISBLANK(C25)), IF(BE25=" "," ", IF(AND(BE25>=1,BE25<=3),"F", IF(AND(BE25>3,BE25<5),"FX", IF(AND(BE25>=5,BE25<=6),"E", IF(AND(BE25>6,BE25<=7),"D", IF(AND(BE25>7,BE25<=8),"C", IF(AND(BE25>8,BE25<=9),"B", IF(AND(BE25>9,BE25<=10),"A", )))))))),"")
B26: =IF(NOT(ISBLANK(C26)),COUNTA($C$6:C26),"") | T26: =IF(NOT(ISBLANK(C26)),IF(COUNTIF(E26:S26,"a")<>0,COUNTIF(E26:S26,"a")*2,""),"") | AJ26: =IF(NOT(ISBLANK(B26)),IF(COUNTIF(U26:AI26,"a")<>0,COUNTIF(U26:AI26,"a")*2,""),"") | AK26: =IF(NOT(ISBLANK(C26)),IF(COUNTIF(E26:AI26,"a")<>0,COUNTIF(E26:AI26,"a")*2,""),"") | AM26: ='Atest. Nr.1_1'!I22 | AN26: ='Atest. Nr.1_2'!I22 | AO26: ='Atest. Nr.1_3'!I22 | AP26: ='Atest. Nr.2_1'!I22 | AQ26: ='Atest. Nr.2_2'!I22 | AR26: ='Atest. Nr.2_3'!I22 | AS26: =Examen!G22 | AT26: =ReExaminare!G22 | AU26: =IF(NOT(ISBLANK(B26)), IF(SUM(E26:S26,U26:AI26)<>0,SUM(E26:S26,U26:AI26),""), "") | AY26: =IF(NOT(ISBLANK(C26)), IF(COUNT(MAX(AVERAGE(AM26:AO26),0)),MAX(AM26:AO26),"n/p"), "") | AZ26: =IF(NOT(ISBLANK(C26)), IF(COUNT(MAX(AVERAGE(AP26:AR26),0)),MAX(AP26:AR26),"n/p"), "") | BA26: ='Ev. Curenta'!I22 | BB26: =IF(NOT(ISBLANK(C26)), IF('L. Indiv.'!G22<>"n/p",'L. Indiv.'!G22,"n/p"), "") | BC26: =IF(NOT(ISBLANK(C26)), IF(OR(AY26="n/p",AZ26="n/p",BA26="n/p",BB26="n/p",AY26<5,AZ26<5,BA26<5,BB26<5)," ",TRUNC(SUM(AY26:BB26)/4,2)), "") | BD26: =IF(NOT(ISBLANK(C26)), IF(BC26=" ","n/a", IF(AX26,AX26, IF(COUNT(MAX(AVERAGE(AS26:AT26),0)),MAX(AS26:AT26),"n/p"))), "") | BE26: =IF(NOT(ISBLANK(C26)), IF(OR(BD26="n/a",BD26="n/p")," ", IF(BD26<5,BD26,TRUNC(BC26*0.6+BD26*0.4,2))), "") | BF26: =IF(NOT(ISBLANK(C26)), IF(BE26=" "," ", IF(AND(BE26>=1,BE26<2),"(unu, "&ROUNDUP(MOD(BE26*100,100),0)&")", IF(AND(BE26>=2,BE26<3),"(doi, "&ROUNDUP(MOD(BE26*100,100),0)&")", IF(AND(BE26>=3,BE26<4),"(trei, "&ROUNDUP(MOD(BE26*100,100),0)&")", IF(AND(BE26>=4,BE26<5),"(patru, "&ROUNDUP(MOD(BE26*100,100),0)&")", IF(AND(BE26>=5,BE26<6),"(cinci, "&ROUNDUP(MOD(BE26*100,100),0)&")", IF(AND(BE26>=6,BE26<7),"(şase, "&ROUNDUP(MOD(BE26*100,100),0)&")", IF(AND(BE26>=7,BE26<8),"(şapte, "&ROUNDUP(MOD(BE26*100,100),0)&")", IF(AND(BE26>=8,BE26<9),"(opt, "&ROUNDUP(MOD(BE26*100,100),0)&")", IF(AND(BE26>=9,BE26<10),"(nouă, "&ROUNDUP(MOD(BE26*100,100),0)&")", IF(BE26=10,"(zece, 00)", ))))))))))),"") | BG26: =IF(NOT(ISBLANK(C26)), IF(BE26=" "," ", IF(AND(BE26>=1,BE26<=3),"F", IF(AND(BE26>3,BE26<5),"FX", IF(AND(BE26>=5,BE26<=6),"E", IF(AND(BE26>6,BE26<=7),"D", IF(AND(BE26>7,BE26<=8),"C", IF(AND(BE26>8,BE26<=9),"B", IF(AND(BE26>9,BE26<=10),"A", )))))))),"")
B27: =IF(NOT(ISBLANK(C27)),COUNTA($C$6:C27),"") | T27: =IF(NOT(ISBLANK(C27)),IF(COUNTIF(E27:S27,"a")<>0,COUNTIF(E27:S27,"a")*2,""),"") | AJ27: =IF(NOT(ISBLANK(B27)),IF(COUNTIF(U27:AI27,"a")<>0,COUNTIF(U27:AI27,"a")*2,""),"") | AK27: =IF(NOT(ISBLANK(C27)),IF(COUNTIF(E27:AI27,"a")<>0,COUNTIF(E27:AI27,"a")*2,""),"") | AM27: ='Atest. Nr.1_1'!I23 | AN27: ='Atest. Nr.1_2'!I23 | AO27: ='Atest. Nr.1_3'!I23 | AP27: ='Atest. Nr.2_1'!I23 | AQ27: ='Atest. Nr.2_2'!I23 | AR27: ='Atest. Nr.2_3'!I23 | AS27: =Examen!G23 | AT27: =ReExaminare!G23 | AU27: =IF(NOT(ISBLANK(B27)), IF(SUM(E27:S27,U27:AI27)<>0,SUM(E27:S27,U27:AI27),""), "") | AY27: =IF(NOT(ISBLANK(C27)), IF(COUNT(MAX(AVERAGE(AM27:AO27),0)),MAX(AM27:AO27),"n/p"), "") | AZ27: =IF(NOT(ISBLANK(C27)), IF(COUNT(MAX(AVERAGE(AP27:AR27),0)),MAX(AP27:AR27),"n/p"), "") | BA27: ='Ev. Curenta'!I23 | BB27: =IF(NOT(ISBLANK(C27)), IF('L. Indiv.'!G23<>"n/p",'L. Indiv.'!G23,"n/p"), "") | BC27: =IF(NOT(ISBLANK(C27)), IF(OR(AY27="n/p",AZ27="n/p",BA27="n/p",BB27="n/p",AY27<5,AZ27<5,BA27<5,BB27<5)," ",TRUNC(SUM(AY27:BB27)/4,2)), "") | BD27: =IF(NOT(ISBLANK(C27)), IF(BC27=" ","n/a", IF(AX27,AX27, IF(COUNT(MAX(AVERAGE(AS27:AT27),0)),MAX(AS27:AT27),"n/p"))), "") | BE27: =IF(NOT(ISBLANK(C27)), IF(OR(BD27="n/a",BD27="n/p")," ", IF(BD27<5,BD27,TRUNC(BC27*0.6+BD27*0.4,2))), "") | BF27: =IF(NOT(ISBLANK(C27)), IF(BE27=" "," ", IF(AND(BE27>=1,BE27<2),"(unu, "&ROUNDUP(MOD(BE27*100,100),0)&")", IF(AND(BE27>=2,BE27<3),"(doi, "&ROUNDUP(MOD(BE27*100,100),0)&")", IF(AND(BE27>=3,BE27<4),"(trei, "&ROUNDUP(MOD(BE27*100,100),0)&")", IF(AND(BE27>=4,BE27<5),"(patru, "&ROUNDUP(MOD(BE27*100,100),0)&")", IF(AND(BE27>=5,BE27<6),"(cinci, "&ROUNDUP(MOD(BE27*100,100),0)&")", IF(AND(BE27>=6,BE27<7),"(şase, "&ROUNDUP(MOD(BE27*100,100),0)&")", IF(AND(BE27>=7,BE27<8),"(şapte, "&ROUNDUP(MOD(BE27*100,100),0)&")", IF(AND(BE27>=8,BE27<9),"(opt, "&ROUNDUP(MOD(BE27*100,100),0)&")", IF(AND(BE27>=9,BE27<10),"(nouă, "&ROUNDUP(MOD(BE27*100,100),0)&")", IF(BE27=10,"(zece, 00)", ))))))))))),"") | BG27: =IF(NOT(ISBLANK(C27)), IF(BE27=" "," ", IF(AND(BE27>=1,BE27<=3),"F", IF(AND(BE27>3,BE27<5),"FX", IF(AND(BE27>=5,BE27<=6),"E", IF(AND(BE27>6,BE27<=7),"D", IF(AND(BE27>7,BE27<=8),"C", IF(AND(BE27>8,BE27<=9),"B", IF(AND(BE27>9,BE27<=10),"A", )))))))),"")
B28: =IF(NOT(ISBLANK(C28)),COUNTA($C$6:C28),"") | T28: =IF(NOT(ISBLANK(C28)),IF(COUNTIF(E28:S28,"a")<>0,COUNTIF(E28:S28,"a")*2,""),"") | AJ28: =IF(NOT(ISBLANK(B28)),IF(COUNTIF(U28:AI28,"a")<>0,COUNTIF(U28:AI28,"a")*2,""),"") | AK28: =IF(NOT(ISBLANK(C28)),IF(COUNTIF(E28:AI28,"a")<>0,COUNTIF(E28:AI28,"a")*2,""),"") | AM28: ='Atest. Nr.1_1'!I24 | AN28: ='Atest. Nr.1_2'!I24 | AO28: ='Atest. Nr.1_3'!I24 | AP28: ='Atest. Nr.2_1'!I24 | AQ28: ='Atest. Nr.2_2'!I24 | AR28: ='Atest. Nr.2_3'!I24 | AS28: =Examen!G24 | AT28: =ReExaminare!G24 | AU28: =IF(NOT(ISBLANK(B28)), IF(SUM(E28:S28,U28:AI28)<>0,SUM(E28:S28,U28:AI28),""), "") | AY28: =IF(NOT(ISBLANK(C28)), IF(COUNT(MAX(AVERAGE(AM28:AO28),0)),MAX(AM28:AO28),"n/p"), "") | AZ28: =IF(NOT(ISBLANK(C28)), IF(COUNT(MAX(AVERAGE(AP28:AR28),0)),MAX(AP28:AR28),"n/p"), "") | BA28: ='Ev. Curenta'!I24 | BB28: =IF(NOT(ISBLANK(C28)), IF('L. Indiv.'!G24<>"n/p",'L. Indiv.'!G24,"n/p"), "") | BC28: =IF(NOT(ISBLANK(C28)), IF(OR(AY28="n/p",AZ28="n/p",BA28="n/p",BB28="n/p",AY28<5,AZ28<5,BA28<5,BB28<5)," ",TRUNC(SUM(AY28:BB28)/4,2)), "") | BD28: =IF(NOT(ISBLANK(C28)), IF(BC28=" ","n/a", IF(AX28,AX28, IF(COUNT(MAX(AVERAGE(AS28:AT28),0)),MAX(AS28:AT28),"n/p"))), "") | BE28: =IF(NOT(ISBLANK(C28)), IF(OR(BD28="n/a",BD28="n/p")," ", IF(BD28<5,BD28,TRUNC(BC28*0.6+BD28*0.4,2))), "") | BF28: =IF(NOT(ISBLANK(C28)), IF(BE28=" "," ", IF(AND(BE28>=1,BE28<2),"(unu, "&ROUNDUP(MOD(BE28*100,100),0)&")", IF(AND(BE28>=2,BE28<3),"(doi, "&ROUNDUP(MOD(BE28*100,100),0)&")", IF(AND(BE28>=3,BE28<4),"(trei, "&ROUNDUP(MOD(BE28*100,100),0)&")", IF(AND(BE28>=4,BE28<5),"(patru, "&ROUNDUP(MOD(BE28*100,100),0)&")", IF(AND(BE28>=5,BE28<6),"(cinci, "&ROUNDUP(MOD(BE28*100,100),0)&")", IF(AND(BE28>=6,BE28<7),"(şase, "&ROUNDUP(MOD(BE28*100,100),0)&")", IF(AND(BE28>=7,BE28<8),"(şapte, "&ROUNDUP(MOD(BE28*100,100),0)&")", IF(AND(BE28>=8,BE28<9),"(opt, "&ROUNDUP(MOD(BE28*100,100),0)&")", IF(AND(BE28>=9,BE28<10),"(nouă, "&ROUNDUP(MOD(BE28*100,100),0)&")", IF(BE28=10,"(zece, 00)", ))))))))))),"") | BG28: =IF(NOT(ISBLANK(C28)), IF(BE28=" "," ", IF(AND(BE28>=1,BE28<=3),"F", IF(AND(BE28>3,BE28<5),"FX", IF(AND(BE28>=5,BE28<=6),"E", IF(AND(BE28>6,BE28<=7),"D", IF(AND(BE28>7,BE28<=8),"C", IF(AND(BE28>8,BE28<=9),"B", IF(AND(BE28>9,BE28<=10),"A", )))))))),"")
B29: =IF(NOT(ISBLANK(C29)),COUNTA($C$6:C29),"") | T29: =IF(NOT(ISBLANK(C29)),IF(COUNTIF(E29:S29,"a")<>0,COUNTIF(E29:S29,"a")*2,""),"") | AJ29: =IF(NOT(ISBLANK(B29)),IF(COUNTIF(U29:AI29,"a")<>0,COUNTIF(U29:AI29,"a")*2,""),"") | AK29: =IF(NOT(ISBLANK(C29)),IF(COUNTIF(E29:AI29,"a")<>0,COUNTIF(E29:AI29,"a")*2,""),"") | AM29: ='Atest. Nr.1_1'!I25 | AN29: ='Atest. Nr.1_2'!I25 | AO29: ='Atest. Nr.1_3'!I25 | AP29: ='Atest. Nr.2_1'!I25 | AQ29: ='Atest. Nr.2_2'!I25 | AR29: ='Atest. Nr.2_3'!I25 | AS29: =Examen!G25 | AT29: =ReExaminare!G25 | AU29: =IF(NOT(ISBLANK(B29)), IF(SUM(E29:S29,U29:AI29)<>0,SUM(E29:S29,U29:AI29),""), "") | AY29: =IF(NOT(ISBLANK(C29)), IF(COUNT(MAX(AVERAGE(AM29:AO29),0)),MAX(AM29:AO29),"n/p"), "") | AZ29: =IF(NOT(ISBLANK(C29)), IF(COUNT(MAX(AVERAGE(AP29:AR29),0)),MAX(AP29:AR29),"n/p"), "") | BA29: ='Ev. Curenta'!I25 | BB29: =IF(NOT(ISBLANK(C29)), IF('L. Indiv.'!G25<>"n/p",'L. Indiv.'!G25,"n/p"), "") | BC29: =IF(NOT(ISBLANK(C29)), IF(OR(AY29="n/p",AZ29="n/p",BA29="n/p",BB29="n/p",AY29<5,AZ29<5,BA29<5,BB29<5)," ",TRUNC(SUM(AY29:BB29)/4,2)), "") | BD29: =IF(NOT(ISBLANK(C29)), IF(BC29=" ","n/a", IF(AX29,AX29, IF(COUNT(MAX(AVERAGE(AS29:AT29),0)),MAX(AS29:AT29),"n/p"))), "") | BE29: =IF(NOT(ISBLANK(C29)), IF(OR(BD29="n/a",BD29="n/p")," ", IF(BD29<5,BD29,TRUNC(BC29*0.6+BD29*0.4,2))), "") | BF29: =IF(NOT(ISBLANK(C29)), IF(BE29=" "," ", IF(AND(BE29>=1,BE29<2),"(unu, "&ROUNDUP(MOD(BE29*100,100),0)&")", IF(AND(BE29>=2,BE29<3),"(doi, "&ROUNDUP(MOD(BE29*100,100),0)&")", IF(AND(BE29>=3,BE29<4),"(trei, "&ROUNDUP(MOD(BE29*100,100),0)&")", IF(AND(BE29>=4,BE29<5),"(patru, "&ROUNDUP(MOD(BE29*100,100),0)&")", IF(AND(BE29>=5,BE29<6),"(cinci, "&ROUNDUP(MOD(BE29*100,100),0)&")", IF(AND(BE29>=6,BE29<7),"(şase, "&ROUNDUP(MOD(BE29*100,100),0)&")", IF(AND(BE29>=7,BE29<8),"(şapte, "&ROUNDUP(MOD(BE29*100,100),0)&")", IF(AND(BE29>=8,BE29<9),"(opt, "&ROUNDUP(MOD(BE29*100,100),0)&")", IF(AND(BE29>=9,BE29<10),"(nouă, "&ROUNDUP(MOD(BE29*100,100),0)&")", IF(BE29=10,"(zece, 00)", ))))))))))),"") | BG29: =IF(NOT(ISBLANK(C29)), IF(BE29=" "," ", IF(AND(BE29>=1,BE29<=3),"F", IF(AND(BE29>3,BE29<5),"FX", IF(AND(BE29>=5,BE29<=6),"E", IF(AND(BE29>6,BE29<=7),"D", IF(AND(BE29>7,BE29<=8),"C", IF(AND(BE29>8,BE29<=9),"B", IF(AND(BE29>9,BE29<=10),"A", )))))))),"")
B30: =IF(NOT(ISBLANK(C30)),COUNTA($C$6:C30),"") | T30: =IF(NOT(ISBLANK(C30)),IF(COUNTIF(E30:S30,"a")<>0,COUNTIF(E30:S30,"a")*2,""),"") | AJ30: =IF(NOT(ISBLANK(B30)),IF(COUNTIF(U30:AI30,"a")<>0,COUNTIF(U30:AI30,"a")*2,""),"") | AK30: =IF(NOT(ISBLANK(C30)),IF(COUNTIF(E30:AI30,"a")<>0,COUNTIF(E30:AI30,"a")*2,""),"") | AM30: ='Atest. Nr.1_1'!I26 | AN30: ='Atest. Nr.1_2'!I26 | AO30: ='Atest. Nr.1_3'!I26 | AP30: ='Atest. Nr.2_1'!I26 | AQ30: ='Atest. Nr.2_2'!I26 | AR30: ='Atest. Nr.2_3'!I26 | AS30: =Examen!G26 | AT30: =ReExaminare!G26 | AU30: =IF(NOT(ISBLANK(B30)), IF(SUM(E30:S30,U30:AI30)<>0,SUM(E30:S30,U30:AI30),""), "") | AY30: =IF(NOT(ISBLANK(C30)), IF(COUNT(MAX(AVERAGE(AM30:AO30),0)),MAX(AM30:AO30),"n/p"), "") | AZ30: =IF(NOT(ISBLANK(C30)), IF(COUNT(MAX(AVERAGE(AP30:AR30),0)),MAX(AP30:AR30),"n/p"), "") | BA30: ='Ev. Curenta'!I26 | BB30: =IF(NOT(ISBLANK(C30)), IF('L. Indiv.'!G26<>"n/p",'L. Indiv.'!G26,"n/p"), "") | BC30: =IF(NOT(ISBLANK(C30)), IF(OR(AY30="n/p",AZ30="n/p",BA30="n/p",BB30="n/p",AY30<5,AZ30<5,BA30<5,BB30<5)," ",TRUNC(SUM(AY30:BB30)/4,2)), "") | BD30: =IF(NOT(ISBLANK(C30)), IF(BC30=" ","n/a", IF(AX30,AX30, IF(COUNT(MAX(AVERAGE(AS30:AT30),0)),MAX(AS30:AT30),"n/p"))), "") | BE30: =IF(NOT(ISBLANK(C30)), IF(OR(BD30="n/a",BD30="n/p")," ", IF(BD30<5,BD30,TRUNC(BC30*0.6+BD30*0.4,2))), "") | BF30: =IF(NOT(ISBLANK(C30)), IF(BE30=" "," ", IF(AND(BE30>=1,BE30<2),"(unu, "&ROUNDUP(MOD(BE30*100,100),0)&")", IF(AND(BE30>=2,BE30<3),"(doi, "&ROUNDUP(MOD(BE30*100,100),0)&")", IF(AND(BE30>=3,BE30<4),"(trei, "&ROUNDUP(MOD(BE30*100,100),0)&")", IF(AND(BE30>=4,BE30<5),"(patru, "&ROUNDUP(MOD(BE30*100,100),0)&")", IF(AND(BE30>=5,BE30<6),"(cinci, "&ROUNDUP(MOD(BE30*100,100),0)&")", IF(AND(BE30>=6,BE30<7),"(şase, "&ROUNDUP(MOD(BE30*100,100),0)&")", IF(AND(BE30>=7,BE30<8),"(şapte, "&ROUNDUP(MOD(BE30*100,100),0)&")", IF(AND(BE30>=8,BE30<9),"(opt, "&ROUNDUP(MOD(BE30*100,100),0)&")", IF(AND(BE30>=9,BE30<10),"(nouă, "&ROUNDUP(MOD(BE30*100,100),0)&")", IF(BE30=10,"(zece, 00)", ))))))))))),"") | BG30: =IF(NOT(ISBLANK(C30)), IF(BE30=" "," ", IF(AND(BE30>=1,BE30<=3),"F", IF(AND(BE30>3,BE30<5),"FX", IF(AND(BE30>=5,BE30<=6),"E", IF(AND(BE30>6,BE30<=7),"D", IF(AND(BE30>7,BE30<=8),"C", IF(AND(BE30>8,BE30<=9),"B", IF(AND(BE30>9,BE30<=10),"A", )))))))),"")
